Workbook

Sheet Bilgiler
A1: 📝 BİLGİLERİ DOLDURUNUZ
A2: Aşağıdaki bilgileri kendi okulunuza ve sınıfınıza göre doldurun. 'Ölçek' sayfasındaki başlıklar otomatik güncellenecek.
A4: Okul Adı
A5: Eğitim Öğretim Yılı
A6: Sınıf / Şube
A7: Dönem
A8: Ders | B8: Görsel Sanatlar
A9: Sınıf Öğretmeni
A10: Okul Müdürü

Sheet Öğrenci Listesi
A1: 📋 SİSTEMDEN ÖĞRENCİ LİSTESİNİ BURAYA YAPIŞTIRIN
A2: Sistemde notları işaretledikten sonra tüm tabloyu kopyalayın (Ctrl+C), aşağıdaki sarı alana yapıştırın (Ctrl+V).
A3: ✓ Öğrenci adları, numaraları ve seviyeler 'Ölçek' sayfasına otomatik aktarılacak.
A5: NO | B5: ADI SOYADI | C5: Geliştirilmeli | D5: Yeterli | E5: İyi | F5: Çok İyi | G5: SONUÇ | H5: (yok sayılır)

Sheet Ölçek
A1: =Bilgiler!B4&" • "&Bilgiler!B5&" EĞİTİM ÖĞRETİM YILI" -> • EĞİTİM ÖĞRETİM YILI
A2: =Bilgiler!B6&" SINIFI "&Bilgiler!B7&" "&Bilgiler!B8&" DERSİ KAZANIM DEĞERLENDİRME ÖLÇEĞİ" -> SINIFI Görsel Sanatlar DERSİ KAZANIM DEĞERLENDİRME ÖLÇEĞİ
A4: NO | B4: ADI VE SOYADI | C4: Görsel sanat çalışmasını oluştururken biçimlendirme basamaklarını kullanır | D4: Deneyimlerini farklı fikirler, sanat formları ve kültürel temalarla ilişkilendirerek görsel sanat çalışması oluşturur | E4: Görsel sanat çalışmasında kompozisyon birliğini oluşturmak için seçimler yapar | F4: İki boyutlu yüzey üzerinde derinlik etkisi oluşturur | G4: Gözleme dayalı çizimlerinde kontur çizgisini ve gölgeleme tekniklerini kullanır | H4: Farklı materyalleri kullanarak üç boyutlu çalışmalar yapar | I4: Görsel sanat çalışmalarını oluştururken sanat elemanları ve tasarım ilkelerini kullanır | J4: Sanatçı ve zanaatkârın rollerini söyler | K4: Türk kültürüne ve diğer kültürlere ait mimari yapıların belirgin özelliklerini karşılaştırır | L4: Farklı kültürlerde yapılmış sanat eserlerinin genel özelliklerini karşılaştırır | M4: Müzedeki farklı kültürlere ait sanat eserlerindeki ortak özellikleri söyler | N4: Görsel sanat alanındaki meslekleri söyler | O4: Soyut, gerçekçi ve figüratif sanat eserleri arasındaki farkları açıklar | P4: Bir sanat eserini seçmesindeki tercih sebebini açıklar | Q4: Estetik tercihlerin kişilere göre nasıl değiştiğini ifade eder | R4: Görsel sanat alanındaki etik kurallara uyar | S4: ORTALAMA | T4: SEVİYE
A5: =IFERROR(IF('Öğrenci Listesi'!A6="","",'Öğrenci Listesi'!A6),"") | B5: =IFERROR(IF('Öğrenci Listesi'!B6="","",'Öğrenci Listesi'!B6),"") | C5: =IF(OR('Öğrenci Listesi'!B6="",T5=""),"",IF(T5="Çok İyi",CHOOSE(RANDBETWEEN(1,5),4,4,4,4,3),IF(T5="İyi",CHOOSE(RANDBETWEEN(1,5),3,3,3,4,2),IF(T5="Yeterli",CHOOSE(RANDBETWEEN(1,5),2,2,2,3,1),IF(T5="Geliştirilmeli",CHOOSE(RANDBETWEEN(1,5),1,1,1,1,2),""))))) | D5: =IF(OR('Öğrenci Listesi'!B6="",T5=""),"",IF(T5="Çok İyi",CHOOSE(RANDBETWEEN(1,5),4,4,4,4,3),IF(T5="İyi",CHOOSE(RANDBETWEEN(1,5),3,3,3,4,2),IF(T5="Yeterli",CHOOSE(RANDBETWEEN(1,5),2,2,2,3,1),IF(T5="Geliştirilmeli",CHOOSE(RANDBETWEEN(1,5),1,1,1,1,2),""))))) | E5: =IF(OR('Öğrenci Listesi'!B6="",T5=""),"",IF(T5="Çok İyi",CHOOSE(RANDBETWEEN(1,5),4,4,4,4,3),IF(T5="İyi",CHOOSE(RANDBETWEEN(1,5),3,3,3,4,2),IF(T5="Yeterli",CHOOSE(RANDBETWEEN(1,5),2,2,2,3,1),IF(T5="Geliştirilmeli",CHOOSE(RANDBETWEEN(1,5),1,1,1,1,2),""))))) | F5: =IF(OR('Öğrenci Listesi'!B6="",T5=""),"",IF(T5="Çok İyi",CHOOSE(RANDBETWEEN(1,5),4,4,4,4,3),IF(T5="İyi",CHOOSE(RANDBETWEEN(1,5),3,3,3,4,2),IF(T5="Yeterli",CHOOSE(RANDBETWEEN(1,5),2,2,2,3,1),IF(T5="Geliştirilmeli",CHOOSE(RANDBETWEEN(1,5),1,1,1,1,2),""))))) | G5: =IF(OR('Öğrenci Listesi'!B6="",T5=""),"",IF(T5="Çok İyi",CHOOSE(RANDBETWEEN(1,5),4,4,4,4,3),IF(T5="İyi",CHOOSE(RANDBETWEEN(1,5),3,3,3,4,2),IF(T5="Yeterli",CHOOSE(RANDBETWEEN(1,5),2,2,2,3,1),IF(T5="Geliştirilmeli",CHOOSE(RANDBETWEEN(1,5),1,1,1,1,2),""))))) | H5: =IF(OR('Öğrenci Listesi'!B6="",T5=""),"",IF(T5="Çok İyi",CHOOSE(RANDBETWEEN(1,5),4,4,4,4,3),IF(T5="İyi",CHOOSE(RANDBETWEEN(1,5),3,3,3,4,2),IF(T5="Yeterli",CHOOSE(RANDBETWEEN(1,5),2,2,2,3,1),IF(T5="Geliştirilmeli",CHOOSE(RANDBETWEEN(1,5),1,1,1,1,2),""))))) | I5: =IF(OR('Öğrenci Listesi'!B6="",T5=""),"",IF(T5="Çok İyi",CHOOSE(RANDBETWEEN(1,5),4,4,4,4,3),IF(T5="İyi",CHOOSE(RANDBETWEEN(1,5),3,3,3,4,2),IF(T5="Yeterli",CHOOSE(RANDBETWEEN(1,5),2,2,2,3,1),IF(T5="Geliştirilmeli",CHOOSE(RANDBETWEEN(1,5),1,1,1,1,2),""))))) | J5: =IF(OR('Öğrenci Listesi'!B6="",T5=""),"",IF(T5="Çok İyi",CHOOSE(RANDBETWEEN(1,5),4,4,4,4,3),IF(T5="İyi",CHOOSE(RANDBETWEEN(1,5),3,3,3,4,2),IF(T5="Yeterli",CHOOSE(RANDBETWEEN(1,5),2,2,2,3,1),IF(T5="Geliştirilmeli",CHOOSE(RANDBETWEEN(1,5),1,1,1,1,2),""))))) | K5: =IF(OR('Öğrenci Listesi'!B6="",T5=""),"",IF(T5="Çok İyi",CHOOSE(RANDBETWEEN(1,5),4,4,4,4,3),IF(T5="İyi",CHOOSE(RANDBETWEEN(1,5),3,3,3,4,2),IF(T5="Yeterli",CHOOSE(RANDBETWEEN(1,5),2,2,2,3,1),IF(T5="Geliştirilmeli",CHOOSE(RANDBETWEEN(1,5),1,1,1,1,2),""))))) | L5: =IF(OR('Öğrenci Listesi'!B6="",T5=""),"",IF(T5="Çok İyi",CHOOSE(RANDBETWEEN(1,5),4,4,4,4,3),IF(T5="İyi",CHOOSE(RANDBETWEEN(1,5),3,3,3,4,2),IF(T5="Yeterli",CHOOSE(RANDBETWEEN(1,5),2,2,2,3,1),IF(T5="Geliştirilmeli",CHOOSE(RANDBETWEEN(1,5),1,1,1,1,2),""))))) | M5: =IF(OR('Öğrenci Listesi'!B6="",T5=""),"",IF(T5="Çok İyi",CHOOSE(RANDBETWEEN(1,5),4,4,4,4,3),IF(T5="İyi",CHOOSE(RANDBETWEEN(1,5),3,3,3,4,2),IF(T5="Yeterli",CHOOSE(RANDBETWEEN(1,5),2,2,2,3,1),IF(T5="Geliştirilmeli",CHOOSE(RANDBETWEEN(1,5),1,1,1,1,2),""))))) | N5: =IF(OR('Öğrenci Listesi'!B6="",T5=""),"",IF(T5="Çok İyi",CHOOSE(RANDBETWEEN(1,5),4,4,4,4,3),IF(T5="İyi",CHOOSE(RANDBETWEEN(1,5),3,3,3,4,2),IF(T5="Yeterli",CHOOSE(RANDBETWEEN(1,5),2,2,2,3,1),IF(T5="Geliştirilmeli",CHOOSE(RANDBETWEEN(1,5),1,1,1,1,2),""))))) | O5: =IF(OR('Öğrenci Listesi'!B6="",T5=""),"",IF(T5="Çok İyi",CHOOSE(RANDBETWEEN(1,5),4,4,4,4,3),IF(T5="İyi",CHOOSE(RANDBETWEEN(1,5),3,3,3,4,2),IF(T5="Yeterli",CHOOSE(RANDBETWEEN(1,5),2,2,2,3,1),IF(T5="Geliştirilmeli",CHOOSE(RANDBETWEEN(1,5),1,1,1,1,2),""))))) | P5: =IF(OR('Öğrenci Listesi'!B6="",T5=""),"",IF(T5="Çok İyi",CHOOSE(RANDBETWEEN(1,5),4,4,4,4,3),IF(T5="İyi",CHOOSE(RANDBETWEEN(1,5),3,3,3,4,2),IF(T5="Yeterli",CHOOSE(RANDBETWEEN(1,5),2,2,2,3,1),IF(T5="Geliştirilmeli",CHOOSE(RANDBETWEEN(1,5),1,1,1,1,2),""))))) | Q5: =IF(OR('Öğrenci Listesi'!B6="",T5=""),"",IF(T5="Çok İyi",CHOOSE(RANDBETWEEN(1,5),4,4,4,4,3),IF(T5="İyi",CHOOSE(RANDBETWEEN(1,5),3,3,3,4,2),IF(T5="Yeterli",CHOOSE(RANDBETWEEN(1,5),2,2,2,3,1),IF(T5="Geliştirilmeli",CHOOSE(RANDBETWEEN(1,5),1,1,1,1,2),""))))) | R5: =IF(OR('Öğrenci Listesi'!B6="",T5=""),"",IF(T5="Çok İyi",CHOOSE(RANDBETWEEN(1,5),4,4,4,4,3),IF(T5="İyi",CHOOSE(RANDBETWEEN(1,5),3,3,3,4,2),IF(T5="Yeterli",CHOOSE(RANDBETWEEN(1,5),2,2,2,3,1),IF(T5="Geliştirilmeli",CHOOSE(RANDBETWEEN(1,5),1,1,1,1,2),""))))) | S5: =IF(OR('Öğrenci Listesi'!B6="",T5=""),"",ROUND(AVERAGE(C5:R5),2)) | T5: =IFERROR(IF('Öğrenci Listesi'!G6="","",IF(UPPER(TRIM('Öğrenci Listesi'!G6))="ÇOK İYİ","Çok İyi",IF(UPPER(TRIM('Öğrenci Listesi'!G6))="İYİ","İyi",IF(UPPER(TRIM('Öğrenci Listesi'!G6))="YETERLİ","Yeterli",IF(UPPER(TRIM('Öğrenci Listesi'!G6))="GELİŞTİRİLMELİ","Geliştirilmeli",'Öğrenci Listesi'!G6))))),"")
A6: =IFERROR(IF('Öğrenci Listesi'!A7="","",'Öğrenci Listesi'!A7),"") | B6: =IFERROR(IF('Öğrenci Listesi'!B7="","",'Öğrenci Listesi'!B7),"") | C6: =IF(OR('Öğrenci Listesi'!B7="",T6=""),"",IF(T6="Çok İyi",CHOOSE(RANDBETWEEN(1,5),4,4,4,4,3),IF(T6="İyi",CHOOSE(RANDBETWEEN(1,5),3,3,3,4,2),IF(T6="Yeterli",CHOOSE(RANDBETWEEN(1,5),2,2,2,3,1),IF(T6="Geliştirilmeli",CHOOSE(RANDBETWEEN(1,5),1,1,1,1,2),""))))) | D6: =IF(OR('Öğrenci Listesi'!B7="",T6=""),"",IF(T6="Çok İyi",CHOOSE(RANDBETWEEN(1,5),4,4,4,4,3),IF(T6="İyi",CHOOSE(RANDBETWEEN(1,5),3,3,3,4,2),IF(T6="Yeterli",CHOOSE(RANDBETWEEN(1,5),2,2,2,3,1),IF(T6="Geliştirilmeli",CHOOSE(RANDBETWEEN(1,5),1,1,1,1,2),""))))) | E6: =IF(OR('Öğrenci Listesi'!B7="",T6=""),"",IF(T6="Çok İyi",CHOOSE(RANDBETWEEN(1,5),4,4,4,4,3),IF(T6="İyi",CHOOSE(RANDBETWEEN(1,5),3,3,3,4,2),IF(T6="Yeterli",CHOOSE(RANDBETWEEN(1,5),2,2,2,3,1),IF(T6="Geliştirilmeli",CHOOSE(RANDBETWEEN(1,5),1,1,1,1,2),""))))) | F6: =IF(OR('Öğrenci Listesi'!B7="",T6=""),"",IF(T6="Çok İyi",CHOOSE(RANDBETWEEN(1,5),4,4,4,4,3),IF(T6="İyi",CHOOSE(RANDBETWEEN(1,5),3,3,3,4,2),IF(T6="Yeterli",CHOOSE(RANDBETWEEN(1,5),2,2,2,3,1),IF(T6="Geliştirilmeli",CHOOSE(RANDBETWEEN(1,5),1,1,1,1,2),""))))) | G6: =IF(OR('Öğrenci Listesi'!B7="",T6=""),"",IF(T6="Çok İyi",CHOOSE(RANDBETWEEN(1,5),4,4,4,4,3),IF(T6="İyi",CHOOSE(RANDBETWEEN(1,5),3,3,3,4,2),IF(T6="Yeterli",CHOOSE(RANDBETWEEN(1,5),2,2,2,3,1),IF(T6="Geliştirilmeli",CHOOSE(RANDBETWEEN(1,5),1,1,1,1,2),""))))) | H6: =IF(OR('Öğrenci Listesi'!B7="",T6=""),"",IF(T6="Çok İyi",CHOOSE(RANDBETWEEN(1,5),4,4,4,4,3),IF(T6="İyi",CHOOSE(RANDBETWEEN(1,5),3,3,3,4,2),IF(T6="Yeterli",CHOOSE(RANDBETWEEN(1,5),2,2,2,3,1),IF(T6="Geliştirilmeli",CHOOSE(RANDBETWEEN(1,5),1,1,1,1,2),""))))) | I6: =IF(OR('Öğrenci Listesi'!B7="",T6=""),"",IF(T6="Çok İyi",CHOOSE(RANDBETWEEN(1,5),4,4,4,4,3),IF(T6="İyi",CHOOSE(RANDBETWEEN(1,5),3,3,3,4,2),IF(T6="Yeterli",CHOOSE(RANDBETWEEN(1,5),2,2,2,3,1),IF(T6="Geliştirilmeli",CHOOSE(RANDBETWEEN(1,5),1,1,1,1,2),""))))) | J6: =IF(OR('Öğrenci Listesi'!B7="",T6=""),"",IF(T6="Çok İyi",CHOOSE(RANDBETWEEN(1,5),4,4,4,4,3),IF(T6="İyi",CHOOSE(RANDBETWEEN(1,5),3,3,3,4,2),IF(T6="Yeterli",CHOOSE(RANDBETWEEN(1,5),2,2,2,3,1),IF(T6="Geliştirilmeli",CHOOSE(RANDBETWEEN(1,5),1,1,1,1,2),""))))) | K6: =IF(OR('Öğrenci Listesi'!B7="",T6=""),"",IF(T6="Çok İyi",CHOOSE(RANDBETWEEN(1,5),4,4,4,4,3),IF(T6="İyi",CHOOSE(RANDBETWEEN(1,5),3,3,3,4,2),IF(T6="Yeterli",CHOOSE(RANDBETWEEN(1,5),2,2,2,3,1),IF(T6="Geliştirilmeli",CHOOSE(RANDBETWEEN(1,5),1,1,1,1,2),""))))) | L6: =IF(OR('Öğrenci Listesi'!B7="",T6=""),"",IF(T6="Çok İyi",CHOOSE(RANDBETWEEN(1,5),4,4,4,4,3),IF(T6="İyi",CHOOSE(RANDBETWEEN(1,5),3,3,3,4,2),IF(T6="Yeterli",CHOOSE(RANDBETWEEN(1,5),2,2,2,3,1),IF(T6="Geliştirilmeli",CHOOSE(RANDBETWEEN(1,5),1,1,1,1,2),""))))) | M6: =IF(OR('Öğrenci Listesi'!B7="",T6=""),"",IF(T6="Çok İyi",CHOOSE(RANDBETWEEN(1,5),4,4,4,4,3),IF(T6="İyi",CHOOSE(RANDBETWEEN(1,5),3,3,3,4,2),IF(T6="Yeterli",CHOOSE(RANDBETWEEN(1,5),2,2,2,3,1),IF(T6="Geliştirilmeli",CHOOSE(RANDBETWEEN(1,5),1,1,1,1,2),""))))) | N6: =IF(OR('Öğrenci Listesi'!B7="",T6=""),"",IF(T6="Çok İyi",CHOOSE(RANDBETWEEN(1,5),4,4,4,4,3),IF(T6="İyi",CHOOSE(RANDBETWEEN(1,5),3,3,3,4,2),IF(T6="Yeterli",CHOOSE(RANDBETWEEN(1,5),2,2,2,3,1),IF(T6="Geliştirilmeli",CHOOSE(RANDBETWEEN(1,5),1,1,1,1,2),""))))) | O6: =IF(OR('Öğrenci Listesi'!B7="",T6=""),"",IF(T6="Çok İyi",CHOOSE(RANDBETWEEN(1,5),4,4,4,4,3),IF(T6="İyi",CHOOSE(RANDBETWEEN(1,5),3,3,3,4,2),IF(T6="Yeterli",CHOOSE(RANDBETWEEN(1,5),2,2,2,3,1),IF(T6="Geliştirilmeli",CHOOSE(RANDBETWEEN(1,5),1,1,1,1,2),""))))) | P6: =IF(OR('Öğrenci Listesi'!B7="",T6=""),"",IF(T6="Çok İyi",CHOOSE(RANDBETWEEN(1,5),4,4,4,4,3),IF(T6="İyi",CHOOSE(RANDBETWEEN(1,5),3,3,3,4,2),IF(T6="Yeterli",CHOOSE(RANDBETWEEN(1,5),2,2,2,3,1),IF(T6="Geliştirilmeli",CHOOSE(RANDBETWEEN(1,5),1,1,1,1,2),""))))) | Q6: =IF(OR('Öğrenci Listesi'!B7="",T6=""),"",IF(T6="Çok İyi",CHOOSE(RANDBETWEEN(1,5),4,4,4,4,3),IF(T6="İyi",CHOOSE(RANDBETWEEN(1,5),3,3,3,4,2),IF(T6="Yeterli",CHOOSE(RANDBETWEEN(1,5),2,2,2,3,1),IF(T6="Geliştirilmeli",CHOOSE(RANDBETWEEN(1,5),1,1,1,1,2),""))))) | R6: =IF(OR('Öğrenci Listesi'!B7="",T6=""),"",IF(T6="Çok İyi",CHOOSE(RANDBETWEEN(1,5),4,4,4,4,3),IF(T6="İyi",CHOOSE(RANDBETWEEN(1,5),3,3,3,4,2),IF(T6="Yeterli",CHOOSE(RANDBETWEEN(1,5),2,2,2,3,1),IF(T6="Geliştirilmeli",CHOOSE(RANDBETWEEN(1,5),1,1,1,1,2),""))))) | S6: =IF(OR('Öğrenci Listesi'!B7="",T6=""),"",ROUND(AVERAGE(C6:R6),2)) | T6: =IFERROR(IF('Öğrenci Listesi'!G7="","",IF(UPPER(TRIM('Öğrenci Listesi'!G7))="ÇOK İYİ","Çok İyi",IF(UPPER(TRIM('Öğrenci Listesi'!G7))="İYİ","İyi",IF(UPPER(TRIM('Öğrenci Listesi'!G7))="YETERLİ","Yeterli",IF(UPPER(TRIM('Öğrenci Listesi'!G7))="GELİŞTİRİLMELİ","Geliştirilmeli",'Öğrenci Listesi'!G7))))),"")
A7: =IFERROR(IF('Öğrenci Listesi'!A8="","",'Öğrenci Listesi'!A8),"") | B7: =IFERROR(IF('Öğrenci Listesi'!B8="","",'Öğrenci Listesi'!B8),"") | C7: =IF(OR('Öğrenci Listesi'!B8="",T7=""),"",IF(T7="Çok İyi",CHOOSE(RANDBETWEEN(1,5),4,4,4,4,3),IF(T7="İyi",CHOOSE(RANDBETWEEN(1,5),3,3,3,4,2),IF(T7="Yeterli",CHOOSE(RANDBETWEEN(1,5),2,2,2,3,1),IF(T7="Geliştirilmeli",CHOOSE(RANDBETWEEN(1,5),1,1,1,1,2),""))))) | D7: =IF(OR('Öğrenci Listesi'!B8="",T7=""),"",IF(T7="Çok İyi",CHOOSE(RANDBETWEEN(1,5),4,4,4,4,3),IF(T7="İyi",CHOOSE(RANDBETWEEN(1,5),3,3,3,4,2),IF(T7="Yeterli",CHOOSE(RANDBETWEEN(1,5),2,2,2,3,1),IF(T7="Geliştirilmeli",CHOOSE(RANDBETWEEN(1,5),1,1,1,1,2),""))))) | E7: =IF(OR('Öğrenci Listesi'!B8="",T7=""),"",IF(T7="Çok İyi",CHOOSE(RANDBETWEEN(1,5),4,4,4,4,3),IF(T7="İyi",CHOOSE(RANDBETWEEN(1,5),3,3,3,4,2),IF(T7="Yeterli",CHOOSE(RANDBETWEEN(1,5),2,2,2,3,1),IF(T7="Geliştirilmeli",CHOOSE(RANDBETWEEN(1,5),1,1,1,1,2),""))))) | F7: =IF(OR('Öğrenci Listesi'!B8="",T7=""),"",IF(T7="Çok İyi",CHOOSE(RANDBETWEEN(1,5),4,4,4,4,3),IF(T7="İyi",CHOOSE(RANDBETWEEN(1,5),3,3,3,4,2),IF(T7="Yeterli",CHOOSE(RANDBETWEEN(1,5),2,2,2,3,1),IF(T7="Geliştirilmeli",CHOOSE(RANDBETWEEN(1,5),1,1,1,1,2),""))))) | G7: =IF(OR('Öğrenci Listesi'!B8="",T7=""),"",IF(T7="Çok İyi",CHOOSE(RANDBETWEEN(1,5),4,4,4,4,3),IF(T7="İyi",CHOOSE(RANDBETWEEN(1,5),3,3,3,4,2),IF(T7="Yeterli",CHOOSE(RANDBETWEEN(1,5),2,2,2,3,1),IF(T7="Geliştirilmeli",CHOOSE(RANDBETWEEN(1,5),1,1,1,1,2),""))))) | H7: =IF(OR('Öğrenci Listesi'!B8="",T7=""),"",IF(T7="Çok İyi",CHOOSE(RANDBETWEEN(1,5),4,4,4,4,3),IF(T7="İyi",CHOOSE(RANDBETWEEN(1,5),3,3,3,4,2),IF(T7="Yeterli",CHOOSE(RANDBETWEEN(1,5),2,2,2,3,1),IF(T7="Geliştirilmeli",CHOOSE(RANDBETWEEN(1,5),1,1,1,1,2),""))))) | I7: =IF(OR('Öğrenci Listesi'!B8="",T7=""),"",IF(T7="Çok İyi",CHOOSE(RANDBETWEEN(1,5),4,4,4,4,3),IF(T7="İyi",CHOOSE(RANDBETWEEN(1,5),3,3,3,4,2),IF(T7="Yeterli",CHOOSE(RANDBETWEEN(1,5),2,2,2,3,1),IF(T7="Geliştirilmeli",CHOOSE(RANDBETWEEN(1,5),1,1,1,1,2),""))))) | J7: =IF(OR('Öğrenci Listesi'!B8="",T7=""),"",IF(T7="Çok İyi",CHOOSE(RANDBETWEEN(1,5),4,4,4,4,3),IF(T7="İyi",CHOOSE(RANDBETWEEN(1,5),3,3,3,4,2),IF(T7="Yeterli",CHOOSE(RANDBETWEEN(1,5),2,2,2,3,1),IF(T7="Geliştirilmeli",CHOOSE(RANDBETWEEN(1,5),1,1,1,1,2),""))))) | K7: =IF(OR('Öğrenci Listesi'!B8="",T7=""),"",IF(T7="Çok İyi",CHOOSE(RANDBETWEEN(1,5),4,4,4,4,3),IF(T7="İyi",CHOOSE(RANDBETWEEN(1,5),3,3,3,4,2),IF(T7="Yeterli",CHOOSE(RANDBETWEEN(1,5),2,2,2,3,1),IF(T7="Geliştirilmeli",CHOOSE(RANDBETWEEN(1,5),1,1,1,1,2),""))))) | L7: =IF(OR('Öğrenci Listesi'!B8="",T7=""),"",IF(T7="Çok İyi",CHOOSE(RANDBETWEEN(1,5),4,4,4,4,3),IF(T7="İyi",CHOOSE(RANDBETWEEN(1,5),3,3,3,4,2),IF(T7="Yeterli",CHOOSE(RANDBETWEEN(1,5),2,2,2,3,1),IF(T7="Geliştirilmeli",CHOOSE(RANDBETWEEN(1,5),1,1,1,1,2),""))))) | M7: =IF(OR('Öğrenci Listesi'!B8="",T7=""),"",IF(T7="Çok İyi",CHOOSE(RANDBETWEEN(1,5),4,4,4,4,3),IF(T7="İyi",CHOOSE(RANDBETWEEN(1,5),3,3,3,4,2),IF(T7="Yeterli",CHOOSE(RANDBETWEEN(1,5),2,2,2,3,1),IF(T7="Geliştirilmeli",CHOOSE(RANDBETWEEN(1,5),1,1,1,1,2),""))))) | N7: =IF(OR('Öğrenci Listesi'!B8="",T7=""),"",IF(T7="Çok İyi",CHOOSE(RANDBETWEEN(1,5),4,4,4,4,3),IF(T7="İyi",CHOOSE(RANDBETWEEN(1,5),3,3,3,4,2),IF(T7="Yeterli",CHOOSE(RANDBETWEEN(1,5),2,2,2,3,1),IF(T7="Geliştirilmeli",CHOOSE(RANDBETWEEN(1,5),1,1,1,1,2),""))))) | O7: =IF(OR('Öğrenci Listesi'!B8="",T7=""),"",IF(T7="Çok İyi",CHOOSE(RANDBETWEEN(1,5),4,4,4,4,3),IF(T7="İyi",CHOOSE(RANDBETWEEN(1,5),3,3,3,4,2),IF(T7="Yeterli",CHOOSE(RANDBETWEEN(1,5),2,2,2,3,1),IF(T7="Geliştirilmeli",CHOOSE(RANDBETWEEN(1,5),1,1,1,1,2),""))))) | P7: =IF(OR('Öğrenci Listesi'!B8="",T7=""),"",IF(T7="Çok İyi",CHOOSE(RANDBETWEEN(1,5),4,4,4,4,3),IF(T7="İyi",CHOOSE(RANDBETWEEN(1,5),3,3,3,4,2),IF(T7="Yeterli",CHOOSE(RANDBETWEEN(1,5),2,2,2,3,1),IF(T7="Geliştirilmeli",CHOOSE(RANDBETWEEN(1,5),1,1,1,1,2),""))))) | Q7: =IF(OR('Öğrenci Listesi'!B8="",T7=""),"",IF(T7="Çok İyi",CHOOSE(RANDBETWEEN(1,5),4,4,4,4,3),IF(T7="İyi",CHOOSE(RANDBETWEEN(1,5),3,3,3,4,2),IF(T7="Yeterli",CHOOSE(RANDBETWEEN(1,5),2,2,2,3,1),IF(T7="Geliştirilmeli",CHOOSE(RANDBETWEEN(1,5),1,1,1,1,2),""))))) | R7: =IF(OR('Öğrenci Listesi'!B8="",T7=""),"",IF(T7="Çok İyi",CHOOSE(RANDBETWEEN(1,5),4,4,4,4,3),IF(T7="İyi",CHOOSE(RANDBETWEEN(1,5),3,3,3,4,2),IF(T7="Yeterli",CHOOSE(RANDBETWEEN(1,5),2,2,2,3,1),IF(T7="Geliştirilmeli",CHOOSE(RANDBETWEEN(1,5),1,1,1,1,2),""))))) | S7: =IF(OR('Öğrenci Listesi'!B8="",T7=""),"",ROUND(AVERAGE(C7:R7),2)) | T7: =IFERROR(IF('Öğrenci Listesi'!G8="","",IF(UPPER(TRIM('Öğrenci Listesi'!G8))="ÇOK İYİ","Çok İyi",IF(UPPER(TRIM('Öğrenci Listesi'!G8))="İYİ","İyi",IF(UPPER(TRIM('Öğrenci Listesi'!G8))="YETERLİ","Yeterli",IF(UPPER(TRIM('Öğrenci Listesi'!G8))="GELİŞTİRİLMELİ","Geliştirilmeli",'Öğrenci Listesi'!G8))))),"")
A8: =IFERROR(IF('Öğrenci Listesi'!A9="","",'Öğrenci Listesi'!A9),"") | B8: =IFERROR(IF('Öğrenci Listesi'!B9="","",'Öğrenci Listesi'!B9),"") | C8: =IF(OR('Öğrenci Listesi'!B9="",T8=""),"",IF(T8="Çok İyi",CHOOSE(RANDBETWEEN(1,5),4,4,4,4,3),IF(T8="İyi",CHOOSE(RANDBETWEEN(1,5),3,3,3,4,2),IF(T8="Yeterli",CHOOSE(RANDBETWEEN(1,5),2,2,2,3,1),IF(T8="Geliştirilmeli",CHOOSE(RANDBETWEEN(1,5),1,1,1,1,2),""))))) | D8: =IF(OR('Öğrenci Listesi'!B9="",T8=""),"",IF(T8="Çok İyi",CHOOSE(RANDBETWEEN(1,5),4,4,4,4,3),IF(T8="İyi",CHOOSE(RANDBETWEEN(1,5),3,3,3,4,2),IF(T8="Yeterli",CHOOSE(RANDBETWEEN(1,5),2,2,2,3,1),IF(T8="Geliştirilmeli",CHOOSE(RANDBETWEEN(1,5),1,1,1,1,2),""))))) | E8: =IF(OR('Öğrenci Listesi'!B9="",T8=""),"",IF(T8="Çok İyi",CHOOSE(RANDBETWEEN(1,5),4,4,4,4,3),IF(T8="İyi",CHOOSE(RANDBETWEEN(1,5),3,3,3,4,2),IF(T8="Yeterli",CHOOSE(RANDBETWEEN(1,5),2,2,2,3,1),IF(T8="Geliştirilmeli",CHOOSE(RANDBETWEEN(1,5),1,1,1,1,2),""))))) | F8: =IF(OR('Öğrenci Listesi'!B9="",T8=""),"",IF(T8="Çok İyi",CHOOSE(RANDBETWEEN(1,5),4,4,4,4,3),IF(T8="İyi",CHOOSE(RANDBETWEEN(1,5),3,3,3,4,2),IF(T8="Yeterli",CHOOSE(RANDBETWEEN(1,5),2,2,2,3,1),IF(T8="Geliştirilmeli",CHOOSE(RANDBETWEEN(1,5),1,1,1,1,2),""))))) | G8: =IF(OR('Öğrenci Listesi'!B9="",T8=""),"",IF(T8="Çok İyi",CHOOSE(RANDBETWEEN(1,5),4,4,4,4,3),IF(T8="İyi",CHOOSE(RANDBETWEEN(1,5),3,3,3,4,2),IF(T8="Yeterli",CHOOSE(RANDBETWEEN(1,5),2,2,2,3,1),IF(T8="Geliştirilmeli",CHOOSE(RANDBETWEEN(1,5),1,1,1,1,2),""))))) | H8: =IF(OR('Öğrenci Listesi'!B9="",T8=""),"",IF(T8="Çok İyi",CHOOSE(RANDBETWEEN(1,5),4,4,4,4,3),IF(T8="İyi",CHOOSE(RANDBETWEEN(1,5),3,3,3,4,2),IF(T8="Yeterli",CHOOSE(RANDBETWEEN(1,5),2,2,2,3,1),IF(T8="Geliştirilmeli",CHOOSE(RANDBETWEEN(1,5),1,1,1,1,2),""))))) | I8: =IF(OR('Öğrenci Listesi'!B9="",T8=""),"",IF(T8="Çok İyi",CHOOSE(RANDBETWEEN(1,5),4,4,4,4,3),IF(T8="İyi",CHOOSE(RANDBETWEEN(1,5),3,3,3,4,2),IF(T8="Yeterli",CHOOSE(RANDBETWEEN(1,5),2,2,2,3,1),IF(T8="Geliştirilmeli",CHOOSE(RANDBETWEEN(1,5),1,1,1,1,2),""))))) | J8: =IF(OR('Öğrenci Listesi'!B9="",T8=""),"",IF(T8="Çok İyi",CHOOSE(RANDBETWEEN(1,5),4,4,4,4,3),IF(T8="İyi",CHOOSE(RANDBETWEEN(1,5),3,3,3,4,2),IF(T8="Yeterli",CHOOSE(RANDBETWEEN(1,5),2,2,2,3,1),IF(T8="Geliştirilmeli",CHOOSE(RANDBETWEEN(1,5),1,1,1,1,2),""))))) | K8: =IF(OR('Öğrenci Listesi'!B9="",T8=""),"",IF(T8="Çok İyi",CHOOSE(RANDBETWEEN(1,5),4,4,4,4,3),IF(T8="İyi",CHOOSE(RANDBETWEEN(1,5),3,3,3,4,2),IF(T8="Yeterli",CHOOSE(RANDBETWEEN(1,5),2,2,2,3,1),IF(T8="Geliştirilmeli",CHOOSE(RANDBETWEEN(1,5),1,1,1,1,2),""))))) | L8: =IF(OR('Öğrenci Listesi'!B9="",T8=""),"",IF(T8="Çok İyi",CHOOSE(RANDBETWEEN(1,5),4,4,4,4,3),IF(T8="İyi",CHOOSE(RANDBETWEEN(1,5),3,3,3,4,2),IF(T8="Yeterli",CHOOSE(RANDBETWEEN(1,5),2,2,2,3,1),IF(T8="Geliştirilmeli",CHOOSE(RANDBETWEEN(1,5),1,1,1,1,2),""))))) | M8: =IF(OR('Öğrenci Listesi'!B9="",T8=""),"",IF(T8="Çok İyi",CHOOSE(RANDBETWEEN(1,5),4,4,4,4,3),IF(T8="İyi",CHOOSE(RANDBETWEEN(1,5),3,3,3,4,2),IF(T8="Yeterli",CHOOSE(RANDBETWEEN(1,5),2,2,2,3,1),IF(T8="Geliştirilmeli",CHOOSE(RANDBETWEEN(1,5),1,1,1,1,2),""))))) | N8: =IF(OR('Öğrenci Listesi'!B9="",T8=""),"",IF(T8="Çok İyi",CHOOSE(RANDBETWEEN(1,5),4,4,4,4,3),IF(T8="İyi",CHOOSE(RANDBETWEEN(1,5),3,3,3,4,2),IF(T8="Yeterli",CHOOSE(RANDBETWEEN(1,5),2,2,2,3,1),IF(T8="Geliştirilmeli",CHOOSE(RANDBETWEEN(1,5),1,1,1,1,2),""))))) | O8: =IF(OR('Öğrenci Listesi'!B9="",T8=""),"",IF(T8="Çok İyi",CHOOSE(RANDBETWEEN(1,5),4,4,4,4,3),IF(T8="İyi",CHOOSE(RANDBETWEEN(1,5),3,3,3,4,2),IF(T8="Yeterli",CHOOSE(RANDBETWEEN(1,5),2,2,2,3,1),IF(T8="Geliştirilmeli",CHOOSE(RANDBETWEEN(1,5),1,1,1,1,2),""))))) | P8: =IF(OR('Öğrenci Listesi'!B9="",T8=""),"",IF(T8="Çok İyi",CHOOSE(RANDBETWEEN(1,5),4,4,4,4,3),IF(T8="İyi",CHOOSE(RANDBETWEEN(1,5),3,3,3,4,2),IF(T8="Yeterli",CHOOSE(RANDBETWEEN(1,5),2,2,2,3,1),IF(T8="Geliştirilmeli",CHOOSE(RANDBETWEEN(1,5),1,1,1,1,2),""))))) | Q8: =IF(OR('Öğrenci Listesi'!B9="",T8=""),"",IF(T8="Çok İyi",CHOOSE(RANDBETWEEN(1,5),4,4,4,4,3),IF(T8="İyi",CHOOSE(RANDBETWEEN(1,5),3,3,3,4,2),IF(T8="Yeterli",CHOOSE(RANDBETWEEN(1,5),2,2,2,3,1),IF(T8="Geliştirilmeli",CHOOSE(RANDBETWEEN(1,5),1,1,1,1,2),""))))) | R8: =IF(OR('Öğrenci Listesi'!B9="",T8=""),"",IF(T8="Çok İyi",CHOOSE(RANDBETWEEN(1,5),4,4,4,4,3),IF(T8="İyi",CHOOSE(RANDBETWEEN(1,5),3,3,3,4,2),IF(T8="Yeterli",CHOOSE(RANDBETWEEN(1,5),2,2,2,3,1),IF(T8="Geliştirilmeli",CHOOSE(RANDBETWEEN(1,5),1,1,1,1,2),""))))) | S8: =IF(OR('Öğrenci Listesi'!B9="",T8=""),"",ROUND(AVERAGE(C8:R8),2)) | T8: =IFERROR(IF('Öğrenci Listesi'!G9="","",IF(UPPER(TRIM('Öğrenci Listesi'!G9))="ÇOK İYİ","Çok İyi",IF(UPPER(TRIM('Öğrenci Listesi'!G9))="İYİ","İyi",IF(UPPER(TRIM('Öğrenci Listesi'!G9))="YETERLİ","Yeterli",IF(UPPER(TRIM('Öğrenci Listesi'!G9))="GELİŞTİRİLMELİ","Geliştirilmeli",'Öğrenci Listesi'!G9))))),"")
A9: =IFERROR(IF('Öğrenci Listesi'!A10="","",'Öğrenci Listesi'!A10),"") | B9: =IFERROR(IF('Öğrenci Listesi'!B10="","",'Öğrenci Listesi'!B10),"") | C9: =IF(OR('Öğrenci Listesi'!B10="",T9=""),"",IF(T9="Çok İyi",CHOOSE(RANDBETWEEN(1,5),4,4,4,4,3),IF(T9="İyi",CHOOSE(RANDBETWEEN(1,5),3,3,3,4,2),IF(T9="Yeterli",CHOOSE(RANDBETWEEN(1,5),2,2,2,3,1),IF(T9="Geliştirilmeli",CHOOSE(RANDBETWEEN(1,5),1,1,1,1,2),""))))) | D9: =IF(OR('Öğrenci Listesi'!B10="",T9=""),"",IF(T9="Çok İyi",CHOOSE(RANDBETWEEN(1,5),4,4,4,4,3),IF(T9="İyi",CHOOSE(RANDBETWEEN(1,5),3,3,3,4,2),IF(T9="Yeterli",CHOOSE(RANDBETWEEN(1,5),2,2,2,3,1),IF(T9="Geliştirilmeli",CHOOSE(RANDBETWEEN(1,5),1,1,1,1,2),""))))) | E9: =IF(OR('Öğrenci Listesi'!B10="",T9=""),"",IF(T9="Çok İyi",CHOOSE(RANDBETWEEN(1,5),4,4,4,4,3),IF(T9="İyi",CHOOSE(RANDBETWEEN(1,5),3,3,3,4,2),IF(T9="Yeterli",CHOOSE(RANDBETWEEN(1,5),2,2,2,3,1),IF(T9="Geliştirilmeli",CHOOSE(RANDBETWEEN(1,5),1,1,1,1,2),""))))) | F9: =IF(OR('Öğrenci Listesi'!B10="",T9=""),"",IF(T9="Çok İyi",CHOOSE(RANDBETWEEN(1,5),4,4,4,4,3),IF(T9="İyi",CHOOSE(RANDBETWEEN(1,5),3,3,3,4,2),IF(T9="Yeterli",CHOOSE(RANDBETWEEN(1,5),2,2,2,3,1),IF(T9="Geliştirilmeli",CHOOSE(RANDBETWEEN(1,5),1,1,1,1,2),""))))) | G9: =IF(OR('Öğrenci Listesi'!B10="",T9=""),"",IF(T9="Çok İyi",CHOOSE(RANDBETWEEN(1,5),4,4,4,4,3),IF(T9="İyi",CHOOSE(RANDBETWEEN(1,5),3,3,3,4,2),IF(T9="Yeterli",CHOOSE(RANDBETWEEN(1,5),2,2,2,3,1),IF(T9="Geliştirilmeli",CHOOSE(RANDBETWEEN(1,5),1,1,1,1,2),""))))) | H9: =IF(OR('Öğrenci Listesi'!B10="",T9=""),"",IF(T9="Çok İyi",CHOOSE(RANDBETWEEN(1,5),4,4,4,4,3),IF(T9="İyi",CHOOSE(RANDBETWEEN(1,5),3,3,3,4,2),IF(T9="Yeterli",CHOOSE(RANDBETWEEN(1,5),2,2,2,3,1),IF(T9="Geliştirilmeli",CHOOSE(RANDBETWEEN(1,5),1,1,1,1,2),""))))) | I9: =IF(OR('Öğrenci Listesi'!B10="",T9=""),"",IF(T9="Çok İyi",CHOOSE(RANDBETWEEN(1,5),4,4,4,4,3),IF(T9="İyi",CHOOSE(RANDBETWEEN(1,5),3,3,3,4,2),IF(T9="Yeterli",CHOOSE(RANDBETWEEN(1,5),2,2,2,3,1),IF(T9="Geliştirilmeli",CHOOSE(RANDBETWEEN(1,5),1,1,1,1,2),""))))) | J9: =IF(OR('Öğrenci Listesi'!B10="",T9=""),"",IF(T9="Çok İyi",CHOOSE(RANDBETWEEN(1,5),4,4,4,4,3),IF(T9="İyi",CHOOSE(RANDBETWEEN(1,5),3,3,3,4,2),IF(T9="Yeterli",CHOOSE(RANDBETWEEN(1,5),2,2,2,3,1),IF(T9="Geliştirilmeli",CHOOSE(RANDBETWEEN(1,5),1,1,1,1,2),""))))) | K9: =IF(OR('Öğrenci Listesi'!B10="",T9=""),"",IF(T9="Çok İyi",CHOOSE(RANDBETWEEN(1,5),4,4,4,4,3),IF(T9="İyi",CHOOSE(RANDBETWEEN(1,5),3,3,3,4,2),IF(T9="Yeterli",CHOOSE(RANDBETWEEN(1,5),2,2,2,3,1),IF(T9="Geliştirilmeli",CHOOSE(RANDBETWEEN(1,5),1,1,1,1,2),""))))) | L9: =IF(OR('Öğrenci Listesi'!B10="",T9=""),"",IF(T9="Çok İyi",CHOOSE(RANDBETWEEN(1,5),4,4,4,4,3),IF(T9="İyi",CHOOSE(RANDBETWEEN(1,5),3,3,3,4,2),IF(T9="Yeterli",CHOOSE(RANDBETWEEN(1,5),2,2,2,3,1),IF(T9="Geliştirilmeli",CHOOSE(RANDBETWEEN(1,5),1,1,1,1,2),""))))) | M9: =IF(OR('Öğrenci Listesi'!B10="",T9=""),"",IF(T9="Çok İyi",CHOOSE(RANDBETWEEN(1,5),4,4,4,4,3),IF(T9="İyi",CHOOSE(RANDBETWEEN(1,5),3,3,3,4,2),IF(T9="Yeterli",CHOOSE(RANDBETWEEN(1,5),2,2,2,3,1),IF(T9="Geliştirilmeli",CHOOSE(RANDBETWEEN(1,5),1,1,1,1,2),""))))) | N9: =IF(OR('Öğrenci Listesi'!B10="",T9=""),"",IF(T9="Çok İyi",CHOOSE(RANDBETWEEN(1,5),4,4,4,4,3),IF(T9="İyi",CHOOSE(RANDBETWEEN(1,5),3,3,3,4,2),IF(T9="Yeterli",CHOOSE(RANDBETWEEN(1,5),2,2,2,3,1),IF(T9="Geliştirilmeli",CHOOSE(RANDBETWEEN(1,5),1,1,1,1,2),""))))) | O9: =IF(OR('Öğrenci Listesi'!B10="",T9=""),"",IF(T9="Çok İyi",CHOOSE(RANDBETWEEN(1,5),4,4,4,4,3),IF(T9="İyi",CHOOSE(RANDBETWEEN(1,5),3,3,3,4,2),IF(T9="Yeterli",CHOOSE(RANDBETWEEN(1,5),2,2,2,3,1),IF(T9="Geliştirilmeli",CHOOSE(RANDBETWEEN(1,5),1,1,1,1,2),""))))) | P9: =IF(OR('Öğrenci Listesi'!B10="",T9=""),"",IF(T9="Çok İyi",CHOOSE(RANDBETWEEN(1,5),4,4,4,4,3),IF(T9="İyi",CHOOSE(RANDBETWEEN(1,5),3,3,3,4,2),IF(T9="Yeterli",CHOOSE(RANDBETWEEN(1,5),2,2,2,3,1),IF(T9="Geliştirilmeli",CHOOSE(RANDBETWEEN(1,5),1,1,1,1,2),""))))) | Q9: =IF(OR('Öğrenci Listesi'!B10="",T9=""),"",IF(T9="Çok İyi",CHOOSE(RANDBETWEEN(1,5),4,4,4,4,3),IF(T9="İyi",CHOOSE(RANDBETWEEN(1,5),3,3,3,4,2),IF(T9="Yeterli",CHOOSE(RANDBETWEEN(1,5),2,2,2,3,1),IF(T9="Geliştirilmeli",CHOOSE(RANDBETWEEN(1,5),1,1,1,1,2),""))))) | R9: =IF(OR('Öğrenci Listesi'!B10="",T9=""),"",IF(T9="Çok İyi",CHOOSE(RANDBETWEEN(1,5),4,4,4,4,3),IF(T9="İyi",CHOOSE(RANDBETWEEN(1,5),3,3,3,4,2),IF(T9="Yeterli",CHOOSE(RANDBETWEEN(1,5),2,2,2,3,1),IF(T9="Geliştirilmeli",CHOOSE(RANDBETWEEN(1,5),1,1,1,1,2),""))))) | S9: =IF(OR('Öğrenci Listesi'!B10="",T9=""),"",ROUND(AVERAGE(C9:R9),2)) | T9: =IFERROR(IF('Öğrenci Listesi'!G10="","",IF(UPPER(TRIM('Öğrenci Listesi'!G10))="ÇOK İYİ","Çok İyi",IF(UPPER(TRIM('Öğrenci Listesi'!G10))="İYİ","İyi",IF(UPPER(TRIM('Öğrenci Listesi'!G10))="YETERLİ","Yeterli",IF(UPPER(TRIM('Öğrenci Listesi'!G10))="GELİŞTİRİLMELİ","Geliştirilmeli",'Öğrenci Listesi'!G10))))),"")
A10: =IFERROR(IF('Öğrenci Listesi'!A11="","",'Öğrenci Listesi'!A11),"") | B10: =IFERROR(IF('Öğrenci Listesi'!B11="","",'Öğrenci Listesi'!B11),"") | C10: =IF(OR('Öğrenci Listesi'!B11="",T10=""),"",IF(T10="Çok İyi",CHOOSE(RANDBETWEEN(1,5),4,4,4,4,3),IF(T10="İyi",CHOOSE(RANDBETWEEN(1,5),3,3,3,4,2),IF(T10="Yeterli",CHOOSE(RANDBETWEEN(1,5),2,2,2,3,1),IF(T10="Geliştirilmeli",CHOOSE(RANDBETWEEN(1,5),1,1,1,1,2),""))))) | D10: =IF(OR('Öğrenci Listesi'!B11="",T10=""),"",IF(T10="Çok İyi",CHOOSE(RANDBETWEEN(1,5),4,4,4,4,3),IF(T10="İyi",CHOOSE(RANDBETWEEN(1,5),3,3,3,4,2),IF(T10="Yeterli",CHOOSE(RANDBETWEEN(1,5),2,2,2,3,1),IF(T10="Geliştirilmeli",CHOOSE(RANDBETWEEN(1,5),1,1,1,1,2),""))))) | E10: =IF(OR('Öğrenci Listesi'!B11="",T10=""),"",IF(T10="Çok İyi",CHOOSE(RANDBETWEEN(1,5),4,4,4,4,3),IF(T10="İyi",CHOOSE(RANDBETWEEN(1,5),3,3,3,4,2),IF(T10="Yeterli",CHOOSE(RANDBETWEEN(1,5),2,2,2,3,1),IF(T10="Geliştirilmeli",CHOOSE(RANDBETWEEN(1,5),1,1,1,1,2),""))))) | F10: =IF(OR('Öğrenci Listesi'!B11="",T10=""),"",IF(T10="Çok İyi",CHOOSE(RANDBETWEEN(1,5),4,4,4,4,3),IF(T10="İyi",CHOOSE(RANDBETWEEN(1,5),3,3,3,4,2),IF(T10="Yeterli",CHOOSE(RANDBETWEEN(1,5),2,2,2,3,1),IF(T10="Geliştirilmeli",CHOOSE(RANDBETWEEN(1,5),1,1,1,1,2),""))))) | G10: =IF(OR('Öğrenci Listesi'!B11="",T10=""),"",IF(T10="Çok İyi",CHOOSE(RANDBETWEEN(1,5),4,4,4,4,3),IF(T10="İyi",CHOOSE(RANDBETWEEN(1,5),3,3,3,4,2),IF(T10="Yeterli",CHOOSE(RANDBETWEEN(1,5),2,2,2,3,1),IF(T10="Geliştirilmeli",CHOOSE(RANDBETWEEN(1,5),1,1,1,1,2),""))))) | H10: =IF(OR('Öğrenci Listesi'!B11="",T10=""),"",IF(T10="Çok İyi",CHOOSE(RANDBETWEEN(1,5),4,4,4,4,3),IF(T10="İyi",CHOOSE(RANDBETWEEN(1,5),3,3,3,4,2),IF(T10="Yeterli",CHOOSE(RANDBETWEEN(1,5),2,2,2,3,1),IF(T10="Geliştirilmeli",CHOOSE(RANDBETWEEN(1,5),1,1,1,1,2),""))))) | I10: =IF(OR('Öğrenci Listesi'!B11="",T10=""),"",IF(T10="Çok İyi",CHOOSE(RANDBETWEEN(1,5),4,4,4,4,3),IF(T10="İyi",CHOOSE(RANDBETWEEN(1,5),3,3,3,4,2),IF(T10="Yeterli",CHOOSE(RANDBETWEEN(1,5),2,2,2,3,1),IF(T10="Geliştirilmeli",CHOOSE(RANDBETWEEN(1,5),1,1,1,1,2),""))))) | J10: =IF(OR('Öğrenci Listesi'!B11="",T10=""),"",IF(T10="Çok İyi",CHOOSE(RANDBETWEEN(1,5),4,4,4,4,3),IF(T10="İyi",CHOOSE(RANDBETWEEN(1,5),3,3,3,4,2),IF(T10="Yeterli",CHOOSE(RANDBETWEEN(1,5),2,2,2,3,1),IF(T10="Geliştirilmeli",CHOOSE(RANDBETWEEN(1,5),1,1,1,1,2),""))))) | K10: =IF(OR('Öğrenci Listesi'!B11="",T10=""),"",IF(T10="Çok İyi",CHOOSE(RANDBETWEEN(1,5),4,4,4,4,3),IF(T10="İyi",CHOOSE(RANDBETWEEN(1,5),3,3,3,4,2),IF(T10="Yeterli",CHOOSE(RANDBETWEEN(1,5),2,2,2,3,1),IF(T10="Geliştirilmeli",CHOOSE(RANDBETWEEN(1,5),1,1,1,1,2),""))))) | L10: =IF(OR('Öğrenci Listesi'!B11="",T10=""),"",IF(T10="Çok İyi",CHOOSE(RANDBETWEEN(1,5),4,4,4,4,3),IF(T10="İyi",CHOOSE(RANDBETWEEN(1,5),3,3,3,4,2),IF(T10="Yeterli",CHOOSE(RANDBETWEEN(1,5),2,2,2,3,1),IF(T10="Geliştirilmeli",CHOOSE(RANDBETWEEN(1,5),1,1,1,1,2),""))))) | M10: =IF(OR('Öğrenci Listesi'!B11="",T10=""),"",IF(T10="Çok İyi",CHOOSE(RANDBETWEEN(1,5),4,4,4,4,3),IF(T10="İyi",CHOOSE(RANDBETWEEN(1,5),3,3,3,4,2),IF(T10="Yeterli",CHOOSE(RANDBETWEEN(1,5),2,2,2,3,1),IF(T10="Geliştirilmeli",CHOOSE(RANDBETWEEN(1,5),1,1,1,1,2),""))))) | N10: =IF(OR('Öğrenci Listesi'!B11="",T10=""),"",IF(T10="Çok İyi",CHOOSE(RANDBETWEEN(1,5),4,4,4,4,3),IF(T10="İyi",CHOOSE(RANDBETWEEN(1,5),3,3,3,4,2),IF(T10="Yeterli",CHOOSE(RANDBETWEEN(1,5),2,2,2,3,1),IF(T10="Geliştirilmeli",CHOOSE(RANDBETWEEN(1,5),1,1,1,1,2),""))))) | O10: =IF(OR('Öğrenci Listesi'!B11="",T10=""),"",IF(T10="Çok İyi",CHOOSE(RANDBETWEEN(1,5),4,4,4,4,3),IF(T10="İyi",CHOOSE(RANDBETWEEN(1,5),3,3,3,4,2),IF(T10="Yeterli",CHOOSE(RANDBETWEEN(1,5),2,2,2,3,1),IF(T10="Geliştirilmeli",CHOOSE(RANDBETWEEN(1,5),1,1,1,1,2),""))))) | P10: =IF(OR('Öğrenci Listesi'!B11="",T10=""),"",IF(T10="Çok İyi",CHOOSE(RANDBETWEEN(1,5),4,4,4,4,3),IF(T10="İyi",CHOOSE(RANDBETWEEN(1,5),3,3,3,4,2),IF(T10="Yeterli",CHOOSE(RANDBETWEEN(1,5),2,2,2,3,1),IF(T10="Geliştirilmeli",CHOOSE(RANDBETWEEN(1,5),1,1,1,1,2),""))))) | Q10: =IF(OR('Öğrenci Listesi'!B11="",T10=""),"",IF(T10="Çok İyi",CHOOSE(RANDBETWEEN(1,5),4,4,4,4,3),IF(T10="İyi",CHOOSE(RANDBETWEEN(1,5),3,3,3,4,2),IF(T10="Yeterli",CHOOSE(RANDBETWEEN(1,5),2,2,2,3,1),IF(T10="Geliştirilmeli",CHOOSE(RANDBETWEEN(1,5),1,1,1,1,2),""))))) | R10: =IF(OR('Öğrenci Listesi'!B11="",T10=""),"",IF(T10="Çok İyi",CHOOSE(RANDBETWEEN(1,5),4,4,4,4,3),IF(T10="İyi",CHOOSE(RANDBETWEEN(1,5),3,3,3,4,2),IF(T10="Yeterli",CHOOSE(RANDBETWEEN(1,5),2,2,2,3,1),IF(T10="Geliştirilmeli",CHOOSE(RANDBETWEEN(1,5),1,1,1,1,2),""))))) | S10: =IF(OR('Öğrenci Listesi'!B11="",T10=""),"",ROUND(AVERAGE(C10:R10),2)) | T10: =IFERROR(IF('Öğrenci Listesi'!G11="","",IF(UPPER(TRIM('Öğrenci Listesi'!G11))="ÇOK İYİ","Çok İyi",IF(UPPER(TRIM('Öğrenci Listesi'!G11))="İYİ","İyi",IF(UPPER(TRIM('Öğrenci Listesi'!G11))="YETERLİ","Yeterli",IF(UPPER(TRIM('Öğrenci Listesi'!G11))="GELİŞTİRİLMELİ","Geliştirilmeli",'Öğrenci Listesi'!G11))))),"")
A11: =IFERROR(IF('Öğrenci Listesi'!A12="","",'Öğrenci Listesi'!A12),"") | B11: =IFERROR(IF('Öğrenci Listesi'!B12="","",'Öğrenci Listesi'!B12),"") | C11: =IF(OR('Öğrenci Listesi'!B12="",T11=""),"",IF(T11="Çok İyi",CHOOSE(RANDBETWEEN(1,5),4,4,4,4,3),IF(T11="İyi",CHOOSE(RANDBETWEEN(1,5),3,3,3,4,2),IF(T11="Yeterli",CHOOSE(RANDBETWEEN(1,5),2,2,2,3,1),IF(T11="Geliştirilmeli",CHOOSE(RANDBETWEEN(1,5),1,1,1,1,2),""))))) | D11: =IF(OR('Öğrenci Listesi'!B12="",T11=""),"",IF(T11="Çok İyi",CHOOSE(RANDBETWEEN(1,5),4,4,4,4,3),IF(T11="İyi",CHOOSE(RANDBETWEEN(1,5),3,3,3,4,2),IF(T11="Yeterli",CHOOSE(RANDBETWEEN(1,5),2,2,2,3,1),IF(T11="Geliştirilmeli",CHOOSE(RANDBETWEEN(1,5),1,1,1,1,2),""))))) | E11: =IF(OR('Öğrenci Listesi'!B12="",T11=""),"",IF(T11="Çok İyi",CHOOSE(RANDBETWEEN(1,5),4,4,4,4,3),IF(T11="İyi",CHOOSE(RANDBETWEEN(1,5),3,3,3,4,2),IF(T11="Yeterli",CHOOSE(RANDBETWEEN(1,5),2,2,2,3,1),IF(T11="Geliştirilmeli",CHOOSE(RANDBETWEEN(1,5),1,1,1,1,2),""))))) | F11: =IF(OR('Öğrenci Listesi'!B12="",T11=""),"",IF(T11="Çok İyi",CHOOSE(RANDBETWEEN(1,5),4,4,4,4,3),IF(T11="İyi",CHOOSE(RANDBETWEEN(1,5),3,3,3,4,2),IF(T11="Yeterli",CHOOSE(RANDBETWEEN(1,5),2,2,2,3,1),IF(T11="Geliştirilmeli",CHOOSE(RANDBETWEEN(1,5),1,1,1,1,2),""))))) | G11: =IF(OR('Öğrenci Listesi'!B12="",T11=""),"",IF(T11="Çok İyi",CHOOSE(RANDBETWEEN(1,5),4,4,4,4,3),IF(T11="İyi",CHOOSE(RANDBETWEEN(1,5),3,3,3,4,2),IF(T11="Yeterli",CHOOSE(RANDBETWEEN(1,5),2,2,2,3,1),IF(T11="Geliştirilmeli",CHOOSE(RANDBETWEEN(1,5),1,1,1,1,2),""))))) | H11: =IF(OR('Öğrenci Listesi'!B12="",T11=""),"",IF(T11="Çok İyi",CHOOSE(RANDBETWEEN(1,5),4,4,4,4,3),IF(T11="İyi",CHOOSE(RANDBETWEEN(1,5),3,3,3,4,2),IF(T11="Yeterli",CHOOSE(RANDBETWEEN(1,5),2,2,2,3,1),IF(T11="Geliştirilmeli",CHOOSE(RANDBETWEEN(1,5),1,1,1,1,2),""))))) | I11: =IF(OR('Öğrenci Listesi'!B12="",T11=""),"",IF(T11="Çok İyi",CHOOSE(RANDBETWEEN(1,5),4,4,4,4,3),IF(T11="İyi",CHOOSE(RANDBETWEEN(1,5),3,3,3,4,2),IF(T11="Yeterli",CHOOSE(RANDBETWEEN(1,5),2,2,2,3,1),IF(T11="Geliştirilmeli",CHOOSE(RANDBETWEEN(1,5),1,1,1,1,2),""))))) | J11: =IF(OR('Öğrenci Listesi'!B12="",T11=""),"",IF(T11="Çok İyi",CHOOSE(RANDBETWEEN(1,5),4,4,4,4,3),IF(T11="İyi",CHOOSE(RANDBETWEEN(1,5),3,3,3,4,2),IF(T11="Yeterli",CHOOSE(RANDBETWEEN(1,5),2,2,2,3,1),IF(T11="Geliştirilmeli",CHOOSE(RANDBETWEEN(1,5),1,1,1,1,2),""))))) | K11: =IF(OR('Öğrenci Listesi'!B12="",T11=""),"",IF(T11="Çok İyi",CHOOSE(RANDBETWEEN(1,5),4,4,4,4,3),IF(T11="İyi",CHOOSE(RANDBETWEEN(1,5),3,3,3,4,2),IF(T11="Yeterli",CHOOSE(RANDBETWEEN(1,5),2,2,2,3,1),IF(T11="Geliştirilmeli",CHOOSE(RANDBETWEEN(1,5),1,1,1,1,2),""))))) | L11: =IF(OR('Öğrenci Listesi'!B12="",T11=""),"",IF(T11="Çok İyi",CHOOSE(RANDBETWEEN(1,5),4,4,4,4,3),IF(T11="İyi",CHOOSE(RANDBETWEEN(1,5),3,3,3,4,2),IF(T11="Yeterli",CHOOSE(RANDBETWEEN(1,5),2,2,2,3,1),IF(T11="Geliştirilmeli",CHOOSE(RANDBETWEEN(1,5),1,1,1,1,2),""))))) | M11: =IF(OR('Öğrenci Listesi'!B12="",T11=""),"",IF(T11="Çok İyi",CHOOSE(RANDBETWEEN(1,5),4,4,4,4,3),IF(T11="İyi",CHOOSE(RANDBETWEEN(1,5),3,3,3,4,2),IF(T11="Yeterli",CHOOSE(RANDBETWEEN(1,5),2,2,2,3,1),IF(T11="Geliştirilmeli",CHOOSE(RANDBETWEEN(1,5),1,1,1,1,2),""))))) | N11: =IF(OR('Öğrenci Listesi'!B12="",T11=""),"",IF(T11="Çok İyi",CHOOSE(RANDBETWEEN(1,5),4,4,4,4,3),IF(T11="İyi",CHOOSE(RANDBETWEEN(1,5),3,3,3,4,2),IF(T11="Yeterli",CHOOSE(RANDBETWEEN(1,5),2,2,2,3,1),IF(T11="Geliştirilmeli",CHOOSE(RANDBETWEEN(1,5),1,1,1,1,2),""))))) | O11: =IF(OR('Öğrenci Listesi'!B12="",T11=""),"",IF(T11="Çok İyi",CHOOSE(RANDBETWEEN(1,5),4,4,4,4,3),IF(T11="İyi",CHOOSE(RANDBETWEEN(1,5),3,3,3,4,2),IF(T11="Yeterli",CHOOSE(RANDBETWEEN(1,5),2,2,2,3,1),IF(T11="Geliştirilmeli",CHOOSE(RANDBETWEEN(1,5),1,1,1,1,2),""))))) | P11: =IF(OR('Öğrenci Listesi'!B12="",T11=""),"",IF(T11="Çok İyi",CHOOSE(RANDBETWEEN(1,5),4,4,4,4,3),IF(T11="İyi",CHOOSE(RANDBETWEEN(1,5),3,3,3,4,2),IF(T11="Yeterli",CHOOSE(RANDBETWEEN(1,5),2,2,2,3,1),IF(T11="Geliştirilmeli",CHOOSE(RANDBETWEEN(1,5),1,1,1,1,2),""))))) | Q11: =IF(OR('Öğrenci Listesi'!B12="",T11=""),"",IF(T11="Çok İyi",CHOOSE(RANDBETWEEN(1,5),4,4,4,4,3),IF(T11="İyi",CHOOSE(RANDBETWEEN(1,5),3,3,3,4,2),IF(T11="Yeterli",CHOOSE(RANDBETWEEN(1,5),2,2,2,3,1),IF(T11="Geliştirilmeli",CHOOSE(RANDBETWEEN(1,5),1,1,1,1,2),""))))) | R11: =IF(OR('Öğrenci Listesi'!B12="",T11=""),"",IF(T11="Çok İyi",CHOOSE(RANDBETWEEN(1,5),4,4,4,4,3),IF(T11="İyi",CHOOSE(RANDBETWEEN(1,5),3,3,3,4,2),IF(T11="Yeterli",CHOOSE(RANDBETWEEN(1,5),2,2,2,3,1),IF(T11="Geliştirilmeli",CHOOSE(RANDBETWEEN(1,5),1,1,1,1,2),""))))) | S11: =IF(OR('Öğrenci Listesi'!B12="",T11=""),"",ROUND(AVERAGE(C11:R11),2)) | T11: =IFERROR(IF('Öğrenci Listesi'!G12="","",IF(UPPER(TRIM('Öğrenci Listesi'!G12))="ÇOK İYİ","Çok İyi",IF(UPPER(TRIM('Öğrenci Listesi'!G12))="İYİ","İyi",IF(UPPER(TRIM('Öğrenci Listesi'!G12))="YETERLİ","Yeterli",IF(UPPER(TRIM('Öğrenci Listesi'!G12))="GELİŞTİRİLMELİ","Geliştirilmeli",'Öğrenci Listesi'!G12))))),"")
A12: =IFERROR(IF('Öğrenci Listesi'!A13="","",'Öğrenci Listesi'!A13),"") | B12: =IFERROR(IF('Öğrenci Listesi'!B13="","",'Öğrenci Listesi'!B13),"") | C12: =IF(OR('Öğrenci Listesi'!B13="",T12=""),"",IF(T12="Çok İyi",CHOOSE(RANDBETWEEN(1,5),4,4,4,4,3),IF(T12="İyi",CHOOSE(RANDBETWEEN(1,5),3,3,3,4,2),IF(T12="Yeterli",CHOOSE(RANDBETWEEN(1,5),2,2,2,3,1),IF(T12="Geliştirilmeli",CHOOSE(RANDBETWEEN(1,5),1,1,1,1,2),""))))) | D12: =IF(OR('Öğrenci Listesi'!B13="",T12=""),"",IF(T12="Çok İyi",CHOOSE(RANDBETWEEN(1,5),4,4,4,4,3),IF(T12="İyi",CHOOSE(RANDBETWEEN(1,5),3,3,3,4,2),IF(T12="Yeterli",CHOOSE(RANDBETWEEN(1,5),2,2,2,3,1),IF(T12="Geliştirilmeli",CHOOSE(RANDBETWEEN(1,5),1,1,1,1,2),""))))) | E12: =IF(OR('Öğrenci Listesi'!B13="",T12=""),"",IF(T12="Çok İyi",CHOOSE(RANDBETWEEN(1,5),4,4,4,4,3),IF(T12="İyi",CHOOSE(RANDBETWEEN(1,5),3,3,3,4,2),IF(T12="Yeterli",CHOOSE(RANDBETWEEN(1,5),2,2,2,3,1),IF(T12="Geliştirilmeli",CHOOSE(RANDBETWEEN(1,5),1,1,1,1,2),""))))) | F12: =IF(OR('Öğrenci Listesi'!B13="",T12=""),"",IF(T12="Çok İyi",CHOOSE(RANDBETWEEN(1,5),4,4,4,4,3),IF(T12="İyi",CHOOSE(RANDBETWEEN(1,5),3,3,3,4,2),IF(T12="Yeterli",CHOOSE(RANDBETWEEN(1,5),2,2,2,3,1),IF(T12="Geliştirilmeli",CHOOSE(RANDBETWEEN(1,5),1,1,1,1,2),""))))) | G12: =IF(OR('Öğrenci Listesi'!B13="",T12=""),"",IF(T12="Çok İyi",CHOOSE(RANDBETWEEN(1,5),4,4,4,4,3),IF(T12="İyi",CHOOSE(RANDBETWEEN(1,5),3,3,3,4,2),IF(T12="Yeterli",CHOOSE(RANDBETWEEN(1,5),2,2,2,3,1),IF(T12="Geliştirilmeli",CHOOSE(RANDBETWEEN(1,5),1,1,1,1,2),""))))) | H12: =IF(OR('Öğrenci Listesi'!B13="",T12=""),"",IF(T12="Çok İyi",CHOOSE(RANDBETWEEN(1,5),4,4,4,4,3),IF(T12="İyi",CHOOSE(RANDBETWEEN(1,5),3,3,3,4,2),IF(T12="Yeterli",CHOOSE(RANDBETWEEN(1,5),2,2,2,3,1),IF(T12="Geliştirilmeli",CHOOSE(RANDBETWEEN(1,5),1,1,1,1,2),""))))) | I12: =IF(OR('Öğrenci Listesi'!B13="",T12=""),"",IF(T12="Çok İyi",CHOOSE(RANDBETWEEN(1,5),4,4,4,4,3),IF(T12="İyi",CHOOSE(RANDBETWEEN(1,5),3,3,3,4,2),IF(T12="Yeterli",CHOOSE(RANDBETWEEN(1,5),2,2,2,3,1),IF(T12="Geliştirilmeli",CHOOSE(RANDBETWEEN(1,5),1,1,1,1,2),""))))) | J12: =IF(OR('Öğrenci Listesi'!B13="",T12=""),"",IF(T12="Çok İyi",CHOOSE(RANDBETWEEN(1,5),4,4,4,4,3),IF(T12="İyi",CHOOSE(RANDBETWEEN(1,5),3,3,3,4,2),IF(T12="Yeterli",CHOOSE(RANDBETWEEN(1,5),2,2,2,3,1),IF(T12="Geliştirilmeli",CHOOSE(RANDBETWEEN(1,5),1,1,1,1,2),""))))) | K12: =IF(OR('Öğrenci Listesi'!B13="",T12=""),"",IF(T12="Çok İyi",CHOOSE(RANDBETWEEN(1,5),4,4,4,4,3),IF(T12="İyi",CHOOSE(RANDBETWEEN(1,5),3,3,3,4,2),IF(T12="Yeterli",CHOOSE(RANDBETWEEN(1,5),2,2,2,3,1),IF(T12="Geliştirilmeli",CHOOSE(RANDBETWEEN(1,5),1,1,1,1,2),""))))) | L12: =IF(OR('Öğrenci Listesi'!B13="",T12=""),"",IF(T12="Çok İyi",CHOOSE(RANDBETWEEN(1,5),4,4,4,4,3),IF(T12="İyi",CHOOSE(RANDBETWEEN(1,5),3,3,3,4,2),IF(T12="Yeterli",CHOOSE(RANDBETWEEN(1,5),2,2,2,3,1),IF(T12="Geliştirilmeli",CHOOSE(RANDBETWEEN(1,5),1,1,1,1,2),""))))) | M12: =IF(OR('Öğrenci Listesi'!B13="",T12=""),"",IF(T12="Çok İyi",CHOOSE(RANDBETWEEN(1,5),4,4,4,4,3),IF(T12="İyi",CHOOSE(RANDBETWEEN(1,5),3,3,3,4,2),IF(T12="Yeterli",CHOOSE(RANDBETWEEN(1,5),2,2,2,3,1),IF(T12="Geliştirilmeli",CHOOSE(RANDBETWEEN(1,5),1,1,1,1,2),""))))) | N12: =IF(OR('Öğrenci Listesi'!B13="",T12=""),"",IF(T12="Çok İyi",CHOOSE(RANDBETWEEN(1,5),4,4,4,4,3),IF(T12="İyi",CHOOSE(RANDBETWEEN(1,5),3,3,3,4,2),IF(T12="Yeterli",CHOOSE(RANDBETWEEN(1,5),2,2,2,3,1),IF(T12="Geliştirilmeli",CHOOSE(RANDBETWEEN(1,5),1,1,1,1,2),""))))) | O12: =IF(OR('Öğrenci Listesi'!B13="",T12=""),"",IF(T12="Çok İyi",CHOOSE(RANDBETWEEN(1,5),4,4,4,4,3),IF(T12="İyi",CHOOSE(RANDBETWEEN(1,5),3,3,3,4,2),IF(T12="Yeterli",CHOOSE(RANDBETWEEN(1,5),2,2,2,3,1),IF(T12="Geliştirilmeli",CHOOSE(RANDBETWEEN(1,5),1,1,1,1,2),""))))) | P12: =IF(OR('Öğrenci Listesi'!B13="",T12=""),"",IF(T12="Çok İyi",CHOOSE(RANDBETWEEN(1,5),4,4,4,4,3),IF(T12="İyi",CHOOSE(RANDBETWEEN(1,5),3,3,3,4,2),IF(T12="Yeterli",CHOOSE(RANDBETWEEN(1,5),2,2,2,3,1),IF(T12="Geliştirilmeli",CHOOSE(RANDBETWEEN(1,5),1,1,1,1,2),""))))) | Q12: =IF(OR('Öğrenci Listesi'!B13="",T12=""),"",IF(T12="Çok İyi",CHOOSE(RANDBETWEEN(1,5),4,4,4,4,3),IF(T12="İyi",CHOOSE(RANDBETWEEN(1,5),3,3,3,4,2),IF(T12="Yeterli",CHOOSE(RANDBETWEEN(1,5),2,2,2,3,1),IF(T12="Geliştirilmeli",CHOOSE(RANDBETWEEN(1,5),1,1,1,1,2),""))))) | R12: =IF(OR('Öğrenci Listesi'!B13="",T12=""),"",IF(T12="Çok İyi",CHOOSE(RANDBETWEEN(1,5),4,4,4,4,3),IF(T12="İyi",CHOOSE(RANDBETWEEN(1,5),3,3,3,4,2),IF(T12="Yeterli",CHOOSE(RANDBETWEEN(1,5),2,2,2,3,1),IF(T12="Geliştirilmeli",CHOOSE(RANDBETWEEN(1,5),1,1,1,1,2),""))))) | S12: =IF(OR('Öğrenci Listesi'!B13="",T12=""),"",ROUND(AVERAGE(C12:R12),2)) | T12: =IFERROR(IF('Öğrenci Listesi'!G13="","",IF(UPPER(TRIM('Öğrenci Listesi'!G13))="ÇOK İYİ","Çok İyi",IF(UPPER(TRIM('Öğrenci Listesi'!G13))="İYİ","İyi",IF(UPPER(TRIM('Öğrenci Listesi'!G13))="YETERLİ","Yeterli",IF(UPPER(TRIM('Öğrenci Listesi'!G13))="GELİŞTİRİLMELİ","Geliştirilmeli",'Öğrenci Listesi'!G13))))),"")
A13: =IFERROR(IF('Öğrenci Listesi'!A14="","",'Öğrenci Listesi'!A14),"") | B13: =IFERROR(IF('Öğrenci Listesi'!B14="","",'Öğrenci Listesi'!B14),"") | C13: =IF(OR('Öğrenci Listesi'!B14="",T13=""),"",IF(T13="Çok İyi",CHOOSE(RANDBETWEEN(1,5),4,4,4,4,3),IF(T13="İyi",CHOOSE(RANDBETWEEN(1,5),3,3,3,4,2),IF(T13="Yeterli",CHOOSE(RANDBETWEEN(1,5),2,2,2,3,1),IF(T13="Geliştirilmeli",CHOOSE(RANDBETWEEN(1,5),1,1,1,1,2),""))))) | D13: =IF(OR('Öğrenci Listesi'!B14="",T13=""),"",IF(T13="Çok İyi",CHOOSE(RANDBETWEEN(1,5),4,4,4,4,3),IF(T13="İyi",CHOOSE(RANDBETWEEN(1,5),3,3,3,4,2),IF(T13="Yeterli",CHOOSE(RANDBETWEEN(1,5),2,2,2,3,1),IF(T13="Geliştirilmeli",CHOOSE(RANDBETWEEN(1,5),1,1,1,1,2),""))))) | E13: =IF(OR('Öğrenci Listesi'!B14="",T13=""),"",IF(T13="Çok İyi",CHOOSE(RANDBETWEEN(1,5),4,4,4,4,3),IF(T13="İyi",CHOOSE(RANDBETWEEN(1,5),3,3,3,4,2),IF(T13="Yeterli",CHOOSE(RANDBETWEEN(1,5),2,2,2,3,1),IF(T13="Geliştirilmeli",CHOOSE(RANDBETWEEN(1,5),1,1,1,1,2),""))))) | F13: =IF(OR('Öğrenci Listesi'!B14="",T13=""),"",IF(T13="Çok İyi",CHOOSE(RANDBETWEEN(1,5),4,4,4,4,3),IF(T13="İyi",CHOOSE(RANDBETWEEN(1,5),3,3,3,4,2),IF(T13="Yeterli",CHOOSE(RANDBETWEEN(1,5),2,2,2,3,1),IF(T13="Geliştirilmeli",CHOOSE(RANDBETWEEN(1,5),1,1,1,1,2),""))))) | G13: =IF(OR('Öğrenci Listesi'!B14="",T13=""),"",IF(T13="Çok İyi",CHOOSE(RANDBETWEEN(1,5),4,4,4,4,3),IF(T13="İyi",CHOOSE(RANDBETWEEN(1,5),3,3,3,4,2),IF(T13="Yeterli",CHOOSE(RANDBETWEEN(1,5),2,2,2,3,1),IF(T13="Geliştirilmeli",CHOOSE(RANDBETWEEN(1,5),1,1,1,1,2),""))))) | H13: =IF(OR('Öğrenci Listesi'!B14="",T13=""),"",IF(T13="Çok İyi",CHOOSE(RANDBETWEEN(1,5),4,4,4,4,3),IF(T13="İyi",CHOOSE(RANDBETWEEN(1,5),3,3,3,4,2),IF(T13="Yeterli",CHOOSE(RANDBETWEEN(1,5),2,2,2,3,1),IF(T13="Geliştirilmeli",CHOOSE(RANDBETWEEN(1,5),1,1,1,1,2),""))))) | I13: =IF(OR('Öğrenci Listesi'!B14="",T13=""),"",IF(T13="Çok İyi",CHOOSE(RANDBETWEEN(1,5),4,4,4,4,3),IF(T13="İyi",CHOOSE(RANDBETWEEN(1,5),3,3,3,4,2),IF(T13="Yeterli",CHOOSE(RANDBETWEEN(1,5),2,2,2,3,1),IF(T13="Geliştirilmeli",CHOOSE(RANDBETWEEN(1,5),1,1,1,1,2),""))))) | J13: =IF(OR('Öğrenci Listesi'!B14="",T13=""),"",IF(T13="Çok İyi",CHOOSE(RANDBETWEEN(1,5),4,4,4,4,3),IF(T13="İyi",CHOOSE(RANDBETWEEN(1,5),3,3,3,4,2),IF(T13="Yeterli",CHOOSE(RANDBETWEEN(1,5),2,2,2,3,1),IF(T13="Geliştirilmeli",CHOOSE(RANDBETWEEN(1,5),1,1,1,1,2),""))))) | K13: =IF(OR('Öğrenci Listesi'!B14="",T13=""),"",IF(T13="Çok İyi",CHOOSE(RANDBETWEEN(1,5),4,4,4,4,3),IF(T13="İyi",CHOOSE(RANDBETWEEN(1,5),3,3,3,4,2),IF(T13="Yeterli",CHOOSE(RANDBETWEEN(1,5),2,2,2,3,1),IF(T13="Geliştirilmeli",CHOOSE(RANDBETWEEN(1,5),1,1,1,1,2),""))))) | L13: =IF(OR('Öğrenci Listesi'!B14="",T13=""),"",IF(T13="Çok İyi",CHOOSE(RANDBETWEEN(1,5),4,4,4,4,3),IF(T13="İyi",CHOOSE(RANDBETWEEN(1,5),3,3,3,4,2),IF(T13="Yeterli",CHOOSE(RANDBETWEEN(1,5),2,2,2,3,1),IF(T13="Geliştirilmeli",CHOOSE(RANDBETWEEN(1,5),1,1,1,1,2),""))))) | M13: =IF(OR('Öğrenci Listesi'!B14="",T13=""),"",IF(T13="Çok İyi",CHOOSE(RANDBETWEEN(1,5),4,4,4,4,3),IF(T13="İyi",CHOOSE(RANDBETWEEN(1,5),3,3,3,4,2),IF(T13="Yeterli",CHOOSE(RANDBETWEEN(1,5),2,2,2,3,1),IF(T13="Geliştirilmeli",CHOOSE(RANDBETWEEN(1,5),1,1,1,1,2),""))))) | N13: =IF(OR('Öğrenci Listesi'!B14="",T13=""),"",IF(T13="Çok İyi",CHOOSE(RANDBETWEEN(1,5),4,4,4,4,3),IF(T13="İyi",CHOOSE(RANDBETWEEN(1,5),3,3,3,4,2),IF(T13="Yeterli",CHOOSE(RANDBETWEEN(1,5),2,2,2,3,1),IF(T13="Geliştirilmeli",CHOOSE(RANDBETWEEN(1,5),1,1,1,1,2),""))))) | O13: =IF(OR('Öğrenci Listesi'!B14="",T13=""),"",IF(T13="Çok İyi",CHOOSE(RANDBETWEEN(1,5),4,4,4,4,3),IF(T13="İyi",CHOOSE(RANDBETWEEN(1,5),3,3,3,4,2),IF(T13="Yeterli",CHOOSE(RANDBETWEEN(1,5),2,2,2,3,1),IF(T13="Geliştirilmeli",CHOOSE(RANDBETWEEN(1,5),1,1,1,1,2),""))))) | P13: =IF(OR('Öğrenci Listesi'!B14="",T13=""),"",IF(T13="Çok İyi",CHOOSE(RANDBETWEEN(1,5),4,4,4,4,3),IF(T13="İyi",CHOOSE(RANDBETWEEN(1,5),3,3,3,4,2),IF(T13="Yeterli",CHOOSE(RANDBETWEEN(1,5),2,2,2,3,1),IF(T13="Geliştirilmeli",CHOOSE(RANDBETWEEN(1,5),1,1,1,1,2),""))))) | Q13: =IF(OR('Öğrenci Listesi'!B14="",T13=""),"",IF(T13="Çok İyi",CHOOSE(RANDBETWEEN(1,5),4,4,4,4,3),IF(T13="İyi",CHOOSE(RANDBETWEEN(1,5),3,3,3,4,2),IF(T13="Yeterli",CHOOSE(RANDBETWEEN(1,5),2,2,2,3,1),IF(T13="Geliştirilmeli",CHOOSE(RANDBETWEEN(1,5),1,1,1,1,2),""))))) | R13: =IF(OR('Öğrenci Listesi'!B14="",T13=""),"",IF(T13="Çok İyi",CHOOSE(RANDBETWEEN(1,5),4,4,4,4,3),IF(T13="İyi",CHOOSE(RANDBETWEEN(1,5),3,3,3,4,2),IF(T13="Yeterli",CHOOSE(RANDBETWEEN(1,5),2,2,2,3,1),IF(T13="Geliştirilmeli",CHOOSE(RANDBETWEEN(1,5),1,1,1,1,2),""))))) | S13: =IF(OR('Öğrenci Listesi'!B14="",T13=""),"",ROUND(AVERAGE(C13:R13),2)) | T13: =IFERROR(IF('Öğrenci Listesi'!G14="","",IF(UPPER(TRIM('Öğrenci Listesi'!G14))="ÇOK İYİ","Çok İyi",IF(UPPER(TRIM('Öğrenci Listesi'!G14))="İYİ","İyi",IF(UPPER(TRIM('Öğrenci Listesi'!G14))="YETERLİ","Yeterli",IF(UPPER(TRIM('Öğrenci Listesi'!G14))="GELİŞTİRİLMELİ","Geliştirilmeli",'Öğrenci Listesi'!G14))))),"")
A14: =IFERROR(IF('Öğrenci Listesi'!A15="","",'Öğrenci Listesi'!A15),"") | B14: =IFERROR(IF('Öğrenci Listesi'!B15="","",'Öğrenci Listesi'!B15),"") | C14: =IF(OR('Öğrenci Listesi'!B15="",T14=""),"",IF(T14="Çok İyi",CHOOSE(RANDBETWEEN(1,5),4,4,4,4,3),IF(T14="İyi",CHOOSE(RANDBETWEEN(1,5),3,3,3,4,2),IF(T14="Yeterli",CHOOSE(RANDBETWEEN(1,5),2,2,2,3,1),IF(T14="Geliştirilmeli",CHOOSE(RANDBETWEEN(1,5),1,1,1,1,2),""))))) | D14: =IF(OR('Öğrenci Listesi'!B15="",T14=""),"",IF(T14="Çok İyi",CHOOSE(RANDBETWEEN(1,5),4,4,4,4,3),IF(T14="İyi",CHOOSE(RANDBETWEEN(1,5),3,3,3,4,2),IF(T14="Yeterli",CHOOSE(RANDBETWEEN(1,5),2,2,2,3,1),IF(T14="Geliştirilmeli",CHOOSE(RANDBETWEEN(1,5),1,1,1,1,2),""))))) | E14: =IF(OR('Öğrenci Listesi'!B15="",T14=""),"",IF(T14="Çok İyi",CHOOSE(RANDBETWEEN(1,5),4,4,4,4,3),IF(T14="İyi",CHOOSE(RANDBETWEEN(1,5),3,3,3,4,2),IF(T14="Yeterli",CHOOSE(RANDBETWEEN(1,5),2,2,2,3,1),IF(T14="Geliştirilmeli",CHOOSE(RANDBETWEEN(1,5),1,1,1,1,2),""))))) | F14: =IF(OR('Öğrenci Listesi'!B15="",T14=""),"",IF(T14="Çok İyi",CHOOSE(RANDBETWEEN(1,5),4,4,4,4,3),IF(T14="İyi",CHOOSE(RANDBETWEEN(1,5),3,3,3,4,2),IF(T14="Yeterli",CHOOSE(RANDBETWEEN(1,5),2,2,2,3,1),IF(T14="Geliştirilmeli",CHOOSE(RANDBETWEEN(1,5),1,1,1,1,2),""))))) | G14: =IF(OR('Öğrenci Listesi'!B15="",T14=""),"",IF(T14="Çok İyi",CHOOSE(RANDBETWEEN(1,5),4,4,4,4,3),IF(T14="İyi",CHOOSE(RANDBETWEEN(1,5),3,3,3,4,2),IF(T14="Yeterli",CHOOSE(RANDBETWEEN(1,5),2,2,2,3,1),IF(T14="Geliştirilmeli",CHOOSE(RANDBETWEEN(1,5),1,1,1,1,2),""))))) | H14: =IF(OR('Öğrenci Listesi'!B15="",T14=""),"",IF(T14="Çok İyi",CHOOSE(RANDBETWEEN(1,5),4,4,4,4,3),IF(T14="İyi",CHOOSE(RANDBETWEEN(1,5),3,3,3,4,2),IF(T14="Yeterli",CHOOSE(RANDBETWEEN(1,5),2,2,2,3,1),IF(T14="Geliştirilmeli",CHOOSE(RANDBETWEEN(1,5),1,1,1,1,2),""))))) | I14: =IF(OR('Öğrenci Listesi'!B15="",T14=""),"",IF(T14="Çok İyi",CHOOSE(RANDBETWEEN(1,5),4,4,4,4,3),IF(T14="İyi",CHOOSE(RANDBETWEEN(1,5),3,3,3,4,2),IF(T14="Yeterli",CHOOSE(RANDBETWEEN(1,5),2,2,2,3,1),IF(T14="Geliştirilmeli",CHOOSE(RANDBETWEEN(1,5),1,1,1,1,2),""))))) | J14: =IF(OR('Öğrenci Listesi'!B15="",T14=""),"",IF(T14="Çok İyi",CHOOSE(RANDBETWEEN(1,5),4,4,4,4,3),IF(T14="İyi",CHOOSE(RANDBETWEEN(1,5),3,3,3,4,2),IF(T14="Yeterli",CHOOSE(RANDBETWEEN(1,5),2,2,2,3,1),IF(T14="Geliştirilmeli",CHOOSE(RANDBETWEEN(1,5),1,1,1,1,2),""))))) | K14: =IF(OR('Öğrenci Listesi'!B15="",T14=""),"",IF(T14="Çok İyi",CHOOSE(RANDBETWEEN(1,5),4,4,4,4,3),IF(T14="İyi",CHOOSE(RANDBETWEEN(1,5),3,3,3,4,2),IF(T14="Yeterli",CHOOSE(RANDBETWEEN(1,5),2,2,2,3,1),IF(T14="Geliştirilmeli",CHOOSE(RANDBETWEEN(1,5),1,1,1,1,2),""))))) | L14: =IF(OR('Öğrenci Listesi'!B15="",T14=""),"",IF(T14="Çok İyi",CHOOSE(RANDBETWEEN(1,5),4,4,4,4,3),IF(T14="İyi",CHOOSE(RANDBETWEEN(1,5),3,3,3,4,2),IF(T14="Yeterli",CHOOSE(RANDBETWEEN(1,5),2,2,2,3,1),IF(T14="Geliştirilmeli",CHOOSE(RANDBETWEEN(1,5),1,1,1,1,2),""))))) | M14: =IF(OR('Öğrenci Listesi'!B15="",T14=""),"",IF(T14="Çok İyi",CHOOSE(RANDBETWEEN(1,5),4,4,4,4,3),IF(T14="İyi",CHOOSE(RANDBETWEEN(1,5),3,3,3,4,2),IF(T14="Yeterli",CHOOSE(RANDBETWEEN(1,5),2,2,2,3,1),IF(T14="Geliştirilmeli",CHOOSE(RANDBETWEEN(1,5),1,1,1,1,2),""))))) | N14: =IF(OR('Öğrenci Listesi'!B15="",T14=""),"",IF(T14="Çok İyi",CHOOSE(RANDBETWEEN(1,5),4,4,4,4,3),IF(T14="İyi",CHOOSE(RANDBETWEEN(1,5),3,3,3,4,2),IF(T14="Yeterli",CHOOSE(RANDBETWEEN(1,5),2,2,2,3,1),IF(T14="Geliştirilmeli",CHOOSE(RANDBETWEEN(1,5),1,1,1,1,2),""))))) | O14: =IF(OR('Öğrenci Listesi'!B15="",T14=""),"",IF(T14="Çok İyi",CHOOSE(RANDBETWEEN(1,5),4,4,4,4,3),IF(T14="İyi",CHOOSE(RANDBETWEEN(1,5),3,3,3,4,2),IF(T14="Yeterli",CHOOSE(RANDBETWEEN(1,5),2,2,2,3,1),IF(T14="Geliştirilmeli",CHOOSE(RANDBETWEEN(1,5),1,1,1,1,2),""))))) | P14: =IF(OR('Öğrenci Listesi'!B15="",T14=""),"",IF(T14="Çok İyi",CHOOSE(RANDBETWEEN(1,5),4,4,4,4,3),IF(T14="İyi",CHOOSE(RANDBETWEEN(1,5),3,3,3,4,2),IF(T14="Yeterli",CHOOSE(RANDBETWEEN(1,5),2,2,2,3,1),IF(T14="Geliştirilmeli",CHOOSE(RANDBETWEEN(1,5),1,1,1,1,2),""))))) | Q14: =IF(OR('Öğrenci Listesi'!B15="",T14=""),"",IF(T14="Çok İyi",CHOOSE(RANDBETWEEN(1,5),4,4,4,4,3),IF(T14="İyi",CHOOSE(RANDBETWEEN(1,5),3,3,3,4,2),IF(T14="Yeterli",CHOOSE(RANDBETWEEN(1,5),2,2,2,3,1),IF(T14="Geliştirilmeli",CHOOSE(RANDBETWEEN(1,5),1,1,1,1,2),""))))) | R14: =IF(OR('Öğrenci Listesi'!B15="",T14=""),"",IF(T14="Çok İyi",CHOOSE(RANDBETWEEN(1,5),4,4,4,4,3),IF(T14="İyi",CHOOSE(RANDBETWEEN(1,5),3,3,3,4,2),IF(T14="Yeterli",CHOOSE(RANDBETWEEN(1,5),2,2,2,3,1),IF(T14="Geliştirilmeli",CHOOSE(RANDBETWEEN(1,5),1,1,1,1,2),""))))) | S14: =IF(OR('Öğrenci Listesi'!B15="",T14=""),"",ROUND(AVERAGE(C14:R14),2)) | T14: =IFERROR(IF('Öğrenci Listesi'!G15="","",IF(UPPER(TRIM('Öğrenci Listesi'!G15))="ÇOK İYİ","Çok İyi",IF(UPPER(TRIM('Öğrenci Listesi'!G15))="İYİ","İyi",IF(UPPER(TRIM('Öğrenci Listesi'!G15))="YETERLİ","Yeterli",IF(UPPER(TRIM('Öğrenci Listesi'!G15))="GELİŞTİRİLMELİ","Geliştirilmeli",'Öğrenci Listesi'!G15))))),"")
A15: =IFERROR(IF('Öğrenci Listesi'!A16="","",'Öğrenci Listesi'!A16),"") | B15: =IFERROR(IF('Öğrenci Listesi'!B16="","",'Öğrenci Listesi'!B16),"") | C15: =IF(OR('Öğrenci Listesi'!B16="",T15=""),"",IF(T15="Çok İyi",CHOOSE(RANDBETWEEN(1,5),4,4,4,4,3),IF(T15="İyi",CHOOSE(RANDBETWEEN(1,5),3,3,3,4,2),IF(T15="Yeterli",CHOOSE(RANDBETWEEN(1,5),2,2,2,3,1),IF(T15="Geliştirilmeli",CHOOSE(RANDBETWEEN(1,5),1,1,1,1,2),""))))) | D15: =IF(OR('Öğrenci Listesi'!B16="",T15=""),"",IF(T15="Çok İyi",CHOOSE(RANDBETWEEN(1,5),4,4,4,4,3),IF(T15="İyi",CHOOSE(RANDBETWEEN(1,5),3,3,3,4,2),IF(T15="Yeterli",CHOOSE(RANDBETWEEN(1,5),2,2,2,3,1),IF(T15="Geliştirilmeli",CHOOSE(RANDBETWEEN(1,5),1,1,1,1,2),""))))) | E15: =IF(OR('Öğrenci Listesi'!B16="",T15=""),"",IF(T15="Çok İyi",CHOOSE(RANDBETWEEN(1,5),4,4,4,4,3),IF(T15="İyi",CHOOSE(RANDBETWEEN(1,5),3,3,3,4,2),IF(T15="Yeterli",CHOOSE(RANDBETWEEN(1,5),2,2,2,3,1),IF(T15="Geliştirilmeli",CHOOSE(RANDBETWEEN(1,5),1,1,1,1,2),""))))) | F15: =IF(OR('Öğrenci Listesi'!B16="",T15=""),"",IF(T15="Çok İyi",CHOOSE(RANDBETWEEN(1,5),4,4,4,4,3),IF(T15="İyi",CHOOSE(RANDBETWEEN(1,5),3,3,3,4,2),IF(T15="Yeterli",CHOOSE(RANDBETWEEN(1,5),2,2,2,3,1),IF(T15="Geliştirilmeli",CHOOSE(RANDBETWEEN(1,5),1,1,1,1,2),""))))) | G15: =IF(OR('Öğrenci Listesi'!B16="",T15=""),"",IF(T15="Çok İyi",CHOOSE(RANDBETWEEN(1,5),4,4,4,4,3),IF(T15="İyi",CHOOSE(RANDBETWEEN(1,5),3,3,3,4,2),IF(T15="Yeterli",CHOOSE(RANDBETWEEN(1,5),2,2,2,3,1),IF(T15="Geliştirilmeli",CHOOSE(RANDBETWEEN(1,5),1,1,1,1,2),""))))) | H15: =IF(OR('Öğrenci Listesi'!B16="",T15=""),"",IF(T15="Çok İyi",CHOOSE(RANDBETWEEN(1,5),4,4,4,4,3),IF(T15="İyi",CHOOSE(RANDBETWEEN(1,5),3,3,3,4,2),IF(T15="Yeterli",CHOOSE(RANDBETWEEN(1,5),2,2,2,3,1),IF(T15="Geliştirilmeli",CHOOSE(RANDBETWEEN(1,5),1,1,1,1,2),""))))) | I15: =IF(OR('Öğrenci Listesi'!B16="",T15=""),"",IF(T15="Çok İyi",CHOOSE(RANDBETWEEN(1,5),4,4,4,4,3),IF(T15="İyi",CHOOSE(RANDBETWEEN(1,5),3,3,3,4,2),IF(T15="Yeterli",CHOOSE(RANDBETWEEN(1,5),2,2,2,3,1),IF(T15="Geliştirilmeli",CHOOSE(RANDBETWEEN(1,5),1,1,1,1,2),""))))) | J15: =IF(OR('Öğrenci Listesi'!B16="",T15=""),"",IF(T15="Çok İyi",CHOOSE(RANDBETWEEN(1,5),4,4,4,4,3),IF(T15="İyi",CHOOSE(RANDBETWEEN(1,5),3,3,3,4,2),IF(T15="Yeterli",CHOOSE(RANDBETWEEN(1,5),2,2,2,3,1),IF(T15="Geliştirilmeli",CHOOSE(RANDBETWEEN(1,5),1,1,1,1,2),""))))) | K15: =IF(OR('Öğrenci Listesi'!B16="",T15=""),"",IF(T15="Çok İyi",CHOOSE(RANDBETWEEN(1,5),4,4,4,4,3),IF(T15="İyi",CHOOSE(RANDBETWEEN(1,5),3,3,3,4,2),IF(T15="Yeterli",CHOOSE(RANDBETWEEN(1,5),2,2,2,3,1),IF(T15="Geliştirilmeli",CHOOSE(RANDBETWEEN(1,5),1,1,1,1,2),""))))) | L15: =IF(OR('Öğrenci Listesi'!B16="",T15=""),"",IF(T15="Çok İyi",CHOOSE(RANDBETWEEN(1,5),4,4,4,4,3),IF(T15="İyi",CHOOSE(RANDBETWEEN(1,5),3,3,3,4,2),IF(T15="Yeterli",CHOOSE(RANDBETWEEN(1,5),2,2,2,3,1),IF(T15="Geliştirilmeli",CHOOSE(RANDBETWEEN(1,5),1,1,1,1,2),""))))) | M15: =IF(OR('Öğrenci Listesi'!B16="",T15=""),"",IF(T15="Çok İyi",CHOOSE(RANDBETWEEN(1,5),4,4,4,4,3),IF(T15="İyi",CHOOSE(RANDBETWEEN(1,5),3,3,3,4,2),IF(T15="Yeterli",CHOOSE(RANDBETWEEN(1,5),2,2,2,3,1),IF(T15="Geliştirilmeli",CHOOSE(RANDBETWEEN(1,5),1,1,1,1,2),""))))) | N15: =IF(OR('Öğrenci Listesi'!B16="",T15=""),"",IF(T15="Çok İyi",CHOOSE(RANDBETWEEN(1,5),4,4,4,4,3),IF(T15="İyi",CHOOSE(RANDBETWEEN(1,5),3,3,3,4,2),IF(T15="Yeterli",CHOOSE(RANDBETWEEN(1,5),2,2,2,3,1),IF(T15="Geliştirilmeli",CHOOSE(RANDBETWEEN(1,5),1,1,1,1,2),""))))) | O15: =IF(OR('Öğrenci Listesi'!B16="",T15=""),"",IF(T15="Çok İyi",CHOOSE(RANDBETWEEN(1,5),4,4,4,4,3),IF(T15="İyi",CHOOSE(RANDBETWEEN(1,5),3,3,3,4,2),IF(T15="Yeterli",CHOOSE(RANDBETWEEN(1,5),2,2,2,3,1),IF(T15="Geliştirilmeli",CHOOSE(RANDBETWEEN(1,5),1,1,1,1,2),""))))) | P15: =IF(OR('Öğrenci Listesi'!B16="",T15=""),"",IF(T15="Çok İyi",CHOOSE(RANDBETWEEN(1,5),4,4,4,4,3),IF(T15="İyi",CHOOSE(RANDBETWEEN(1,5),3,3,3,4,2),IF(T15="Yeterli",CHOOSE(RANDBETWEEN(1,5),2,2,2,3,1),IF(T15="Geliştirilmeli",CHOOSE(RANDBETWEEN(1,5),1,1,1,1,2),""))))) | Q15: =IF(OR('Öğrenci Listesi'!B16="",T15=""),"",IF(T15="Çok İyi",CHOOSE(RANDBETWEEN(1,5),4,4,4,4,3),IF(T15="İyi",CHOOSE(RANDBETWEEN(1,5),3,3,3,4,2),IF(T15="Yeterli",CHOOSE(RANDBETWEEN(1,5),2,2,2,3,1),IF(T15="Geliştirilmeli",CHOOSE(RANDBETWEEN(1,5),1,1,1,1,2),""))))) | R15: =IF(OR('Öğrenci Listesi'!B16="",T15=""),"",IF(T15="Çok İyi",CHOOSE(RANDBETWEEN(1,5),4,4,4,4,3),IF(T15="İyi",CHOOSE(RANDBETWEEN(1,5),3,3,3,4,2),IF(T15="Yeterli",CHOOSE(RANDBETWEEN(1,5),2,2,2,3,1),IF(T15="Geliştirilmeli",CHOOSE(RANDBETWEEN(1,5),1,1,1,1,2),""))))) | S15: =IF(OR('Öğrenci Listesi'!B16="",T15=""),"",ROUND(AVERAGE(C15:R15),2)) | T15: =IFERROR(IF('Öğrenci Listesi'!G16="","",IF(UPPER(TRIM('Öğrenci Listesi'!G16))="ÇOK İYİ","Çok İyi",IF(UPPER(TRIM('Öğrenci Listesi'!G16))="İYİ","İyi",IF(UPPER(TRIM('Öğrenci Listesi'!G16))="YETERLİ","Yeterli",IF(UPPER(TRIM('Öğrenci Listesi'!G16))="GELİŞTİRİLMELİ","Geliştirilmeli",'Öğrenci Listesi'!G16))))),"")
A16: =IFERROR(IF('Öğrenci Listesi'!A17="","",'Öğrenci Listesi'!A17),"") | B16: =IFERROR(IF('Öğrenci Listesi'!B17="","",'Öğrenci Listesi'!B17),"") | C16: =IF(OR('Öğrenci Listesi'!B17="",T16=""),"",IF(T16="Çok İyi",CHOOSE(RANDBETWEEN(1,5),4,4,4,4,3),IF(T16="İyi",CHOOSE(RANDBETWEEN(1,5),3,3,3,4,2),IF(T16="Yeterli",CHOOSE(RANDBETWEEN(1,5),2,2,2,3,1),IF(T16="Geliştirilmeli",CHOOSE(RANDBETWEEN(1,5),1,1,1,1,2),""))))) | D16: =IF(OR('Öğrenci Listesi'!B17="",T16=""),"",IF(T16="Çok İyi",CHOOSE(RANDBETWEEN(1,5),4,4,4,4,3),IF(T16="İyi",CHOOSE(RANDBETWEEN(1,5),3,3,3,4,2),IF(T16="Yeterli",CHOOSE(RANDBETWEEN(1,5),2,2,2,3,1),IF(T16="Geliştirilmeli",CHOOSE(RANDBETWEEN(1,5),1,1,1,1,2),""))))) | E16: =IF(OR('Öğrenci Listesi'!B17="",T16=""),"",IF(T16="Çok İyi",CHOOSE(RANDBETWEEN(1,5),4,4,4,4,3),IF(T16="İyi",CHOOSE(RANDBETWEEN(1,5),3,3,3,4,2),IF(T16="Yeterli",CHOOSE(RANDBETWEEN(1,5),2,2,2,3,1),IF(T16="Geliştirilmeli",CHOOSE(RANDBETWEEN(1,5),1,1,1,1,2),""))))) | F16: =IF(OR('Öğrenci Listesi'!B17="",T16=""),"",IF(T16="Çok İyi",CHOOSE(RANDBETWEEN(1,5),4,4,4,4,3),IF(T16="İyi",CHOOSE(RANDBETWEEN(1,5),3,3,3,4,2),IF(T16="Yeterli",CHOOSE(RANDBETWEEN(1,5),2,2,2,3,1),IF(T16="Geliştirilmeli",CHOOSE(RANDBETWEEN(1,5),1,1,1,1,2),""))))) | G16: =IF(OR('Öğrenci Listesi'!B17="",T16=""),"",IF(T16="Çok İyi",CHOOSE(RANDBETWEEN(1,5),4,4,4,4,3),IF(T16="İyi",CHOOSE(RANDBETWEEN(1,5),3,3,3,4,2),IF(T16="Yeterli",CHOOSE(RANDBETWEEN(1,5),2,2,2,3,1),IF(T16="Geliştirilmeli",CHOOSE(RANDBETWEEN(1,5),1,1,1,1,2),""))))) | H16: =IF(OR('Öğrenci Listesi'!B17="",T16=""),"",IF(T16="Çok İyi",CHOOSE(RANDBETWEEN(1,5),4,4,4,4,3),IF(T16="İyi",CHOOSE(RANDBETWEEN(1,5),3,3,3,4,2),IF(T16="Yeterli",CHOOSE(RANDBETWEEN(1,5),2,2,2,3,1),IF(T16="Geliştirilmeli",CHOOSE(RANDBETWEEN(1,5),1,1,1,1,2),""))))) | I16: =IF(OR('Öğrenci Listesi'!B17="",T16=""),"",IF(T16="Çok İyi",CHOOSE(RANDBETWEEN(1,5),4,4,4,4,3),IF(T16="İyi",CHOOSE(RANDBETWEEN(1,5),3,3,3,4,2),IF(T16="Yeterli",CHOOSE(RANDBETWEEN(1,5),2,2,2,3,1),IF(T16="Geliştirilmeli",CHOOSE(RANDBETWEEN(1,5),1,1,1,1,2),""))))) | J16: =IF(OR('Öğrenci Listesi'!B17="",T16=""),"",IF(T16="Çok İyi",CHOOSE(RANDBETWEEN(1,5),4,4,4,4,3),IF(T16="İyi",CHOOSE(RANDBETWEEN(1,5),3,3,3,4,2),IF(T16="Yeterli",CHOOSE(RANDBETWEEN(1,5),2,2,2,3,1),IF(T16="Geliştirilmeli",CHOOSE(RANDBETWEEN(1,5),1,1,1,1,2),""))))) | K16: =IF(OR('Öğrenci Listesi'!B17="",T16=""),"",IF(T16="Çok İyi",CHOOSE(RANDBETWEEN(1,5),4,4,4,4,3),IF(T16="İyi",CHOOSE(RANDBETWEEN(1,5),3,3,3,4,2),IF(T16="Yeterli",CHOOSE(RANDBETWEEN(1,5),2,2,2,3,1),IF(T16="Geliştirilmeli",CHOOSE(RANDBETWEEN(1,5),1,1,1,1,2),""))))) | L16: =IF(OR('Öğrenci Listesi'!B17="",T16=""),"",IF(T16="Çok İyi",CHOOSE(RANDBETWEEN(1,5),4,4,4,4,3),IF(T16="İyi",CHOOSE(RANDBETWEEN(1,5),3,3,3,4,2),IF(T16="Yeterli",CHOOSE(RANDBETWEEN(1,5),2,2,2,3,1),IF(T16="Geliştirilmeli",CHOOSE(RANDBETWEEN(1,5),1,1,1,1,2),""))))) | M16: =IF(OR('Öğrenci Listesi'!B17="",T16=""),"",IF(T16="Çok İyi",CHOOSE(RANDBETWEEN(1,5),4,4,4,4,3),IF(T16="İyi",CHOOSE(RANDBETWEEN(1,5),3,3,3,4,2),IF(T16="Yeterli",CHOOSE(RANDBETWEEN(1,5),2,2,2,3,1),IF(T16="Geliştirilmeli",CHOOSE(RANDBETWEEN(1,5),1,1,1,1,2),""))))) | N16: =IF(OR('Öğrenci Listesi'!B17="",T16=""),"",IF(T16="Çok İyi",CHOOSE(RANDBETWEEN(1,5),4,4,4,4,3),IF(T16="İyi",CHOOSE(RANDBETWEEN(1,5),3,3,3,4,2),IF(T16="Yeterli",CHOOSE(RANDBETWEEN(1,5),2,2,2,3,1),IF(T16="Geliştirilmeli",CHOOSE(RANDBETWEEN(1,5),1,1,1,1,2),""))))) | O16: =IF(OR('Öğrenci Listesi'!B17="",T16=""),"",IF(T16="Çok İyi",CHOOSE(RANDBETWEEN(1,5),4,4,4,4,3),IF(T16="İyi",CHOOSE(RANDBETWEEN(1,5),3,3,3,4,2),IF(T16="Yeterli",CHOOSE(RANDBETWEEN(1,5),2,2,2,3,1),IF(T16="Geliştirilmeli",CHOOSE(RANDBETWEEN(1,5),1,1,1,1,2),""))))) | P16: =IF(OR('Öğrenci Listesi'!B17="",T16=""),"",IF(T16="Çok İyi",CHOOSE(RANDBETWEEN(1,5),4,4,4,4,3),IF(T16="İyi",CHOOSE(RANDBETWEEN(1,5),3,3,3,4,2),IF(T16="Yeterli",CHOOSE(RANDBETWEEN(1,5),2,2,2,3,1),IF(T16="Geliştirilmeli",CHOOSE(RANDBETWEEN(1,5),1,1,1,1,2),""))))) | Q16: =IF(OR('Öğrenci Listesi'!B17="",T16=""),"",IF(T16="Çok İyi",CHOOSE(RANDBETWEEN(1,5),4,4,4,4,3),IF(T16="İyi",CHOOSE(RANDBETWEEN(1,5),3,3,3,4,2),IF(T16="Yeterli",CHOOSE(RANDBETWEEN(1,5),2,2,2,3,1),IF(T16="Geliştirilmeli",CHOOSE(RANDBETWEEN(1,5),1,1,1,1,2),""))))) | R16: =IF(OR('Öğrenci Listesi'!B17="",T16=""),"",IF(T16="Çok İyi",CHOOSE(RANDBETWEEN(1,5),4,4,4,4,3),IF(T16="İyi",CHOOSE(RANDBETWEEN(1,5),3,3,3,4,2),IF(T16="Yeterli",CHOOSE(RANDBETWEEN(1,5),2,2,2,3,1),IF(T16="Geliştirilmeli",CHOOSE(RANDBETWEEN(1,5),1,1,1,1,2),""))))) | S16: =IF(OR('Öğrenci Listesi'!B17="",T16=""),"",ROUND(AVERAGE(C16:R16),2)) | T16: =IFERROR(IF('Öğrenci Listesi'!G17="","",IF(UPPER(TRIM('Öğrenci Listesi'!G17))="ÇOK İYİ","Çok İyi",IF(UPPER(TRIM('Öğrenci Listesi'!G17))="İYİ","İyi",IF(UPPER(TRIM('Öğrenci Listesi'!G17))="YETERLİ","Yeterli",IF(UPPER(TRIM('Öğrenci Listesi'!G17))="GELİŞTİRİLMELİ","Geliştirilmeli",'Öğrenci Listesi'!G17))))),"")
