Workbook

Sheet Bilgiler
A1: 📝 BİLGİLERİ DOLDURUNUZ
A2: Aşağıdaki bilgileri kendi okulunuza ve sınıfınıza göre doldurun. 'Ölçek' sayfasındaki başlıklar otomatik güncellenecek.
A4: Okul Adı
A5: Eğitim Öğretim Yılı
A6: Sınıf / Şube
A7: Dönem
A8: Ders | B8: Beden Eğitimi ve Oyun
A9: Sınıf Öğretmeni
A10: Okul Müdürü

Sheet Öğrenci Listesi
A1: 📋 SİSTEMDEN ÖĞRENCİ LİSTESİNİ BURAYA YAPIŞTIRIN
A2: Sistemde notları işaretledikten sonra tüm tabloyu kopyalayın (Ctrl+C), aşağıdaki sarı alana yapıştırın (Ctrl+V).
A3: ✓ Öğrenci adları, numaraları ve seviyeler 'Ölçek' sayfasına otomatik aktarılacak.
A5: NO | B5: ADI SOYADI | C5: Geliştirilmeli | D5: Yeterli | E5: İyi | F5: Çok İyi | G5: SONUÇ | H5: (yok sayılır)

Sheet Ölçek
A1: =Bilgiler!B4&" • "&Bilgiler!B5&" EĞİTİM ÖĞRETİM YILI"
A2: =Bilgiler!B6&" SINIFI "&Bilgiler!B7&" "&Bilgiler!B8&" DERSİ KAZANIM DEĞERLENDİRME ÖLÇEĞİ"
A4: NO | B4: ADI VE SOYADI | C4: Yer değiştirme hareketlerini artan çeviklikle yapar | D4: Yer değiştirme hareketlerini vücut farkındalığıyla yapar | E4: Çeşitli nesnelerin üzerinde dengeleme hareketleri yapar | F4: Dengeleme hareketlerini artan doğrulukla yapar | G4: Nesne kontrolü hareketlerini artan beceriyle yapar | H4: Ritmik hareketleri müzikle koordineli yapar | I4: Temel jimnastik hareketlerini doğru teknikle uygular | J4: Atletizm temel hareketlerini uygular | K4: Kurallı oyunlarda iş birliği yaparak oynar | L4: Oyunlarda adil oyun ilkelerine uyar | M4: Geleneksel oyunları oynar | N4: Takım oyunlarında görev alır | O4: Oyunlarda kazanmayı ve kaybetmeyi olgunlukla karşılar | P4: Oyunlarda güvenlik kurallarına uyar | Q4: Farklı oyun aletlerini kullanır | R4: Yaratıcı hareket oyunlarına katılır | S4: Egzersiz öncesi ısınma yapar | T4: Düzenli fiziksel aktivitenin önemini açıklar | U4: Sağlıklı beslenme ile spor ilişkisini açıklar | V4: Temizlik ve hijyen kurallarını uygular | W4: Beden eğitiminde güvenlik kurallarını uygular | X4: Türk sporcularını ve başarılarını araştırır | Y4: Olimpiyat oyunlarını tanır | Z4: Fair play kavramını örneklerle açıklar | AA4: Sporu bir yaşam biçimi olarak benimser | AB4: ORTALAMA | AC4: SEVİYE
A5: =IFERROR(IF('Öğrenci Listesi'!A6="","",'Öğrenci Listesi'!A6),"") | B5: =IFERROR(IF('Öğrenci Listesi'!B6="","",'Öğrenci Listesi'!B6),"") | C5: =IF(OR('Öğrenci Listesi'!B6="",AC5=""),"",IF(AC5="Çok İyi",CHOOSE(RANDBETWEEN(1,5),4,4,4,4,3),IF(AC5="İyi",CHOOSE(RANDBETWEEN(1,5),3,3,3,4,2),IF(AC5="Yeterli",CHOOSE(RANDBETWEEN(1,5),2,2,2,3,1),IF(AC5="Geliştirilmeli",CHOOSE(RANDBETWEEN(1,5),1,1,1,1,2),""))))) | D5: =IF(OR('Öğrenci Listesi'!B6="",AC5=""),"",IF(AC5="Çok İyi",CHOOSE(RANDBETWEEN(1,5),4,4,4,4,3),IF(AC5="İyi",CHOOSE(RANDBETWEEN(1,5),3,3,3,4,2),IF(AC5="Yeterli",CHOOSE(RANDBETWEEN(1,5),2,2,2,3,1),IF(AC5="Geliştirilmeli",CHOOSE(RANDBETWEEN(1,5),1,1,1,1,2),""))))) | E5: =IF(OR('Öğrenci Listesi'!B6="",AC5=""),"",IF(AC5="Çok İyi",CHOOSE(RANDBETWEEN(1,5),4,4,4,4,3),IF(AC5="İyi",CHOOSE(RANDBETWEEN(1,5),3,3,3,4,2),IF(AC5="Yeterli",CHOOSE(RANDBETWEEN(1,5),2,2,2,3,1),IF(AC5="Geliştirilmeli",CHOOSE(RANDBETWEEN(1,5),1,1,1,1,2),""))))) | F5: =IF(OR('Öğrenci Listesi'!B6="",AC5=""),"",IF(AC5="Çok İyi",CHOOSE(RANDBETWEEN(1,5),4,4,4,4,3),IF(AC5="İyi",CHOOSE(RANDBETWEEN(1,5),3,3,3,4,2),IF(AC5="Yeterli",CHOOSE(RANDBETWEEN(1,5),2,2,2,3,1),IF(AC5="Geliştirilmeli",CHOOSE(RANDBETWEEN(1,5),1,1,1,1,2),""))))) | G5: =IF(OR('Öğrenci Listesi'!B6="",AC5=""),"",IF(AC5="Çok İyi",CHOOSE(RANDBETWEEN(1,5),4,4,4,4,3),IF(AC5="İyi",CHOOSE(RANDBETWEEN(1,5),3,3,3,4,2),IF(AC5="Yeterli",CHOOSE(RANDBETWEEN(1,5),2,2,2,3,1),IF(AC5="Geliştirilmeli",CHOOSE(RANDBETWEEN(1,5),1,1,1,1,2),""))))) | H5: =IF(OR('Öğrenci Listesi'!B6="",AC5=""),"",IF(AC5="Çok İyi",CHOOSE(RANDBETWEEN(1,5),4,4,4,4,3),IF(AC5="İyi",CHOOSE(RANDBETWEEN(1,5),3,3,3,4,2),IF(AC5="Yeterli",CHOOSE(RANDBETWEEN(1,5),2,2,2,3,1),IF(AC5="Geliştirilmeli",CHOOSE(RANDBETWEEN(1,5),1,1,1,1,2),""))))) | I5: =IF(OR('Öğrenci Listesi'!B6="",AC5=""),"",IF(AC5="Çok İyi",CHOOSE(RANDBETWEEN(1,5),4,4,4,4,3),IF(AC5="İyi",CHOOSE(RANDBETWEEN(1,5),3,3,3,4,2),IF(AC5="Yeterli",CHOOSE(RANDBETWEEN(1,5),2,2,2,3,1),IF(AC5="Geliştirilmeli",CHOOSE(RANDBETWEEN(1,5),1,1,1,1,2),""))))) | J5: =IF(OR('Öğrenci Listesi'!B6="",AC5=""),"",IF(AC5="Çok İyi",CHOOSE(RANDBETWEEN(1,5),4,4,4,4,3),IF(AC5="İyi",CHOOSE(RANDBETWEEN(1,5),3,3,3,4,2),IF(AC5="Yeterli",CHOOSE(RANDBETWEEN(1,5),2,2,2,3,1),IF(AC5="Geliştirilmeli",CHOOSE(RANDBETWEEN(1,5),1,1,1,1,2),""))))) | K5: =IF(OR('Öğrenci Listesi'!B6="",AC5=""),"",IF(AC5="Çok İyi",CHOOSE(RANDBETWEEN(1,5),4,4,4,4,3),IF(AC5="İyi",CHOOSE(RANDBETWEEN(1,5),3,3,3,4,2),IF(AC5="Yeterli",CHOOSE(RANDBETWEEN(1,5),2,2,2,3,1),IF(AC5="Geliştirilmeli",CHOOSE(RANDBETWEEN(1,5),1,1,1,1,2),""))))) | L5: =IF(OR('Öğrenci Listesi'!B6="",AC5=""),"",IF(AC5="Çok İyi",CHOOSE(RANDBETWEEN(1,5),4,4,4,4,3),IF(AC5="İyi",CHOOSE(RANDBETWEEN(1,5),3,3,3,4,2),IF(AC5="Yeterli",CHOOSE(RANDBETWEEN(1,5),2,2,2,3,1),IF(AC5="Geliştirilmeli",CHOOSE(RANDBETWEEN(1,5),1,1,1,1,2),""))))) | M5: =IF(OR('Öğrenci Listesi'!B6="",AC5=""),"",IF(AC5="Çok İyi",CHOOSE(RANDBETWEEN(1,5),4,4,4,4,3),IF(AC5="İyi",CHOOSE(RANDBETWEEN(1,5),3,3,3,4,2),IF(AC5="Yeterli",CHOOSE(RANDBETWEEN(1,5),2,2,2,3,1),IF(AC5="Geliştirilmeli",CHOOSE(RANDBETWEEN(1,5),1,1,1,1,2),""))))) | N5: =IF(OR('Öğrenci Listesi'!B6="",AC5=""),"",IF(AC5="Çok İyi",CHOOSE(RANDBETWEEN(1,5),4,4,4,4,3),IF(AC5="İyi",CHOOSE(RANDBETWEEN(1,5),3,3,3,4,2),IF(AC5="Yeterli",CHOOSE(RANDBETWEEN(1,5),2,2,2,3,1),IF(AC5="Geliştirilmeli",CHOOSE(RANDBETWEEN(1,5),1,1,1,1,2),""))))) | O5: =IF(OR('Öğrenci Listesi'!B6="",AC5=""),"",IF(AC5="Çok İyi",CHOOSE(RANDBETWEEN(1,5),4,4,4,4,3),IF(AC5="İyi",CHOOSE(RANDBETWEEN(1,5),3,3,3,4,2),IF(AC5="Yeterli",CHOOSE(RANDBETWEEN(1,5),2,2,2,3,1),IF(AC5="Geliştirilmeli",CHOOSE(RANDBETWEEN(1,5),1,1,1,1,2),""))))) | P5: =IF(OR('Öğrenci Listesi'!B6="",AC5=""),"",IF(AC5="Çok İyi",CHOOSE(RANDBETWEEN(1,5),4,4,4,4,3),IF(AC5="İyi",CHOOSE(RANDBETWEEN(1,5),3,3,3,4,2),IF(AC5="Yeterli",CHOOSE(RANDBETWEEN(1,5),2,2,2,3,1),IF(AC5="Geliştirilmeli",CHOOSE(RANDBETWEEN(1,5),1,1,1,1,2),""))))) | Q5: =IF(OR('Öğrenci Listesi'!B6="",AC5=""),"",IF(AC5="Çok İyi",CHOOSE(RANDBETWEEN(1,5),4,4,4,4,3),IF(AC5="İyi",CHOOSE(RANDBETWEEN(1,5),3,3,3,4,2),IF(AC5="Yeterli",CHOOSE(RANDBETWEEN(1,5),2,2,2,3,1),IF(AC5="Geliştirilmeli",CHOOSE(RANDBETWEEN(1,5),1,1,1,1,2),""))))) | R5: =IF(OR('Öğrenci Listesi'!B6="",AC5=""),"",IF(AC5="Çok İyi",CHOOSE(RANDBETWEEN(1,5),4,4,4,4,3),IF(AC5="İyi",CHOOSE(RANDBETWEEN(1,5),3,3,3,4,2),IF(AC5="Yeterli",CHOOSE(RANDBETWEEN(1,5),2,2,2,3,1),IF(AC5="Geliştirilmeli",CHOOSE(RANDBETWEEN(1,5),1,1,1,1,2),""))))) | S5: =IF(OR('Öğrenci Listesi'!B6="",AC5=""),"",IF(AC5="Çok İyi",CHOOSE(RANDBETWEEN(1,5),4,4,4,4,3),IF(AC5="İyi",CHOOSE(RANDBETWEEN(1,5),3,3,3,4,2),IF(AC5="Yeterli",CHOOSE(RANDBETWEEN(1,5),2,2,2,3,1),IF(AC5="Geliştirilmeli",CHOOSE(RANDBETWEEN(1,5),1,1,1,1,2),""))))) | T5: =IF(OR('Öğrenci Listesi'!B6="",AC5=""),"",IF(AC5="Çok İyi",CHOOSE(RANDBETWEEN(1,5),4,4,4,4,3),IF(AC5="İyi",CHOOSE(RANDBETWEEN(1,5),3,3,3,4,2),IF(AC5="Yeterli",CHOOSE(RANDBETWEEN(1,5),2,2,2,3,1),IF(AC5="Geliştirilmeli",CHOOSE(RANDBETWEEN(1,5),1,1,1,1,2),""))))) | U5: =IF(OR('Öğrenci Listesi'!B6="",AC5=""),"",IF(AC5="Çok İyi",CHOOSE(RANDBETWEEN(1,5),4,4,4,4,3),IF(AC5="İyi",CHOOSE(RANDBETWEEN(1,5),3,3,3,4,2),IF(AC5="Yeterli",CHOOSE(RANDBETWEEN(1,5),2,2,2,3,1),IF(AC5="Geliştirilmeli",CHOOSE(RANDBETWEEN(1,5),1,1,1,1,2),""))))) | V5: =IF(OR('Öğrenci Listesi'!B6="",AC5=""),"",IF(AC5="Çok İyi",CHOOSE(RANDBETWEEN(1,5),4,4,4,4,3),IF(AC5="İyi",CHOOSE(RANDBETWEEN(1,5),3,3,3,4,2),IF(AC5="Yeterli",CHOOSE(RANDBETWEEN(1,5),2,2,2,3,1),IF(AC5="Geliştirilmeli",CHOOSE(RANDBETWEEN(1,5),1,1,1,1,2),""))))) | W5: =IF(OR('Öğrenci Listesi'!B6="",AC5=""),"",IF(AC5="Çok İyi",CHOOSE(RANDBETWEEN(1,5),4,4,4,4,3),IF(AC5="İyi",CHOOSE(RANDBETWEEN(1,5),3,3,3,4,2),IF(AC5="Yeterli",CHOOSE(RANDBETWEEN(1,5),2,2,2,3,1),IF(AC5="Geliştirilmeli",CHOOSE(RANDBETWEEN(1,5),1,1,1,1,2),""))))) | X5: =IF(OR('Öğrenci Listesi'!B6="",AC5=""),"",IF(AC5="Çok İyi",CHOOSE(RANDBETWEEN(1,5),4,4,4,4,3),IF(AC5="İyi",CHOOSE(RANDBETWEEN(1,5),3,3,3,4,2),IF(AC5="Yeterli",CHOOSE(RANDBETWEEN(1,5),2,2,2,3,1),IF(AC5="Geliştirilmeli",CHOOSE(RANDBETWEEN(1,5),1,1,1,1,2),""))))) | Y5: =IF(OR('Öğrenci Listesi'!B6="",AC5=""),"",IF(AC5="Çok İyi",CHOOSE(RANDBETWEEN(1,5),4,4,4,4,3),IF(AC5="İyi",CHOOSE(RANDBETWEEN(1,5),3,3,3,4,2),IF(AC5="Yeterli",CHOOSE(RANDBETWEEN(1,5),2,2,2,3,1),IF(AC5="Geliştirilmeli",CHOOSE(RANDBETWEEN(1,5),1,1,1,1,2),""))))) | Z5: =IF(OR('Öğrenci Listesi'!B6="",AC5=""),"",IF(AC5="Çok İyi",CHOOSE(RANDBETWEEN(1,5),4,4,4,4,3),IF(AC5="İyi",CHOOSE(RANDBETWEEN(1,5),3,3,3,4,2),IF(AC5="Yeterli",CHOOSE(RANDBETWEEN(1,5),2,2,2,3,1),IF(AC5="Geliştirilmeli",CHOOSE(RANDBETWEEN(1,5),1,1,1,1,2),""))))) | AA5: =IF(OR('Öğrenci Listesi'!B6="",AC5=""),"",IF(AC5="Çok İyi",CHOOSE(RANDBETWEEN(1,5),4,4,4,4,3),IF(AC5="İyi",CHOOSE(RANDBETWEEN(1,5),3,3,3,4,2),IF(AC5="Yeterli",CHOOSE(RANDBETWEEN(1,5),2,2,2,3,1),IF(AC5="Geliştirilmeli",CHOOSE(RANDBETWEEN(1,5),1,1,1,1,2),""))))) | AB5: =IF(OR('Öğrenci Listesi'!B6="",AC5=""),"",ROUND(AVERAGE(C5:AA5),2)) | AC5: =IFERROR(IF('Öğrenci Listesi'!G6="","",IF(UPPER(TRIM('Öğrenci Listesi'!G6))="ÇOK İYİ","Çok İyi",IF(UPPER(TRIM('Öğrenci Listesi'!G6))="İYİ","İyi",IF(UPPER(TRIM('Öğrenci Listesi'!G6))="YETERLİ","Yeterli",IF(UPPER(TRIM('Öğrenci Listesi'!G6))="GELİŞTİRİLMELİ","Geliştirilmeli",'Öğrenci Listesi'!G6))))),"")
A6: =IFERROR(IF('Öğrenci Listesi'!A7="","",'Öğrenci Listesi'!A7),"") | B6: =IFERROR(IF('Öğrenci Listesi'!B7="","",'Öğrenci Listesi'!B7),"") | C6: =IF(OR('Öğrenci Listesi'!B7="",AC6=""),"",IF(AC6="Çok İyi",CHOOSE(RANDBETWEEN(1,5),4,4,4,4,3),IF(AC6="İyi",CHOOSE(RANDBETWEEN(1,5),3,3,3,4,2),IF(AC6="Yeterli",CHOOSE(RANDBETWEEN(1,5),2,2,2,3,1),IF(AC6="Geliştirilmeli",CHOOSE(RANDBETWEEN(1,5),1,1,1,1,2),""))))) | D6: =IF(OR('Öğrenci Listesi'!B7="",AC6=""),"",IF(AC6="Çok İyi",CHOOSE(RANDBETWEEN(1,5),4,4,4,4,3),IF(AC6="İyi",CHOOSE(RANDBETWEEN(1,5),3,3,3,4,2),IF(AC6="Yeterli",CHOOSE(RANDBETWEEN(1,5),2,2,2,3,1),IF(AC6="Geliştirilmeli",CHOOSE(RANDBETWEEN(1,5),1,1,1,1,2),""))))) | E6: =IF(OR('Öğrenci Listesi'!B7="",AC6=""),"",IF(AC6="Çok İyi",CHOOSE(RANDBETWEEN(1,5),4,4,4,4,3),IF(AC6="İyi",CHOOSE(RANDBETWEEN(1,5),3,3,3,4,2),IF(AC6="Yeterli",CHOOSE(RANDBETWEEN(1,5),2,2,2,3,1),IF(AC6="Geliştirilmeli",CHOOSE(RANDBETWEEN(1,5),1,1,1,1,2),""))))) | F6: =IF(OR('Öğrenci Listesi'!B7="",AC6=""),"",IF(AC6="Çok İyi",CHOOSE(RANDBETWEEN(1,5),4,4,4,4,3),IF(AC6="İyi",CHOOSE(RANDBETWEEN(1,5),3,3,3,4,2),IF(AC6="Yeterli",CHOOSE(RANDBETWEEN(1,5),2,2,2,3,1),IF(AC6="Geliştirilmeli",CHOOSE(RANDBETWEEN(1,5),1,1,1,1,2),""))))) | G6: =IF(OR('Öğrenci Listesi'!B7="",AC6=""),"",IF(AC6="Çok İyi",CHOOSE(RANDBETWEEN(1,5),4,4,4,4,3),IF(AC6="İyi",CHOOSE(RANDBETWEEN(1,5),3,3,3,4,2),IF(AC6="Yeterli",CHOOSE(RANDBETWEEN(1,5),2,2,2,3,1),IF(AC6="Geliştirilmeli",CHOOSE(RANDBETWEEN(1,5),1,1,1,1,2),""))))) | H6: =IF(OR('Öğrenci Listesi'!B7="",AC6=""),"",IF(AC6="Çok İyi",CHOOSE(RANDBETWEEN(1,5),4,4,4,4,3),IF(AC6="İyi",CHOOSE(RANDBETWEEN(1,5),3,3,3,4,2),IF(AC6="Yeterli",CHOOSE(RANDBETWEEN(1,5),2,2,2,3,1),IF(AC6="Geliştirilmeli",CHOOSE(RANDBETWEEN(1,5),1,1,1,1,2),""))))) | I6: =IF(OR('Öğrenci Listesi'!B7="",AC6=""),"",IF(AC6="Çok İyi",CHOOSE(RANDBETWEEN(1,5),4,4,4,4,3),IF(AC6="İyi",CHOOSE(RANDBETWEEN(1,5),3,3,3,4,2),IF(AC6="Yeterli",CHOOSE(RANDBETWEEN(1,5),2,2,2,3,1),IF(AC6="Geliştirilmeli",CHOOSE(RANDBETWEEN(1,5),1,1,1,1,2),""))))) | J6: =IF(OR('Öğrenci Listesi'!B7="",AC6=""),"",IF(AC6="Çok İyi",CHOOSE(RANDBETWEEN(1,5),4,4,4,4,3),IF(AC6="İyi",CHOOSE(RANDBETWEEN(1,5),3,3,3,4,2),IF(AC6="Yeterli",CHOOSE(RANDBETWEEN(1,5),2,2,2,3,1),IF(AC6="Geliştirilmeli",CHOOSE(RANDBETWEEN(1,5),1,1,1,1,2),""))))) | K6: =IF(OR('Öğrenci Listesi'!B7="",AC6=""),"",IF(AC6="Çok İyi",CHOOSE(RANDBETWEEN(1,5),4,4,4,4,3),IF(AC6="İyi",CHOOSE(RANDBETWEEN(1,5),3,3,3,4,2),IF(AC6="Yeterli",CHOOSE(RANDBETWEEN(1,5),2,2,2,3,1),IF(AC6="Geliştirilmeli",CHOOSE(RANDBETWEEN(1,5),1,1,1,1,2),""))))) | L6: =IF(OR('Öğrenci Listesi'!B7="",AC6=""),"",IF(AC6="Çok İyi",CHOOSE(RANDBETWEEN(1,5),4,4,4,4,3),IF(AC6="İyi",CHOOSE(RANDBETWEEN(1,5),3,3,3,4,2),IF(AC6="Yeterli",CHOOSE(RANDBETWEEN(1,5),2,2,2,3,1),IF(AC6="Geliştirilmeli",CHOOSE(RANDBETWEEN(1,5),1,1,1,1,2),""))))) | M6: =IF(OR('Öğrenci Listesi'!B7="",AC6=""),"",IF(AC6="Çok İyi",CHOOSE(RANDBETWEEN(1,5),4,4,4,4,3),IF(AC6="İyi",CHOOSE(RANDBETWEEN(1,5),3,3,3,4,2),IF(AC6="Yeterli",CHOOSE(RANDBETWEEN(1,5),2,2,2,3,1),IF(AC6="Geliştirilmeli",CHOOSE(RANDBETWEEN(1,5),1,1,1,1,2),""))))) | N6: =IF(OR('Öğrenci Listesi'!B7="",AC6=""),"",IF(AC6="Çok İyi",CHOOSE(RANDBETWEEN(1,5),4,4,4,4,3),IF(AC6="İyi",CHOOSE(RANDBETWEEN(1,5),3,3,3,4,2),IF(AC6="Yeterli",CHOOSE(RANDBETWEEN(1,5),2,2,2,3,1),IF(AC6="Geliştirilmeli",CHOOSE(RANDBETWEEN(1,5),1,1,1,1,2),""))))) | O6: =IF(OR('Öğrenci Listesi'!B7="",AC6=""),"",IF(AC6="Çok İyi",CHOOSE(RANDBETWEEN(1,5),4,4,4,4,3),IF(AC6="İyi",CHOOSE(RANDBETWEEN(1,5),3,3,3,4,2),IF(AC6="Yeterli",CHOOSE(RANDBETWEEN(1,5),2,2,2,3,1),IF(AC6="Geliştirilmeli",CHOOSE(RANDBETWEEN(1,5),1,1,1,1,2),""))))) | P6: =IF(OR('Öğrenci Listesi'!B7="",AC6=""),"",IF(AC6="Çok İyi",CHOOSE(RANDBETWEEN(1,5),4,4,4,4,3),IF(AC6="İyi",CHOOSE(RANDBETWEEN(1,5),3,3,3,4,2),IF(AC6="Yeterli",CHOOSE(RANDBETWEEN(1,5),2,2,2,3,1),IF(AC6="Geliştirilmeli",CHOOSE(RANDBETWEEN(1,5),1,1,1,1,2),""))))) | Q6: =IF(OR('Öğrenci Listesi'!B7="",AC6=""),"",IF(AC6="Çok İyi",CHOOSE(RANDBETWEEN(1,5),4,4,4,4,3),IF(AC6="İyi",CHOOSE(RANDBETWEEN(1,5),3,3,3,4,2),IF(AC6="Yeterli",CHOOSE(RANDBETWEEN(1,5),2,2,2,3,1),IF(AC6="Geliştirilmeli",CHOOSE(RANDBETWEEN(1,5),1,1,1,1,2),""))))) | R6: =IF(OR('Öğrenci Listesi'!B7="",AC6=""),"",IF(AC6="Çok İyi",CHOOSE(RANDBETWEEN(1,5),4,4,4,4,3),IF(AC6="İyi",CHOOSE(RANDBETWEEN(1,5),3,3,3,4,2),IF(AC6="Yeterli",CHOOSE(RANDBETWEEN(1,5),2,2,2,3,1),IF(AC6="Geliştirilmeli",CHOOSE(RANDBETWEEN(1,5),1,1,1,1,2),""))))) | S6: =IF(OR('Öğrenci Listesi'!B7="",AC6=""),"",IF(AC6="Çok İyi",CHOOSE(RANDBETWEEN(1,5),4,4,4,4,3),IF(AC6="İyi",CHOOSE(RANDBETWEEN(1,5),3,3,3,4,2),IF(AC6="Yeterli",CHOOSE(RANDBETWEEN(1,5),2,2,2,3,1),IF(AC6="Geliştirilmeli",CHOOSE(RANDBETWEEN(1,5),1,1,1,1,2),""))))) | T6: =IF(OR('Öğrenci Listesi'!B7="",AC6=""),"",IF(AC6="Çok İyi",CHOOSE(RANDBETWEEN(1,5),4,4,4,4,3),IF(AC6="İyi",CHOOSE(RANDBETWEEN(1,5),3,3,3,4,2),IF(AC6="Yeterli",CHOOSE(RANDBETWEEN(1,5),2,2,2,3,1),IF(AC6="Geliştirilmeli",CHOOSE(RANDBETWEEN(1,5),1,1,1,1,2),""))))) | U6: =IF(OR('Öğrenci Listesi'!B7="",AC6=""),"",IF(AC6="Çok İyi",CHOOSE(RANDBETWEEN(1,5),4,4,4,4,3),IF(AC6="İyi",CHOOSE(RANDBETWEEN(1,5),3,3,3,4,2),IF(AC6="Yeterli",CHOOSE(RANDBETWEEN(1,5),2,2,2,3,1),IF(AC6="Geliştirilmeli",CHOOSE(RANDBETWEEN(1,5),1,1,1,1,2),""))))) | V6: =IF(OR('Öğrenci Listesi'!B7="",AC6=""),"",IF(AC6="Çok İyi",CHOOSE(RANDBETWEEN(1,5),4,4,4,4,3),IF(AC6="İyi",CHOOSE(RANDBETWEEN(1,5),3,3,3,4,2),IF(AC6="Yeterli",CHOOSE(RANDBETWEEN(1,5),2,2,2,3,1),IF(AC6="Geliştirilmeli",CHOOSE(RANDBETWEEN(1,5),1,1,1,1,2),""))))) | W6: =IF(OR('Öğrenci Listesi'!B7="",AC6=""),"",IF(AC6="Çok İyi",CHOOSE(RANDBETWEEN(1,5),4,4,4,4,3),IF(AC6="İyi",CHOOSE(RANDBETWEEN(1,5),3,3,3,4,2),IF(AC6="Yeterli",CHOOSE(RANDBETWEEN(1,5),2,2,2,3,1),IF(AC6="Geliştirilmeli",CHOOSE(RANDBETWEEN(1,5),1,1,1,1,2),""))))) | X6: =IF(OR('Öğrenci Listesi'!B7="",AC6=""),"",IF(AC6="Çok İyi",CHOOSE(RANDBETWEEN(1,5),4,4,4,4,3),IF(AC6="İyi",CHOOSE(RANDBETWEEN(1,5),3,3,3,4,2),IF(AC6="Yeterli",CHOOSE(RANDBETWEEN(1,5),2,2,2,3,1),IF(AC6="Geliştirilmeli",CHOOSE(RANDBETWEEN(1,5),1,1,1,1,2),""))))) | Y6: =IF(OR('Öğrenci Listesi'!B7="",AC6=""),"",IF(AC6="Çok İyi",CHOOSE(RANDBETWEEN(1,5),4,4,4,4,3),IF(AC6="İyi",CHOOSE(RANDBETWEEN(1,5),3,3,3,4,2),IF(AC6="Yeterli",CHOOSE(RANDBETWEEN(1,5),2,2,2,3,1),IF(AC6="Geliştirilmeli",CHOOSE(RANDBETWEEN(1,5),1,1,1,1,2),""))))) | Z6: =IF(OR('Öğrenci Listesi'!B7="",AC6=""),"",IF(AC6="Çok İyi",CHOOSE(RANDBETWEEN(1,5),4,4,4,4,3),IF(AC6="İyi",CHOOSE(RANDBETWEEN(1,5),3,3,3,4,2),IF(AC6="Yeterli",CHOOSE(RANDBETWEEN(1,5),2,2,2,3,1),IF(AC6="Geliştirilmeli",CHOOSE(RANDBETWEEN(1,5),1,1,1,1,2),""))))) | AA6: =IF(OR('Öğrenci Listesi'!B7="",AC6=""),"",IF(AC6="Çok İyi",CHOOSE(RANDBETWEEN(1,5),4,4,4,4,3),IF(AC6="İyi",CHOOSE(RANDBETWEEN(1,5),3,3,3,4,2),IF(AC6="Yeterli",CHOOSE(RANDBETWEEN(1,5),2,2,2,3,1),IF(AC6="Geliştirilmeli",CHOOSE(RANDBETWEEN(1,5),1,1,1,1,2),""))))) | AB6: =IF(OR('Öğrenci Listesi'!B7="",AC6=""),"",ROUND(AVERAGE(C6:AA6),2)) | AC6: =IFERROR(IF('Öğrenci Listesi'!G7="","",IF(UPPER(TRIM('Öğrenci Listesi'!G7))="ÇOK İYİ","Çok İyi",IF(UPPER(TRIM('Öğrenci Listesi'!G7))="İYİ","İyi",IF(UPPER(TRIM('Öğrenci Listesi'!G7))="YETERLİ","Yeterli",IF(UPPER(TRIM('Öğrenci Listesi'!G7))="GELİŞTİRİLMELİ","Geliştirilmeli",'Öğrenci Listesi'!G7))))),"")
A7: =IFERROR(IF('Öğrenci Listesi'!A8="","",'Öğrenci Listesi'!A8),"") | B7: =IFERROR(IF('Öğrenci Listesi'!B8="","",'Öğrenci Listesi'!B8),"") | C7: =IF(OR('Öğrenci Listesi'!B8="",AC7=""),"",IF(AC7="Çok İyi",CHOOSE(RANDBETWEEN(1,5),4,4,4,4,3),IF(AC7="İyi",CHOOSE(RANDBETWEEN(1,5),3,3,3,4,2),IF(AC7="Yeterli",CHOOSE(RANDBETWEEN(1,5),2,2,2,3,1),IF(AC7="Geliştirilmeli",CHOOSE(RANDBETWEEN(1,5),1,1,1,1,2),""))))) | D7: =IF(OR('Öğrenci Listesi'!B8="",AC7=""),"",IF(AC7="Çok İyi",CHOOSE(RANDBETWEEN(1,5),4,4,4,4,3),IF(AC7="İyi",CHOOSE(RANDBETWEEN(1,5),3,3,3,4,2),IF(AC7="Yeterli",CHOOSE(RANDBETWEEN(1,5),2,2,2,3,1),IF(AC7="Geliştirilmeli",CHOOSE(RANDBETWEEN(1,5),1,1,1,1,2),""))))) | E7: =IF(OR('Öğrenci Listesi'!B8="",AC7=""),"",IF(AC7="Çok İyi",CHOOSE(RANDBETWEEN(1,5),4,4,4,4,3),IF(AC7="İyi",CHOOSE(RANDBETWEEN(1,5),3,3,3,4,2),IF(AC7="Yeterli",CHOOSE(RANDBETWEEN(1,5),2,2,2,3,1),IF(AC7="Geliştirilmeli",CHOOSE(RANDBETWEEN(1,5),1,1,1,1,2),""))))) | F7: =IF(OR('Öğrenci Listesi'!B8="",AC7=""),"",IF(AC7="Çok İyi",CHOOSE(RANDBETWEEN(1,5),4,4,4,4,3),IF(AC7="İyi",CHOOSE(RANDBETWEEN(1,5),3,3,3,4,2),IF(AC7="Yeterli",CHOOSE(RANDBETWEEN(1,5),2,2,2,3,1),IF(AC7="Geliştirilmeli",CHOOSE(RANDBETWEEN(1,5),1,1,1,1,2),""))))) | G7: =IF(OR('Öğrenci Listesi'!B8="",AC7=""),"",IF(AC7="Çok İyi",CHOOSE(RANDBETWEEN(1,5),4,4,4,4,3),IF(AC7="İyi",CHOOSE(RANDBETWEEN(1,5),3,3,3,4,2),IF(AC7="Yeterli",CHOOSE(RANDBETWEEN(1,5),2,2,2,3,1),IF(AC7="Geliştirilmeli",CHOOSE(RANDBETWEEN(1,5),1,1,1,1,2),""))))) | H7: =IF(OR('Öğrenci Listesi'!B8="",AC7=""),"",IF(AC7="Çok İyi",CHOOSE(RANDBETWEEN(1,5),4,4,4,4,3),IF(AC7="İyi",CHOOSE(RANDBETWEEN(1,5),3,3,3,4,2),IF(AC7="Yeterli",CHOOSE(RANDBETWEEN(1,5),2,2,2,3,1),IF(AC7="Geliştirilmeli",CHOOSE(RANDBETWEEN(1,5),1,1,1,1,2),""))))) | I7: =IF(OR('Öğrenci Listesi'!B8="",AC7=""),"",IF(AC7="Çok İyi",CHOOSE(RANDBETWEEN(1,5),4,4,4,4,3),IF(AC7="İyi",CHOOSE(RANDBETWEEN(1,5),3,3,3,4,2),IF(AC7="Yeterli",CHOOSE(RANDBETWEEN(1,5),2,2,2,3,1),IF(AC7="Geliştirilmeli",CHOOSE(RANDBETWEEN(1,5),1,1,1,1,2),""))))) | J7: =IF(OR('Öğrenci Listesi'!B8="",AC7=""),"",IF(AC7="Çok İyi",CHOOSE(RANDBETWEEN(1,5),4,4,4,4,3),IF(AC7="İyi",CHOOSE(RANDBETWEEN(1,5),3,3,3,4,2),IF(AC7="Yeterli",CHOOSE(RANDBETWEEN(1,5),2,2,2,3,1),IF(AC7="Geliştirilmeli",CHOOSE(RANDBETWEEN(1,5),1,1,1,1,2),""))))) | K7: =IF(OR('Öğrenci Listesi'!B8="",AC7=""),"",IF(AC7="Çok İyi",CHOOSE(RANDBETWEEN(1,5),4,4,4,4,3),IF(AC7="İyi",CHOOSE(RANDBETWEEN(1,5),3,3,3,4,2),IF(AC7="Yeterli",CHOOSE(RANDBETWEEN(1,5),2,2,2,3,1),IF(AC7="Geliştirilmeli",CHOOSE(RANDBETWEEN(1,5),1,1,1,1,2),""))))) | L7: =IF(OR('Öğrenci Listesi'!B8="",AC7=""),"",IF(AC7="Çok İyi",CHOOSE(RANDBETWEEN(1,5),4,4,4,4,3),IF(AC7="İyi",CHOOSE(RANDBETWEEN(1,5),3,3,3,4,2),IF(AC7="Yeterli",CHOOSE(RANDBETWEEN(1,5),2,2,2,3,1),IF(AC7="Geliştirilmeli",CHOOSE(RANDBETWEEN(1,5),1,1,1,1,2),""))))) | M7: =IF(OR('Öğrenci Listesi'!B8="",AC7=""),"",IF(AC7="Çok İyi",CHOOSE(RANDBETWEEN(1,5),4,4,4,4,3),IF(AC7="İyi",CHOOSE(RANDBETWEEN(1,5),3,3,3,4,2),IF(AC7="Yeterli",CHOOSE(RANDBETWEEN(1,5),2,2,2,3,1),IF(AC7="Geliştirilmeli",CHOOSE(RANDBETWEEN(1,5),1,1,1,1,2),""))))) | N7: =IF(OR('Öğrenci Listesi'!B8="",AC7=""),"",IF(AC7="Çok İyi",CHOOSE(RANDBETWEEN(1,5),4,4,4,4,3),IF(AC7="İyi",CHOOSE(RANDBETWEEN(1,5),3,3,3,4,2),IF(AC7="Yeterli",CHOOSE(RANDBETWEEN(1,5),2,2,2,3,1),IF(AC7="Geliştirilmeli",CHOOSE(RANDBETWEEN(1,5),1,1,1,1,2),""))))) | O7: =IF(OR('Öğrenci Listesi'!B8="",AC7=""),"",IF(AC7="Çok İyi",CHOOSE(RANDBETWEEN(1,5),4,4,4,4,3),IF(AC7="İyi",CHOOSE(RANDBETWEEN(1,5),3,3,3,4,2),IF(AC7="Yeterli",CHOOSE(RANDBETWEEN(1,5),2,2,2,3,1),IF(AC7="Geliştirilmeli",CHOOSE(RANDBETWEEN(1,5),1,1,1,1,2),""))))) | P7: =IF(OR('Öğrenci Listesi'!B8="",AC7=""),"",IF(AC7="Çok İyi",CHOOSE(RANDBETWEEN(1,5),4,4,4,4,3),IF(AC7="İyi",CHOOSE(RANDBETWEEN(1,5),3,3,3,4,2),IF(AC7="Yeterli",CHOOSE(RANDBETWEEN(1,5),2,2,2,3,1),IF(AC7="Geliştirilmeli",CHOOSE(RANDBETWEEN(1,5),1,1,1,1,2),""))))) | Q7: =IF(OR('Öğrenci Listesi'!B8="",AC7=""),"",IF(AC7="Çok İyi",CHOOSE(RANDBETWEEN(1,5),4,4,4,4,3),IF(AC7="İyi",CHOOSE(RANDBETWEEN(1,5),3,3,3,4,2),IF(AC7="Yeterli",CHOOSE(RANDBETWEEN(1,5),2,2,2,3,1),IF(AC7="Geliştirilmeli",CHOOSE(RANDBETWEEN(1,5),1,1,1,1,2),""))))) | R7: =IF(OR('Öğrenci Listesi'!B8="",AC7=""),"",IF(AC7="Çok İyi",CHOOSE(RANDBETWEEN(1,5),4,4,4,4,3),IF(AC7="İyi",CHOOSE(RANDBETWEEN(1,5),3,3,3,4,2),IF(AC7="Yeterli",CHOOSE(RANDBETWEEN(1,5),2,2,2,3,1),IF(AC7="Geliştirilmeli",CHOOSE(RANDBETWEEN(1,5),1,1,1,1,2),""))))) | S7: =IF(OR('Öğrenci Listesi'!B8="",AC7=""),"",IF(AC7="Çok İyi",CHOOSE(RANDBETWEEN(1,5),4,4,4,4,3),IF(AC7="İyi",CHOOSE(RANDBETWEEN(1,5),3,3,3,4,2),IF(AC7="Yeterli",CHOOSE(RANDBETWEEN(1,5),2,2,2,3,1),IF(AC7="Geliştirilmeli",CHOOSE(RANDBETWEEN(1,5),1,1,1,1,2),""))))) | T7: =IF(OR('Öğrenci Listesi'!B8="",AC7=""),"",IF(AC7="Çok İyi",CHOOSE(RANDBETWEEN(1,5),4,4,4,4,3),IF(AC7="İyi",CHOOSE(RANDBETWEEN(1,5),3,3,3,4,2),IF(AC7="Yeterli",CHOOSE(RANDBETWEEN(1,5),2,2,2,3,1),IF(AC7="Geliştirilmeli",CHOOSE(RANDBETWEEN(1,5),1,1,1,1,2),""))))) | U7: =IF(OR('Öğrenci Listesi'!B8="",AC7=""),"",IF(AC7="Çok İyi",CHOOSE(RANDBETWEEN(1,5),4,4,4,4,3),IF(AC7="İyi",CHOOSE(RANDBETWEEN(1,5),3,3,3,4,2),IF(AC7="Yeterli",CHOOSE(RANDBETWEEN(1,5),2,2,2,3,1),IF(AC7="Geliştirilmeli",CHOOSE(RANDBETWEEN(1,5),1,1,1,1,2),""))))) | V7: =IF(OR('Öğrenci Listesi'!B8="",AC7=""),"",IF(AC7="Çok İyi",CHOOSE(RANDBETWEEN(1,5),4,4,4,4,3),IF(AC7="İyi",CHOOSE(RANDBETWEEN(1,5),3,3,3,4,2),IF(AC7="Yeterli",CHOOSE(RANDBETWEEN(1,5),2,2,2,3,1),IF(AC7="Geliştirilmeli",CHOOSE(RANDBETWEEN(1,5),1,1,1,1,2),""))))) | W7: =IF(OR('Öğrenci Listesi'!B8="",AC7=""),"",IF(AC7="Çok İyi",CHOOSE(RANDBETWEEN(1,5),4,4,4,4,3),IF(AC7="İyi",CHOOSE(RANDBETWEEN(1,5),3,3,3,4,2),IF(AC7="Yeterli",CHOOSE(RANDBETWEEN(1,5),2,2,2,3,1),IF(AC7="Geliştirilmeli",CHOOSE(RANDBETWEEN(1,5),1,1,1,1,2),""))))) | X7: =IF(OR('Öğrenci Listesi'!B8="",AC7=""),"",IF(AC7="Çok İyi",CHOOSE(RANDBETWEEN(1,5),4,4,4,4,3),IF(AC7="İyi",CHOOSE(RANDBETWEEN(1,5),3,3,3,4,2),IF(AC7="Yeterli",CHOOSE(RANDBETWEEN(1,5),2,2,2,3,1),IF(AC7="Geliştirilmeli",CHOOSE(RANDBETWEEN(1,5),1,1,1,1,2),""))))) | Y7: =IF(OR('Öğrenci Listesi'!B8="",AC7=""),"",IF(AC7="Çok İyi",CHOOSE(RANDBETWEEN(1,5),4,4,4,4,3),IF(AC7="İyi",CHOOSE(RANDBETWEEN(1,5),3,3,3,4,2),IF(AC7="Yeterli",CHOOSE(RANDBETWEEN(1,5),2,2,2,3,1),IF(AC7="Geliştirilmeli",CHOOSE(RANDBETWEEN(1,5),1,1,1,1,2),""))))) | Z7: =IF(OR('Öğrenci Listesi'!B8="",AC7=""),"",IF(AC7="Çok İyi",CHOOSE(RANDBETWEEN(1,5),4,4,4,4,3),IF(AC7="İyi",CHOOSE(RANDBETWEEN(1,5),3,3,3,4,2),IF(AC7="Yeterli",CHOOSE(RANDBETWEEN(1,5),2,2,2,3,1),IF(AC7="Geliştirilmeli",CHOOSE(RANDBETWEEN(1,5),1,1,1,1,2),""))))) | AA7: =IF(OR('Öğrenci Listesi'!B8="",AC7=""),"",IF(AC7="Çok İyi",CHOOSE(RANDBETWEEN(1,5),4,4,4,4,3),IF(AC7="İyi",CHOOSE(RANDBETWEEN(1,5),3,3,3,4,2),IF(AC7="Yeterli",CHOOSE(RANDBETWEEN(1,5),2,2,2,3,1),IF(AC7="Geliştirilmeli",CHOOSE(RANDBETWEEN(1,5),1,1,1,1,2),""))))) | AB7: =IF(OR('Öğrenci Listesi'!B8="",AC7=""),"",ROUND(AVERAGE(C7:AA7),2)) | AC7: =IFERROR(IF('Öğrenci Listesi'!G8="","",IF(UPPER(TRIM('Öğrenci Listesi'!G8))="ÇOK İYİ","Çok İyi",IF(UPPER(TRIM('Öğrenci Listesi'!G8))="İYİ","İyi",IF(UPPER(TRIM('Öğrenci Listesi'!G8))="YETERLİ","Yeterli",IF(UPPER(TRIM('Öğrenci Listesi'!G8))="GELİŞTİRİLMELİ","Geliştirilmeli",'Öğrenci Listesi'!G8))))),"")
A8: =IFERROR(IF('Öğrenci Listesi'!A9="","",'Öğrenci Listesi'!A9),"") | B8: =IFERROR(IF('Öğrenci Listesi'!B9="","",'Öğrenci Listesi'!B9),"") | C8: =IF(OR('Öğrenci Listesi'!B9="",AC8=""),"",IF(AC8="Çok İyi",CHOOSE(RANDBETWEEN(1,5),4,4,4,4,3),IF(AC8="İyi",CHOOSE(RANDBETWEEN(1,5),3,3,3,4,2),IF(AC8="Yeterli",CHOOSE(RANDBETWEEN(1,5),2,2,2,3,1),IF(AC8="Geliştirilmeli",CHOOSE(RANDBETWEEN(1,5),1,1,1,1,2),""))))) | D8: =IF(OR('Öğrenci Listesi'!B9="",AC8=""),"",IF(AC8="Çok İyi",CHOOSE(RANDBETWEEN(1,5),4,4,4,4,3),IF(AC8="İyi",CHOOSE(RANDBETWEEN(1,5),3,3,3,4,2),IF(AC8="Yeterli",CHOOSE(RANDBETWEEN(1,5),2,2,2,3,1),IF(AC8="Geliştirilmeli",CHOOSE(RANDBETWEEN(1,5),1,1,1,1,2),""))))) | E8: =IF(OR('Öğrenci Listesi'!B9="",AC8=""),"",IF(AC8="Çok İyi",CHOOSE(RANDBETWEEN(1,5),4,4,4,4,3),IF(AC8="İyi",CHOOSE(RANDBETWEEN(1,5),3,3,3,4,2),IF(AC8="Yeterli",CHOOSE(RANDBETWEEN(1,5),2,2,2,3,1),IF(AC8="Geliştirilmeli",CHOOSE(RANDBETWEEN(1,5),1,1,1,1,2),""))))) | F8: =IF(OR('Öğrenci Listesi'!B9="",AC8=""),"",IF(AC8="Çok İyi",CHOOSE(RANDBETWEEN(1,5),4,4,4,4,3),IF(AC8="İyi",CHOOSE(RANDBETWEEN(1,5),3,3,3,4,2),IF(AC8="Yeterli",CHOOSE(RANDBETWEEN(1,5),2,2,2,3,1),IF(AC8="Geliştirilmeli",CHOOSE(RANDBETWEEN(1,5),1,1,1,1,2),""))))) | G8: =IF(OR('Öğrenci Listesi'!B9="",AC8=""),"",IF(AC8="Çok İyi",CHOOSE(RANDBETWEEN(1,5),4,4,4,4,3),IF(AC8="İyi",CHOOSE(RANDBETWEEN(1,5),3,3,3,4,2),IF(AC8="Yeterli",CHOOSE(RANDBETWEEN(1,5),2,2,2,3,1),IF(AC8="Geliştirilmeli",CHOOSE(RANDBETWEEN(1,5),1,1,1,1,2),""))))) | H8: =IF(OR('Öğrenci Listesi'!B9="",AC8=""),"",IF(AC8="Çok İyi",CHOOSE(RANDBETWEEN(1,5),4,4,4,4,3),IF(AC8="İyi",CHOOSE(RANDBETWEEN(1,5),3,3,3,4,2),IF(AC8="Yeterli",CHOOSE(RANDBETWEEN(1,5),2,2,2,3,1),IF(AC8="Geliştirilmeli",CHOOSE(RANDBETWEEN(1,5),1,1,1,1,2),""))))) | I8: =IF(OR('Öğrenci Listesi'!B9="",AC8=""),"",IF(AC8="Çok İyi",CHOOSE(RANDBETWEEN(1,5),4,4,4,4,3),IF(AC8="İyi",CHOOSE(RANDBETWEEN(1,5),3,3,3,4,2),IF(AC8="Yeterli",CHOOSE(RANDBETWEEN(1,5),2,2,2,3,1),IF(AC8="Geliştirilmeli",CHOOSE(RANDBETWEEN(1,5),1,1,1,1,2),""))))) | J8: =IF(OR('Öğrenci Listesi'!B9="",AC8=""),"",IF(AC8="Çok İyi",CHOOSE(RANDBETWEEN(1,5),4,4,4,4,3),IF(AC8="İyi",CHOOSE(RANDBETWEEN(1,5),3,3,3,4,2),IF(AC8="Yeterli",CHOOSE(RANDBETWEEN(1,5),2,2,2,3,1),IF(AC8="Geliştirilmeli",CHOOSE(RANDBETWEEN(1,5),1,1,1,1,2),""))))) | K8: =IF(OR('Öğrenci Listesi'!B9="",AC8=""),"",IF(AC8="Çok İyi",CHOOSE(RANDBETWEEN(1,5),4,4,4,4,3),IF(AC8="İyi",CHOOSE(RANDBETWEEN(1,5),3,3,3,4,2),IF(AC8="Yeterli",CHOOSE(RANDBETWEEN(1,5),2,2,2,3,1),IF(AC8="Geliştirilmeli",CHOOSE(RANDBETWEEN(1,5),1,1,1,1,2),""))))) | L8: =IF(OR('Öğrenci Listesi'!B9="",AC8=""),"",IF(AC8="Çok İyi",CHOOSE(RANDBETWEEN(1,5),4,4,4,4,3),IF(AC8="İyi",CHOOSE(RANDBETWEEN(1,5),3,3,3,4,2),IF(AC8="Yeterli",CHOOSE(RANDBETWEEN(1,5),2,2,2,3,1),IF(AC8="Geliştirilmeli",CHOOSE(RANDBETWEEN(1,5),1,1,1,1,2),""))))) | M8: =IF(OR('Öğrenci Listesi'!B9="",AC8=""),"",IF(AC8="Çok İyi",CHOOSE(RANDBETWEEN(1,5),4,4,4,4,3),IF(AC8="İyi",CHOOSE(RANDBETWEEN(1,5),3,3,3,4,2),IF(AC8="Yeterli",CHOOSE(RANDBETWEEN(1,5),2,2,2,3,1),IF(AC8="Geliştirilmeli",CHOOSE(RANDBETWEEN(1,5),1,1,1,1,2),""))))) | N8: =IF(OR('Öğrenci Listesi'!B9="",AC8=""),"",IF(AC8="Çok İyi",CHOOSE(RANDBETWEEN(1,5),4,4,4,4,3),IF(AC8="İyi",CHOOSE(RANDBETWEEN(1,5),3,3,3,4,2),IF(AC8="Yeterli",CHOOSE(RANDBETWEEN(1,5),2,2,2,3,1),IF(AC8="Geliştirilmeli",CHOOSE(RANDBETWEEN(1,5),1,1,1,1,2),""))))) | O8: =IF(OR('Öğrenci Listesi'!B9="",AC8=""),"",IF(AC8="Çok İyi",CHOOSE(RANDBETWEEN(1,5),4,4,4,4,3),IF(AC8="İyi",CHOOSE(RANDBETWEEN(1,5),3,3,3,4,2),IF(AC8="Yeterli",CHOOSE(RANDBETWEEN(1,5),2,2,2,3,1),IF(AC8="Geliştirilmeli",CHOOSE(RANDBETWEEN(1,5),1,1,1,1,2),""))))) | P8: =IF(OR('Öğrenci Listesi'!B9="",AC8=""),"",IF(AC8="Çok İyi",CHOOSE(RANDBETWEEN(1,5),4,4,4,4,3),IF(AC8="İyi",CHOOSE(RANDBETWEEN(1,5),3,3,3,4,2),IF(AC8="Yeterli",CHOOSE(RANDBETWEEN(1,5),2,2,2,3,1),IF(AC8="Geliştirilmeli",CHOOSE(RANDBETWEEN(1,5),1,1,1,1,2),""))))) | Q8: =IF(OR('Öğrenci Listesi'!B9="",AC8=""),"",IF(AC8="Çok İyi",CHOOSE(RANDBETWEEN(1,5),4,4,4,4,3),IF(AC8="İyi",CHOOSE(RANDBETWEEN(1,5),3,3,3,4,2),IF(AC8="Yeterli",CHOOSE(RANDBETWEEN(1,5),2,2,2,3,1),IF(AC8="Geliştirilmeli",CHOOSE(RANDBETWEEN(1,5),1,1,1,1,2),""))))) | R8: =IF(OR('Öğrenci Listesi'!B9="",AC8=""),"",IF(AC8="Çok İyi",CHOOSE(RANDBETWEEN(1,5),4,4,4,4,3),IF(AC8="İyi",CHOOSE(RANDBETWEEN(1,5),3,3,3,4,2),IF(AC8="Yeterli",CHOOSE(RANDBETWEEN(1,5),2,2,2,3,1),IF(AC8="Geliştirilmeli",CHOOSE(RANDBETWEEN(1,5),1,1,1,1,2),""))))) | S8: =IF(OR('Öğrenci Listesi'!B9="",AC8=""),"",IF(AC8="Çok İyi",CHOOSE(RANDBETWEEN(1,5),4,4,4,4,3),IF(AC8="İyi",CHOOSE(RANDBETWEEN(1,5),3,3,3,4,2),IF(AC8="Yeterli",CHOOSE(RANDBETWEEN(1,5),2,2,2,3,1),IF(AC8="Geliştirilmeli",CHOOSE(RANDBETWEEN(1,5),1,1,1,1,2),""))))) | T8: =IF(OR('Öğrenci Listesi'!B9="",AC8=""),"",IF(AC8="Çok İyi",CHOOSE(RANDBETWEEN(1,5),4,4,4,4,3),IF(AC8="İyi",CHOOSE(RANDBETWEEN(1,5),3,3,3,4,2),IF(AC8="Yeterli",CHOOSE(RANDBETWEEN(1,5),2,2,2,3,1),IF(AC8="Geliştirilmeli",CHOOSE(RANDBETWEEN(1,5),1,1,1,1,2),""))))) | U8: =IF(OR('Öğrenci Listesi'!B9="",AC8=""),"",IF(AC8="Çok İyi",CHOOSE(RANDBETWEEN(1,5),4,4,4,4,3),IF(AC8="İyi",CHOOSE(RANDBETWEEN(1,5),3,3,3,4,2),IF(AC8="Yeterli",CHOOSE(RANDBETWEEN(1,5),2,2,2,3,1),IF(AC8="Geliştirilmeli",CHOOSE(RANDBETWEEN(1,5),1,1,1,1,2),""))))) | V8: =IF(OR('Öğrenci Listesi'!B9="",AC8=""),"",IF(AC8="Çok İyi",CHOOSE(RANDBETWEEN(1,5),4,4,4,4,3),IF(AC8="İyi",CHOOSE(RANDBETWEEN(1,5),3,3,3,4,2),IF(AC8="Yeterli",CHOOSE(RANDBETWEEN(1,5),2,2,2,3,1),IF(AC8="Geliştirilmeli",CHOOSE(RANDBETWEEN(1,5),1,1,1,1,2),""))))) | W8: =IF(OR('Öğrenci Listesi'!B9="",AC8=""),"",IF(AC8="Çok İyi",CHOOSE(RANDBETWEEN(1,5),4,4,4,4,3),IF(AC8="İyi",CHOOSE(RANDBETWEEN(1,5),3,3,3,4,2),IF(AC8="Yeterli",CHOOSE(RANDBETWEEN(1,5),2,2,2,3,1),IF(AC8="Geliştirilmeli",CHOOSE(RANDBETWEEN(1,5),1,1,1,1,2),""))))) | X8: =IF(OR('Öğrenci Listesi'!B9="",AC8=""),"",IF(AC8="Çok İyi",CHOOSE(RANDBETWEEN(1,5),4,4,4,4,3),IF(AC8="İyi",CHOOSE(RANDBETWEEN(1,5),3,3,3,4,2),IF(AC8="Yeterli",CHOOSE(RANDBETWEEN(1,5),2,2,2,3,1),IF(AC8="Geliştirilmeli",CHOOSE(RANDBETWEEN(1,5),1,1,1,1,2),""))))) | Y8: =IF(OR('Öğrenci Listesi'!B9="",AC8=""),"",IF(AC8="Çok İyi",CHOOSE(RANDBETWEEN(1,5),4,4,4,4,3),IF(AC8="İyi",CHOOSE(RANDBETWEEN(1,5),3,3,3,4,2),IF(AC8="Yeterli",CHOOSE(RANDBETWEEN(1,5),2,2,2,3,1),IF(AC8="Geliştirilmeli",CHOOSE(RANDBETWEEN(1,5),1,1,1,1,2),""))))) | Z8: =IF(OR('Öğrenci Listesi'!B9="",AC8=""),"",IF(AC8="Çok İyi",CHOOSE(RANDBETWEEN(1,5),4,4,4,4,3),IF(AC8="İyi",CHOOSE(RANDBETWEEN(1,5),3,3,3,4,2),IF(AC8="Yeterli",CHOOSE(RANDBETWEEN(1,5),2,2,2,3,1),IF(AC8="Geliştirilmeli",CHOOSE(RANDBETWEEN(1,5),1,1,1,1,2),""))))) | AA8: =IF(OR('Öğrenci Listesi'!B9="",AC8=""),"",IF(AC8="Çok İyi",CHOOSE(RANDBETWEEN(1,5),4,4,4,4,3),IF(AC8="İyi",CHOOSE(RANDBETWEEN(1,5),3,3,3,4,2),IF(AC8="Yeterli",CHOOSE(RANDBETWEEN(1,5),2,2,2,3,1),IF(AC8="Geliştirilmeli",CHOOSE(RANDBETWEEN(1,5),1,1,1,1,2),""))))) | AB8: =IF(OR('Öğrenci Listesi'!B9="",AC8=""),"",ROUND(AVERAGE(C8:AA8),2)) | AC8: =IFERROR(IF('Öğrenci Listesi'!G9="","",IF(UPPER(TRIM('Öğrenci Listesi'!G9))="ÇOK İYİ","Çok İyi",IF(UPPER(TRIM('Öğrenci Listesi'!G9))="İYİ","İyi",IF(UPPER(TRIM('Öğrenci Listesi'!G9))="YETERLİ","Yeterli",IF(UPPER(TRIM('Öğrenci Listesi'!G9))="GELİŞTİRİLMELİ","Geliştirilmeli",'Öğrenci Listesi'!G9))))),"")
A9: =IFERROR(IF('Öğrenci Listesi'!A10="","",'Öğrenci Listesi'!A10),"") | B9: =IFERROR(IF('Öğrenci Listesi'!B10="","",'Öğrenci Listesi'!B10),"") | C9: =IF(OR('Öğrenci Listesi'!B10="",AC9=""),"",IF(AC9="Çok İyi",CHOOSE(RANDBETWEEN(1,5),4,4,4,4,3),IF(AC9="İyi",CHOOSE(RANDBETWEEN(1,5),3,3,3,4,2),IF(AC9="Yeterli",CHOOSE(RANDBETWEEN(1,5),2,2,2,3,1),IF(AC9="Geliştirilmeli",CHOOSE(RANDBETWEEN(1,5),1,1,1,1,2),""))))) | D9: =IF(OR('Öğrenci Listesi'!B10="",AC9=""),"",IF(AC9="Çok İyi",CHOOSE(RANDBETWEEN(1,5),4,4,4,4,3),IF(AC9="İyi",CHOOSE(RANDBETWEEN(1,5),3,3,3,4,2),IF(AC9="Yeterli",CHOOSE(RANDBETWEEN(1,5),2,2,2,3,1),IF(AC9="Geliştirilmeli",CHOOSE(RANDBETWEEN(1,5),1,1,1,1,2),""))))) | E9: =IF(OR('Öğrenci Listesi'!B10="",AC9=""),"",IF(AC9="Çok İyi",CHOOSE(RANDBETWEEN(1,5),4,4,4,4,3),IF(AC9="İyi",CHOOSE(RANDBETWEEN(1,5),3,3,3,4,2),IF(AC9="Yeterli",CHOOSE(RANDBETWEEN(1,5),2,2,2,3,1),IF(AC9="Geliştirilmeli",CHOOSE(RANDBETWEEN(1,5),1,1,1,1,2),""))))) | F9: =IF(OR('Öğrenci Listesi'!B10="",AC9=""),"",IF(AC9="Çok İyi",CHOOSE(RANDBETWEEN(1,5),4,4,4,4,3),IF(AC9="İyi",CHOOSE(RANDBETWEEN(1,5),3,3,3,4,2),IF(AC9="Yeterli",CHOOSE(RANDBETWEEN(1,5),2,2,2,3,1),IF(AC9="Geliştirilmeli",CHOOSE(RANDBETWEEN(1,5),1,1,1,1,2),""))))) | G9: =IF(OR('Öğrenci Listesi'!B10="",AC9=""),"",IF(AC9="Çok İyi",CHOOSE(RANDBETWEEN(1,5),4,4,4,4,3),IF(AC9="İyi",CHOOSE(RANDBETWEEN(1,5),3,3,3,4,2),IF(AC9="Yeterli",CHOOSE(RANDBETWEEN(1,5),2,2,2,3,1),IF(AC9="Geliştirilmeli",CHOOSE(RANDBETWEEN(1,5),1,1,1,1,2),""))))) | H9: =IF(OR('Öğrenci Listesi'!B10="",AC9=""),"",IF(AC9="Çok İyi",CHOOSE(RANDBETWEEN(1,5),4,4,4,4,3),IF(AC9="İyi",CHOOSE(RANDBETWEEN(1,5),3,3,3,4,2),IF(AC9="Yeterli",CHOOSE(RANDBETWEEN(1,5),2,2,2,3,1),IF(AC9="Geliştirilmeli",CHOOSE(RANDBETWEEN(1,5),1,1,1,1,2),""))))) | I9: =IF(OR('Öğrenci Listesi'!B10="",AC9=""),"",IF(AC9="Çok İyi",CHOOSE(RANDBETWEEN(1,5),4,4,4,4,3),IF(AC9="İyi",CHOOSE(RANDBETWEEN(1,5),3,3,3,4,2),IF(AC9="Yeterli",CHOOSE(RANDBETWEEN(1,5),2,2,2,3,1),IF(AC9="Geliştirilmeli",CHOOSE(RANDBETWEEN(1,5),1,1,1,1,2),""))))) | J9: =IF(OR('Öğrenci Listesi'!B10="",AC9=""),"",IF(AC9="Çok İyi",CHOOSE(RANDBETWEEN(1,5),4,4,4,4,3),IF(AC9="İyi",CHOOSE(RANDBETWEEN(1,5),3,3,3,4,2),IF(AC9="Yeterli",CHOOSE(RANDBETWEEN(1,5),2,2,2,3,1),IF(AC9="Geliştirilmeli",CHOOSE(RANDBETWEEN(1,5),1,1,1,1,2),""))))) | K9: =IF(OR('Öğrenci Listesi'!B10="",AC9=""),"",IF(AC9="Çok İyi",CHOOSE(RANDBETWEEN(1,5),4,4,4,4,3),IF(AC9="İyi",CHOOSE(RANDBETWEEN(1,5),3,3,3,4,2),IF(AC9="Yeterli",CHOOSE(RANDBETWEEN(1,5),2,2,2,3,1),IF(AC9="Geliştirilmeli",CHOOSE(RANDBETWEEN(1,5),1,1,1,1,2),""))))) | L9: =IF(OR('Öğrenci Listesi'!B10="",AC9=""),"",IF(AC9="Çok İyi",CHOOSE(RANDBETWEEN(1,5),4,4,4,4,3),IF(AC9="İyi",CHOOSE(RANDBETWEEN(1,5),3,3,3,4,2),IF(AC9="Yeterli",CHOOSE(RANDBETWEEN(1,5),2,2,2,3,1),IF(AC9="Geliştirilmeli",CHOOSE(RANDBETWEEN(1,5),1,1,1,1,2),""))))) | M9: =IF(OR('Öğrenci Listesi'!B10="",AC9=""),"",IF(AC9="Çok İyi",CHOOSE(RANDBETWEEN(1,5),4,4,4,4,3),IF(AC9="İyi",CHOOSE(RANDBETWEEN(1,5),3,3,3,4,2),IF(AC9="Yeterli",CHOOSE(RANDBETWEEN(1,5),2,2,2,3,1),IF(AC9="Geliştirilmeli",CHOOSE(RANDBETWEEN(1,5),1,1,1,1,2),""))))) | N9: =IF(OR('Öğrenci Listesi'!B10="",AC9=""),"",IF(AC9="Çok İyi",CHOOSE(RANDBETWEEN(1,5),4,4,4,4,3),IF(AC9="İyi",CHOOSE(RANDBETWEEN(1,5),3,3,3,4,2),IF(AC9="Yeterli",CHOOSE(RANDBETWEEN(1,5),2,2,2,3,1),IF(AC9="Geliştirilmeli",CHOOSE(RANDBETWEEN(1,5),1,1,1,1,2),""))))) | O9: =IF(OR('Öğrenci Listesi'!B10="",AC9=""),"",IF(AC9="Çok İyi",CHOOSE(RANDBETWEEN(1,5),4,4,4,4,3),IF(AC9="İyi",CHOOSE(RANDBETWEEN(1,5),3,3,3,4,2),IF(AC9="Yeterli",CHOOSE(RANDBETWEEN(1,5),2,2,2,3,1),IF(AC9="Geliştirilmeli",CHOOSE(RANDBETWEEN(1,5),1,1,1,1,2),""))))) | P9: =IF(OR('Öğrenci Listesi'!B10="",AC9=""),"",IF(AC9="Çok İyi",CHOOSE(RANDBETWEEN(1,5),4,4,4,4,3),IF(AC9="İyi",CHOOSE(RANDBETWEEN(1,5),3,3,3,4,2),IF(AC9="Yeterli",CHOOSE(RANDBETWEEN(1,5),2,2,2,3,1),IF(AC9="Geliştirilmeli",CHOOSE(RANDBETWEEN(1,5),1,1,1,1,2),""))))) | Q9: =IF(OR('Öğrenci Listesi'!B10="",AC9=""),"",IF(AC9="Çok İyi",CHOOSE(RANDBETWEEN(1,5),4,4,4,4,3),IF(AC9="İyi",CHOOSE(RANDBETWEEN(1,5),3,3,3,4,2),IF(AC9="Yeterli",CHOOSE(RANDBETWEEN(1,5),2,2,2,3,1),IF(AC9="Geliştirilmeli",CHOOSE(RANDBETWEEN(1,5),1,1,1,1,2),""))))) | R9: =IF(OR('Öğrenci Listesi'!B10="",AC9=""),"",IF(AC9="Çok İyi",CHOOSE(RANDBETWEEN(1,5),4,4,4,4,3),IF(AC9="İyi",CHOOSE(RANDBETWEEN(1,5),3,3,3,4,2),IF(AC9="Yeterli",CHOOSE(RANDBETWEEN(1,5),2,2,2,3,1),IF(AC9="Geliştirilmeli",CHOOSE(RANDBETWEEN(1,5),1,1,1,1,2),""))))) | S9: =IF(OR('Öğrenci Listesi'!B10="",AC9=""),"",IF(AC9="Çok İyi",CHOOSE(RANDBETWEEN(1,5),4,4,4,4,3),IF(AC9="İyi",CHOOSE(RANDBETWEEN(1,5),3,3,3,4,2),IF(AC9="Yeterli",CHOOSE(RANDBETWEEN(1,5),2,2,2,3,1),IF(AC9="Geliştirilmeli",CHOOSE(RANDBETWEEN(1,5),1,1,1,1,2),""))))) | T9: =IF(OR('Öğrenci Listesi'!B10="",AC9=""),"",IF(AC9="Çok İyi",CHOOSE(RANDBETWEEN(1,5),4,4,4,4,3),IF(AC9="İyi",CHOOSE(RANDBETWEEN(1,5),3,3,3,4,2),IF(AC9="Yeterli",CHOOSE(RANDBETWEEN(1,5),2,2,2,3,1),IF(AC9="Geliştirilmeli",CHOOSE(RANDBETWEEN(1,5),1,1,1,1,2),""))))) | U9: =IF(OR('Öğrenci Listesi'!B10="",AC9=""),"",IF(AC9="Çok İyi",CHOOSE(RANDBETWEEN(1,5),4,4,4,4,3),IF(AC9="İyi",CHOOSE(RANDBETWEEN(1,5),3,3,3,4,2),IF(AC9="Yeterli",CHOOSE(RANDBETWEEN(1,5),2,2,2,3,1),IF(AC9="Geliştirilmeli",CHOOSE(RANDBETWEEN(1,5),1,1,1,1,2),""))))) | V9: =IF(OR('Öğrenci Listesi'!B10="",AC9=""),"",IF(AC9="Çok İyi",CHOOSE(RANDBETWEEN(1,5),4,4,4,4,3),IF(AC9="İyi",CHOOSE(RANDBETWEEN(1,5),3,3,3,4,2),IF(AC9="Yeterli",CHOOSE(RANDBETWEEN(1,5),2,2,2,3,1),IF(AC9="Geliştirilmeli",CHOOSE(RANDBETWEEN(1,5),1,1,1,1,2),""))))) | W9: =IF(OR('Öğrenci Listesi'!B10="",AC9=""),"",IF(AC9="Çok İyi",CHOOSE(RANDBETWEEN(1,5),4,4,4,4,3),IF(AC9="İyi",CHOOSE(RANDBETWEEN(1,5),3,3,3,4,2),IF(AC9="Yeterli",CHOOSE(RANDBETWEEN(1,5),2,2,2,3,1),IF(AC9="Geliştirilmeli",CHOOSE(RANDBETWEEN(1,5),1,1,1,1,2),""))))) | X9: =IF(OR('Öğrenci Listesi'!B10="",AC9=""),"",IF(AC9="Çok İyi",CHOOSE(RANDBETWEEN(1,5),4,4,4,4,3),IF(AC9="İyi",CHOOSE(RANDBETWEEN(1,5),3,3,3,4,2),IF(AC9="Yeterli",CHOOSE(RANDBETWEEN(1,5),2,2,2,3,1),IF(AC9="Geliştirilmeli",CHOOSE(RANDBETWEEN(1,5),1,1,1,1,2),""))))) | Y9: =IF(OR('Öğrenci Listesi'!B10="",AC9=""),"",IF(AC9="Çok İyi",CHOOSE(RANDBETWEEN(1,5),4,4,4,4,3),IF(AC9="İyi",CHOOSE(RANDBETWEEN(1,5),3,3,3,4,2),IF(AC9="Yeterli",CHOOSE(RANDBETWEEN(1,5),2,2,2,3,1),IF(AC9="Geliştirilmeli",CHOOSE(RANDBETWEEN(1,5),1,1,1,1,2),""))))) | Z9: =IF(OR('Öğrenci Listesi'!B10="",AC9=""),"",IF(AC9="Çok İyi",CHOOSE(RANDBETWEEN(1,5),4,4,4,4,3),IF(AC9="İyi",CHOOSE(RANDBETWEEN(1,5),3,3,3,4,2),IF(AC9="Yeterli",CHOOSE(RANDBETWEEN(1,5),2,2,2,3,1),IF(AC9="Geliştirilmeli",CHOOSE(RANDBETWEEN(1,5),1,1,1,1,2),""))))) | AA9: =IF(OR('Öğrenci Listesi'!B10="",AC9=""),"",IF(AC9="Çok İyi",CHOOSE(RANDBETWEEN(1,5),4,4,4,4,3),IF(AC9="İyi",CHOOSE(RANDBETWEEN(1,5),3,3,3,4,2),IF(AC9="Yeterli",CHOOSE(RANDBETWEEN(1,5),2,2,2,3,1),IF(AC9="Geliştirilmeli",CHOOSE(RANDBETWEEN(1,5),1,1,1,1,2),""))))) | AB9: =IF(OR('Öğrenci Listesi'!B10="",AC9=""),"",ROUND(AVERAGE(C9:AA9),2)) | AC9: =IFERROR(IF('Öğrenci Listesi'!G10="","",IF(UPPER(TRIM('Öğrenci Listesi'!G10))="ÇOK İYİ","Çok İyi",IF(UPPER(TRIM('Öğrenci Listesi'!G10))="İYİ","İyi",IF(UPPER(TRIM('Öğrenci Listesi'!G10))="YETERLİ","Yeterli",IF(UPPER(TRIM('Öğrenci Listesi'!G10))="GELİŞTİRİLMELİ","Geliştirilmeli",'Öğrenci Listesi'!G10))))),"")
A10: =IFERROR(IF('Öğrenci Listesi'!A11="","",'Öğrenci Listesi'!A11),"") | B10: =IFERROR(IF('Öğrenci Listesi'!B11="","",'Öğrenci Listesi'!B11),"") | C10: =IF(OR('Öğrenci Listesi'!B11="",AC10=""),"",IF(AC10="Çok İyi",CHOOSE(RANDBETWEEN(1,5),4,4,4,4,3),IF(AC10="İyi",CHOOSE(RANDBETWEEN(1,5),3,3,3,4,2),IF(AC10="Yeterli",CHOOSE(RANDBETWEEN(1,5),2,2,2,3,1),IF(AC10="Geliştirilmeli",CHOOSE(RANDBETWEEN(1,5),1,1,1,1,2),""))))) | D10: =IF(OR('Öğrenci Listesi'!B11="",AC10=""),"",IF(AC10="Çok İyi",CHOOSE(RANDBETWEEN(1,5),4,4,4,4,3),IF(AC10="İyi",CHOOSE(RANDBETWEEN(1,5),3,3,3,4,2),IF(AC10="Yeterli",CHOOSE(RANDBETWEEN(1,5),2,2,2,3,1),IF(AC10="Geliştirilmeli",CHOOSE(RANDBETWEEN(1,5),1,1,1,1,2),""))))) | E10: =IF(OR('Öğrenci Listesi'!B11="",AC10=""),"",IF(AC10="Çok İyi",CHOOSE(RANDBETWEEN(1,5),4,4,4,4,3),IF(AC10="İyi",CHOOSE(RANDBETWEEN(1,5),3,3,3,4,2),IF(AC10="Yeterli",CHOOSE(RANDBETWEEN(1,5),2,2,2,3,1),IF(AC10="Geliştirilmeli",CHOOSE(RANDBETWEEN(1,5),1,1,1,1,2),""))))) | F10: =IF(OR('Öğrenci Listesi'!B11="",AC10=""),"",IF(AC10="Çok İyi",CHOOSE(RANDBETWEEN(1,5),4,4,4,4,3),IF(AC10="İyi",CHOOSE(RANDBETWEEN(1,5),3,3,3,4,2),IF(AC10="Yeterli",CHOOSE(RANDBETWEEN(1,5),2,2,2,3,1),IF(AC10="Geliştirilmeli",CHOOSE(RANDBETWEEN(1,5),1,1,1,1,2),""))))) | G10: =IF(OR('Öğrenci Listesi'!B11="",AC10=""),"",IF(AC10="Çok İyi",CHOOSE(RANDBETWEEN(1,5),4,4,4,4,3),IF(AC10="İyi",CHOOSE(RANDBETWEEN(1,5),3,3,3,4,2),IF(AC10="Yeterli",CHOOSE(RANDBETWEEN(1,5),2,2,2,3,1),IF(AC10="Geliştirilmeli",CHOOSE(RANDBETWEEN(1,5),1,1,1,1,2),""))))) | H10: =IF(OR('Öğrenci Listesi'!B11="",AC10=""),"",IF(AC10="Çok İyi",CHOOSE(RANDBETWEEN(1,5),4,4,4,4,3),IF(AC10="İyi",CHOOSE(RANDBETWEEN(1,5),3,3,3,4,2),IF(AC10="Yeterli",CHOOSE(RANDBETWEEN(1,5),2,2,2,3,1),IF(AC10="Geliştirilmeli",CHOOSE(RANDBETWEEN(1,5),1,1,1,1,2),""))))) | I10: =IF(OR('Öğrenci Listesi'!B11="",AC10=""),"",IF(AC10="Çok İyi",CHOOSE(RANDBETWEEN(1,5),4,4,4,4,3),IF(AC10="İyi",CHOOSE(RANDBETWEEN(1,5),3,3,3,4,2),IF(AC10="Yeterli",CHOOSE(RANDBETWEEN(1,5),2,2,2,3,1),IF(AC10="Geliştirilmeli",CHOOSE(RANDBETWEEN(1,5),1,1,1,1,2),""))))) | J10: =IF(OR('Öğrenci Listesi'!B11="",AC10=""),"",IF(AC10="Çok İyi",CHOOSE(RANDBETWEEN(1,5),4,4,4,4,3),IF(AC10="İyi",CHOOSE(RANDBETWEEN(1,5),3,3,3,4,2),IF(AC10="Yeterli",CHOOSE(RANDBETWEEN(1,5),2,2,2,3,1),IF(AC10="Geliştirilmeli",CHOOSE(RANDBETWEEN(1,5),1,1,1,1,2),""))))) | K10: =IF(OR('Öğrenci Listesi'!B11="",AC10=""),"",IF(AC10="Çok İyi",CHOOSE(RANDBETWEEN(1,5),4,4,4,4,3),IF(AC10="İyi",CHOOSE(RANDBETWEEN(1,5),3,3,3,4,2),IF(AC10="Yeterli",CHOOSE(RANDBETWEEN(1,5),2,2,2,3,1),IF(AC10="Geliştirilmeli",CHOOSE(RANDBETWEEN(1,5),1,1,1,1,2),""))))) | L10: =IF(OR('Öğrenci Listesi'!B11="",AC10=""),"",IF(AC10="Çok İyi",CHOOSE(RANDBETWEEN(1,5),4,4,4,4,3),IF(AC10="İyi",CHOOSE(RANDBETWEEN(1,5),3,3,3,4,2),IF(AC10="Yeterli",CHOOSE(RANDBETWEEN(1,5),2,2,2,3,1),IF(AC10="Geliştirilmeli",CHOOSE(RANDBETWEEN(1,5),1,1,1,1,2),""))))) | M10: =IF(OR('Öğrenci Listesi'!B11="",AC10=""),"",IF(AC10="Çok İyi",CHOOSE(RANDBETWEEN(1,5),4,4,4,4,3),IF(AC10="İyi",CHOOSE(RANDBETWEEN(1,5),3,3,3,4,2),IF(AC10="Yeterli",CHOOSE(RANDBETWEEN(1,5),2,2,2,3,1),IF(AC10="Geliştirilmeli",CHOOSE(RANDBETWEEN(1,5),1,1,1,1,2),""))))) | N10: =IF(OR('Öğrenci Listesi'!B11="",AC10=""),"",IF(AC10="Çok İyi",CHOOSE(RANDBETWEEN(1,5),4,4,4,4,3),IF(AC10="İyi",CHOOSE(RANDBETWEEN(1,5),3,3,3,4,2),IF(AC10="Yeterli",CHOOSE(RANDBETWEEN(1,5),2,2,2,3,1),IF(AC10="Geliştirilmeli",CHOOSE(RANDBETWEEN(1,5),1,1,1,1,2),""))))) | O10: =IF(OR('Öğrenci Listesi'!B11="",AC10=""),"",IF(AC10="Çok İyi",CHOOSE(RANDBETWEEN(1,5),4,4,4,4,3),IF(AC10="İyi",CHOOSE(RANDBETWEEN(1,5),3,3,3,4,2),IF(AC10="Yeterli",CHOOSE(RANDBETWEEN(1,5),2,2,2,3,1),IF(AC10="Geliştirilmeli",CHOOSE(RANDBETWEEN(1,5),1,1,1,1,2),""))))) | P10: =IF(OR('Öğrenci Listesi'!B11="",AC10=""),"",IF(AC10="Çok İyi",CHOOSE(RANDBETWEEN(1,5),4,4,4,4,3),IF(AC10="İyi",CHOOSE(RANDBETWEEN(1,5),3,3,3,4,2),IF(AC10="Yeterli",CHOOSE(RANDBETWEEN(1,5),2,2,2,3,1),IF(AC10="Geliştirilmeli",CHOOSE(RANDBETWEEN(1,5),1,1,1,1,2),""))))) | Q10: =IF(OR('Öğrenci Listesi'!B11="",AC10=""),"",IF(AC10="Çok İyi",CHOOSE(RANDBETWEEN(1,5),4,4,4,4,3),IF(AC10="İyi",CHOOSE(RANDBETWEEN(1,5),3,3,3,4,2),IF(AC10="Yeterli",CHOOSE(RANDBETWEEN(1,5),2,2,2,3,1),IF(AC10="Geliştirilmeli",CHOOSE(RANDBETWEEN(1,5),1,1,1,1,2),""))))) | R10: =IF(OR('Öğrenci Listesi'!B11="",AC10=""),"",IF(AC10="Çok İyi",CHOOSE(RANDBETWEEN(1,5),4,4,4,4,3),IF(AC10="İyi",CHOOSE(RANDBETWEEN(1,5),3,3,3,4,2),IF(AC10="Yeterli",CHOOSE(RANDBETWEEN(1,5),2,2,2,3,1),IF(AC10="Geliştirilmeli",CHOOSE(RANDBETWEEN(1,5),1,1,1,1,2),""))))) | S10: =IF(OR('Öğrenci Listesi'!B11="",AC10=""),"",IF(AC10="Çok İyi",CHOOSE(RANDBETWEEN(1,5),4,4,4,4,3),IF(AC10="İyi",CHOOSE(RANDBETWEEN(1,5),3,3,3,4,2),IF(AC10="Yeterli",CHOOSE(RANDBETWEEN(1,5),2,2,2,3,1),IF(AC10="Geliştirilmeli",CHOOSE(RANDBETWEEN(1,5),1,1,1,1,2),""))))) | T10: =IF(OR('Öğrenci Listesi'!B11="",AC10=""),"",IF(AC10="Çok İyi",CHOOSE(RANDBETWEEN(1,5),4,4,4,4,3),IF(AC10="İyi",CHOOSE(RANDBETWEEN(1,5),3,3,3,4,2),IF(AC10="Yeterli",CHOOSE(RANDBETWEEN(1,5),2,2,2,3,1),IF(AC10="Geliştirilmeli",CHOOSE(RANDBETWEEN(1,5),1,1,1,1,2),""))))) | U10: =IF(OR('Öğrenci Listesi'!B11="",AC10=""),"",IF(AC10="Çok İyi",CHOOSE(RANDBETWEEN(1,5),4,4,4,4,3),IF(AC10="İyi",CHOOSE(RANDBETWEEN(1,5),3,3,3,4,2),IF(AC10="Yeterli",CHOOSE(RANDBETWEEN(1,5),2,2,2,3,1),IF(AC10="Geliştirilmeli",CHOOSE(RANDBETWEEN(1,5),1,1,1,1,2),""))))) | V10: =IF(OR('Öğrenci Listesi'!B11="",AC10=""),"",IF(AC10="Çok İyi",CHOOSE(RANDBETWEEN(1,5),4,4,4,4,3),IF(AC10="İyi",CHOOSE(RANDBETWEEN(1,5),3,3,3,4,2),IF(AC10="Yeterli",CHOOSE(RANDBETWEEN(1,5),2,2,2,3,1),IF(AC10="Geliştirilmeli",CHOOSE(RANDBETWEEN(1,5),1,1,1,1,2),""))))) | W10: =IF(OR('Öğrenci Listesi'!B11="",AC10=""),"",IF(AC10="Çok İyi",CHOOSE(RANDBETWEEN(1,5),4,4,4,4,3),IF(AC10="İyi",CHOOSE(RANDBETWEEN(1,5),3,3,3,4,2),IF(AC10="Yeterli",CHOOSE(RANDBETWEEN(1,5),2,2,2,3,1),IF(AC10="Geliştirilmeli",CHOOSE(RANDBETWEEN(1,5),1,1,1,1,2),""))))) | X10: =IF(OR('Öğrenci Listesi'!B11="",AC10=""),"",IF(AC10="Çok İyi",CHOOSE(RANDBETWEEN(1,5),4,4,4,4,3),IF(AC10="İyi",CHOOSE(RANDBETWEEN(1,5),3,3,3,4,2),IF(AC10="Yeterli",CHOOSE(RANDBETWEEN(1,5),2,2,2,3,1),IF(AC10="Geliştirilmeli",CHOOSE(RANDBETWEEN(1,5),1,1,1,1,2),""))))) | Y10: =IF(OR('Öğrenci Listesi'!B11="",AC10=""),"",IF(AC10="Çok İyi",CHOOSE(RANDBETWEEN(1,5),4,4,4,4,3),IF(AC10="İyi",CHOOSE(RANDBETWEEN(1,5),3,3,3,4,2),IF(AC10="Yeterli",CHOOSE(RANDBETWEEN(1,5),2,2,2,3,1),IF(AC10="Geliştirilmeli",CHOOSE(RANDBETWEEN(1,5),1,1,1,1,2),""))))) | Z10: =IF(OR('Öğrenci Listesi'!B11="",AC10=""),"",IF(AC10="Çok İyi",CHOOSE(RANDBETWEEN(1,5),4,4,4,4,3),IF(AC10="İyi",CHOOSE(RANDBETWEEN(1,5),3,3,3,4,2),IF(AC10="Yeterli",CHOOSE(RANDBETWEEN(1,5),2,2,2,3,1),IF(AC10="Geliştirilmeli",CHOOSE(RANDBETWEEN(1,5),1,1,1,1,2),""))))) | AA10: =IF(OR('Öğrenci Listesi'!B11="",AC10=""),"",IF(AC10="Çok İyi",CHOOSE(RANDBETWEEN(1,5),4,4,4,4,3),IF(AC10="İyi",CHOOSE(RANDBETWEEN(1,5),3,3,3,4,2),IF(AC10="Yeterli",CHOOSE(RANDBETWEEN(1,5),2,2,2,3,1),IF(AC10="Geliştirilmeli",CHOOSE(RANDBETWEEN(1,5),1,1,1,1,2),""))))) | AB10: =IF(OR('Öğrenci Listesi'!B11="",AC10=""),"",ROUND(AVERAGE(C10:AA10),2)) | AC10: =IFERROR(IF('Öğrenci Listesi'!G11="","",IF(UPPER(TRIM('Öğrenci Listesi'!G11))="ÇOK İYİ","Çok İyi",IF(UPPER(TRIM('Öğrenci Listesi'!G11))="İYİ","İyi",IF(UPPER(TRIM('Öğrenci Listesi'!G11))="YETERLİ","Yeterli",IF(UPPER(TRIM('Öğrenci Listesi'!G11))="GELİŞTİRİLMELİ","Geliştirilmeli",'Öğrenci Listesi'!G11))))),"")
A11: =IFERROR(IF('Öğrenci Listesi'!A12="","",'Öğrenci Listesi'!A12),"") | B11: =IFERROR(IF('Öğrenci Listesi'!B12="","",'Öğrenci Listesi'!B12),"") | C11: =IF(OR('Öğrenci Listesi'!B12="",AC11=""),"",IF(AC11="Çok İyi",CHOOSE(RANDBETWEEN(1,5),4,4,4,4,3),IF(AC11="İyi",CHOOSE(RANDBETWEEN(1,5),3,3,3,4,2),IF(AC11="Yeterli",CHOOSE(RANDBETWEEN(1,5),2,2,2,3,1),IF(AC11="Geliştirilmeli",CHOOSE(RANDBETWEEN(1,5),1,1,1,1,2),""))))) | D11: =IF(OR('Öğrenci Listesi'!B12="",AC11=""),"",IF(AC11="Çok İyi",CHOOSE(RANDBETWEEN(1,5),4,4,4,4,3),IF(AC11="İyi",CHOOSE(RANDBETWEEN(1,5),3,3,3,4,2),IF(AC11="Yeterli",CHOOSE(RANDBETWEEN(1,5),2,2,2,3,1),IF(AC11="Geliştirilmeli",CHOOSE(RANDBETWEEN(1,5),1,1,1,1,2),""))))) | E11: =IF(OR('Öğrenci Listesi'!B12="",AC11=""),"",IF(AC11="Çok İyi",CHOOSE(RANDBETWEEN(1,5),4,4,4,4,3),IF(AC11="İyi",CHOOSE(RANDBETWEEN(1,5),3,3,3,4,2),IF(AC11="Yeterli",CHOOSE(RANDBETWEEN(1,5),2,2,2,3,1),IF(AC11="Geliştirilmeli",CHOOSE(RANDBETWEEN(1,5),1,1,1,1,2),""))))) | F11: =IF(OR('Öğrenci Listesi'!B12="",AC11=""),"",IF(AC11="Çok İyi",CHOOSE(RANDBETWEEN(1,5),4,4,4,4,3),IF(AC11="İyi",CHOOSE(RANDBETWEEN(1,5),3,3,3,4,2),IF(AC11="Yeterli",CHOOSE(RANDBETWEEN(1,5),2,2,2,3,1),IF(AC11="Geliştirilmeli",CHOOSE(RANDBETWEEN(1,5),1,1,1,1,2),""))))) | G11: =IF(OR('Öğrenci Listesi'!B12="",AC11=""),"",IF(AC11="Çok İyi",CHOOSE(RANDBETWEEN(1,5),4,4,4,4,3),IF(AC11="İyi",CHOOSE(RANDBETWEEN(1,5),3,3,3,4,2),IF(AC11="Yeterli",CHOOSE(RANDBETWEEN(1,5),2,2,2,3,1),IF(AC11="Geliştirilmeli",CHOOSE(RANDBETWEEN(1,5),1,1,1,1,2),""))))) | H11: =IF(OR('Öğrenci Listesi'!B12="",AC11=""),"",IF(AC11="Çok İyi",CHOOSE(RANDBETWEEN(1,5),4,4,4,4,3),IF(AC11="İyi",CHOOSE(RANDBETWEEN(1,5),3,3,3,4,2),IF(AC11="Yeterli",CHOOSE(RANDBETWEEN(1,5),2,2,2,3,1),IF(AC11="Geliştirilmeli",CHOOSE(RANDBETWEEN(1,5),1,1,1,1,2),""))))) | I11: =IF(OR('Öğrenci Listesi'!B12="",AC11=""),"",IF(AC11="Çok İyi",CHOOSE(RANDBETWEEN(1,5),4,4,4,4,3),IF(AC11="İyi",CHOOSE(RANDBETWEEN(1,5),3,3,3,4,2),IF(AC11="Yeterli",CHOOSE(RANDBETWEEN(1,5),2,2,2,3,1),IF(AC11="Geliştirilmeli",CHOOSE(RANDBETWEEN(1,5),1,1,1,1,2),""))))) | J11: =IF(OR('Öğrenci Listesi'!B12="",AC11=""),"",IF(AC11="Çok İyi",CHOOSE(RANDBETWEEN(1,5),4,4,4,4,3),IF(AC11="İyi",CHOOSE(RANDBETWEEN(1,5),3,3,3,4,2),IF(AC11="Yeterli",CHOOSE(RANDBETWEEN(1,5),2,2,2,3,1),IF(AC11="Geliştirilmeli",CHOOSE(RANDBETWEEN(1,5),1,1,1,1,2),""))))) | K11: =IF(OR('Öğrenci Listesi'!B12="",AC11=""),"",IF(AC11="Çok İyi",CHOOSE(RANDBETWEEN(1,5),4,4,4,4,3),IF(AC11="İyi",CHOOSE(RANDBETWEEN(1,5),3,3,3,4,2),IF(AC11="Yeterli",CHOOSE(RANDBETWEEN(1,5),2,2,2,3,1),IF(AC11="Geliştirilmeli",CHOOSE(RANDBETWEEN(1,5),1,1,1,1,2),""))))) | L11: =IF(OR('Öğrenci Listesi'!B12="",AC11=""),"",IF(AC11="Çok İyi",CHOOSE(RANDBETWEEN(1,5),4,4,4,4,3),IF(AC11="İyi",CHOOSE(RANDBETWEEN(1,5),3,3,3,4,2),IF(AC11="Yeterli",CHOOSE(RANDBETWEEN(1,5),2,2,2,3,1),IF(AC11="Geliştirilmeli",CHOOSE(RANDBETWEEN(1,5),1,1,1,1,2),""))))) | M11: =IF(OR('Öğrenci Listesi'!B12="",AC11=""),"",IF(AC11="Çok İyi",CHOOSE(RANDBETWEEN(1,5),4,4,4,4,3),IF(AC11="İyi",CHOOSE(RANDBETWEEN(1,5),3,3,3,4,2),IF(AC11="Yeterli",CHOOSE(RANDBETWEEN(1,5),2,2,2,3,1),IF(AC11="Geliştirilmeli",CHOOSE(RANDBETWEEN(1,5),1,1,1,1,2),""))))) | N11: =IF(OR('Öğrenci Listesi'!B12="",AC11=""),"",IF(AC11="Çok İyi",CHOOSE(RANDBETWEEN(1,5),4,4,4,4,3),IF(AC11="İyi",CHOOSE(RANDBETWEEN(1,5),3,3,3,4,2),IF(AC11="Yeterli",CHOOSE(RANDBETWEEN(1,5),2,2,2,3,1),IF(AC11="Geliştirilmeli",CHOOSE(RANDBETWEEN(1,5),1,1,1,1,2),""))))) | O11: =IF(OR('Öğrenci Listesi'!B12="",AC11=""),"",IF(AC11="Çok İyi",CHOOSE(RANDBETWEEN(1,5),4,4,4,4,3),IF(AC11="İyi",CHOOSE(RANDBETWEEN(1,5),3,3,3,4,2),IF(AC11="Yeterli",CHOOSE(RANDBETWEEN(1,5),2,2,2,3,1),IF(AC11="Geliştirilmeli",CHOOSE(RANDBETWEEN(1,5),1,1,1,1,2),""))))) | P11: =IF(OR('Öğrenci Listesi'!B12="",AC11=""),"",IF(AC11="Çok İyi",CHOOSE(RANDBETWEEN(1,5),4,4,4,4,3),IF(AC11="İyi",CHOOSE(RANDBETWEEN(1,5),3,3,3,4,2),IF(AC11="Yeterli",CHOOSE(RANDBETWEEN(1,5),2,2,2,3,1),IF(AC11="Geliştirilmeli",CHOOSE(RANDBETWEEN(1,5),1,1,1,1,2),""))))) | Q11: =IF(OR('Öğrenci Listesi'!B12="",AC11=""),"",IF(AC11="Çok İyi",CHOOSE(RANDBETWEEN(1,5),4,4,4,4,3),IF(AC11="İyi",CHOOSE(RANDBETWEEN(1,5),3,3,3,4,2),IF(AC11="Yeterli",CHOOSE(RANDBETWEEN(1,5),2,2,2,3,1),IF(AC11="Geliştirilmeli",CHOOSE(RANDBETWEEN(1,5),1,1,1,1,2),""))))) | R11: =IF(OR('Öğrenci Listesi'!B12="",AC11=""),"",IF(AC11="Çok İyi",CHOOSE(RANDBETWEEN(1,5),4,4,4,4,3),IF(AC11="İyi",CHOOSE(RANDBETWEEN(1,5),3,3,3,4,2),IF(AC11="Yeterli",CHOOSE(RANDBETWEEN(1,5),2,2,2,3,1),IF(AC11="Geliştirilmeli",CHOOSE(RANDBETWEEN(1,5),1,1,1,1,2),""))))) | S11: =IF(OR('Öğrenci Listesi'!B12="",AC11=""),"",IF(AC11="Çok İyi",CHOOSE(RANDBETWEEN(1,5),4,4,4,4,3),IF(AC11="İyi",CHOOSE(RANDBETWEEN(1,5),3,3,3,4,2),IF(AC11="Yeterli",CHOOSE(RANDBETWEEN(1,5),2,2,2,3,1),IF(AC11="Geliştirilmeli",CHOOSE(RANDBETWEEN(1,5),1,1,1,1,2),""))))) | T11: =IF(OR('Öğrenci Listesi'!B12="",AC11=""),"",IF(AC11="Çok İyi",CHOOSE(RANDBETWEEN(1,5),4,4,4,4,3),IF(AC11="İyi",CHOOSE(RANDBETWEEN(1,5),3,3,3,4,2),IF(AC11="Yeterli",CHOOSE(RANDBETWEEN(1,5),2,2,2,3,1),IF(AC11="Geliştirilmeli",CHOOSE(RANDBETWEEN(1,5),1,1,1,1,2),""))))) | U11: =IF(OR('Öğrenci Listesi'!B12="",AC11=""),"",IF(AC11="Çok İyi",CHOOSE(RANDBETWEEN(1,5),4,4,4,4,3),IF(AC11="İyi",CHOOSE(RANDBETWEEN(1,5),3,3,3,4,2),IF(AC11="Yeterli",CHOOSE(RANDBETWEEN(1,5),2,2,2,3,1),IF(AC11="Geliştirilmeli",CHOOSE(RANDBETWEEN(1,5),1,1,1,1,2),""))))) | V11: =IF(OR('Öğrenci Listesi'!B12="",AC11=""),"",IF(AC11="Çok İyi",CHOOSE(RANDBETWEEN(1,5),4,4,4,4,3),IF(AC11="İyi",CHOOSE(RANDBETWEEN(1,5),3,3,3,4,2),IF(AC11="Yeterli",CHOOSE(RANDBETWEEN(1,5),2,2,2,3,1),IF(AC11="Geliştirilmeli",CHOOSE(RANDBETWEEN(1,5),1,1,1,1,2),""))))) | W11: =IF(OR('Öğrenci Listesi'!B12="",AC11=""),"",IF(AC11="Çok İyi",CHOOSE(RANDBETWEEN(1,5),4,4,4,4,3),IF(AC11="İyi",CHOOSE(RANDBETWEEN(1,5),3,3,3,4,2),IF(AC11="Yeterli",CHOOSE(RANDBETWEEN(1,5),2,2,2,3,1),IF(AC11="Geliştirilmeli",CHOOSE(RANDBETWEEN(1,5),1,1,1,1,2),""))))) | X11: =IF(OR('Öğrenci Listesi'!B12="",AC11=""),"",IF(AC11="Çok İyi",CHOOSE(RANDBETWEEN(1,5),4,4,4,4,3),IF(AC11="İyi",CHOOSE(RANDBETWEEN(1,5),3,3,3,4,2),IF(AC11="Yeterli",CHOOSE(RANDBETWEEN(1,5),2,2,2,3,1),IF(AC11="Geliştirilmeli",CHOOSE(RANDBETWEEN(1,5),1,1,1,1,2),""))))) | Y11: =IF(OR('Öğrenci Listesi'!B12="",AC11=""),"",IF(AC11="Çok İyi",CHOOSE(RANDBETWEEN(1,5),4,4,4,4,3),IF(AC11="İyi",CHOOSE(RANDBETWEEN(1,5),3,3,3,4,2),IF(AC11="Yeterli",CHOOSE(RANDBETWEEN(1,5),2,2,2,3,1),IF(AC11="Geliştirilmeli",CHOOSE(RANDBETWEEN(1,5),1,1,1,1,2),""))))) | Z11: =IF(OR('Öğrenci Listesi'!B12="",AC11=""),"",IF(AC11="Çok İyi",CHOOSE(RANDBETWEEN(1,5),4,4,4,4,3),IF(AC11="İyi",CHOOSE(RANDBETWEEN(1,5),3,3,3,4,2),IF(AC11="Yeterli",CHOOSE(RANDBETWEEN(1,5),2,2,2,3,1),IF(AC11="Geliştirilmeli",CHOOSE(RANDBETWEEN(1,5),1,1,1,1,2),""))))) | AA11: =IF(OR('Öğrenci Listesi'!B12="",AC11=""),"",IF(AC11="Çok İyi",CHOOSE(RANDBETWEEN(1,5),4,4,4,4,3),IF(AC11="İyi",CHOOSE(RANDBETWEEN(1,5),3,3,3,4,2),IF(AC11="Yeterli",CHOOSE(RANDBETWEEN(1,5),2,2,2,3,1),IF(AC11="Geliştirilmeli",CHOOSE(RANDBETWEEN(1,5),1,1,1,1,2),""))))) | AB11: =IF(OR('Öğrenci Listesi'!B12="",AC11=""),"",ROUND(AVERAGE(C11:AA11),2)) | AC11: =IFERROR(IF('Öğrenci Listesi'!G12="","",IF(UPPER(TRIM('Öğrenci Listesi'!G12))="ÇOK İYİ","Çok İyi",IF(UPPER(TRIM('Öğrenci Listesi'!G12))="İYİ","İyi",IF(UPPER(TRIM('Öğrenci Listesi'!G12))="YETERLİ","Yeterli",IF(UPPER(TRIM('Öğrenci Listesi'!G12))="GELİŞTİRİLMELİ","Geliştirilmeli",'Öğrenci Listesi'!G12))))),"")
