Workbook

Sheet Bilgiler
A1: 📝 BİLGİLERİ DOLDURUNUZ
A2: Aşağıdaki bilgileri kendi okulunuza ve sınıfınıza göre doldurun. 'Ölçek' sayfasındaki başlıklar otomatik güncellenecek.
A4: Okul Adı
A5: Eğitim Öğretim Yılı
A6: Sınıf / Şube
A7: Dönem
A8: Ders | B8: Trafik Güvenliği
A9: Sınıf Öğretmeni
A10: Okul Müdürü

Sheet Öğrenci Listesi
A1: 📋 SİSTEMDEN ÖĞRENCİ LİSTESİNİ BURAYA YAPIŞTIRIN
A2: Sistemde notları işaretledikten sonra tüm tabloyu kopyalayın (Ctrl+C), aşağıdaki sarı alana yapıştırın (Ctrl+V).
A3: ✓ Öğrenci adları, numaraları ve seviyeler 'Ölçek' sayfasına otomatik aktarılacak.
A5: NO | B5: ADI SOYADI | C5: Geliştirilmeli | D5: Yeterli | E5: İyi | F5: Çok İyi | G5: SONUÇ | H5: (yok sayılır)

Sheet Ölçek
A1: =Bilgiler!B4&" • "&Bilgiler!B5&" EĞİTİM ÖĞRETİM YILI" -> • EĞİTİM ÖĞRETİM YILI
A2: =Bilgiler!B6&" SINIFI "&Bilgiler!B7&" "&Bilgiler!B8&" DERSİ KAZANIM DEĞERLENDİRME ÖLÇEĞİ" -> SINIFI Trafik Güvenliği DERSİ KAZANIM DEĞERLENDİRME ÖLÇEĞİ
A4: NO | B4: ADI VE SOYADI | C4: Trafikte kendisinin ve başkalarının hayatının önemli olduğunu fark eder | D4: Trafikle ilgili temel kavramları açıklar | E4: Trafik işaretleri ve işaret levhalarının önemini araştırır | F4: Yaya olarak trafik kurallarına uyar | G4: Günlük yaşantısında çevresindeki güvenli yolları kullanır | H4: Taşıt trafiğine kapalı alanlarda oyun araçlarını güvenli kullanır | I4: Ulaşım araçlarını çeşitli özellikleri açısından karşılaştırır | J4: Trafikte geçiş üstünlüğü olan taşıtları tanır | K4: Trafikle ilgili meslekleri ve kurumları araştırır | L4: Trafikte toplu taşıma araçlarını kullanmanın önemini kavrar | M4: Taşıtlara binerken, taşıtlardan inerken ve taşıtlarda yolculuk ederken kurallara uyar | N4: Trafikte karşılaşılabilecek tehlikelere örnekler verir | O4: Trafikte karşılaşabileceği tehlikelere karşı alınması gereken önlemleri nedenleriyle açıklar | P4: Taşıt trafiğinde tehlikeli hareketlerden kaçınır | Q4: Trafikte sorumlu, saygılı ve sabırlı olmanın gerekliliğini sorgular | R4: Trafik kurallarına uymanın birey ve toplum hayatına etkilerini tartışır | S4: Trafik kurallarının etkin bir şekilde uygulanmasına yönelik önerilerde bulunur | T4: Taşıtlarda bulunması gereken ilk yardım malzemelerini tanır | U4: Trafikte ilk yardım gerektiren durumlarda kimlerden ve nasıl yardım istenmesi gerektiğini açıklar | V4: İlk yardım uygulamalarında doğru müdahalenin önemini tartışır | W4: Hafif yaralanmalarda yapılacak ilk yardım uygulamalarını araştırır | X4: ORTALAMA | Y4: SEVİYE
A5: =IFERROR(IF('Öğrenci Listesi'!A6="","",'Öğrenci Listesi'!A6),"") | B5: =IFERROR(IF('Öğrenci Listesi'!B6="","",'Öğrenci Listesi'!B6),"") | C5: =IF(OR('Öğrenci Listesi'!B6="",Y5=""),"",IF(Y5="Çok İyi",CHOOSE(RANDBETWEEN(1,5),4,4,4,4,3),IF(Y5="İyi",CHOOSE(RANDBETWEEN(1,5),3,3,3,4,2),IF(Y5="Yeterli",CHOOSE(RANDBETWEEN(1,5),2,2,2,3,1),IF(Y5="Geliştirilmeli",CHOOSE(RANDBETWEEN(1,5),1,1,1,1,2),""))))) | D5: =IF(OR('Öğrenci Listesi'!B6="",Y5=""),"",IF(Y5="Çok İyi",CHOOSE(RANDBETWEEN(1,5),4,4,4,4,3),IF(Y5="İyi",CHOOSE(RANDBETWEEN(1,5),3,3,3,4,2),IF(Y5="Yeterli",CHOOSE(RANDBETWEEN(1,5),2,2,2,3,1),IF(Y5="Geliştirilmeli",CHOOSE(RANDBETWEEN(1,5),1,1,1,1,2),""))))) | E5: =IF(OR('Öğrenci Listesi'!B6="",Y5=""),"",IF(Y5="Çok İyi",CHOOSE(RANDBETWEEN(1,5),4,4,4,4,3),IF(Y5="İyi",CHOOSE(RANDBETWEEN(1,5),3,3,3,4,2),IF(Y5="Yeterli",CHOOSE(RANDBETWEEN(1,5),2,2,2,3,1),IF(Y5="Geliştirilmeli",CHOOSE(RANDBETWEEN(1,5),1,1,1,1,2),""))))) | F5: =IF(OR('Öğrenci Listesi'!B6="",Y5=""),"",IF(Y5="Çok İyi",CHOOSE(RANDBETWEEN(1,5),4,4,4,4,3),IF(Y5="İyi",CHOOSE(RANDBETWEEN(1,5),3,3,3,4,2),IF(Y5="Yeterli",CHOOSE(RANDBETWEEN(1,5),2,2,2,3,1),IF(Y5="Geliştirilmeli",CHOOSE(RANDBETWEEN(1,5),1,1,1,1,2),""))))) | G5: =IF(OR('Öğrenci Listesi'!B6="",Y5=""),"",IF(Y5="Çok İyi",CHOOSE(RANDBETWEEN(1,5),4,4,4,4,3),IF(Y5="İyi",CHOOSE(RANDBETWEEN(1,5),3,3,3,4,2),IF(Y5="Yeterli",CHOOSE(RANDBETWEEN(1,5),2,2,2,3,1),IF(Y5="Geliştirilmeli",CHOOSE(RANDBETWEEN(1,5),1,1,1,1,2),""))))) | H5: =IF(OR('Öğrenci Listesi'!B6="",Y5=""),"",IF(Y5="Çok İyi",CHOOSE(RANDBETWEEN(1,5),4,4,4,4,3),IF(Y5="İyi",CHOOSE(RANDBETWEEN(1,5),3,3,3,4,2),IF(Y5="Yeterli",CHOOSE(RANDBETWEEN(1,5),2,2,2,3,1),IF(Y5="Geliştirilmeli",CHOOSE(RANDBETWEEN(1,5),1,1,1,1,2),""))))) | I5: =IF(OR('Öğrenci Listesi'!B6="",Y5=""),"",IF(Y5="Çok İyi",CHOOSE(RANDBETWEEN(1,5),4,4,4,4,3),IF(Y5="İyi",CHOOSE(RANDBETWEEN(1,5),3,3,3,4,2),IF(Y5="Yeterli",CHOOSE(RANDBETWEEN(1,5),2,2,2,3,1),IF(Y5="Geliştirilmeli",CHOOSE(RANDBETWEEN(1,5),1,1,1,1,2),""))))) | J5: =IF(OR('Öğrenci Listesi'!B6="",Y5=""),"",IF(Y5="Çok İyi",CHOOSE(RANDBETWEEN(1,5),4,4,4,4,3),IF(Y5="İyi",CHOOSE(RANDBETWEEN(1,5),3,3,3,4,2),IF(Y5="Yeterli",CHOOSE(RANDBETWEEN(1,5),2,2,2,3,1),IF(Y5="Geliştirilmeli",CHOOSE(RANDBETWEEN(1,5),1,1,1,1,2),""))))) | K5: =IF(OR('Öğrenci Listesi'!B6="",Y5=""),"",IF(Y5="Çok İyi",CHOOSE(RANDBETWEEN(1,5),4,4,4,4,3),IF(Y5="İyi",CHOOSE(RANDBETWEEN(1,5),3,3,3,4,2),IF(Y5="Yeterli",CHOOSE(RANDBETWEEN(1,5),2,2,2,3,1),IF(Y5="Geliştirilmeli",CHOOSE(RANDBETWEEN(1,5),1,1,1,1,2),""))))) | L5: =IF(OR('Öğrenci Listesi'!B6="",Y5=""),"",IF(Y5="Çok İyi",CHOOSE(RANDBETWEEN(1,5),4,4,4,4,3),IF(Y5="İyi",CHOOSE(RANDBETWEEN(1,5),3,3,3,4,2),IF(Y5="Yeterli",CHOOSE(RANDBETWEEN(1,5),2,2,2,3,1),IF(Y5="Geliştirilmeli",CHOOSE(RANDBETWEEN(1,5),1,1,1,1,2),""))))) | M5: =IF(OR('Öğrenci Listesi'!B6="",Y5=""),"",IF(Y5="Çok İyi",CHOOSE(RANDBETWEEN(1,5),4,4,4,4,3),IF(Y5="İyi",CHOOSE(RANDBETWEEN(1,5),3,3,3,4,2),IF(Y5="Yeterli",CHOOSE(RANDBETWEEN(1,5),2,2,2,3,1),IF(Y5="Geliştirilmeli",CHOOSE(RANDBETWEEN(1,5),1,1,1,1,2),""))))) | N5: =IF(OR('Öğrenci Listesi'!B6="",Y5=""),"",IF(Y5="Çok İyi",CHOOSE(RANDBETWEEN(1,5),4,4,4,4,3),IF(Y5="İyi",CHOOSE(RANDBETWEEN(1,5),3,3,3,4,2),IF(Y5="Yeterli",CHOOSE(RANDBETWEEN(1,5),2,2,2,3,1),IF(Y5="Geliştirilmeli",CHOOSE(RANDBETWEEN(1,5),1,1,1,1,2),""))))) | O5: =IF(OR('Öğrenci Listesi'!B6="",Y5=""),"",IF(Y5="Çok İyi",CHOOSE(RANDBETWEEN(1,5),4,4,4,4,3),IF(Y5="İyi",CHOOSE(RANDBETWEEN(1,5),3,3,3,4,2),IF(Y5="Yeterli",CHOOSE(RANDBETWEEN(1,5),2,2,2,3,1),IF(Y5="Geliştirilmeli",CHOOSE(RANDBETWEEN(1,5),1,1,1,1,2),""))))) | P5: =IF(OR('Öğrenci Listesi'!B6="",Y5=""),"",IF(Y5="Çok İyi",CHOOSE(RANDBETWEEN(1,5),4,4,4,4,3),IF(Y5="İyi",CHOOSE(RANDBETWEEN(1,5),3,3,3,4,2),IF(Y5="Yeterli",CHOOSE(RANDBETWEEN(1,5),2,2,2,3,1),IF(Y5="Geliştirilmeli",CHOOSE(RANDBETWEEN(1,5),1,1,1,1,2),""))))) | Q5: =IF(OR('Öğrenci Listesi'!B6="",Y5=""),"",IF(Y5="Çok İyi",CHOOSE(RANDBETWEEN(1,5),4,4,4,4,3),IF(Y5="İyi",CHOOSE(RANDBETWEEN(1,5),3,3,3,4,2),IF(Y5="Yeterli",CHOOSE(RANDBETWEEN(1,5),2,2,2,3,1),IF(Y5="Geliştirilmeli",CHOOSE(RANDBETWEEN(1,5),1,1,1,1,2),""))))) | R5: =IF(OR('Öğrenci Listesi'!B6="",Y5=""),"",IF(Y5="Çok İyi",CHOOSE(RANDBETWEEN(1,5),4,4,4,4,3),IF(Y5="İyi",CHOOSE(RANDBETWEEN(1,5),3,3,3,4,2),IF(Y5="Yeterli",CHOOSE(RANDBETWEEN(1,5),2,2,2,3,1),IF(Y5="Geliştirilmeli",CHOOSE(RANDBETWEEN(1,5),1,1,1,1,2),""))))) | S5: =IF(OR('Öğrenci Listesi'!B6="",Y5=""),"",IF(Y5="Çok İyi",CHOOSE(RANDBETWEEN(1,5),4,4,4,4,3),IF(Y5="İyi",CHOOSE(RANDBETWEEN(1,5),3,3,3,4,2),IF(Y5="Yeterli",CHOOSE(RANDBETWEEN(1,5),2,2,2,3,1),IF(Y5="Geliştirilmeli",CHOOSE(RANDBETWEEN(1,5),1,1,1,1,2),""))))) | T5: =IF(OR('Öğrenci Listesi'!B6="",Y5=""),"",IF(Y5="Çok İyi",CHOOSE(RANDBETWEEN(1,5),4,4,4,4,3),IF(Y5="İyi",CHOOSE(RANDBETWEEN(1,5),3,3,3,4,2),IF(Y5="Yeterli",CHOOSE(RANDBETWEEN(1,5),2,2,2,3,1),IF(Y5="Geliştirilmeli",CHOOSE(RANDBETWEEN(1,5),1,1,1,1,2),""))))) | U5: =IF(OR('Öğrenci Listesi'!B6="",Y5=""),"",IF(Y5="Çok İyi",CHOOSE(RANDBETWEEN(1,5),4,4,4,4,3),IF(Y5="İyi",CHOOSE(RANDBETWEEN(1,5),3,3,3,4,2),IF(Y5="Yeterli",CHOOSE(RANDBETWEEN(1,5),2,2,2,3,1),IF(Y5="Geliştirilmeli",CHOOSE(RANDBETWEEN(1,5),1,1,1,1,2),""))))) | V5: =IF(OR('Öğrenci Listesi'!B6="",Y5=""),"",IF(Y5="Çok İyi",CHOOSE(RANDBETWEEN(1,5),4,4,4,4,3),IF(Y5="İyi",CHOOSE(RANDBETWEEN(1,5),3,3,3,4,2),IF(Y5="Yeterli",CHOOSE(RANDBETWEEN(1,5),2,2,2,3,1),IF(Y5="Geliştirilmeli",CHOOSE(RANDBETWEEN(1,5),1,1,1,1,2),""))))) | W5: =IF(OR('Öğrenci Listesi'!B6="",Y5=""),"",IF(Y5="Çok İyi",CHOOSE(RANDBETWEEN(1,5),4,4,4,4,3),IF(Y5="İyi",CHOOSE(RANDBETWEEN(1,5),3,3,3,4,2),IF(Y5="Yeterli",CHOOSE(RANDBETWEEN(1,5),2,2,2,3,1),IF(Y5="Geliştirilmeli",CHOOSE(RANDBETWEEN(1,5),1,1,1,1,2),""))))) | X5: =IF(OR('Öğrenci Listesi'!B6="",Y5=""),"",ROUND(AVERAGE(C5:W5),2)) | Y5: =IFERROR(IF('Öğrenci Listesi'!G6="","",IF(UPPER(TRIM('Öğrenci Listesi'!G6))="ÇOK İYİ","Çok İyi",IF(UPPER(TRIM('Öğrenci Listesi'!G6))="İYİ","İyi",IF(UPPER(TRIM('Öğrenci Listesi'!G6))="YETERLİ","Yeterli",IF(UPPER(TRIM('Öğrenci Listesi'!G6))="GELİŞTİRİLMELİ","Geliştirilmeli",'Öğrenci Listesi'!G6))))),"")
A6: =IFERROR(IF('Öğrenci Listesi'!A7="","",'Öğrenci Listesi'!A7),"") | B6: =IFERROR(IF('Öğrenci Listesi'!B7="","",'Öğrenci Listesi'!B7),"") | C6: =IF(OR('Öğrenci Listesi'!B7="",Y6=""),"",IF(Y6="Çok İyi",CHOOSE(RANDBETWEEN(1,5),4,4,4,4,3),IF(Y6="İyi",CHOOSE(RANDBETWEEN(1,5),3,3,3,4,2),IF(Y6="Yeterli",CHOOSE(RANDBETWEEN(1,5),2,2,2,3,1),IF(Y6="Geliştirilmeli",CHOOSE(RANDBETWEEN(1,5),1,1,1,1,2),""))))) | D6: =IF(OR('Öğrenci Listesi'!B7="",Y6=""),"",IF(Y6="Çok İyi",CHOOSE(RANDBETWEEN(1,5),4,4,4,4,3),IF(Y6="İyi",CHOOSE(RANDBETWEEN(1,5),3,3,3,4,2),IF(Y6="Yeterli",CHOOSE(RANDBETWEEN(1,5),2,2,2,3,1),IF(Y6="Geliştirilmeli",CHOOSE(RANDBETWEEN(1,5),1,1,1,1,2),""))))) | E6: =IF(OR('Öğrenci Listesi'!B7="",Y6=""),"",IF(Y6="Çok İyi",CHOOSE(RANDBETWEEN(1,5),4,4,4,4,3),IF(Y6="İyi",CHOOSE(RANDBETWEEN(1,5),3,3,3,4,2),IF(Y6="Yeterli",CHOOSE(RANDBETWEEN(1,5),2,2,2,3,1),IF(Y6="Geliştirilmeli",CHOOSE(RANDBETWEEN(1,5),1,1,1,1,2),""))))) | F6: =IF(OR('Öğrenci Listesi'!B7="",Y6=""),"",IF(Y6="Çok İyi",CHOOSE(RANDBETWEEN(1,5),4,4,4,4,3),IF(Y6="İyi",CHOOSE(RANDBETWEEN(1,5),3,3,3,4,2),IF(Y6="Yeterli",CHOOSE(RANDBETWEEN(1,5),2,2,2,3,1),IF(Y6="Geliştirilmeli",CHOOSE(RANDBETWEEN(1,5),1,1,1,1,2),""))))) | G6: =IF(OR('Öğrenci Listesi'!B7="",Y6=""),"",IF(Y6="Çok İyi",CHOOSE(RANDBETWEEN(1,5),4,4,4,4,3),IF(Y6="İyi",CHOOSE(RANDBETWEEN(1,5),3,3,3,4,2),IF(Y6="Yeterli",CHOOSE(RANDBETWEEN(1,5),2,2,2,3,1),IF(Y6="Geliştirilmeli",CHOOSE(RANDBETWEEN(1,5),1,1,1,1,2),""))))) | H6: =IF(OR('Öğrenci Listesi'!B7="",Y6=""),"",IF(Y6="Çok İyi",CHOOSE(RANDBETWEEN(1,5),4,4,4,4,3),IF(Y6="İyi",CHOOSE(RANDBETWEEN(1,5),3,3,3,4,2),IF(Y6="Yeterli",CHOOSE(RANDBETWEEN(1,5),2,2,2,3,1),IF(Y6="Geliştirilmeli",CHOOSE(RANDBETWEEN(1,5),1,1,1,1,2),""))))) | I6: =IF(OR('Öğrenci Listesi'!B7="",Y6=""),"",IF(Y6="Çok İyi",CHOOSE(RANDBETWEEN(1,5),4,4,4,4,3),IF(Y6="İyi",CHOOSE(RANDBETWEEN(1,5),3,3,3,4,2),IF(Y6="Yeterli",CHOOSE(RANDBETWEEN(1,5),2,2,2,3,1),IF(Y6="Geliştirilmeli",CHOOSE(RANDBETWEEN(1,5),1,1,1,1,2),""))))) | J6: =IF(OR('Öğrenci Listesi'!B7="",Y6=""),"",IF(Y6="Çok İyi",CHOOSE(RANDBETWEEN(1,5),4,4,4,4,3),IF(Y6="İyi",CHOOSE(RANDBETWEEN(1,5),3,3,3,4,2),IF(Y6="Yeterli",CHOOSE(RANDBETWEEN(1,5),2,2,2,3,1),IF(Y6="Geliştirilmeli",CHOOSE(RANDBETWEEN(1,5),1,1,1,1,2),""))))) | K6: =IF(OR('Öğrenci Listesi'!B7="",Y6=""),"",IF(Y6="Çok İyi",CHOOSE(RANDBETWEEN(1,5),4,4,4,4,3),IF(Y6="İyi",CHOOSE(RANDBETWEEN(1,5),3,3,3,4,2),IF(Y6="Yeterli",CHOOSE(RANDBETWEEN(1,5),2,2,2,3,1),IF(Y6="Geliştirilmeli",CHOOSE(RANDBETWEEN(1,5),1,1,1,1,2),""))))) | L6: =IF(OR('Öğrenci Listesi'!B7="",Y6=""),"",IF(Y6="Çok İyi",CHOOSE(RANDBETWEEN(1,5),4,4,4,4,3),IF(Y6="İyi",CHOOSE(RANDBETWEEN(1,5),3,3,3,4,2),IF(Y6="Yeterli",CHOOSE(RANDBETWEEN(1,5),2,2,2,3,1),IF(Y6="Geliştirilmeli",CHOOSE(RANDBETWEEN(1,5),1,1,1,1,2),""))))) | M6: =IF(OR('Öğrenci Listesi'!B7="",Y6=""),"",IF(Y6="Çok İyi",CHOOSE(RANDBETWEEN(1,5),4,4,4,4,3),IF(Y6="İyi",CHOOSE(RANDBETWEEN(1,5),3,3,3,4,2),IF(Y6="Yeterli",CHOOSE(RANDBETWEEN(1,5),2,2,2,3,1),IF(Y6="Geliştirilmeli",CHOOSE(RANDBETWEEN(1,5),1,1,1,1,2),""))))) | N6: =IF(OR('Öğrenci Listesi'!B7="",Y6=""),"",IF(Y6="Çok İyi",CHOOSE(RANDBETWEEN(1,5),4,4,4,4,3),IF(Y6="İyi",CHOOSE(RANDBETWEEN(1,5),3,3,3,4,2),IF(Y6="Yeterli",CHOOSE(RANDBETWEEN(1,5),2,2,2,3,1),IF(Y6="Geliştirilmeli",CHOOSE(RANDBETWEEN(1,5),1,1,1,1,2),""))))) | O6: =IF(OR('Öğrenci Listesi'!B7="",Y6=""),"",IF(Y6="Çok İyi",CHOOSE(RANDBETWEEN(1,5),4,4,4,4,3),IF(Y6="İyi",CHOOSE(RANDBETWEEN(1,5),3,3,3,4,2),IF(Y6="Yeterli",CHOOSE(RANDBETWEEN(1,5),2,2,2,3,1),IF(Y6="Geliştirilmeli",CHOOSE(RANDBETWEEN(1,5),1,1,1,1,2),""))))) | P6: =IF(OR('Öğrenci Listesi'!B7="",Y6=""),"",IF(Y6="Çok İyi",CHOOSE(RANDBETWEEN(1,5),4,4,4,4,3),IF(Y6="İyi",CHOOSE(RANDBETWEEN(1,5),3,3,3,4,2),IF(Y6="Yeterli",CHOOSE(RANDBETWEEN(1,5),2,2,2,3,1),IF(Y6="Geliştirilmeli",CHOOSE(RANDBETWEEN(1,5),1,1,1,1,2),""))))) | Q6: =IF(OR('Öğrenci Listesi'!B7="",Y6=""),"",IF(Y6="Çok İyi",CHOOSE(RANDBETWEEN(1,5),4,4,4,4,3),IF(Y6="İyi",CHOOSE(RANDBETWEEN(1,5),3,3,3,4,2),IF(Y6="Yeterli",CHOOSE(RANDBETWEEN(1,5),2,2,2,3,1),IF(Y6="Geliştirilmeli",CHOOSE(RANDBETWEEN(1,5),1,1,1,1,2),""))))) | R6: =IF(OR('Öğrenci Listesi'!B7="",Y6=""),"",IF(Y6="Çok İyi",CHOOSE(RANDBETWEEN(1,5),4,4,4,4,3),IF(Y6="İyi",CHOOSE(RANDBETWEEN(1,5),3,3,3,4,2),IF(Y6="Yeterli",CHOOSE(RANDBETWEEN(1,5),2,2,2,3,1),IF(Y6="Geliştirilmeli",CHOOSE(RANDBETWEEN(1,5),1,1,1,1,2),""))))) | S6: =IF(OR('Öğrenci Listesi'!B7="",Y6=""),"",IF(Y6="Çok İyi",CHOOSE(RANDBETWEEN(1,5),4,4,4,4,3),IF(Y6="İyi",CHOOSE(RANDBETWEEN(1,5),3,3,3,4,2),IF(Y6="Yeterli",CHOOSE(RANDBETWEEN(1,5),2,2,2,3,1),IF(Y6="Geliştirilmeli",CHOOSE(RANDBETWEEN(1,5),1,1,1,1,2),""))))) | T6: =IF(OR('Öğrenci Listesi'!B7="",Y6=""),"",IF(Y6="Çok İyi",CHOOSE(RANDBETWEEN(1,5),4,4,4,4,3),IF(Y6="İyi",CHOOSE(RANDBETWEEN(1,5),3,3,3,4,2),IF(Y6="Yeterli",CHOOSE(RANDBETWEEN(1,5),2,2,2,3,1),IF(Y6="Geliştirilmeli",CHOOSE(RANDBETWEEN(1,5),1,1,1,1,2),""))))) | U6: =IF(OR('Öğrenci Listesi'!B7="",Y6=""),"",IF(Y6="Çok İyi",CHOOSE(RANDBETWEEN(1,5),4,4,4,4,3),IF(Y6="İyi",CHOOSE(RANDBETWEEN(1,5),3,3,3,4,2),IF(Y6="Yeterli",CHOOSE(RANDBETWEEN(1,5),2,2,2,3,1),IF(Y6="Geliştirilmeli",CHOOSE(RANDBETWEEN(1,5),1,1,1,1,2),""))))) | V6: =IF(OR('Öğrenci Listesi'!B7="",Y6=""),"",IF(Y6="Çok İyi",CHOOSE(RANDBETWEEN(1,5),4,4,4,4,3),IF(Y6="İyi",CHOOSE(RANDBETWEEN(1,5),3,3,3,4,2),IF(Y6="Yeterli",CHOOSE(RANDBETWEEN(1,5),2,2,2,3,1),IF(Y6="Geliştirilmeli",CHOOSE(RANDBETWEEN(1,5),1,1,1,1,2),""))))) | W6: =IF(OR('Öğrenci Listesi'!B7="",Y6=""),"",IF(Y6="Çok İyi",CHOOSE(RANDBETWEEN(1,5),4,4,4,4,3),IF(Y6="İyi",CHOOSE(RANDBETWEEN(1,5),3,3,3,4,2),IF(Y6="Yeterli",CHOOSE(RANDBETWEEN(1,5),2,2,2,3,1),IF(Y6="Geliştirilmeli",CHOOSE(RANDBETWEEN(1,5),1,1,1,1,2),""))))) | X6: =IF(OR('Öğrenci Listesi'!B7="",Y6=""),"",ROUND(AVERAGE(C6:W6),2)) | Y6: =IFERROR(IF('Öğrenci Listesi'!G7="","",IF(UPPER(TRIM('Öğrenci Listesi'!G7))="ÇOK İYİ","Çok İyi",IF(UPPER(TRIM('Öğrenci Listesi'!G7))="İYİ","İyi",IF(UPPER(TRIM('Öğrenci Listesi'!G7))="YETERLİ","Yeterli",IF(UPPER(TRIM('Öğrenci Listesi'!G7))="GELİŞTİRİLMELİ","Geliştirilmeli",'Öğrenci Listesi'!G7))))),"")
A7: =IFERROR(IF('Öğrenci Listesi'!A8="","",'Öğrenci Listesi'!A8),"") | B7: =IFERROR(IF('Öğrenci Listesi'!B8="","",'Öğrenci Listesi'!B8),"") | C7: =IF(OR('Öğrenci Listesi'!B8="",Y7=""),"",IF(Y7="Çok İyi",CHOOSE(RANDBETWEEN(1,5),4,4,4,4,3),IF(Y7="İyi",CHOOSE(RANDBETWEEN(1,5),3,3,3,4,2),IF(Y7="Yeterli",CHOOSE(RANDBETWEEN(1,5),2,2,2,3,1),IF(Y7="Geliştirilmeli",CHOOSE(RANDBETWEEN(1,5),1,1,1,1,2),""))))) | D7: =IF(OR('Öğrenci Listesi'!B8="",Y7=""),"",IF(Y7="Çok İyi",CHOOSE(RANDBETWEEN(1,5),4,4,4,4,3),IF(Y7="İyi",CHOOSE(RANDBETWEEN(1,5),3,3,3,4,2),IF(Y7="Yeterli",CHOOSE(RANDBETWEEN(1,5),2,2,2,3,1),IF(Y7="Geliştirilmeli",CHOOSE(RANDBETWEEN(1,5),1,1,1,1,2),""))))) | E7: =IF(OR('Öğrenci Listesi'!B8="",Y7=""),"",IF(Y7="Çok İyi",CHOOSE(RANDBETWEEN(1,5),4,4,4,4,3),IF(Y7="İyi",CHOOSE(RANDBETWEEN(1,5),3,3,3,4,2),IF(Y7="Yeterli",CHOOSE(RANDBETWEEN(1,5),2,2,2,3,1),IF(Y7="Geliştirilmeli",CHOOSE(RANDBETWEEN(1,5),1,1,1,1,2),""))))) | F7: =IF(OR('Öğrenci Listesi'!B8="",Y7=""),"",IF(Y7="Çok İyi",CHOOSE(RANDBETWEEN(1,5),4,4,4,4,3),IF(Y7="İyi",CHOOSE(RANDBETWEEN(1,5),3,3,3,4,2),IF(Y7="Yeterli",CHOOSE(RANDBETWEEN(1,5),2,2,2,3,1),IF(Y7="Geliştirilmeli",CHOOSE(RANDBETWEEN(1,5),1,1,1,1,2),""))))) | G7: =IF(OR('Öğrenci Listesi'!B8="",Y7=""),"",IF(Y7="Çok İyi",CHOOSE(RANDBETWEEN(1,5),4,4,4,4,3),IF(Y7="İyi",CHOOSE(RANDBETWEEN(1,5),3,3,3,4,2),IF(Y7="Yeterli",CHOOSE(RANDBETWEEN(1,5),2,2,2,3,1),IF(Y7="Geliştirilmeli",CHOOSE(RANDBETWEEN(1,5),1,1,1,1,2),""))))) | H7: =IF(OR('Öğrenci Listesi'!B8="",Y7=""),"",IF(Y7="Çok İyi",CHOOSE(RANDBETWEEN(1,5),4,4,4,4,3),IF(Y7="İyi",CHOOSE(RANDBETWEEN(1,5),3,3,3,4,2),IF(Y7="Yeterli",CHOOSE(RANDBETWEEN(1,5),2,2,2,3,1),IF(Y7="Geliştirilmeli",CHOOSE(RANDBETWEEN(1,5),1,1,1,1,2),""))))) | I7: =IF(OR('Öğrenci Listesi'!B8="",Y7=""),"",IF(Y7="Çok İyi",CHOOSE(RANDBETWEEN(1,5),4,4,4,4,3),IF(Y7="İyi",CHOOSE(RANDBETWEEN(1,5),3,3,3,4,2),IF(Y7="Yeterli",CHOOSE(RANDBETWEEN(1,5),2,2,2,3,1),IF(Y7="Geliştirilmeli",CHOOSE(RANDBETWEEN(1,5),1,1,1,1,2),""))))) | J7: =IF(OR('Öğrenci Listesi'!B8="",Y7=""),"",IF(Y7="Çok İyi",CHOOSE(RANDBETWEEN(1,5),4,4,4,4,3),IF(Y7="İyi",CHOOSE(RANDBETWEEN(1,5),3,3,3,4,2),IF(Y7="Yeterli",CHOOSE(RANDBETWEEN(1,5),2,2,2,3,1),IF(Y7="Geliştirilmeli",CHOOSE(RANDBETWEEN(1,5),1,1,1,1,2),""))))) | K7: =IF(OR('Öğrenci Listesi'!B8="",Y7=""),"",IF(Y7="Çok İyi",CHOOSE(RANDBETWEEN(1,5),4,4,4,4,3),IF(Y7="İyi",CHOOSE(RANDBETWEEN(1,5),3,3,3,4,2),IF(Y7="Yeterli",CHOOSE(RANDBETWEEN(1,5),2,2,2,3,1),IF(Y7="Geliştirilmeli",CHOOSE(RANDBETWEEN(1,5),1,1,1,1,2),""))))) | L7: =IF(OR('Öğrenci Listesi'!B8="",Y7=""),"",IF(Y7="Çok İyi",CHOOSE(RANDBETWEEN(1,5),4,4,4,4,3),IF(Y7="İyi",CHOOSE(RANDBETWEEN(1,5),3,3,3,4,2),IF(Y7="Yeterli",CHOOSE(RANDBETWEEN(1,5),2,2,2,3,1),IF(Y7="Geliştirilmeli",CHOOSE(RANDBETWEEN(1,5),1,1,1,1,2),""))))) | M7: =IF(OR('Öğrenci Listesi'!B8="",Y7=""),"",IF(Y7="Çok İyi",CHOOSE(RANDBETWEEN(1,5),4,4,4,4,3),IF(Y7="İyi",CHOOSE(RANDBETWEEN(1,5),3,3,3,4,2),IF(Y7="Yeterli",CHOOSE(RANDBETWEEN(1,5),2,2,2,3,1),IF(Y7="Geliştirilmeli",CHOOSE(RANDBETWEEN(1,5),1,1,1,1,2),""))))) | N7: =IF(OR('Öğrenci Listesi'!B8="",Y7=""),"",IF(Y7="Çok İyi",CHOOSE(RANDBETWEEN(1,5),4,4,4,4,3),IF(Y7="İyi",CHOOSE(RANDBETWEEN(1,5),3,3,3,4,2),IF(Y7="Yeterli",CHOOSE(RANDBETWEEN(1,5),2,2,2,3,1),IF(Y7="Geliştirilmeli",CHOOSE(RANDBETWEEN(1,5),1,1,1,1,2),""))))) | O7: =IF(OR('Öğrenci Listesi'!B8="",Y7=""),"",IF(Y7="Çok İyi",CHOOSE(RANDBETWEEN(1,5),4,4,4,4,3),IF(Y7="İyi",CHOOSE(RANDBETWEEN(1,5),3,3,3,4,2),IF(Y7="Yeterli",CHOOSE(RANDBETWEEN(1,5),2,2,2,3,1),IF(Y7="Geliştirilmeli",CHOOSE(RANDBETWEEN(1,5),1,1,1,1,2),""))))) | P7: =IF(OR('Öğrenci Listesi'!B8="",Y7=""),"",IF(Y7="Çok İyi",CHOOSE(RANDBETWEEN(1,5),4,4,4,4,3),IF(Y7="İyi",CHOOSE(RANDBETWEEN(1,5),3,3,3,4,2),IF(Y7="Yeterli",CHOOSE(RANDBETWEEN(1,5),2,2,2,3,1),IF(Y7="Geliştirilmeli",CHOOSE(RANDBETWEEN(1,5),1,1,1,1,2),""))))) | Q7: =IF(OR('Öğrenci Listesi'!B8="",Y7=""),"",IF(Y7="Çok İyi",CHOOSE(RANDBETWEEN(1,5),4,4,4,4,3),IF(Y7="İyi",CHOOSE(RANDBETWEEN(1,5),3,3,3,4,2),IF(Y7="Yeterli",CHOOSE(RANDBETWEEN(1,5),2,2,2,3,1),IF(Y7="Geliştirilmeli",CHOOSE(RANDBETWEEN(1,5),1,1,1,1,2),""))))) | R7: =IF(OR('Öğrenci Listesi'!B8="",Y7=""),"",IF(Y7="Çok İyi",CHOOSE(RANDBETWEEN(1,5),4,4,4,4,3),IF(Y7="İyi",CHOOSE(RANDBETWEEN(1,5),3,3,3,4,2),IF(Y7="Yeterli",CHOOSE(RANDBETWEEN(1,5),2,2,2,3,1),IF(Y7="Geliştirilmeli",CHOOSE(RANDBETWEEN(1,5),1,1,1,1,2),""))))) | S7: =IF(OR('Öğrenci Listesi'!B8="",Y7=""),"",IF(Y7="Çok İyi",CHOOSE(RANDBETWEEN(1,5),4,4,4,4,3),IF(Y7="İyi",CHOOSE(RANDBETWEEN(1,5),3,3,3,4,2),IF(Y7="Yeterli",CHOOSE(RANDBETWEEN(1,5),2,2,2,3,1),IF(Y7="Geliştirilmeli",CHOOSE(RANDBETWEEN(1,5),1,1,1,1,2),""))))) | T7: =IF(OR('Öğrenci Listesi'!B8="",Y7=""),"",IF(Y7="Çok İyi",CHOOSE(RANDBETWEEN(1,5),4,4,4,4,3),IF(Y7="İyi",CHOOSE(RANDBETWEEN(1,5),3,3,3,4,2),IF(Y7="Yeterli",CHOOSE(RANDBETWEEN(1,5),2,2,2,3,1),IF(Y7="Geliştirilmeli",CHOOSE(RANDBETWEEN(1,5),1,1,1,1,2),""))))) | U7: =IF(OR('Öğrenci Listesi'!B8="",Y7=""),"",IF(Y7="Çok İyi",CHOOSE(RANDBETWEEN(1,5),4,4,4,4,3),IF(Y7="İyi",CHOOSE(RANDBETWEEN(1,5),3,3,3,4,2),IF(Y7="Yeterli",CHOOSE(RANDBETWEEN(1,5),2,2,2,3,1),IF(Y7="Geliştirilmeli",CHOOSE(RANDBETWEEN(1,5),1,1,1,1,2),""))))) | V7: =IF(OR('Öğrenci Listesi'!B8="",Y7=""),"",IF(Y7="Çok İyi",CHOOSE(RANDBETWEEN(1,5),4,4,4,4,3),IF(Y7="İyi",CHOOSE(RANDBETWEEN(1,5),3,3,3,4,2),IF(Y7="Yeterli",CHOOSE(RANDBETWEEN(1,5),2,2,2,3,1),IF(Y7="Geliştirilmeli",CHOOSE(RANDBETWEEN(1,5),1,1,1,1,2),""))))) | W7: =IF(OR('Öğrenci Listesi'!B8="",Y7=""),"",IF(Y7="Çok İyi",CHOOSE(RANDBETWEEN(1,5),4,4,4,4,3),IF(Y7="İyi",CHOOSE(RANDBETWEEN(1,5),3,3,3,4,2),IF(Y7="Yeterli",CHOOSE(RANDBETWEEN(1,5),2,2,2,3,1),IF(Y7="Geliştirilmeli",CHOOSE(RANDBETWEEN(1,5),1,1,1,1,2),""))))) | X7: =IF(OR('Öğrenci Listesi'!B8="",Y7=""),"",ROUND(AVERAGE(C7:W7),2)) | Y7: =IFERROR(IF('Öğrenci Listesi'!G8="","",IF(UPPER(TRIM('Öğrenci Listesi'!G8))="ÇOK İYİ","Çok İyi",IF(UPPER(TRIM('Öğrenci Listesi'!G8))="İYİ","İyi",IF(UPPER(TRIM('Öğrenci Listesi'!G8))="YETERLİ","Yeterli",IF(UPPER(TRIM('Öğrenci Listesi'!G8))="GELİŞTİRİLMELİ","Geliştirilmeli",'Öğrenci Listesi'!G8))))),"")
A8: =IFERROR(IF('Öğrenci Listesi'!A9="","",'Öğrenci Listesi'!A9),"") | B8: =IFERROR(IF('Öğrenci Listesi'!B9="","",'Öğrenci Listesi'!B9),"") | C8: =IF(OR('Öğrenci Listesi'!B9="",Y8=""),"",IF(Y8="Çok İyi",CHOOSE(RANDBETWEEN(1,5),4,4,4,4,3),IF(Y8="İyi",CHOOSE(RANDBETWEEN(1,5),3,3,3,4,2),IF(Y8="Yeterli",CHOOSE(RANDBETWEEN(1,5),2,2,2,3,1),IF(Y8="Geliştirilmeli",CHOOSE(RANDBETWEEN(1,5),1,1,1,1,2),""))))) | D8: =IF(OR('Öğrenci Listesi'!B9="",Y8=""),"",IF(Y8="Çok İyi",CHOOSE(RANDBETWEEN(1,5),4,4,4,4,3),IF(Y8="İyi",CHOOSE(RANDBETWEEN(1,5),3,3,3,4,2),IF(Y8="Yeterli",CHOOSE(RANDBETWEEN(1,5),2,2,2,3,1),IF(Y8="Geliştirilmeli",CHOOSE(RANDBETWEEN(1,5),1,1,1,1,2),""))))) | E8: =IF(OR('Öğrenci Listesi'!B9="",Y8=""),"",IF(Y8="Çok İyi",CHOOSE(RANDBETWEEN(1,5),4,4,4,4,3),IF(Y8="İyi",CHOOSE(RANDBETWEEN(1,5),3,3,3,4,2),IF(Y8="Yeterli",CHOOSE(RANDBETWEEN(1,5),2,2,2,3,1),IF(Y8="Geliştirilmeli",CHOOSE(RANDBETWEEN(1,5),1,1,1,1,2),""))))) | F8: =IF(OR('Öğrenci Listesi'!B9="",Y8=""),"",IF(Y8="Çok İyi",CHOOSE(RANDBETWEEN(1,5),4,4,4,4,3),IF(Y8="İyi",CHOOSE(RANDBETWEEN(1,5),3,3,3,4,2),IF(Y8="Yeterli",CHOOSE(RANDBETWEEN(1,5),2,2,2,3,1),IF(Y8="Geliştirilmeli",CHOOSE(RANDBETWEEN(1,5),1,1,1,1,2),""))))) | G8: =IF(OR('Öğrenci Listesi'!B9="",Y8=""),"",IF(Y8="Çok İyi",CHOOSE(RANDBETWEEN(1,5),4,4,4,4,3),IF(Y8="İyi",CHOOSE(RANDBETWEEN(1,5),3,3,3,4,2),IF(Y8="Yeterli",CHOOSE(RANDBETWEEN(1,5),2,2,2,3,1),IF(Y8="Geliştirilmeli",CHOOSE(RANDBETWEEN(1,5),1,1,1,1,2),""))))) | H8: =IF(OR('Öğrenci Listesi'!B9="",Y8=""),"",IF(Y8="Çok İyi",CHOOSE(RANDBETWEEN(1,5),4,4,4,4,3),IF(Y8="İyi",CHOOSE(RANDBETWEEN(1,5),3,3,3,4,2),IF(Y8="Yeterli",CHOOSE(RANDBETWEEN(1,5),2,2,2,3,1),IF(Y8="Geliştirilmeli",CHOOSE(RANDBETWEEN(1,5),1,1,1,1,2),""))))) | I8: =IF(OR('Öğrenci Listesi'!B9="",Y8=""),"",IF(Y8="Çok İyi",CHOOSE(RANDBETWEEN(1,5),4,4,4,4,3),IF(Y8="İyi",CHOOSE(RANDBETWEEN(1,5),3,3,3,4,2),IF(Y8="Yeterli",CHOOSE(RANDBETWEEN(1,5),2,2,2,3,1),IF(Y8="Geliştirilmeli",CHOOSE(RANDBETWEEN(1,5),1,1,1,1,2),""))))) | J8: =IF(OR('Öğrenci Listesi'!B9="",Y8=""),"",IF(Y8="Çok İyi",CHOOSE(RANDBETWEEN(1,5),4,4,4,4,3),IF(Y8="İyi",CHOOSE(RANDBETWEEN(1,5),3,3,3,4,2),IF(Y8="Yeterli",CHOOSE(RANDBETWEEN(1,5),2,2,2,3,1),IF(Y8="Geliştirilmeli",CHOOSE(RANDBETWEEN(1,5),1,1,1,1,2),""))))) | K8: =IF(OR('Öğrenci Listesi'!B9="",Y8=""),"",IF(Y8="Çok İyi",CHOOSE(RANDBETWEEN(1,5),4,4,4,4,3),IF(Y8="İyi",CHOOSE(RANDBETWEEN(1,5),3,3,3,4,2),IF(Y8="Yeterli",CHOOSE(RANDBETWEEN(1,5),2,2,2,3,1),IF(Y8="Geliştirilmeli",CHOOSE(RANDBETWEEN(1,5),1,1,1,1,2),""))))) | L8: =IF(OR('Öğrenci Listesi'!B9="",Y8=""),"",IF(Y8="Çok İyi",CHOOSE(RANDBETWEEN(1,5),4,4,4,4,3),IF(Y8="İyi",CHOOSE(RANDBETWEEN(1,5),3,3,3,4,2),IF(Y8="Yeterli",CHOOSE(RANDBETWEEN(1,5),2,2,2,3,1),IF(Y8="Geliştirilmeli",CHOOSE(RANDBETWEEN(1,5),1,1,1,1,2),""))))) | M8: =IF(OR('Öğrenci Listesi'!B9="",Y8=""),"",IF(Y8="Çok İyi",CHOOSE(RANDBETWEEN(1,5),4,4,4,4,3),IF(Y8="İyi",CHOOSE(RANDBETWEEN(1,5),3,3,3,4,2),IF(Y8="Yeterli",CHOOSE(RANDBETWEEN(1,5),2,2,2,3,1),IF(Y8="Geliştirilmeli",CHOOSE(RANDBETWEEN(1,5),1,1,1,1,2),""))))) | N8: =IF(OR('Öğrenci Listesi'!B9="",Y8=""),"",IF(Y8="Çok İyi",CHOOSE(RANDBETWEEN(1,5),4,4,4,4,3),IF(Y8="İyi",CHOOSE(RANDBETWEEN(1,5),3,3,3,4,2),IF(Y8="Yeterli",CHOOSE(RANDBETWEEN(1,5),2,2,2,3,1),IF(Y8="Geliştirilmeli",CHOOSE(RANDBETWEEN(1,5),1,1,1,1,2),""))))) | O8: =IF(OR('Öğrenci Listesi'!B9="",Y8=""),"",IF(Y8="Çok İyi",CHOOSE(RANDBETWEEN(1,5),4,4,4,4,3),IF(Y8="İyi",CHOOSE(RANDBETWEEN(1,5),3,3,3,4,2),IF(Y8="Yeterli",CHOOSE(RANDBETWEEN(1,5),2,2,2,3,1),IF(Y8="Geliştirilmeli",CHOOSE(RANDBETWEEN(1,5),1,1,1,1,2),""))))) | P8: =IF(OR('Öğrenci Listesi'!B9="",Y8=""),"",IF(Y8="Çok İyi",CHOOSE(RANDBETWEEN(1,5),4,4,4,4,3),IF(Y8="İyi",CHOOSE(RANDBETWEEN(1,5),3,3,3,4,2),IF(Y8="Yeterli",CHOOSE(RANDBETWEEN(1,5),2,2,2,3,1),IF(Y8="Geliştirilmeli",CHOOSE(RANDBETWEEN(1,5),1,1,1,1,2),""))))) | Q8: =IF(OR('Öğrenci Listesi'!B9="",Y8=""),"",IF(Y8="Çok İyi",CHOOSE(RANDBETWEEN(1,5),4,4,4,4,3),IF(Y8="İyi",CHOOSE(RANDBETWEEN(1,5),3,3,3,4,2),IF(Y8="Yeterli",CHOOSE(RANDBETWEEN(1,5),2,2,2,3,1),IF(Y8="Geliştirilmeli",CHOOSE(RANDBETWEEN(1,5),1,1,1,1,2),""))))) | R8: =IF(OR('Öğrenci Listesi'!B9="",Y8=""),"",IF(Y8="Çok İyi",CHOOSE(RANDBETWEEN(1,5),4,4,4,4,3),IF(Y8="İyi",CHOOSE(RANDBETWEEN(1,5),3,3,3,4,2),IF(Y8="Yeterli",CHOOSE(RANDBETWEEN(1,5),2,2,2,3,1),IF(Y8="Geliştirilmeli",CHOOSE(RANDBETWEEN(1,5),1,1,1,1,2),""))))) | S8: =IF(OR('Öğrenci Listesi'!B9="",Y8=""),"",IF(Y8="Çok İyi",CHOOSE(RANDBETWEEN(1,5),4,4,4,4,3),IF(Y8="İyi",CHOOSE(RANDBETWEEN(1,5),3,3,3,4,2),IF(Y8="Yeterli",CHOOSE(RANDBETWEEN(1,5),2,2,2,3,1),IF(Y8="Geliştirilmeli",CHOOSE(RANDBETWEEN(1,5),1,1,1,1,2),""))))) | T8: =IF(OR('Öğrenci Listesi'!B9="",Y8=""),"",IF(Y8="Çok İyi",CHOOSE(RANDBETWEEN(1,5),4,4,4,4,3),IF(Y8="İyi",CHOOSE(RANDBETWEEN(1,5),3,3,3,4,2),IF(Y8="Yeterli",CHOOSE(RANDBETWEEN(1,5),2,2,2,3,1),IF(Y8="Geliştirilmeli",CHOOSE(RANDBETWEEN(1,5),1,1,1,1,2),""))))) | U8: =IF(OR('Öğrenci Listesi'!B9="",Y8=""),"",IF(Y8="Çok İyi",CHOOSE(RANDBETWEEN(1,5),4,4,4,4,3),IF(Y8="İyi",CHOOSE(RANDBETWEEN(1,5),3,3,3,4,2),IF(Y8="Yeterli",CHOOSE(RANDBETWEEN(1,5),2,2,2,3,1),IF(Y8="Geliştirilmeli",CHOOSE(RANDBETWEEN(1,5),1,1,1,1,2),""))))) | V8: =IF(OR('Öğrenci Listesi'!B9="",Y8=""),"",IF(Y8="Çok İyi",CHOOSE(RANDBETWEEN(1,5),4,4,4,4,3),IF(Y8="İyi",CHOOSE(RANDBETWEEN(1,5),3,3,3,4,2),IF(Y8="Yeterli",CHOOSE(RANDBETWEEN(1,5),2,2,2,3,1),IF(Y8="Geliştirilmeli",CHOOSE(RANDBETWEEN(1,5),1,1,1,1,2),""))))) | W8: =IF(OR('Öğrenci Listesi'!B9="",Y8=""),"",IF(Y8="Çok İyi",CHOOSE(RANDBETWEEN(1,5),4,4,4,4,3),IF(Y8="İyi",CHOOSE(RANDBETWEEN(1,5),3,3,3,4,2),IF(Y8="Yeterli",CHOOSE(RANDBETWEEN(1,5),2,2,2,3,1),IF(Y8="Geliştirilmeli",CHOOSE(RANDBETWEEN(1,5),1,1,1,1,2),""))))) | X8: =IF(OR('Öğrenci Listesi'!B9="",Y8=""),"",ROUND(AVERAGE(C8:W8),2)) | Y8: =IFERROR(IF('Öğrenci Listesi'!G9="","",IF(UPPER(TRIM('Öğrenci Listesi'!G9))="ÇOK İYİ","Çok İyi",IF(UPPER(TRIM('Öğrenci Listesi'!G9))="İYİ","İyi",IF(UPPER(TRIM('Öğrenci Listesi'!G9))="YETERLİ","Yeterli",IF(UPPER(TRIM('Öğrenci Listesi'!G9))="GELİŞTİRİLMELİ","Geliştirilmeli",'Öğrenci Listesi'!G9))))),"")
A9: =IFERROR(IF('Öğrenci Listesi'!A10="","",'Öğrenci Listesi'!A10),"") | B9: =IFERROR(IF('Öğrenci Listesi'!B10="","",'Öğrenci Listesi'!B10),"") | C9: =IF(OR('Öğrenci Listesi'!B10="",Y9=""),"",IF(Y9="Çok İyi",CHOOSE(RANDBETWEEN(1,5),4,4,4,4,3),IF(Y9="İyi",CHOOSE(RANDBETWEEN(1,5),3,3,3,4,2),IF(Y9="Yeterli",CHOOSE(RANDBETWEEN(1,5),2,2,2,3,1),IF(Y9="Geliştirilmeli",CHOOSE(RANDBETWEEN(1,5),1,1,1,1,2),""))))) | D9: =IF(OR('Öğrenci Listesi'!B10="",Y9=""),"",IF(Y9="Çok İyi",CHOOSE(RANDBETWEEN(1,5),4,4,4,4,3),IF(Y9="İyi",CHOOSE(RANDBETWEEN(1,5),3,3,3,4,2),IF(Y9="Yeterli",CHOOSE(RANDBETWEEN(1,5),2,2,2,3,1),IF(Y9="Geliştirilmeli",CHOOSE(RANDBETWEEN(1,5),1,1,1,1,2),""))))) | E9: =IF(OR('Öğrenci Listesi'!B10="",Y9=""),"",IF(Y9="Çok İyi",CHOOSE(RANDBETWEEN(1,5),4,4,4,4,3),IF(Y9="İyi",CHOOSE(RANDBETWEEN(1,5),3,3,3,4,2),IF(Y9="Yeterli",CHOOSE(RANDBETWEEN(1,5),2,2,2,3,1),IF(Y9="Geliştirilmeli",CHOOSE(RANDBETWEEN(1,5),1,1,1,1,2),""))))) | F9: =IF(OR('Öğrenci Listesi'!B10="",Y9=""),"",IF(Y9="Çok İyi",CHOOSE(RANDBETWEEN(1,5),4,4,4,4,3),IF(Y9="İyi",CHOOSE(RANDBETWEEN(1,5),3,3,3,4,2),IF(Y9="Yeterli",CHOOSE(RANDBETWEEN(1,5),2,2,2,3,1),IF(Y9="Geliştirilmeli",CHOOSE(RANDBETWEEN(1,5),1,1,1,1,2),""))))) | G9: =IF(OR('Öğrenci Listesi'!B10="",Y9=""),"",IF(Y9="Çok İyi",CHOOSE(RANDBETWEEN(1,5),4,4,4,4,3),IF(Y9="İyi",CHOOSE(RANDBETWEEN(1,5),3,3,3,4,2),IF(Y9="Yeterli",CHOOSE(RANDBETWEEN(1,5),2,2,2,3,1),IF(Y9="Geliştirilmeli",CHOOSE(RANDBETWEEN(1,5),1,1,1,1,2),""))))) | H9: =IF(OR('Öğrenci Listesi'!B10="",Y9=""),"",IF(Y9="Çok İyi",CHOOSE(RANDBETWEEN(1,5),4,4,4,4,3),IF(Y9="İyi",CHOOSE(RANDBETWEEN(1,5),3,3,3,4,2),IF(Y9="Yeterli",CHOOSE(RANDBETWEEN(1,5),2,2,2,3,1),IF(Y9="Geliştirilmeli",CHOOSE(RANDBETWEEN(1,5),1,1,1,1,2),""))))) | I9: =IF(OR('Öğrenci Listesi'!B10="",Y9=""),"",IF(Y9="Çok İyi",CHOOSE(RANDBETWEEN(1,5),4,4,4,4,3),IF(Y9="İyi",CHOOSE(RANDBETWEEN(1,5),3,3,3,4,2),IF(Y9="Yeterli",CHOOSE(RANDBETWEEN(1,5),2,2,2,3,1),IF(Y9="Geliştirilmeli",CHOOSE(RANDBETWEEN(1,5),1,1,1,1,2),""))))) | J9: =IF(OR('Öğrenci Listesi'!B10="",Y9=""),"",IF(Y9="Çok İyi",CHOOSE(RANDBETWEEN(1,5),4,4,4,4,3),IF(Y9="İyi",CHOOSE(RANDBETWEEN(1,5),3,3,3,4,2),IF(Y9="Yeterli",CHOOSE(RANDBETWEEN(1,5),2,2,2,3,1),IF(Y9="Geliştirilmeli",CHOOSE(RANDBETWEEN(1,5),1,1,1,1,2),""))))) | K9: =IF(OR('Öğrenci Listesi'!B10="",Y9=""),"",IF(Y9="Çok İyi",CHOOSE(RANDBETWEEN(1,5),4,4,4,4,3),IF(Y9="İyi",CHOOSE(RANDBETWEEN(1,5),3,3,3,4,2),IF(Y9="Yeterli",CHOOSE(RANDBETWEEN(1,5),2,2,2,3,1),IF(Y9="Geliştirilmeli",CHOOSE(RANDBETWEEN(1,5),1,1,1,1,2),""))))) | L9: =IF(OR('Öğrenci Listesi'!B10="",Y9=""),"",IF(Y9="Çok İyi",CHOOSE(RANDBETWEEN(1,5),4,4,4,4,3),IF(Y9="İyi",CHOOSE(RANDBETWEEN(1,5),3,3,3,4,2),IF(Y9="Yeterli",CHOOSE(RANDBETWEEN(1,5),2,2,2,3,1),IF(Y9="Geliştirilmeli",CHOOSE(RANDBETWEEN(1,5),1,1,1,1,2),""))))) | M9: =IF(OR('Öğrenci Listesi'!B10="",Y9=""),"",IF(Y9="Çok İyi",CHOOSE(RANDBETWEEN(1,5),4,4,4,4,3),IF(Y9="İyi",CHOOSE(RANDBETWEEN(1,5),3,3,3,4,2),IF(Y9="Yeterli",CHOOSE(RANDBETWEEN(1,5),2,2,2,3,1),IF(Y9="Geliştirilmeli",CHOOSE(RANDBETWEEN(1,5),1,1,1,1,2),""))))) | N9: =IF(OR('Öğrenci Listesi'!B10="",Y9=""),"",IF(Y9="Çok İyi",CHOOSE(RANDBETWEEN(1,5),4,4,4,4,3),IF(Y9="İyi",CHOOSE(RANDBETWEEN(1,5),3,3,3,4,2),IF(Y9="Yeterli",CHOOSE(RANDBETWEEN(1,5),2,2,2,3,1),IF(Y9="Geliştirilmeli",CHOOSE(RANDBETWEEN(1,5),1,1,1,1,2),""))))) | O9: =IF(OR('Öğrenci Listesi'!B10="",Y9=""),"",IF(Y9="Çok İyi",CHOOSE(RANDBETWEEN(1,5),4,4,4,4,3),IF(Y9="İyi",CHOOSE(RANDBETWEEN(1,5),3,3,3,4,2),IF(Y9="Yeterli",CHOOSE(RANDBETWEEN(1,5),2,2,2,3,1),IF(Y9="Geliştirilmeli",CHOOSE(RANDBETWEEN(1,5),1,1,1,1,2),""))))) | P9: =IF(OR('Öğrenci Listesi'!B10="",Y9=""),"",IF(Y9="Çok İyi",CHOOSE(RANDBETWEEN(1,5),4,4,4,4,3),IF(Y9="İyi",CHOOSE(RANDBETWEEN(1,5),3,3,3,4,2),IF(Y9="Yeterli",CHOOSE(RANDBETWEEN(1,5),2,2,2,3,1),IF(Y9="Geliştirilmeli",CHOOSE(RANDBETWEEN(1,5),1,1,1,1,2),""))))) | Q9: =IF(OR('Öğrenci Listesi'!B10="",Y9=""),"",IF(Y9="Çok İyi",CHOOSE(RANDBETWEEN(1,5),4,4,4,4,3),IF(Y9="İyi",CHOOSE(RANDBETWEEN(1,5),3,3,3,4,2),IF(Y9="Yeterli",CHOOSE(RANDBETWEEN(1,5),2,2,2,3,1),IF(Y9="Geliştirilmeli",CHOOSE(RANDBETWEEN(1,5),1,1,1,1,2),""))))) | R9: =IF(OR('Öğrenci Listesi'!B10="",Y9=""),"",IF(Y9="Çok İyi",CHOOSE(RANDBETWEEN(1,5),4,4,4,4,3),IF(Y9="İyi",CHOOSE(RANDBETWEEN(1,5),3,3,3,4,2),IF(Y9="Yeterli",CHOOSE(RANDBETWEEN(1,5),2,2,2,3,1),IF(Y9="Geliştirilmeli",CHOOSE(RANDBETWEEN(1,5),1,1,1,1,2),""))))) | S9: =IF(OR('Öğrenci Listesi'!B10="",Y9=""),"",IF(Y9="Çok İyi",CHOOSE(RANDBETWEEN(1,5),4,4,4,4,3),IF(Y9="İyi",CHOOSE(RANDBETWEEN(1,5),3,3,3,4,2),IF(Y9="Yeterli",CHOOSE(RANDBETWEEN(1,5),2,2,2,3,1),IF(Y9="Geliştirilmeli",CHOOSE(RANDBETWEEN(1,5),1,1,1,1,2),""))))) | T9: =IF(OR('Öğrenci Listesi'!B10="",Y9=""),"",IF(Y9="Çok İyi",CHOOSE(RANDBETWEEN(1,5),4,4,4,4,3),IF(Y9="İyi",CHOOSE(RANDBETWEEN(1,5),3,3,3,4,2),IF(Y9="Yeterli",CHOOSE(RANDBETWEEN(1,5),2,2,2,3,1),IF(Y9="Geliştirilmeli",CHOOSE(RANDBETWEEN(1,5),1,1,1,1,2),""))))) | U9: =IF(OR('Öğrenci Listesi'!B10="",Y9=""),"",IF(Y9="Çok İyi",CHOOSE(RANDBETWEEN(1,5),4,4,4,4,3),IF(Y9="İyi",CHOOSE(RANDBETWEEN(1,5),3,3,3,4,2),IF(Y9="Yeterli",CHOOSE(RANDBETWEEN(1,5),2,2,2,3,1),IF(Y9="Geliştirilmeli",CHOOSE(RANDBETWEEN(1,5),1,1,1,1,2),""))))) | V9: =IF(OR('Öğrenci Listesi'!B10="",Y9=""),"",IF(Y9="Çok İyi",CHOOSE(RANDBETWEEN(1,5),4,4,4,4,3),IF(Y9="İyi",CHOOSE(RANDBETWEEN(1,5),3,3,3,4,2),IF(Y9="Yeterli",CHOOSE(RANDBETWEEN(1,5),2,2,2,3,1),IF(Y9="Geliştirilmeli",CHOOSE(RANDBETWEEN(1,5),1,1,1,1,2),""))))) | W9: =IF(OR('Öğrenci Listesi'!B10="",Y9=""),"",IF(Y9="Çok İyi",CHOOSE(RANDBETWEEN(1,5),4,4,4,4,3),IF(Y9="İyi",CHOOSE(RANDBETWEEN(1,5),3,3,3,4,2),IF(Y9="Yeterli",CHOOSE(RANDBETWEEN(1,5),2,2,2,3,1),IF(Y9="Geliştirilmeli",CHOOSE(RANDBETWEEN(1,5),1,1,1,1,2),""))))) | X9: =IF(OR('Öğrenci Listesi'!B10="",Y9=""),"",ROUND(AVERAGE(C9:W9),2)) | Y9: =IFERROR(IF('Öğrenci Listesi'!G10="","",IF(UPPER(TRIM('Öğrenci Listesi'!G10))="ÇOK İYİ","Çok İyi",IF(UPPER(TRIM('Öğrenci Listesi'!G10))="İYİ","İyi",IF(UPPER(TRIM('Öğrenci Listesi'!G10))="YETERLİ","Yeterli",IF(UPPER(TRIM('Öğrenci Listesi'!G10))="GELİŞTİRİLMELİ","Geliştirilmeli",'Öğrenci Listesi'!G10))))),"")
A10: =IFERROR(IF('Öğrenci Listesi'!A11="","",'Öğrenci Listesi'!A11),"") | B10: =IFERROR(IF('Öğrenci Listesi'!B11="","",'Öğrenci Listesi'!B11),"") | C10: =IF(OR('Öğrenci Listesi'!B11="",Y10=""),"",IF(Y10="Çok İyi",CHOOSE(RANDBETWEEN(1,5),4,4,4,4,3),IF(Y10="İyi",CHOOSE(RANDBETWEEN(1,5),3,3,3,4,2),IF(Y10="Yeterli",CHOOSE(RANDBETWEEN(1,5),2,2,2,3,1),IF(Y10="Geliştirilmeli",CHOOSE(RANDBETWEEN(1,5),1,1,1,1,2),""))))) | D10: =IF(OR('Öğrenci Listesi'!B11="",Y10=""),"",IF(Y10="Çok İyi",CHOOSE(RANDBETWEEN(1,5),4,4,4,4,3),IF(Y10="İyi",CHOOSE(RANDBETWEEN(1,5),3,3,3,4,2),IF(Y10="Yeterli",CHOOSE(RANDBETWEEN(1,5),2,2,2,3,1),IF(Y10="Geliştirilmeli",CHOOSE(RANDBETWEEN(1,5),1,1,1,1,2),""))))) | E10: =IF(OR('Öğrenci Listesi'!B11="",Y10=""),"",IF(Y10="Çok İyi",CHOOSE(RANDBETWEEN(1,5),4,4,4,4,3),IF(Y10="İyi",CHOOSE(RANDBETWEEN(1,5),3,3,3,4,2),IF(Y10="Yeterli",CHOOSE(RANDBETWEEN(1,5),2,2,2,3,1),IF(Y10="Geliştirilmeli",CHOOSE(RANDBETWEEN(1,5),1,1,1,1,2),""))))) | F10: =IF(OR('Öğrenci Listesi'!B11="",Y10=""),"",IF(Y10="Çok İyi",CHOOSE(RANDBETWEEN(1,5),4,4,4,4,3),IF(Y10="İyi",CHOOSE(RANDBETWEEN(1,5),3,3,3,4,2),IF(Y10="Yeterli",CHOOSE(RANDBETWEEN(1,5),2,2,2,3,1),IF(Y10="Geliştirilmeli",CHOOSE(RANDBETWEEN(1,5),1,1,1,1,2),""))))) | G10: =IF(OR('Öğrenci Listesi'!B11="",Y10=""),"",IF(Y10="Çok İyi",CHOOSE(RANDBETWEEN(1,5),4,4,4,4,3),IF(Y10="İyi",CHOOSE(RANDBETWEEN(1,5),3,3,3,4,2),IF(Y10="Yeterli",CHOOSE(RANDBETWEEN(1,5),2,2,2,3,1),IF(Y10="Geliştirilmeli",CHOOSE(RANDBETWEEN(1,5),1,1,1,1,2),""))))) | H10: =IF(OR('Öğrenci Listesi'!B11="",Y10=""),"",IF(Y10="Çok İyi",CHOOSE(RANDBETWEEN(1,5),4,4,4,4,3),IF(Y10="İyi",CHOOSE(RANDBETWEEN(1,5),3,3,3,4,2),IF(Y10="Yeterli",CHOOSE(RANDBETWEEN(1,5),2,2,2,3,1),IF(Y10="Geliştirilmeli",CHOOSE(RANDBETWEEN(1,5),1,1,1,1,2),""))))) | I10: =IF(OR('Öğrenci Listesi'!B11="",Y10=""),"",IF(Y10="Çok İyi",CHOOSE(RANDBETWEEN(1,5),4,4,4,4,3),IF(Y10="İyi",CHOOSE(RANDBETWEEN(1,5),3,3,3,4,2),IF(Y10="Yeterli",CHOOSE(RANDBETWEEN(1,5),2,2,2,3,1),IF(Y10="Geliştirilmeli",CHOOSE(RANDBETWEEN(1,5),1,1,1,1,2),""))))) | J10: =IF(OR('Öğrenci Listesi'!B11="",Y10=""),"",IF(Y10="Çok İyi",CHOOSE(RANDBETWEEN(1,5),4,4,4,4,3),IF(Y10="İyi",CHOOSE(RANDBETWEEN(1,5),3,3,3,4,2),IF(Y10="Yeterli",CHOOSE(RANDBETWEEN(1,5),2,2,2,3,1),IF(Y10="Geliştirilmeli",CHOOSE(RANDBETWEEN(1,5),1,1,1,1,2),""))))) | K10: =IF(OR('Öğrenci Listesi'!B11="",Y10=""),"",IF(Y10="Çok İyi",CHOOSE(RANDBETWEEN(1,5),4,4,4,4,3),IF(Y10="İyi",CHOOSE(RANDBETWEEN(1,5),3,3,3,4,2),IF(Y10="Yeterli",CHOOSE(RANDBETWEEN(1,5),2,2,2,3,1),IF(Y10="Geliştirilmeli",CHOOSE(RANDBETWEEN(1,5),1,1,1,1,2),""))))) | L10: =IF(OR('Öğrenci Listesi'!B11="",Y10=""),"",IF(Y10="Çok İyi",CHOOSE(RANDBETWEEN(1,5),4,4,4,4,3),IF(Y10="İyi",CHOOSE(RANDBETWEEN(1,5),3,3,3,4,2),IF(Y10="Yeterli",CHOOSE(RANDBETWEEN(1,5),2,2,2,3,1),IF(Y10="Geliştirilmeli",CHOOSE(RANDBETWEEN(1,5),1,1,1,1,2),""))))) | M10: =IF(OR('Öğrenci Listesi'!B11="",Y10=""),"",IF(Y10="Çok İyi",CHOOSE(RANDBETWEEN(1,5),4,4,4,4,3),IF(Y10="İyi",CHOOSE(RANDBETWEEN(1,5),3,3,3,4,2),IF(Y10="Yeterli",CHOOSE(RANDBETWEEN(1,5),2,2,2,3,1),IF(Y10="Geliştirilmeli",CHOOSE(RANDBETWEEN(1,5),1,1,1,1,2),""))))) | N10: =IF(OR('Öğrenci Listesi'!B11="",Y10=""),"",IF(Y10="Çok İyi",CHOOSE(RANDBETWEEN(1,5),4,4,4,4,3),IF(Y10="İyi",CHOOSE(RANDBETWEEN(1,5),3,3,3,4,2),IF(Y10="Yeterli",CHOOSE(RANDBETWEEN(1,5),2,2,2,3,1),IF(Y10="Geliştirilmeli",CHOOSE(RANDBETWEEN(1,5),1,1,1,1,2),""))))) | O10: =IF(OR('Öğrenci Listesi'!B11="",Y10=""),"",IF(Y10="Çok İyi",CHOOSE(RANDBETWEEN(1,5),4,4,4,4,3),IF(Y10="İyi",CHOOSE(RANDBETWEEN(1,5),3,3,3,4,2),IF(Y10="Yeterli",CHOOSE(RANDBETWEEN(1,5),2,2,2,3,1),IF(Y10="Geliştirilmeli",CHOOSE(RANDBETWEEN(1,5),1,1,1,1,2),""))))) | P10: =IF(OR('Öğrenci Listesi'!B11="",Y10=""),"",IF(Y10="Çok İyi",CHOOSE(RANDBETWEEN(1,5),4,4,4,4,3),IF(Y10="İyi",CHOOSE(RANDBETWEEN(1,5),3,3,3,4,2),IF(Y10="Yeterli",CHOOSE(RANDBETWEEN(1,5),2,2,2,3,1),IF(Y10="Geliştirilmeli",CHOOSE(RANDBETWEEN(1,5),1,1,1,1,2),""))))) | Q10: =IF(OR('Öğrenci Listesi'!B11="",Y10=""),"",IF(Y10="Çok İyi",CHOOSE(RANDBETWEEN(1,5),4,4,4,4,3),IF(Y10="İyi",CHOOSE(RANDBETWEEN(1,5),3,3,3,4,2),IF(Y10="Yeterli",CHOOSE(RANDBETWEEN(1,5),2,2,2,3,1),IF(Y10="Geliştirilmeli",CHOOSE(RANDBETWEEN(1,5),1,1,1,1,2),""))))) | R10: =IF(OR('Öğrenci Listesi'!B11="",Y10=""),"",IF(Y10="Çok İyi",CHOOSE(RANDBETWEEN(1,5),4,4,4,4,3),IF(Y10="İyi",CHOOSE(RANDBETWEEN(1,5),3,3,3,4,2),IF(Y10="Yeterli",CHOOSE(RANDBETWEEN(1,5),2,2,2,3,1),IF(Y10="Geliştirilmeli",CHOOSE(RANDBETWEEN(1,5),1,1,1,1,2),""))))) | S10: =IF(OR('Öğrenci Listesi'!B11="",Y10=""),"",IF(Y10="Çok İyi",CHOOSE(RANDBETWEEN(1,5),4,4,4,4,3),IF(Y10="İyi",CHOOSE(RANDBETWEEN(1,5),3,3,3,4,2),IF(Y10="Yeterli",CHOOSE(RANDBETWEEN(1,5),2,2,2,3,1),IF(Y10="Geliştirilmeli",CHOOSE(RANDBETWEEN(1,5),1,1,1,1,2),""))))) | T10: =IF(OR('Öğrenci Listesi'!B11="",Y10=""),"",IF(Y10="Çok İyi",CHOOSE(RANDBETWEEN(1,5),4,4,4,4,3),IF(Y10="İyi",CHOOSE(RANDBETWEEN(1,5),3,3,3,4,2),IF(Y10="Yeterli",CHOOSE(RANDBETWEEN(1,5),2,2,2,3,1),IF(Y10="Geliştirilmeli",CHOOSE(RANDBETWEEN(1,5),1,1,1,1,2),""))))) | U10: =IF(OR('Öğrenci Listesi'!B11="",Y10=""),"",IF(Y10="Çok İyi",CHOOSE(RANDBETWEEN(1,5),4,4,4,4,3),IF(Y10="İyi",CHOOSE(RANDBETWEEN(1,5),3,3,3,4,2),IF(Y10="Yeterli",CHOOSE(RANDBETWEEN(1,5),2,2,2,3,1),IF(Y10="Geliştirilmeli",CHOOSE(RANDBETWEEN(1,5),1,1,1,1,2),""))))) | V10: =IF(OR('Öğrenci Listesi'!B11="",Y10=""),"",IF(Y10="Çok İyi",CHOOSE(RANDBETWEEN(1,5),4,4,4,4,3),IF(Y10="İyi",CHOOSE(RANDBETWEEN(1,5),3,3,3,4,2),IF(Y10="Yeterli",CHOOSE(RANDBETWEEN(1,5),2,2,2,3,1),IF(Y10="Geliştirilmeli",CHOOSE(RANDBETWEEN(1,5),1,1,1,1,2),""))))) | W10: =IF(OR('Öğrenci Listesi'!B11="",Y10=""),"",IF(Y10="Çok İyi",CHOOSE(RANDBETWEEN(1,5),4,4,4,4,3),IF(Y10="İyi",CHOOSE(RANDBETWEEN(1,5),3,3,3,4,2),IF(Y10="Yeterli",CHOOSE(RANDBETWEEN(1,5),2,2,2,3,1),IF(Y10="Geliştirilmeli",CHOOSE(RANDBETWEEN(1,5),1,1,1,1,2),""))))) | X10: =IF(OR('Öğrenci Listesi'!B11="",Y10=""),"",ROUND(AVERAGE(C10:W10),2)) | Y10: =IFERROR(IF('Öğrenci Listesi'!G11="","",IF(UPPER(TRIM('Öğrenci Listesi'!G11))="ÇOK İYİ","Çok İyi",IF(UPPER(TRIM('Öğrenci Listesi'!G11))="İYİ","İyi",IF(UPPER(TRIM('Öğrenci Listesi'!G11))="YETERLİ","Yeterli",IF(UPPER(TRIM('Öğrenci Listesi'!G11))="GELİŞTİRİLMELİ","Geliştirilmeli",'Öğrenci Listesi'!G11))))),"")
A11: =IFERROR(IF('Öğrenci Listesi'!A12="","",'Öğrenci Listesi'!A12),"") | B11: =IFERROR(IF('Öğrenci Listesi'!B12="","",'Öğrenci Listesi'!B12),"") | C11: =IF(OR('Öğrenci Listesi'!B12="",Y11=""),"",IF(Y11="Çok İyi",CHOOSE(RANDBETWEEN(1,5),4,4,4,4,3),IF(Y11="İyi",CHOOSE(RANDBETWEEN(1,5),3,3,3,4,2),IF(Y11="Yeterli",CHOOSE(RANDBETWEEN(1,5),2,2,2,3,1),IF(Y11="Geliştirilmeli",CHOOSE(RANDBETWEEN(1,5),1,1,1,1,2),""))))) | D11: =IF(OR('Öğrenci Listesi'!B12="",Y11=""),"",IF(Y11="Çok İyi",CHOOSE(RANDBETWEEN(1,5),4,4,4,4,3),IF(Y11="İyi",CHOOSE(RANDBETWEEN(1,5),3,3,3,4,2),IF(Y11="Yeterli",CHOOSE(RANDBETWEEN(1,5),2,2,2,3,1),IF(Y11="Geliştirilmeli",CHOOSE(RANDBETWEEN(1,5),1,1,1,1,2),""))))) | E11: =IF(OR('Öğrenci Listesi'!B12="",Y11=""),"",IF(Y11="Çok İyi",CHOOSE(RANDBETWEEN(1,5),4,4,4,4,3),IF(Y11="İyi",CHOOSE(RANDBETWEEN(1,5),3,3,3,4,2),IF(Y11="Yeterli",CHOOSE(RANDBETWEEN(1,5),2,2,2,3,1),IF(Y11="Geliştirilmeli",CHOOSE(RANDBETWEEN(1,5),1,1,1,1,2),""))))) | F11: =IF(OR('Öğrenci Listesi'!B12="",Y11=""),"",IF(Y11="Çok İyi",CHOOSE(RANDBETWEEN(1,5),4,4,4,4,3),IF(Y11="İyi",CHOOSE(RANDBETWEEN(1,5),3,3,3,4,2),IF(Y11="Yeterli",CHOOSE(RANDBETWEEN(1,5),2,2,2,3,1),IF(Y11="Geliştirilmeli",CHOOSE(RANDBETWEEN(1,5),1,1,1,1,2),""))))) | G11: =IF(OR('Öğrenci Listesi'!B12="",Y11=""),"",IF(Y11="Çok İyi",CHOOSE(RANDBETWEEN(1,5),4,4,4,4,3),IF(Y11="İyi",CHOOSE(RANDBETWEEN(1,5),3,3,3,4,2),IF(Y11="Yeterli",CHOOSE(RANDBETWEEN(1,5),2,2,2,3,1),IF(Y11="Geliştirilmeli",CHOOSE(RANDBETWEEN(1,5),1,1,1,1,2),""))))) | H11: =IF(OR('Öğrenci Listesi'!B12="",Y11=""),"",IF(Y11="Çok İyi",CHOOSE(RANDBETWEEN(1,5),4,4,4,4,3),IF(Y11="İyi",CHOOSE(RANDBETWEEN(1,5),3,3,3,4,2),IF(Y11="Yeterli",CHOOSE(RANDBETWEEN(1,5),2,2,2,3,1),IF(Y11="Geliştirilmeli",CHOOSE(RANDBETWEEN(1,5),1,1,1,1,2),""))))) | I11: =IF(OR('Öğrenci Listesi'!B12="",Y11=""),"",IF(Y11="Çok İyi",CHOOSE(RANDBETWEEN(1,5),4,4,4,4,3),IF(Y11="İyi",CHOOSE(RANDBETWEEN(1,5),3,3,3,4,2),IF(Y11="Yeterli",CHOOSE(RANDBETWEEN(1,5),2,2,2,3,1),IF(Y11="Geliştirilmeli",CHOOSE(RANDBETWEEN(1,5),1,1,1,1,2),""))))) | J11: =IF(OR('Öğrenci Listesi'!B12="",Y11=""),"",IF(Y11="Çok İyi",CHOOSE(RANDBETWEEN(1,5),4,4,4,4,3),IF(Y11="İyi",CHOOSE(RANDBETWEEN(1,5),3,3,3,4,2),IF(Y11="Yeterli",CHOOSE(RANDBETWEEN(1,5),2,2,2,3,1),IF(Y11="Geliştirilmeli",CHOOSE(RANDBETWEEN(1,5),1,1,1,1,2),""))))) | K11: =IF(OR('Öğrenci Listesi'!B12="",Y11=""),"",IF(Y11="Çok İyi",CHOOSE(RANDBETWEEN(1,5),4,4,4,4,3),IF(Y11="İyi",CHOOSE(RANDBETWEEN(1,5),3,3,3,4,2),IF(Y11="Yeterli",CHOOSE(RANDBETWEEN(1,5),2,2,2,3,1),IF(Y11="Geliştirilmeli",CHOOSE(RANDBETWEEN(1,5),1,1,1,1,2),""))))) | L11: =IF(OR('Öğrenci Listesi'!B12="",Y11=""),"",IF(Y11="Çok İyi",CHOOSE(RANDBETWEEN(1,5),4,4,4,4,3),IF(Y11="İyi",CHOOSE(RANDBETWEEN(1,5),3,3,3,4,2),IF(Y11="Yeterli",CHOOSE(RANDBETWEEN(1,5),2,2,2,3,1),IF(Y11="Geliştirilmeli",CHOOSE(RANDBETWEEN(1,5),1,1,1,1,2),""))))) | M11: =IF(OR('Öğrenci Listesi'!B12="",Y11=""),"",IF(Y11="Çok İyi",CHOOSE(RANDBETWEEN(1,5),4,4,4,4,3),IF(Y11="İyi",CHOOSE(RANDBETWEEN(1,5),3,3,3,4,2),IF(Y11="Yeterli",CHOOSE(RANDBETWEEN(1,5),2,2,2,3,1),IF(Y11="Geliştirilmeli",CHOOSE(RANDBETWEEN(1,5),1,1,1,1,2),""))))) | N11: =IF(OR('Öğrenci Listesi'!B12="",Y11=""),"",IF(Y11="Çok İyi",CHOOSE(RANDBETWEEN(1,5),4,4,4,4,3),IF(Y11="İyi",CHOOSE(RANDBETWEEN(1,5),3,3,3,4,2),IF(Y11="Yeterli",CHOOSE(RANDBETWEEN(1,5),2,2,2,3,1),IF(Y11="Geliştirilmeli",CHOOSE(RANDBETWEEN(1,5),1,1,1,1,2),""))))) | O11: =IF(OR('Öğrenci Listesi'!B12="",Y11=""),"",IF(Y11="Çok İyi",CHOOSE(RANDBETWEEN(1,5),4,4,4,4,3),IF(Y11="İyi",CHOOSE(RANDBETWEEN(1,5),3,3,3,4,2),IF(Y11="Yeterli",CHOOSE(RANDBETWEEN(1,5),2,2,2,3,1),IF(Y11="Geliştirilmeli",CHOOSE(RANDBETWEEN(1,5),1,1,1,1,2),""))))) | P11: =IF(OR('Öğrenci Listesi'!B12="",Y11=""),"",IF(Y11="Çok İyi",CHOOSE(RANDBETWEEN(1,5),4,4,4,4,3),IF(Y11="İyi",CHOOSE(RANDBETWEEN(1,5),3,3,3,4,2),IF(Y11="Yeterli",CHOOSE(RANDBETWEEN(1,5),2,2,2,3,1),IF(Y11="Geliştirilmeli",CHOOSE(RANDBETWEEN(1,5),1,1,1,1,2),""))))) | Q11: =IF(OR('Öğrenci Listesi'!B12="",Y11=""),"",IF(Y11="Çok İyi",CHOOSE(RANDBETWEEN(1,5),4,4,4,4,3),IF(Y11="İyi",CHOOSE(RANDBETWEEN(1,5),3,3,3,4,2),IF(Y11="Yeterli",CHOOSE(RANDBETWEEN(1,5),2,2,2,3,1),IF(Y11="Geliştirilmeli",CHOOSE(RANDBETWEEN(1,5),1,1,1,1,2),""))))) | R11: =IF(OR('Öğrenci Listesi'!B12="",Y11=""),"",IF(Y11="Çok İyi",CHOOSE(RANDBETWEEN(1,5),4,4,4,4,3),IF(Y11="İyi",CHOOSE(RANDBETWEEN(1,5),3,3,3,4,2),IF(Y11="Yeterli",CHOOSE(RANDBETWEEN(1,5),2,2,2,3,1),IF(Y11="Geliştirilmeli",CHOOSE(RANDBETWEEN(1,5),1,1,1,1,2),""))))) | S11: =IF(OR('Öğrenci Listesi'!B12="",Y11=""),"",IF(Y11="Çok İyi",CHOOSE(RANDBETWEEN(1,5),4,4,4,4,3),IF(Y11="İyi",CHOOSE(RANDBETWEEN(1,5),3,3,3,4,2),IF(Y11="Yeterli",CHOOSE(RANDBETWEEN(1,5),2,2,2,3,1),IF(Y11="Geliştirilmeli",CHOOSE(RANDBETWEEN(1,5),1,1,1,1,2),""))))) | T11: =IF(OR('Öğrenci Listesi'!B12="",Y11=""),"",IF(Y11="Çok İyi",CHOOSE(RANDBETWEEN(1,5),4,4,4,4,3),IF(Y11="İyi",CHOOSE(RANDBETWEEN(1,5),3,3,3,4,2),IF(Y11="Yeterli",CHOOSE(RANDBETWEEN(1,5),2,2,2,3,1),IF(Y11="Geliştirilmeli",CHOOSE(RANDBETWEEN(1,5),1,1,1,1,2),""))))) | U11: =IF(OR('Öğrenci Listesi'!B12="",Y11=""),"",IF(Y11="Çok İyi",CHOOSE(RANDBETWEEN(1,5),4,4,4,4,3),IF(Y11="İyi",CHOOSE(RANDBETWEEN(1,5),3,3,3,4,2),IF(Y11="Yeterli",CHOOSE(RANDBETWEEN(1,5),2,2,2,3,1),IF(Y11="Geliştirilmeli",CHOOSE(RANDBETWEEN(1,5),1,1,1,1,2),""))))) | V11: =IF(OR('Öğrenci Listesi'!B12="",Y11=""),"",IF(Y11="Çok İyi",CHOOSE(RANDBETWEEN(1,5),4,4,4,4,3),IF(Y11="İyi",CHOOSE(RANDBETWEEN(1,5),3,3,3,4,2),IF(Y11="Yeterli",CHOOSE(RANDBETWEEN(1,5),2,2,2,3,1),IF(Y11="Geliştirilmeli",CHOOSE(RANDBETWEEN(1,5),1,1,1,1,2),""))))) | W11: =IF(OR('Öğrenci Listesi'!B12="",Y11=""),"",IF(Y11="Çok İyi",CHOOSE(RANDBETWEEN(1,5),4,4,4,4,3),IF(Y11="İyi",CHOOSE(RANDBETWEEN(1,5),3,3,3,4,2),IF(Y11="Yeterli",CHOOSE(RANDBETWEEN(1,5),2,2,2,3,1),IF(Y11="Geliştirilmeli",CHOOSE(RANDBETWEEN(1,5),1,1,1,1,2),""))))) | X11: =IF(OR('Öğrenci Listesi'!B12="",Y11=""),"",ROUND(AVERAGE(C11:W11),2)) | Y11: =IFERROR(IF('Öğrenci Listesi'!G12="","",IF(UPPER(TRIM('Öğrenci Listesi'!G12))="ÇOK İYİ","Çok İyi",IF(UPPER(TRIM('Öğrenci Listesi'!G12))="İYİ","İyi",IF(UPPER(TRIM('Öğrenci Listesi'!G12))="YETERLİ","Yeterli",IF(UPPER(TRIM('Öğrenci Listesi'!G12))="GELİŞTİRİLMELİ","Geliştirilmeli",'Öğrenci Listesi'!G12))))),"")
A12: =IFERROR(IF('Öğrenci Listesi'!A13="","",'Öğrenci Listesi'!A13),"") | B12: =IFERROR(IF('Öğrenci Listesi'!B13="","",'Öğrenci Listesi'!B13),"") | C12: =IF(OR('Öğrenci Listesi'!B13="",Y12=""),"",IF(Y12="Çok İyi",CHOOSE(RANDBETWEEN(1,5),4,4,4,4,3),IF(Y12="İyi",CHOOSE(RANDBETWEEN(1,5),3,3,3,4,2),IF(Y12="Yeterli",CHOOSE(RANDBETWEEN(1,5),2,2,2,3,1),IF(Y12="Geliştirilmeli",CHOOSE(RANDBETWEEN(1,5),1,1,1,1,2),""))))) | D12: =IF(OR('Öğrenci Listesi'!B13="",Y12=""),"",IF(Y12="Çok İyi",CHOOSE(RANDBETWEEN(1,5),4,4,4,4,3),IF(Y12="İyi",CHOOSE(RANDBETWEEN(1,5),3,3,3,4,2),IF(Y12="Yeterli",CHOOSE(RANDBETWEEN(1,5),2,2,2,3,1),IF(Y12="Geliştirilmeli",CHOOSE(RANDBETWEEN(1,5),1,1,1,1,2),""))))) | E12: =IF(OR('Öğrenci Listesi'!B13="",Y12=""),"",IF(Y12="Çok İyi",CHOOSE(RANDBETWEEN(1,5),4,4,4,4,3),IF(Y12="İyi",CHOOSE(RANDBETWEEN(1,5),3,3,3,4,2),IF(Y12="Yeterli",CHOOSE(RANDBETWEEN(1,5),2,2,2,3,1),IF(Y12="Geliştirilmeli",CHOOSE(RANDBETWEEN(1,5),1,1,1,1,2),""))))) | F12: =IF(OR('Öğrenci Listesi'!B13="",Y12=""),"",IF(Y12="Çok İyi",CHOOSE(RANDBETWEEN(1,5),4,4,4,4,3),IF(Y12="İyi",CHOOSE(RANDBETWEEN(1,5),3,3,3,4,2),IF(Y12="Yeterli",CHOOSE(RANDBETWEEN(1,5),2,2,2,3,1),IF(Y12="Geliştirilmeli",CHOOSE(RANDBETWEEN(1,5),1,1,1,1,2),""))))) | G12: =IF(OR('Öğrenci Listesi'!B13="",Y12=""),"",IF(Y12="Çok İyi",CHOOSE(RANDBETWEEN(1,5),4,4,4,4,3),IF(Y12="İyi",CHOOSE(RANDBETWEEN(1,5),3,3,3,4,2),IF(Y12="Yeterli",CHOOSE(RANDBETWEEN(1,5),2,2,2,3,1),IF(Y12="Geliştirilmeli",CHOOSE(RANDBETWEEN(1,5),1,1,1,1,2),""))))) | H12: =IF(OR('Öğrenci Listesi'!B13="",Y12=""),"",IF(Y12="Çok İyi",CHOOSE(RANDBETWEEN(1,5),4,4,4,4,3),IF(Y12="İyi",CHOOSE(RANDBETWEEN(1,5),3,3,3,4,2),IF(Y12="Yeterli",CHOOSE(RANDBETWEEN(1,5),2,2,2,3,1),IF(Y12="Geliştirilmeli",CHOOSE(RANDBETWEEN(1,5),1,1,1,1,2),""))))) | I12: =IF(OR('Öğrenci Listesi'!B13="",Y12=""),"",IF(Y12="Çok İyi",CHOOSE(RANDBETWEEN(1,5),4,4,4,4,3),IF(Y12="İyi",CHOOSE(RANDBETWEEN(1,5),3,3,3,4,2),IF(Y12="Yeterli",CHOOSE(RANDBETWEEN(1,5),2,2,2,3,1),IF(Y12="Geliştirilmeli",CHOOSE(RANDBETWEEN(1,5),1,1,1,1,2),""))))) | J12: =IF(OR('Öğrenci Listesi'!B13="",Y12=""),"",IF(Y12="Çok İyi",CHOOSE(RANDBETWEEN(1,5),4,4,4,4,3),IF(Y12="İyi",CHOOSE(RANDBETWEEN(1,5),3,3,3,4,2),IF(Y12="Yeterli",CHOOSE(RANDBETWEEN(1,5),2,2,2,3,1),IF(Y12="Geliştirilmeli",CHOOSE(RANDBETWEEN(1,5),1,1,1,1,2),""))))) | K12: =IF(OR('Öğrenci Listesi'!B13="",Y12=""),"",IF(Y12="Çok İyi",CHOOSE(RANDBETWEEN(1,5),4,4,4,4,3),IF(Y12="İyi",CHOOSE(RANDBETWEEN(1,5),3,3,3,4,2),IF(Y12="Yeterli",CHOOSE(RANDBETWEEN(1,5),2,2,2,3,1),IF(Y12="Geliştirilmeli",CHOOSE(RANDBETWEEN(1,5),1,1,1,1,2),""))))) | L12: =IF(OR('Öğrenci Listesi'!B13="",Y12=""),"",IF(Y12="Çok İyi",CHOOSE(RANDBETWEEN(1,5),4,4,4,4,3),IF(Y12="İyi",CHOOSE(RANDBETWEEN(1,5),3,3,3,4,2),IF(Y12="Yeterli",CHOOSE(RANDBETWEEN(1,5),2,2,2,3,1),IF(Y12="Geliştirilmeli",CHOOSE(RANDBETWEEN(1,5),1,1,1,1,2),""))))) | M12: =IF(OR('Öğrenci Listesi'!B13="",Y12=""),"",IF(Y12="Çok İyi",CHOOSE(RANDBETWEEN(1,5),4,4,4,4,3),IF(Y12="İyi",CHOOSE(RANDBETWEEN(1,5),3,3,3,4,2),IF(Y12="Yeterli",CHOOSE(RANDBETWEEN(1,5),2,2,2,3,1),IF(Y12="Geliştirilmeli",CHOOSE(RANDBETWEEN(1,5),1,1,1,1,2),""))))) | N12: =IF(OR('Öğrenci Listesi'!B13="",Y12=""),"",IF(Y12="Çok İyi",CHOOSE(RANDBETWEEN(1,5),4,4,4,4,3),IF(Y12="İyi",CHOOSE(RANDBETWEEN(1,5),3,3,3,4,2),IF(Y12="Yeterli",CHOOSE(RANDBETWEEN(1,5),2,2,2,3,1),IF(Y12="Geliştirilmeli",CHOOSE(RANDBETWEEN(1,5),1,1,1,1,2),""))))) | O12: =IF(OR('Öğrenci Listesi'!B13="",Y12=""),"",IF(Y12="Çok İyi",CHOOSE(RANDBETWEEN(1,5),4,4,4,4,3),IF(Y12="İyi",CHOOSE(RANDBETWEEN(1,5),3,3,3,4,2),IF(Y12="Yeterli",CHOOSE(RANDBETWEEN(1,5),2,2,2,3,1),IF(Y12="Geliştirilmeli",CHOOSE(RANDBETWEEN(1,5),1,1,1,1,2),""))))) | P12: =IF(OR('Öğrenci Listesi'!B13="",Y12=""),"",IF(Y12="Çok İyi",CHOOSE(RANDBETWEEN(1,5),4,4,4,4,3),IF(Y12="İyi",CHOOSE(RANDBETWEEN(1,5),3,3,3,4,2),IF(Y12="Yeterli",CHOOSE(RANDBETWEEN(1,5),2,2,2,3,1),IF(Y12="Geliştirilmeli",CHOOSE(RANDBETWEEN(1,5),1,1,1,1,2),""))))) | Q12: =IF(OR('Öğrenci Listesi'!B13="",Y12=""),"",IF(Y12="Çok İyi",CHOOSE(RANDBETWEEN(1,5),4,4,4,4,3),IF(Y12="İyi",CHOOSE(RANDBETWEEN(1,5),3,3,3,4,2),IF(Y12="Yeterli",CHOOSE(RANDBETWEEN(1,5),2,2,2,3,1),IF(Y12="Geliştirilmeli",CHOOSE(RANDBETWEEN(1,5),1,1,1,1,2),""))))) | R12: =IF(OR('Öğrenci Listesi'!B13="",Y12=""),"",IF(Y12="Çok İyi",CHOOSE(RANDBETWEEN(1,5),4,4,4,4,3),IF(Y12="İyi",CHOOSE(RANDBETWEEN(1,5),3,3,3,4,2),IF(Y12="Yeterli",CHOOSE(RANDBETWEEN(1,5),2,2,2,3,1),IF(Y12="Geliştirilmeli",CHOOSE(RANDBETWEEN(1,5),1,1,1,1,2),""))))) | S12: =IF(OR('Öğrenci Listesi'!B13="",Y12=""),"",IF(Y12="Çok İyi",CHOOSE(RANDBETWEEN(1,5),4,4,4,4,3),IF(Y12="İyi",CHOOSE(RANDBETWEEN(1,5),3,3,3,4,2),IF(Y12="Yeterli",CHOOSE(RANDBETWEEN(1,5),2,2,2,3,1),IF(Y12="Geliştirilmeli",CHOOSE(RANDBETWEEN(1,5),1,1,1,1,2),""))))) | T12: =IF(OR('Öğrenci Listesi'!B13="",Y12=""),"",IF(Y12="Çok İyi",CHOOSE(RANDBETWEEN(1,5),4,4,4,4,3),IF(Y12="İyi",CHOOSE(RANDBETWEEN(1,5),3,3,3,4,2),IF(Y12="Yeterli",CHOOSE(RANDBETWEEN(1,5),2,2,2,3,1),IF(Y12="Geliştirilmeli",CHOOSE(RANDBETWEEN(1,5),1,1,1,1,2),""))))) | U12: =IF(OR('Öğrenci Listesi'!B13="",Y12=""),"",IF(Y12="Çok İyi",CHOOSE(RANDBETWEEN(1,5),4,4,4,4,3),IF(Y12="İyi",CHOOSE(RANDBETWEEN(1,5),3,3,3,4,2),IF(Y12="Yeterli",CHOOSE(RANDBETWEEN(1,5),2,2,2,3,1),IF(Y12="Geliştirilmeli",CHOOSE(RANDBETWEEN(1,5),1,1,1,1,2),""))))) | V12: =IF(OR('Öğrenci Listesi'!B13="",Y12=""),"",IF(Y12="Çok İyi",CHOOSE(RANDBETWEEN(1,5),4,4,4,4,3),IF(Y12="İyi",CHOOSE(RANDBETWEEN(1,5),3,3,3,4,2),IF(Y12="Yeterli",CHOOSE(RANDBETWEEN(1,5),2,2,2,3,1),IF(Y12="Geliştirilmeli",CHOOSE(RANDBETWEEN(1,5),1,1,1,1,2),""))))) | W12: =IF(OR('Öğrenci Listesi'!B13="",Y12=""),"",IF(Y12="Çok İyi",CHOOSE(RANDBETWEEN(1,5),4,4,4,4,3),IF(Y12="İyi",CHOOSE(RANDBETWEEN(1,5),3,3,3,4,2),IF(Y12="Yeterli",CHOOSE(RANDBETWEEN(1,5),2,2,2,3,1),IF(Y12="Geliştirilmeli",CHOOSE(RANDBETWEEN(1,5),1,1,1,1,2),""))))) | X12: =IF(OR('Öğrenci Listesi'!B13="",Y12=""),"",ROUND(AVERAGE(C12:W12),2)) | Y12: =IFERROR(IF('Öğrenci Listesi'!G13="","",IF(UPPER(TRIM('Öğrenci Listesi'!G13))="ÇOK İYİ","Çok İyi",IF(UPPER(TRIM('Öğrenci Listesi'!G13))="İYİ","İyi",IF(UPPER(TRIM('Öğrenci Listesi'!G13))="YETERLİ","Yeterli",IF(UPPER(TRIM('Öğrenci Listesi'!G13))="GELİŞTİRİLMELİ","Geliştirilmeli",'Öğrenci Listesi'!G13))))),"")
A13: =IFERROR(IF('Öğrenci Listesi'!A14="","",'Öğrenci Listesi'!A14),"") | B13: =IFERROR(IF('Öğrenci Listesi'!B14="","",'Öğrenci Listesi'!B14),"") | C13: =IF(OR('Öğrenci Listesi'!B14="",Y13=""),"",IF(Y13="Çok İyi",CHOOSE(RANDBETWEEN(1,5),4,4,4,4,3),IF(Y13="İyi",CHOOSE(RANDBETWEEN(1,5),3,3,3,4,2),IF(Y13="Yeterli",CHOOSE(RANDBETWEEN(1,5),2,2,2,3,1),IF(Y13="Geliştirilmeli",CHOOSE(RANDBETWEEN(1,5),1,1,1,1,2),""))))) | D13: =IF(OR('Öğrenci Listesi'!B14="",Y13=""),"",IF(Y13="Çok İyi",CHOOSE(RANDBETWEEN(1,5),4,4,4,4,3),IF(Y13="İyi",CHOOSE(RANDBETWEEN(1,5),3,3,3,4,2),IF(Y13="Yeterli",CHOOSE(RANDBETWEEN(1,5),2,2,2,3,1),IF(Y13="Geliştirilmeli",CHOOSE(RANDBETWEEN(1,5),1,1,1,1,2),""))))) | E13: =IF(OR('Öğrenci Listesi'!B14="",Y13=""),"",IF(Y13="Çok İyi",CHOOSE(RANDBETWEEN(1,5),4,4,4,4,3),IF(Y13="İyi",CHOOSE(RANDBETWEEN(1,5),3,3,3,4,2),IF(Y13="Yeterli",CHOOSE(RANDBETWEEN(1,5),2,2,2,3,1),IF(Y13="Geliştirilmeli",CHOOSE(RANDBETWEEN(1,5),1,1,1,1,2),""))))) | F13: =IF(OR('Öğrenci Listesi'!B14="",Y13=""),"",IF(Y13="Çok İyi",CHOOSE(RANDBETWEEN(1,5),4,4,4,4,3),IF(Y13="İyi",CHOOSE(RANDBETWEEN(1,5),3,3,3,4,2),IF(Y13="Yeterli",CHOOSE(RANDBETWEEN(1,5),2,2,2,3,1),IF(Y13="Geliştirilmeli",CHOOSE(RANDBETWEEN(1,5),1,1,1,1,2),""))))) | G13: =IF(OR('Öğrenci Listesi'!B14="",Y13=""),"",IF(Y13="Çok İyi",CHOOSE(RANDBETWEEN(1,5),4,4,4,4,3),IF(Y13="İyi",CHOOSE(RANDBETWEEN(1,5),3,3,3,4,2),IF(Y13="Yeterli",CHOOSE(RANDBETWEEN(1,5),2,2,2,3,1),IF(Y13="Geliştirilmeli",CHOOSE(RANDBETWEEN(1,5),1,1,1,1,2),""))))) | H13: =IF(OR('Öğrenci Listesi'!B14="",Y13=""),"",IF(Y13="Çok İyi",CHOOSE(RANDBETWEEN(1,5),4,4,4,4,3),IF(Y13="İyi",CHOOSE(RANDBETWEEN(1,5),3,3,3,4,2),IF(Y13="Yeterli",CHOOSE(RANDBETWEEN(1,5),2,2,2,3,1),IF(Y13="Geliştirilmeli",CHOOSE(RANDBETWEEN(1,5),1,1,1,1,2),""))))) | I13: =IF(OR('Öğrenci Listesi'!B14="",Y13=""),"",IF(Y13="Çok İyi",CHOOSE(RANDBETWEEN(1,5),4,4,4,4,3),IF(Y13="İyi",CHOOSE(RANDBETWEEN(1,5),3,3,3,4,2),IF(Y13="Yeterli",CHOOSE(RANDBETWEEN(1,5),2,2,2,3,1),IF(Y13="Geliştirilmeli",CHOOSE(RANDBETWEEN(1,5),1,1,1,1,2),""))))) | J13: =IF(OR('Öğrenci Listesi'!B14="",Y13=""),"",IF(Y13="Çok İyi",CHOOSE(RANDBETWEEN(1,5),4,4,4,4,3),IF(Y13="İyi",CHOOSE(RANDBETWEEN(1,5),3,3,3,4,2),IF(Y13="Yeterli",CHOOSE(RANDBETWEEN(1,5),2,2,2,3,1),IF(Y13="Geliştirilmeli",CHOOSE(RANDBETWEEN(1,5),1,1,1,1,2),""))))) | K13: =IF(OR('Öğrenci Listesi'!B14="",Y13=""),"",IF(Y13="Çok İyi",CHOOSE(RANDBETWEEN(1,5),4,4,4,4,3),IF(Y13="İyi",CHOOSE(RANDBETWEEN(1,5),3,3,3,4,2),IF(Y13="Yeterli",CHOOSE(RANDBETWEEN(1,5),2,2,2,3,1),IF(Y13="Geliştirilmeli",CHOOSE(RANDBETWEEN(1,5),1,1,1,1,2),""))))) | L13: =IF(OR('Öğrenci Listesi'!B14="",Y13=""),"",IF(Y13="Çok İyi",CHOOSE(RANDBETWEEN(1,5),4,4,4,4,3),IF(Y13="İyi",CHOOSE(RANDBETWEEN(1,5),3,3,3,4,2),IF(Y13="Yeterli",CHOOSE(RANDBETWEEN(1,5),2,2,2,3,1),IF(Y13="Geliştirilmeli",CHOOSE(RANDBETWEEN(1,5),1,1,1,1,2),""))))) | M13: =IF(OR('Öğrenci Listesi'!B14="",Y13=""),"",IF(Y13="Çok İyi",CHOOSE(RANDBETWEEN(1,5),4,4,4,4,3),IF(Y13="İyi",CHOOSE(RANDBETWEEN(1,5),3,3,3,4,2),IF(Y13="Yeterli",CHOOSE(RANDBETWEEN(1,5),2,2,2,3,1),IF(Y13="Geliştirilmeli",CHOOSE(RANDBETWEEN(1,5),1,1,1,1,2),""))))) | N13: =IF(OR('Öğrenci Listesi'!B14="",Y13=""),"",IF(Y13="Çok İyi",CHOOSE(RANDBETWEEN(1,5),4,4,4,4,3),IF(Y13="İyi",CHOOSE(RANDBETWEEN(1,5),3,3,3,4,2),IF(Y13="Yeterli",CHOOSE(RANDBETWEEN(1,5),2,2,2,3,1),IF(Y13="Geliştirilmeli",CHOOSE(RANDBETWEEN(1,5),1,1,1,1,2),""))))) | O13: =IF(OR('Öğrenci Listesi'!B14="",Y13=""),"",IF(Y13="Çok İyi",CHOOSE(RANDBETWEEN(1,5),4,4,4,4,3),IF(Y13="İyi",CHOOSE(RANDBETWEEN(1,5),3,3,3,4,2),IF(Y13="Yeterli",CHOOSE(RANDBETWEEN(1,5),2,2,2,3,1),IF(Y13="Geliştirilmeli",CHOOSE(RANDBETWEEN(1,5),1,1,1,1,2),""))))) | P13: =IF(OR('Öğrenci Listesi'!B14="",Y13=""),"",IF(Y13="Çok İyi",CHOOSE(RANDBETWEEN(1,5),4,4,4,4,3),IF(Y13="İyi",CHOOSE(RANDBETWEEN(1,5),3,3,3,4,2),IF(Y13="Yeterli",CHOOSE(RANDBETWEEN(1,5),2,2,2,3,1),IF(Y13="Geliştirilmeli",CHOOSE(RANDBETWEEN(1,5),1,1,1,1,2),""))))) | Q13: =IF(OR('Öğrenci Listesi'!B14="",Y13=""),"",IF(Y13="Çok İyi",CHOOSE(RANDBETWEEN(1,5),4,4,4,4,3),IF(Y13="İyi",CHOOSE(RANDBETWEEN(1,5),3,3,3,4,2),IF(Y13="Yeterli",CHOOSE(RANDBETWEEN(1,5),2,2,2,3,1),IF(Y13="Geliştirilmeli",CHOOSE(RANDBETWEEN(1,5),1,1,1,1,2),""))))) | R13: =IF(OR('Öğrenci Listesi'!B14="",Y13=""),"",IF(Y13="Çok İyi",CHOOSE(RANDBETWEEN(1,5),4,4,4,4,3),IF(Y13="İyi",CHOOSE(RANDBETWEEN(1,5),3,3,3,4,2),IF(Y13="Yeterli",CHOOSE(RANDBETWEEN(1,5),2,2,2,3,1),IF(Y13="Geliştirilmeli",CHOOSE(RANDBETWEEN(1,5),1,1,1,1,2),""))))) | S13: =IF(OR('Öğrenci Listesi'!B14="",Y13=""),"",IF(Y13="Çok İyi",CHOOSE(RANDBETWEEN(1,5),4,4,4,4,3),IF(Y13="İyi",CHOOSE(RANDBETWEEN(1,5),3,3,3,4,2),IF(Y13="Yeterli",CHOOSE(RANDBETWEEN(1,5),2,2,2,3,1),IF(Y13="Geliştirilmeli",CHOOSE(RANDBETWEEN(1,5),1,1,1,1,2),""))))) | T13: =IF(OR('Öğrenci Listesi'!B14="",Y13=""),"",IF(Y13="Çok İyi",CHOOSE(RANDBETWEEN(1,5),4,4,4,4,3),IF(Y13="İyi",CHOOSE(RANDBETWEEN(1,5),3,3,3,4,2),IF(Y13="Yeterli",CHOOSE(RANDBETWEEN(1,5),2,2,2,3,1),IF(Y13="Geliştirilmeli",CHOOSE(RANDBETWEEN(1,5),1,1,1,1,2),""))))) | U13: =IF(OR('Öğrenci Listesi'!B14="",Y13=""),"",IF(Y13="Çok İyi",CHOOSE(RANDBETWEEN(1,5),4,4,4,4,3),IF(Y13="İyi",CHOOSE(RANDBETWEEN(1,5),3,3,3,4,2),IF(Y13="Yeterli",CHOOSE(RANDBETWEEN(1,5),2,2,2,3,1),IF(Y13="Geliştirilmeli",CHOOSE(RANDBETWEEN(1,5),1,1,1,1,2),""))))) | V13: =IF(OR('Öğrenci Listesi'!B14="",Y13=""),"",IF(Y13="Çok İyi",CHOOSE(RANDBETWEEN(1,5),4,4,4,4,3),IF(Y13="İyi",CHOOSE(RANDBETWEEN(1,5),3,3,3,4,2),IF(Y13="Yeterli",CHOOSE(RANDBETWEEN(1,5),2,2,2,3,1),IF(Y13="Geliştirilmeli",CHOOSE(RANDBETWEEN(1,5),1,1,1,1,2),""))))) | W13: =IF(OR('Öğrenci Listesi'!B14="",Y13=""),"",IF(Y13="Çok İyi",CHOOSE(RANDBETWEEN(1,5),4,4,4,4,3),IF(Y13="İyi",CHOOSE(RANDBETWEEN(1,5),3,3,3,4,2),IF(Y13="Yeterli",CHOOSE(RANDBETWEEN(1,5),2,2,2,3,1),IF(Y13="Geliştirilmeli",CHOOSE(RANDBETWEEN(1,5),1,1,1,1,2),""))))) | X13: =IF(OR('Öğrenci Listesi'!B14="",Y13=""),"",ROUND(AVERAGE(C13:W13),2)) | Y13: =IFERROR(IF('Öğrenci Listesi'!G14="","",IF(UPPER(TRIM('Öğrenci Listesi'!G14))="ÇOK İYİ","Çok İyi",IF(UPPER(TRIM('Öğrenci Listesi'!G14))="İYİ","İyi",IF(UPPER(TRIM('Öğrenci Listesi'!G14))="YETERLİ","Yeterli",IF(UPPER(TRIM('Öğrenci Listesi'!G14))="GELİŞTİRİLMELİ","Geliştirilmeli",'Öğrenci Listesi'!G14))))),"")
