Workbook

Sheet Bilgiler
A1: 📝 BİLGİLERİ DOLDURUNUZ
A2: Aşağıdaki bilgileri kendi okulunuza ve sınıfınıza göre doldurun. 'Ölçek' sayfasındaki başlıklar otomatik güncellenecek.
A4: Okul Adı
A5: Eğitim Öğretim Yılı
A6: Sınıf / Şube
A7: Dönem
A8: Ders | B8: Matematik
A9: Sınıf Öğretmeni
A10: Okul Müdürü

Sheet Öğrenci Listesi
A1: 📋 SİSTEMDEN ÖĞRENCİ LİSTESİNİ BURAYA YAPIŞTIRIN
A2: Sistemde notları işaretledikten sonra tüm tabloyu kopyalayın (Ctrl+C), aşağıdaki sarı alana yapıştırın (Ctrl+V).
A3: ✓ Öğrenci adları, numaraları ve seviyeler 'Ölçek' sayfasına otomatik aktarılacak.
A5: NO | B5: ADI SOYADI | C5: Geliştirilmeli | D5: Yeterli | E5: İyi | F5: Çok İyi | G5: SONUÇ | H5: (yok sayılır)

Sheet Ölçek
A1: =Bilgiler!B4&" • "&Bilgiler!B5&" EĞİTİM ÖĞRETİM YILI" -> • EĞİTİM ÖĞRETİM YILI
A2: =Bilgiler!B6&" SINIFI "&Bilgiler!B7&" "&Bilgiler!B8&" DERSİ KAZANIM DEĞERLENDİRME ÖLÇEĞİ" -> SINIFI Matematik DERSİ KAZANIM DEĞERLENDİRME ÖLÇEĞİ
A4: NO | B4: ADI VE SOYADI | C4: 4, 5 ve 6 basamaklı doğal sayıları okur ve yazar | D4: 4, 5 ve 6 basamaklı doğal sayıların bölüklerini ve basamaklarını, basamaklarındaki rakamların basamak değerlerini belirler ve çözümler | E4: En çok altı basamaklı doğal sayıları büyük/küçük sembolü kullanarak sıralar | F4: En çok dört basamaklı doğal sayılarla toplama işlemini yapar | G4: En çok dört basamaklı doğal sayıları 100’ün katlarıyla zihinden toplar | H4: Üç basamaklı doğal sayılardan 10’un katı olan iki basamaklı doğal sayıları ve 100’ün katı olan üç basamaklı doğal sayıları zihinden çıkarır | I4: Doğal sayılarla toplama ve çıkarma işlemini gerektiren problemleri çözer | J4: Üç doğal sayı ile yapılan çarpma işleminde sayıların birbirleriyle çarpılma sırasının değişmesinin, sonucu değiştirmediğini gösterir | K4: En çok üç basamaklı doğal sayıları 10, 100 ve 1000 ile zihinden çarpar | L4: Doğal sayılarla çarpma işlemini gerektiren problemleri çözer | M4: Son üç basamağı sıfır olan en çok beş basamaklı doğal sayıları 10, 100 ve 1000’e zihinden böler | N4: Çarpma ve bölme arasındaki ilişkiyi fark eder | O4: Aralarında eşitlik durumu olan iki matematiksel ifadeden birinde verilmeyen değeri belirler ve eşitliğin sağlandığını açıklar | P4: Basit, bileşik ve tam sayılı kesri tanır ve modellerle gösterir | Q4: Paydaları eşit olan en çok üç kesri karşılaştırır | R4: Kesirlerle toplama ve çıkarma işlemlerini gerektiren problemleri çözer | S4: Kare ve dikdörtgenin kenar özelliklerini belirler | T4: Açınımı verilen küpü oluşturur | U4: Ayna simetrisini, geometrik şekiller ve modeller üzerinde açıklayarak simetri doğrusunu çizer | V4: Açıyı oluşturan ışınları ve köşeyi belirler, açıyı isimlendirir ve sembolle gösterir | W4: Açıları standart açı ölçme araçlarıyla ölçerek dar, dik, geniş ve doğru açı olarak belirler | X4: Standart uzunluk ölçme birimlerinden milimetrenin kullanım alanlarını belirtir | Y4: Doğrudan ölçebileceği bir uzunluğu en uygun uzunluk ölçme birimiyle tahmin eder ve tahminini ölçme yaparak kontrol eder | Z4: Aynı çevre uzunluğuna sahip farklı geometrik şekiller oluşturur | AA4: Şekillerin alanlarının, bu alanı kaplayan birim karelerin sayısı olduğunu belirler | AB4: Zaman ölçme birimleri arasındaki ilişkiyi açıklar | AC4: Yarım ve çeyrek kilogramı gram cinsinden ifade eder | AD4: Ton ve miligramın kullanıldığı yerleri belirler | AE4: Mililitrenin kullanıldığı yerleri açıklar | AF4: Litre ve mililitreyi miktar belirtmek için bir arada kullanır | AG4: Litre ve mililitre ile ilgili problemleri çözer | AH4: Sütun grafiğini oluşturur | AI4: ORTALAMA | AJ4: SEVİYE
A5: =IFERROR(IF('Öğrenci Listesi'!A6="","",'Öğrenci Listesi'!A6),"") | B5: =IFERROR(IF('Öğrenci Listesi'!B6="","",'Öğrenci Listesi'!B6),"") | C5: =IF(OR('Öğrenci Listesi'!B6="",AJ5=""),"",IF(AJ5="Çok İyi",CHOOSE(RANDBETWEEN(1,5),4,4,4,4,3),IF(AJ5="İyi",CHOOSE(RANDBETWEEN(1,5),3,3,3,4,2),IF(AJ5="Yeterli",CHOOSE(RANDBETWEEN(1,5),2,2,2,3,1),IF(AJ5="Geliştirilmeli",CHOOSE(RANDBETWEEN(1,5),1,1,1,1,2),""))))) | D5: =IF(OR('Öğrenci Listesi'!B6="",AJ5=""),"",IF(AJ5="Çok İyi",CHOOSE(RANDBETWEEN(1,5),4,4,4,4,3),IF(AJ5="İyi",CHOOSE(RANDBETWEEN(1,5),3,3,3,4,2),IF(AJ5="Yeterli",CHOOSE(RANDBETWEEN(1,5),2,2,2,3,1),IF(AJ5="Geliştirilmeli",CHOOSE(RANDBETWEEN(1,5),1,1,1,1,2),""))))) | E5: =IF(OR('Öğrenci Listesi'!B6="",AJ5=""),"",IF(AJ5="Çok İyi",CHOOSE(RANDBETWEEN(1,5),4,4,4,4,3),IF(AJ5="İyi",CHOOSE(RANDBETWEEN(1,5),3,3,3,4,2),IF(AJ5="Yeterli",CHOOSE(RANDBETWEEN(1,5),2,2,2,3,1),IF(AJ5="Geliştirilmeli",CHOOSE(RANDBETWEEN(1,5),1,1,1,1,2),""))))) | F5: =IF(OR('Öğrenci Listesi'!B6="",AJ5=""),"",IF(AJ5="Çok İyi",CHOOSE(RANDBETWEEN(1,5),4,4,4,4,3),IF(AJ5="İyi",CHOOSE(RANDBETWEEN(1,5),3,3,3,4,2),IF(AJ5="Yeterli",CHOOSE(RANDBETWEEN(1,5),2,2,2,3,1),IF(AJ5="Geliştirilmeli",CHOOSE(RANDBETWEEN(1,5),1,1,1,1,2),""))))) | G5: =IF(OR('Öğrenci Listesi'!B6="",AJ5=""),"",IF(AJ5="Çok İyi",CHOOSE(RANDBETWEEN(1,5),4,4,4,4,3),IF(AJ5="İyi",CHOOSE(RANDBETWEEN(1,5),3,3,3,4,2),IF(AJ5="Yeterli",CHOOSE(RANDBETWEEN(1,5),2,2,2,3,1),IF(AJ5="Geliştirilmeli",CHOOSE(RANDBETWEEN(1,5),1,1,1,1,2),""))))) | H5: =IF(OR('Öğrenci Listesi'!B6="",AJ5=""),"",IF(AJ5="Çok İyi",CHOOSE(RANDBETWEEN(1,5),4,4,4,4,3),IF(AJ5="İyi",CHOOSE(RANDBETWEEN(1,5),3,3,3,4,2),IF(AJ5="Yeterli",CHOOSE(RANDBETWEEN(1,5),2,2,2,3,1),IF(AJ5="Geliştirilmeli",CHOOSE(RANDBETWEEN(1,5),1,1,1,1,2),""))))) | I5: =IF(OR('Öğrenci Listesi'!B6="",AJ5=""),"",IF(AJ5="Çok İyi",CHOOSE(RANDBETWEEN(1,5),4,4,4,4,3),IF(AJ5="İyi",CHOOSE(RANDBETWEEN(1,5),3,3,3,4,2),IF(AJ5="Yeterli",CHOOSE(RANDBETWEEN(1,5),2,2,2,3,1),IF(AJ5="Geliştirilmeli",CHOOSE(RANDBETWEEN(1,5),1,1,1,1,2),""))))) | J5: =IF(OR('Öğrenci Listesi'!B6="",AJ5=""),"",IF(AJ5="Çok İyi",CHOOSE(RANDBETWEEN(1,5),4,4,4,4,3),IF(AJ5="İyi",CHOOSE(RANDBETWEEN(1,5),3,3,3,4,2),IF(AJ5="Yeterli",CHOOSE(RANDBETWEEN(1,5),2,2,2,3,1),IF(AJ5="Geliştirilmeli",CHOOSE(RANDBETWEEN(1,5),1,1,1,1,2),""))))) | K5: =IF(OR('Öğrenci Listesi'!B6="",AJ5=""),"",IF(AJ5="Çok İyi",CHOOSE(RANDBETWEEN(1,5),4,4,4,4,3),IF(AJ5="İyi",CHOOSE(RANDBETWEEN(1,5),3,3,3,4,2),IF(AJ5="Yeterli",CHOOSE(RANDBETWEEN(1,5),2,2,2,3,1),IF(AJ5="Geliştirilmeli",CHOOSE(RANDBETWEEN(1,5),1,1,1,1,2),""))))) | L5: =IF(OR('Öğrenci Listesi'!B6="",AJ5=""),"",IF(AJ5="Çok İyi",CHOOSE(RANDBETWEEN(1,5),4,4,4,4,3),IF(AJ5="İyi",CHOOSE(RANDBETWEEN(1,5),3,3,3,4,2),IF(AJ5="Yeterli",CHOOSE(RANDBETWEEN(1,5),2,2,2,3,1),IF(AJ5="Geliştirilmeli",CHOOSE(RANDBETWEEN(1,5),1,1,1,1,2),""))))) | M5: =IF(OR('Öğrenci Listesi'!B6="",AJ5=""),"",IF(AJ5="Çok İyi",CHOOSE(RANDBETWEEN(1,5),4,4,4,4,3),IF(AJ5="İyi",CHOOSE(RANDBETWEEN(1,5),3,3,3,4,2),IF(AJ5="Yeterli",CHOOSE(RANDBETWEEN(1,5),2,2,2,3,1),IF(AJ5="Geliştirilmeli",CHOOSE(RANDBETWEEN(1,5),1,1,1,1,2),""))))) | N5: =IF(OR('Öğrenci Listesi'!B6="",AJ5=""),"",IF(AJ5="Çok İyi",CHOOSE(RANDBETWEEN(1,5),4,4,4,4,3),IF(AJ5="İyi",CHOOSE(RANDBETWEEN(1,5),3,3,3,4,2),IF(AJ5="Yeterli",CHOOSE(RANDBETWEEN(1,5),2,2,2,3,1),IF(AJ5="Geliştirilmeli",CHOOSE(RANDBETWEEN(1,5),1,1,1,1,2),""))))) | O5: =IF(OR('Öğrenci Listesi'!B6="",AJ5=""),"",IF(AJ5="Çok İyi",CHOOSE(RANDBETWEEN(1,5),4,4,4,4,3),IF(AJ5="İyi",CHOOSE(RANDBETWEEN(1,5),3,3,3,4,2),IF(AJ5="Yeterli",CHOOSE(RANDBETWEEN(1,5),2,2,2,3,1),IF(AJ5="Geliştirilmeli",CHOOSE(RANDBETWEEN(1,5),1,1,1,1,2),""))))) | P5: =IF(OR('Öğrenci Listesi'!B6="",AJ5=""),"",IF(AJ5="Çok İyi",CHOOSE(RANDBETWEEN(1,5),4,4,4,4,3),IF(AJ5="İyi",CHOOSE(RANDBETWEEN(1,5),3,3,3,4,2),IF(AJ5="Yeterli",CHOOSE(RANDBETWEEN(1,5),2,2,2,3,1),IF(AJ5="Geliştirilmeli",CHOOSE(RANDBETWEEN(1,5),1,1,1,1,2),""))))) | Q5: =IF(OR('Öğrenci Listesi'!B6="",AJ5=""),"",IF(AJ5="Çok İyi",CHOOSE(RANDBETWEEN(1,5),4,4,4,4,3),IF(AJ5="İyi",CHOOSE(RANDBETWEEN(1,5),3,3,3,4,2),IF(AJ5="Yeterli",CHOOSE(RANDBETWEEN(1,5),2,2,2,3,1),IF(AJ5="Geliştirilmeli",CHOOSE(RANDBETWEEN(1,5),1,1,1,1,2),""))))) | R5: =IF(OR('Öğrenci Listesi'!B6="",AJ5=""),"",IF(AJ5="Çok İyi",CHOOSE(RANDBETWEEN(1,5),4,4,4,4,3),IF(AJ5="İyi",CHOOSE(RANDBETWEEN(1,5),3,3,3,4,2),IF(AJ5="Yeterli",CHOOSE(RANDBETWEEN(1,5),2,2,2,3,1),IF(AJ5="Geliştirilmeli",CHOOSE(RANDBETWEEN(1,5),1,1,1,1,2),""))))) | S5: =IF(OR('Öğrenci Listesi'!B6="",AJ5=""),"",IF(AJ5="Çok İyi",CHOOSE(RANDBETWEEN(1,5),4,4,4,4,3),IF(AJ5="İyi",CHOOSE(RANDBETWEEN(1,5),3,3,3,4,2),IF(AJ5="Yeterli",CHOOSE(RANDBETWEEN(1,5),2,2,2,3,1),IF(AJ5="Geliştirilmeli",CHOOSE(RANDBETWEEN(1,5),1,1,1,1,2),""))))) | T5: =IF(OR('Öğrenci Listesi'!B6="",AJ5=""),"",IF(AJ5="Çok İyi",CHOOSE(RANDBETWEEN(1,5),4,4,4,4,3),IF(AJ5="İyi",CHOOSE(RANDBETWEEN(1,5),3,3,3,4,2),IF(AJ5="Yeterli",CHOOSE(RANDBETWEEN(1,5),2,2,2,3,1),IF(AJ5="Geliştirilmeli",CHOOSE(RANDBETWEEN(1,5),1,1,1,1,2),""))))) | U5: =IF(OR('Öğrenci Listesi'!B6="",AJ5=""),"",IF(AJ5="Çok İyi",CHOOSE(RANDBETWEEN(1,5),4,4,4,4,3),IF(AJ5="İyi",CHOOSE(RANDBETWEEN(1,5),3,3,3,4,2),IF(AJ5="Yeterli",CHOOSE(RANDBETWEEN(1,5),2,2,2,3,1),IF(AJ5="Geliştirilmeli",CHOOSE(RANDBETWEEN(1,5),1,1,1,1,2),""))))) | V5: =IF(OR('Öğrenci Listesi'!B6="",AJ5=""),"",IF(AJ5="Çok İyi",CHOOSE(RANDBETWEEN(1,5),4,4,4,4,3),IF(AJ5="İyi",CHOOSE(RANDBETWEEN(1,5),3,3,3,4,2),IF(AJ5="Yeterli",CHOOSE(RANDBETWEEN(1,5),2,2,2,3,1),IF(AJ5="Geliştirilmeli",CHOOSE(RANDBETWEEN(1,5),1,1,1,1,2),""))))) | W5: =IF(OR('Öğrenci Listesi'!B6="",AJ5=""),"",IF(AJ5="Çok İyi",CHOOSE(RANDBETWEEN(1,5),4,4,4,4,3),IF(AJ5="İyi",CHOOSE(RANDBETWEEN(1,5),3,3,3,4,2),IF(AJ5="Yeterli",CHOOSE(RANDBETWEEN(1,5),2,2,2,3,1),IF(AJ5="Geliştirilmeli",CHOOSE(RANDBETWEEN(1,5),1,1,1,1,2),""))))) | X5: =IF(OR('Öğrenci Listesi'!B6="",AJ5=""),"",IF(AJ5="Çok İyi",CHOOSE(RANDBETWEEN(1,5),4,4,4,4,3),IF(AJ5="İyi",CHOOSE(RANDBETWEEN(1,5),3,3,3,4,2),IF(AJ5="Yeterli",CHOOSE(RANDBETWEEN(1,5),2,2,2,3,1),IF(AJ5="Geliştirilmeli",CHOOSE(RANDBETWEEN(1,5),1,1,1,1,2),""))))) | Y5: =IF(OR('Öğrenci Listesi'!B6="",AJ5=""),"",IF(AJ5="Çok İyi",CHOOSE(RANDBETWEEN(1,5),4,4,4,4,3),IF(AJ5="İyi",CHOOSE(RANDBETWEEN(1,5),3,3,3,4,2),IF(AJ5="Yeterli",CHOOSE(RANDBETWEEN(1,5),2,2,2,3,1),IF(AJ5="Geliştirilmeli",CHOOSE(RANDBETWEEN(1,5),1,1,1,1,2),""))))) | Z5: =IF(OR('Öğrenci Listesi'!B6="",AJ5=""),"",IF(AJ5="Çok İyi",CHOOSE(RANDBETWEEN(1,5),4,4,4,4,3),IF(AJ5="İyi",CHOOSE(RANDBETWEEN(1,5),3,3,3,4,2),IF(AJ5="Yeterli",CHOOSE(RANDBETWEEN(1,5),2,2,2,3,1),IF(AJ5="Geliştirilmeli",CHOOSE(RANDBETWEEN(1,5),1,1,1,1,2),""))))) | AA5: =IF(OR('Öğrenci Listesi'!B6="",AJ5=""),"",IF(AJ5="Çok İyi",CHOOSE(RANDBETWEEN(1,5),4,4,4,4,3),IF(AJ5="İyi",CHOOSE(RANDBETWEEN(1,5),3,3,3,4,2),IF(AJ5="Yeterli",CHOOSE(RANDBETWEEN(1,5),2,2,2,3,1),IF(AJ5="Geliştirilmeli",CHOOSE(RANDBETWEEN(1,5),1,1,1,1,2),""))))) | AB5: =IF(OR('Öğrenci Listesi'!B6="",AJ5=""),"",IF(AJ5="Çok İyi",CHOOSE(RANDBETWEEN(1,5),4,4,4,4,3),IF(AJ5="İyi",CHOOSE(RANDBETWEEN(1,5),3,3,3,4,2),IF(AJ5="Yeterli",CHOOSE(RANDBETWEEN(1,5),2,2,2,3,1),IF(AJ5="Geliştirilmeli",CHOOSE(RANDBETWEEN(1,5),1,1,1,1,2),""))))) | AC5: =IF(OR('Öğrenci Listesi'!B6="",AJ5=""),"",IF(AJ5="Çok İyi",CHOOSE(RANDBETWEEN(1,5),4,4,4,4,3),IF(AJ5="İyi",CHOOSE(RANDBETWEEN(1,5),3,3,3,4,2),IF(AJ5="Yeterli",CHOOSE(RANDBETWEEN(1,5),2,2,2,3,1),IF(AJ5="Geliştirilmeli",CHOOSE(RANDBETWEEN(1,5),1,1,1,1,2),""))))) | AD5: =IF(OR('Öğrenci Listesi'!B6="",AJ5=""),"",IF(AJ5="Çok İyi",CHOOSE(RANDBETWEEN(1,5),4,4,4,4,3),IF(AJ5="İyi",CHOOSE(RANDBETWEEN(1,5),3,3,3,4,2),IF(AJ5="Yeterli",CHOOSE(RANDBETWEEN(1,5),2,2,2,3,1),IF(AJ5="Geliştirilmeli",CHOOSE(RANDBETWEEN(1,5),1,1,1,1,2),""))))) | AE5: =IF(OR('Öğrenci Listesi'!B6="",AJ5=""),"",IF(AJ5="Çok İyi",CHOOSE(RANDBETWEEN(1,5),4,4,4,4,3),IF(AJ5="İyi",CHOOSE(RANDBETWEEN(1,5),3,3,3,4,2),IF(AJ5="Yeterli",CHOOSE(RANDBETWEEN(1,5),2,2,2,3,1),IF(AJ5="Geliştirilmeli",CHOOSE(RANDBETWEEN(1,5),1,1,1,1,2),""))))) | AF5: =IF(OR('Öğrenci Listesi'!B6="",AJ5=""),"",IF(AJ5="Çok İyi",CHOOSE(RANDBETWEEN(1,5),4,4,4,4,3),IF(AJ5="İyi",CHOOSE(RANDBETWEEN(1,5),3,3,3,4,2),IF(AJ5="Yeterli",CHOOSE(RANDBETWEEN(1,5),2,2,2,3,1),IF(AJ5="Geliştirilmeli",CHOOSE(RANDBETWEEN(1,5),1,1,1,1,2),""))))) | AG5: =IF(OR('Öğrenci Listesi'!B6="",AJ5=""),"",IF(AJ5="Çok İyi",CHOOSE(RANDBETWEEN(1,5),4,4,4,4,3),IF(AJ5="İyi",CHOOSE(RANDBETWEEN(1,5),3,3,3,4,2),IF(AJ5="Yeterli",CHOOSE(RANDBETWEEN(1,5),2,2,2,3,1),IF(AJ5="Geliştirilmeli",CHOOSE(RANDBETWEEN(1,5),1,1,1,1,2),""))))) | AH5: =IF(OR('Öğrenci Listesi'!B6="",AJ5=""),"",IF(AJ5="Çok İyi",CHOOSE(RANDBETWEEN(1,5),4,4,4,4,3),IF(AJ5="İyi",CHOOSE(RANDBETWEEN(1,5),3,3,3,4,2),IF(AJ5="Yeterli",CHOOSE(RANDBETWEEN(1,5),2,2,2,3,1),IF(AJ5="Geliştirilmeli",CHOOSE(RANDBETWEEN(1,5),1,1,1,1,2),""))))) | AI5: =IF(OR('Öğrenci Listesi'!B6="",AJ5=""),"",ROUND(AVERAGE(C5:AH5),2)) | AJ5: =IFERROR(IF('Öğrenci Listesi'!G6="","",IF(UPPER(TRIM('Öğrenci Listesi'!G6))="ÇOK İYİ","Çok İyi",IF(UPPER(TRIM('Öğrenci Listesi'!G6))="İYİ","İyi",IF(UPPER(TRIM('Öğrenci Listesi'!G6))="YETERLİ","Yeterli",IF(UPPER(TRIM('Öğrenci Listesi'!G6))="GELİŞTİRİLMELİ","Geliştirilmeli",'Öğrenci Listesi'!G6))))),"")
A6: =IFERROR(IF('Öğrenci Listesi'!A7="","",'Öğrenci Listesi'!A7),"") | B6: =IFERROR(IF('Öğrenci Listesi'!B7="","",'Öğrenci Listesi'!B7),"") | C6: =IF(OR('Öğrenci Listesi'!B7="",AJ6=""),"",IF(AJ6="Çok İyi",CHOOSE(RANDBETWEEN(1,5),4,4,4,4,3),IF(AJ6="İyi",CHOOSE(RANDBETWEEN(1,5),3,3,3,4,2),IF(AJ6="Yeterli",CHOOSE(RANDBETWEEN(1,5),2,2,2,3,1),IF(AJ6="Geliştirilmeli",CHOOSE(RANDBETWEEN(1,5),1,1,1,1,2),""))))) | D6: =IF(OR('Öğrenci Listesi'!B7="",AJ6=""),"",IF(AJ6="Çok İyi",CHOOSE(RANDBETWEEN(1,5),4,4,4,4,3),IF(AJ6="İyi",CHOOSE(RANDBETWEEN(1,5),3,3,3,4,2),IF(AJ6="Yeterli",CHOOSE(RANDBETWEEN(1,5),2,2,2,3,1),IF(AJ6="Geliştirilmeli",CHOOSE(RANDBETWEEN(1,5),1,1,1,1,2),""))))) | E6: =IF(OR('Öğrenci Listesi'!B7="",AJ6=""),"",IF(AJ6="Çok İyi",CHOOSE(RANDBETWEEN(1,5),4,4,4,4,3),IF(AJ6="İyi",CHOOSE(RANDBETWEEN(1,5),3,3,3,4,2),IF(AJ6="Yeterli",CHOOSE(RANDBETWEEN(1,5),2,2,2,3,1),IF(AJ6="Geliştirilmeli",CHOOSE(RANDBETWEEN(1,5),1,1,1,1,2),""))))) | F6: =IF(OR('Öğrenci Listesi'!B7="",AJ6=""),"",IF(AJ6="Çok İyi",CHOOSE(RANDBETWEEN(1,5),4,4,4,4,3),IF(AJ6="İyi",CHOOSE(RANDBETWEEN(1,5),3,3,3,4,2),IF(AJ6="Yeterli",CHOOSE(RANDBETWEEN(1,5),2,2,2,3,1),IF(AJ6="Geliştirilmeli",CHOOSE(RANDBETWEEN(1,5),1,1,1,1,2),""))))) | G6: =IF(OR('Öğrenci Listesi'!B7="",AJ6=""),"",IF(AJ6="Çok İyi",CHOOSE(RANDBETWEEN(1,5),4,4,4,4,3),IF(AJ6="İyi",CHOOSE(RANDBETWEEN(1,5),3,3,3,4,2),IF(AJ6="Yeterli",CHOOSE(RANDBETWEEN(1,5),2,2,2,3,1),IF(AJ6="Geliştirilmeli",CHOOSE(RANDBETWEEN(1,5),1,1,1,1,2),""))))) | H6: =IF(OR('Öğrenci Listesi'!B7="",AJ6=""),"",IF(AJ6="Çok İyi",CHOOSE(RANDBETWEEN(1,5),4,4,4,4,3),IF(AJ6="İyi",CHOOSE(RANDBETWEEN(1,5),3,3,3,4,2),IF(AJ6="Yeterli",CHOOSE(RANDBETWEEN(1,5),2,2,2,3,1),IF(AJ6="Geliştirilmeli",CHOOSE(RANDBETWEEN(1,5),1,1,1,1,2),""))))) | I6: =IF(OR('Öğrenci Listesi'!B7="",AJ6=""),"",IF(AJ6="Çok İyi",CHOOSE(RANDBETWEEN(1,5),4,4,4,4,3),IF(AJ6="İyi",CHOOSE(RANDBETWEEN(1,5),3,3,3,4,2),IF(AJ6="Yeterli",CHOOSE(RANDBETWEEN(1,5),2,2,2,3,1),IF(AJ6="Geliştirilmeli",CHOOSE(RANDBETWEEN(1,5),1,1,1,1,2),""))))) | J6: =IF(OR('Öğrenci Listesi'!B7="",AJ6=""),"",IF(AJ6="Çok İyi",CHOOSE(RANDBETWEEN(1,5),4,4,4,4,3),IF(AJ6="İyi",CHOOSE(RANDBETWEEN(1,5),3,3,3,4,2),IF(AJ6="Yeterli",CHOOSE(RANDBETWEEN(1,5),2,2,2,3,1),IF(AJ6="Geliştirilmeli",CHOOSE(RANDBETWEEN(1,5),1,1,1,1,2),""))))) | K6: =IF(OR('Öğrenci Listesi'!B7="",AJ6=""),"",IF(AJ6="Çok İyi",CHOOSE(RANDBETWEEN(1,5),4,4,4,4,3),IF(AJ6="İyi",CHOOSE(RANDBETWEEN(1,5),3,3,3,4,2),IF(AJ6="Yeterli",CHOOSE(RANDBETWEEN(1,5),2,2,2,3,1),IF(AJ6="Geliştirilmeli",CHOOSE(RANDBETWEEN(1,5),1,1,1,1,2),""))))) | L6: =IF(OR('Öğrenci Listesi'!B7="",AJ6=""),"",IF(AJ6="Çok İyi",CHOOSE(RANDBETWEEN(1,5),4,4,4,4,3),IF(AJ6="İyi",CHOOSE(RANDBETWEEN(1,5),3,3,3,4,2),IF(AJ6="Yeterli",CHOOSE(RANDBETWEEN(1,5),2,2,2,3,1),IF(AJ6="Geliştirilmeli",CHOOSE(RANDBETWEEN(1,5),1,1,1,1,2),""))))) | M6: =IF(OR('Öğrenci Listesi'!B7="",AJ6=""),"",IF(AJ6="Çok İyi",CHOOSE(RANDBETWEEN(1,5),4,4,4,4,3),IF(AJ6="İyi",CHOOSE(RANDBETWEEN(1,5),3,3,3,4,2),IF(AJ6="Yeterli",CHOOSE(RANDBETWEEN(1,5),2,2,2,3,1),IF(AJ6="Geliştirilmeli",CHOOSE(RANDBETWEEN(1,5),1,1,1,1,2),""))))) | N6: =IF(OR('Öğrenci Listesi'!B7="",AJ6=""),"",IF(AJ6="Çok İyi",CHOOSE(RANDBETWEEN(1,5),4,4,4,4,3),IF(AJ6="İyi",CHOOSE(RANDBETWEEN(1,5),3,3,3,4,2),IF(AJ6="Yeterli",CHOOSE(RANDBETWEEN(1,5),2,2,2,3,1),IF(AJ6="Geliştirilmeli",CHOOSE(RANDBETWEEN(1,5),1,1,1,1,2),""))))) | O6: =IF(OR('Öğrenci Listesi'!B7="",AJ6=""),"",IF(AJ6="Çok İyi",CHOOSE(RANDBETWEEN(1,5),4,4,4,4,3),IF(AJ6="İyi",CHOOSE(RANDBETWEEN(1,5),3,3,3,4,2),IF(AJ6="Yeterli",CHOOSE(RANDBETWEEN(1,5),2,2,2,3,1),IF(AJ6="Geliştirilmeli",CHOOSE(RANDBETWEEN(1,5),1,1,1,1,2),""))))) | P6: =IF(OR('Öğrenci Listesi'!B7="",AJ6=""),"",IF(AJ6="Çok İyi",CHOOSE(RANDBETWEEN(1,5),4,4,4,4,3),IF(AJ6="İyi",CHOOSE(RANDBETWEEN(1,5),3,3,3,4,2),IF(AJ6="Yeterli",CHOOSE(RANDBETWEEN(1,5),2,2,2,3,1),IF(AJ6="Geliştirilmeli",CHOOSE(RANDBETWEEN(1,5),1,1,1,1,2),""))))) | Q6: =IF(OR('Öğrenci Listesi'!B7="",AJ6=""),"",IF(AJ6="Çok İyi",CHOOSE(RANDBETWEEN(1,5),4,4,4,4,3),IF(AJ6="İyi",CHOOSE(RANDBETWEEN(1,5),3,3,3,4,2),IF(AJ6="Yeterli",CHOOSE(RANDBETWEEN(1,5),2,2,2,3,1),IF(AJ6="Geliştirilmeli",CHOOSE(RANDBETWEEN(1,5),1,1,1,1,2),""))))) | R6: =IF(OR('Öğrenci Listesi'!B7="",AJ6=""),"",IF(AJ6="Çok İyi",CHOOSE(RANDBETWEEN(1,5),4,4,4,4,3),IF(AJ6="İyi",CHOOSE(RANDBETWEEN(1,5),3,3,3,4,2),IF(AJ6="Yeterli",CHOOSE(RANDBETWEEN(1,5),2,2,2,3,1),IF(AJ6="Geliştirilmeli",CHOOSE(RANDBETWEEN(1,5),1,1,1,1,2),""))))) | S6: =IF(OR('Öğrenci Listesi'!B7="",AJ6=""),"",IF(AJ6="Çok İyi",CHOOSE(RANDBETWEEN(1,5),4,4,4,4,3),IF(AJ6="İyi",CHOOSE(RANDBETWEEN(1,5),3,3,3,4,2),IF(AJ6="Yeterli",CHOOSE(RANDBETWEEN(1,5),2,2,2,3,1),IF(AJ6="Geliştirilmeli",CHOOSE(RANDBETWEEN(1,5),1,1,1,1,2),""))))) | T6: =IF(OR('Öğrenci Listesi'!B7="",AJ6=""),"",IF(AJ6="Çok İyi",CHOOSE(RANDBETWEEN(1,5),4,4,4,4,3),IF(AJ6="İyi",CHOOSE(RANDBETWEEN(1,5),3,3,3,4,2),IF(AJ6="Yeterli",CHOOSE(RANDBETWEEN(1,5),2,2,2,3,1),IF(AJ6="Geliştirilmeli",CHOOSE(RANDBETWEEN(1,5),1,1,1,1,2),""))))) | U6: =IF(OR('Öğrenci Listesi'!B7="",AJ6=""),"",IF(AJ6="Çok İyi",CHOOSE(RANDBETWEEN(1,5),4,4,4,4,3),IF(AJ6="İyi",CHOOSE(RANDBETWEEN(1,5),3,3,3,4,2),IF(AJ6="Yeterli",CHOOSE(RANDBETWEEN(1,5),2,2,2,3,1),IF(AJ6="Geliştirilmeli",CHOOSE(RANDBETWEEN(1,5),1,1,1,1,2),""))))) | V6: =IF(OR('Öğrenci Listesi'!B7="",AJ6=""),"",IF(AJ6="Çok İyi",CHOOSE(RANDBETWEEN(1,5),4,4,4,4,3),IF(AJ6="İyi",CHOOSE(RANDBETWEEN(1,5),3,3,3,4,2),IF(AJ6="Yeterli",CHOOSE(RANDBETWEEN(1,5),2,2,2,3,1),IF(AJ6="Geliştirilmeli",CHOOSE(RANDBETWEEN(1,5),1,1,1,1,2),""))))) | W6: =IF(OR('Öğrenci Listesi'!B7="",AJ6=""),"",IF(AJ6="Çok İyi",CHOOSE(RANDBETWEEN(1,5),4,4,4,4,3),IF(AJ6="İyi",CHOOSE(RANDBETWEEN(1,5),3,3,3,4,2),IF(AJ6="Yeterli",CHOOSE(RANDBETWEEN(1,5),2,2,2,3,1),IF(AJ6="Geliştirilmeli",CHOOSE(RANDBETWEEN(1,5),1,1,1,1,2),""))))) | X6: =IF(OR('Öğrenci Listesi'!B7="",AJ6=""),"",IF(AJ6="Çok İyi",CHOOSE(RANDBETWEEN(1,5),4,4,4,4,3),IF(AJ6="İyi",CHOOSE(RANDBETWEEN(1,5),3,3,3,4,2),IF(AJ6="Yeterli",CHOOSE(RANDBETWEEN(1,5),2,2,2,3,1),IF(AJ6="Geliştirilmeli",CHOOSE(RANDBETWEEN(1,5),1,1,1,1,2),""))))) | Y6: =IF(OR('Öğrenci Listesi'!B7="",AJ6=""),"",IF(AJ6="Çok İyi",CHOOSE(RANDBETWEEN(1,5),4,4,4,4,3),IF(AJ6="İyi",CHOOSE(RANDBETWEEN(1,5),3,3,3,4,2),IF(AJ6="Yeterli",CHOOSE(RANDBETWEEN(1,5),2,2,2,3,1),IF(AJ6="Geliştirilmeli",CHOOSE(RANDBETWEEN(1,5),1,1,1,1,2),""))))) | Z6: =IF(OR('Öğrenci Listesi'!B7="",AJ6=""),"",IF(AJ6="Çok İyi",CHOOSE(RANDBETWEEN(1,5),4,4,4,4,3),IF(AJ6="İyi",CHOOSE(RANDBETWEEN(1,5),3,3,3,4,2),IF(AJ6="Yeterli",CHOOSE(RANDBETWEEN(1,5),2,2,2,3,1),IF(AJ6="Geliştirilmeli",CHOOSE(RANDBETWEEN(1,5),1,1,1,1,2),""))))) | AA6: =IF(OR('Öğrenci Listesi'!B7="",AJ6=""),"",IF(AJ6="Çok İyi",CHOOSE(RANDBETWEEN(1,5),4,4,4,4,3),IF(AJ6="İyi",CHOOSE(RANDBETWEEN(1,5),3,3,3,4,2),IF(AJ6="Yeterli",CHOOSE(RANDBETWEEN(1,5),2,2,2,3,1),IF(AJ6="Geliştirilmeli",CHOOSE(RANDBETWEEN(1,5),1,1,1,1,2),""))))) | AB6: =IF(OR('Öğrenci Listesi'!B7="",AJ6=""),"",IF(AJ6="Çok İyi",CHOOSE(RANDBETWEEN(1,5),4,4,4,4,3),IF(AJ6="İyi",CHOOSE(RANDBETWEEN(1,5),3,3,3,4,2),IF(AJ6="Yeterli",CHOOSE(RANDBETWEEN(1,5),2,2,2,3,1),IF(AJ6="Geliştirilmeli",CHOOSE(RANDBETWEEN(1,5),1,1,1,1,2),""))))) | AC6: =IF(OR('Öğrenci Listesi'!B7="",AJ6=""),"",IF(AJ6="Çok İyi",CHOOSE(RANDBETWEEN(1,5),4,4,4,4,3),IF(AJ6="İyi",CHOOSE(RANDBETWEEN(1,5),3,3,3,4,2),IF(AJ6="Yeterli",CHOOSE(RANDBETWEEN(1,5),2,2,2,3,1),IF(AJ6="Geliştirilmeli",CHOOSE(RANDBETWEEN(1,5),1,1,1,1,2),""))))) | AD6: =IF(OR('Öğrenci Listesi'!B7="",AJ6=""),"",IF(AJ6="Çok İyi",CHOOSE(RANDBETWEEN(1,5),4,4,4,4,3),IF(AJ6="İyi",CHOOSE(RANDBETWEEN(1,5),3,3,3,4,2),IF(AJ6="Yeterli",CHOOSE(RANDBETWEEN(1,5),2,2,2,3,1),IF(AJ6="Geliştirilmeli",CHOOSE(RANDBETWEEN(1,5),1,1,1,1,2),""))))) | AE6: =IF(OR('Öğrenci Listesi'!B7="",AJ6=""),"",IF(AJ6="Çok İyi",CHOOSE(RANDBETWEEN(1,5),4,4,4,4,3),IF(AJ6="İyi",CHOOSE(RANDBETWEEN(1,5),3,3,3,4,2),IF(AJ6="Yeterli",CHOOSE(RANDBETWEEN(1,5),2,2,2,3,1),IF(AJ6="Geliştirilmeli",CHOOSE(RANDBETWEEN(1,5),1,1,1,1,2),""))))) | AF6: =IF(OR('Öğrenci Listesi'!B7="",AJ6=""),"",IF(AJ6="Çok İyi",CHOOSE(RANDBETWEEN(1,5),4,4,4,4,3),IF(AJ6="İyi",CHOOSE(RANDBETWEEN(1,5),3,3,3,4,2),IF(AJ6="Yeterli",CHOOSE(RANDBETWEEN(1,5),2,2,2,3,1),IF(AJ6="Geliştirilmeli",CHOOSE(RANDBETWEEN(1,5),1,1,1,1,2),""))))) | AG6: =IF(OR('Öğrenci Listesi'!B7="",AJ6=""),"",IF(AJ6="Çok İyi",CHOOSE(RANDBETWEEN(1,5),4,4,4,4,3),IF(AJ6="İyi",CHOOSE(RANDBETWEEN(1,5),3,3,3,4,2),IF(AJ6="Yeterli",CHOOSE(RANDBETWEEN(1,5),2,2,2,3,1),IF(AJ6="Geliştirilmeli",CHOOSE(RANDBETWEEN(1,5),1,1,1,1,2),""))))) | AH6: =IF(OR('Öğrenci Listesi'!B7="",AJ6=""),"",IF(AJ6="Çok İyi",CHOOSE(RANDBETWEEN(1,5),4,4,4,4,3),IF(AJ6="İyi",CHOOSE(RANDBETWEEN(1,5),3,3,3,4,2),IF(AJ6="Yeterli",CHOOSE(RANDBETWEEN(1,5),2,2,2,3,1),IF(AJ6="Geliştirilmeli",CHOOSE(RANDBETWEEN(1,5),1,1,1,1,2),""))))) | AI6: =IF(OR('Öğrenci Listesi'!B7="",AJ6=""),"",ROUND(AVERAGE(C6:AH6),2)) | AJ6: =IFERROR(IF('Öğrenci Listesi'!G7="","",IF(UPPER(TRIM('Öğrenci Listesi'!G7))="ÇOK İYİ","Çok İyi",IF(UPPER(TRIM('Öğrenci Listesi'!G7))="İYİ","İyi",IF(UPPER(TRIM('Öğrenci Listesi'!G7))="YETERLİ","Yeterli",IF(UPPER(TRIM('Öğrenci Listesi'!G7))="GELİŞTİRİLMELİ","Geliştirilmeli",'Öğrenci Listesi'!G7))))),"")
A7: =IFERROR(IF('Öğrenci Listesi'!A8="","",'Öğrenci Listesi'!A8),"") | B7: =IFERROR(IF('Öğrenci Listesi'!B8="","",'Öğrenci Listesi'!B8),"") | C7: =IF(OR('Öğrenci Listesi'!B8="",AJ7=""),"",IF(AJ7="Çok İyi",CHOOSE(RANDBETWEEN(1,5),4,4,4,4,3),IF(AJ7="İyi",CHOOSE(RANDBETWEEN(1,5),3,3,3,4,2),IF(AJ7="Yeterli",CHOOSE(RANDBETWEEN(1,5),2,2,2,3,1),IF(AJ7="Geliştirilmeli",CHOOSE(RANDBETWEEN(1,5),1,1,1,1,2),""))))) | D7: =IF(OR('Öğrenci Listesi'!B8="",AJ7=""),"",IF(AJ7="Çok İyi",CHOOSE(RANDBETWEEN(1,5),4,4,4,4,3),IF(AJ7="İyi",CHOOSE(RANDBETWEEN(1,5),3,3,3,4,2),IF(AJ7="Yeterli",CHOOSE(RANDBETWEEN(1,5),2,2,2,3,1),IF(AJ7="Geliştirilmeli",CHOOSE(RANDBETWEEN(1,5),1,1,1,1,2),""))))) | E7: =IF(OR('Öğrenci Listesi'!B8="",AJ7=""),"",IF(AJ7="Çok İyi",CHOOSE(RANDBETWEEN(1,5),4,4,4,4,3),IF(AJ7="İyi",CHOOSE(RANDBETWEEN(1,5),3,3,3,4,2),IF(AJ7="Yeterli",CHOOSE(RANDBETWEEN(1,5),2,2,2,3,1),IF(AJ7="Geliştirilmeli",CHOOSE(RANDBETWEEN(1,5),1,1,1,1,2),""))))) | F7: =IF(OR('Öğrenci Listesi'!B8="",AJ7=""),"",IF(AJ7="Çok İyi",CHOOSE(RANDBETWEEN(1,5),4,4,4,4,3),IF(AJ7="İyi",CHOOSE(RANDBETWEEN(1,5),3,3,3,4,2),IF(AJ7="Yeterli",CHOOSE(RANDBETWEEN(1,5),2,2,2,3,1),IF(AJ7="Geliştirilmeli",CHOOSE(RANDBETWEEN(1,5),1,1,1,1,2),""))))) | G7: =IF(OR('Öğrenci Listesi'!B8="",AJ7=""),"",IF(AJ7="Çok İyi",CHOOSE(RANDBETWEEN(1,5),4,4,4,4,3),IF(AJ7="İyi",CHOOSE(RANDBETWEEN(1,5),3,3,3,4,2),IF(AJ7="Yeterli",CHOOSE(RANDBETWEEN(1,5),2,2,2,3,1),IF(AJ7="Geliştirilmeli",CHOOSE(RANDBETWEEN(1,5),1,1,1,1,2),""))))) | H7: =IF(OR('Öğrenci Listesi'!B8="",AJ7=""),"",IF(AJ7="Çok İyi",CHOOSE(RANDBETWEEN(1,5),4,4,4,4,3),IF(AJ7="İyi",CHOOSE(RANDBETWEEN(1,5),3,3,3,4,2),IF(AJ7="Yeterli",CHOOSE(RANDBETWEEN(1,5),2,2,2,3,1),IF(AJ7="Geliştirilmeli",CHOOSE(RANDBETWEEN(1,5),1,1,1,1,2),""))))) | I7: =IF(OR('Öğrenci Listesi'!B8="",AJ7=""),"",IF(AJ7="Çok İyi",CHOOSE(RANDBETWEEN(1,5),4,4,4,4,3),IF(AJ7="İyi",CHOOSE(RANDBETWEEN(1,5),3,3,3,4,2),IF(AJ7="Yeterli",CHOOSE(RANDBETWEEN(1,5),2,2,2,3,1),IF(AJ7="Geliştirilmeli",CHOOSE(RANDBETWEEN(1,5),1,1,1,1,2),""))))) | J7: =IF(OR('Öğrenci Listesi'!B8="",AJ7=""),"",IF(AJ7="Çok İyi",CHOOSE(RANDBETWEEN(1,5),4,4,4,4,3),IF(AJ7="İyi",CHOOSE(RANDBETWEEN(1,5),3,3,3,4,2),IF(AJ7="Yeterli",CHOOSE(RANDBETWEEN(1,5),2,2,2,3,1),IF(AJ7="Geliştirilmeli",CHOOSE(RANDBETWEEN(1,5),1,1,1,1,2),""))))) | K7: =IF(OR('Öğrenci Listesi'!B8="",AJ7=""),"",IF(AJ7="Çok İyi",CHOOSE(RANDBETWEEN(1,5),4,4,4,4,3),IF(AJ7="İyi",CHOOSE(RANDBETWEEN(1,5),3,3,3,4,2),IF(AJ7="Yeterli",CHOOSE(RANDBETWEEN(1,5),2,2,2,3,1),IF(AJ7="Geliştirilmeli",CHOOSE(RANDBETWEEN(1,5),1,1,1,1,2),""))))) | L7: =IF(OR('Öğrenci Listesi'!B8="",AJ7=""),"",IF(AJ7="Çok İyi",CHOOSE(RANDBETWEEN(1,5),4,4,4,4,3),IF(AJ7="İyi",CHOOSE(RANDBETWEEN(1,5),3,3,3,4,2),IF(AJ7="Yeterli",CHOOSE(RANDBETWEEN(1,5),2,2,2,3,1),IF(AJ7="Geliştirilmeli",CHOOSE(RANDBETWEEN(1,5),1,1,1,1,2),""))))) | M7: =IF(OR('Öğrenci Listesi'!B8="",AJ7=""),"",IF(AJ7="Çok İyi",CHOOSE(RANDBETWEEN(1,5),4,4,4,4,3),IF(AJ7="İyi",CHOOSE(RANDBETWEEN(1,5),3,3,3,4,2),IF(AJ7="Yeterli",CHOOSE(RANDBETWEEN(1,5),2,2,2,3,1),IF(AJ7="Geliştirilmeli",CHOOSE(RANDBETWEEN(1,5),1,1,1,1,2),""))))) | N7: =IF(OR('Öğrenci Listesi'!B8="",AJ7=""),"",IF(AJ7="Çok İyi",CHOOSE(RANDBETWEEN(1,5),4,4,4,4,3),IF(AJ7="İyi",CHOOSE(RANDBETWEEN(1,5),3,3,3,4,2),IF(AJ7="Yeterli",CHOOSE(RANDBETWEEN(1,5),2,2,2,3,1),IF(AJ7="Geliştirilmeli",CHOOSE(RANDBETWEEN(1,5),1,1,1,1,2),""))))) | O7: =IF(OR('Öğrenci Listesi'!B8="",AJ7=""),"",IF(AJ7="Çok İyi",CHOOSE(RANDBETWEEN(1,5),4,4,4,4,3),IF(AJ7="İyi",CHOOSE(RANDBETWEEN(1,5),3,3,3,4,2),IF(AJ7="Yeterli",CHOOSE(RANDBETWEEN(1,5),2,2,2,3,1),IF(AJ7="Geliştirilmeli",CHOOSE(RANDBETWEEN(1,5),1,1,1,1,2),""))))) | P7: =IF(OR('Öğrenci Listesi'!B8="",AJ7=""),"",IF(AJ7="Çok İyi",CHOOSE(RANDBETWEEN(1,5),4,4,4,4,3),IF(AJ7="İyi",CHOOSE(RANDBETWEEN(1,5),3,3,3,4,2),IF(AJ7="Yeterli",CHOOSE(RANDBETWEEN(1,5),2,2,2,3,1),IF(AJ7="Geliştirilmeli",CHOOSE(RANDBETWEEN(1,5),1,1,1,1,2),""))))) | Q7: =IF(OR('Öğrenci Listesi'!B8="",AJ7=""),"",IF(AJ7="Çok İyi",CHOOSE(RANDBETWEEN(1,5),4,4,4,4,3),IF(AJ7="İyi",CHOOSE(RANDBETWEEN(1,5),3,3,3,4,2),IF(AJ7="Yeterli",CHOOSE(RANDBETWEEN(1,5),2,2,2,3,1),IF(AJ7="Geliştirilmeli",CHOOSE(RANDBETWEEN(1,5),1,1,1,1,2),""))))) | R7: =IF(OR('Öğrenci Listesi'!B8="",AJ7=""),"",IF(AJ7="Çok İyi",CHOOSE(RANDBETWEEN(1,5),4,4,4,4,3),IF(AJ7="İyi",CHOOSE(RANDBETWEEN(1,5),3,3,3,4,2),IF(AJ7="Yeterli",CHOOSE(RANDBETWEEN(1,5),2,2,2,3,1),IF(AJ7="Geliştirilmeli",CHOOSE(RANDBETWEEN(1,5),1,1,1,1,2),""))))) | S7: =IF(OR('Öğrenci Listesi'!B8="",AJ7=""),"",IF(AJ7="Çok İyi",CHOOSE(RANDBETWEEN(1,5),4,4,4,4,3),IF(AJ7="İyi",CHOOSE(RANDBETWEEN(1,5),3,3,3,4,2),IF(AJ7="Yeterli",CHOOSE(RANDBETWEEN(1,5),2,2,2,3,1),IF(AJ7="Geliştirilmeli",CHOOSE(RANDBETWEEN(1,5),1,1,1,1,2),""))))) | T7: =IF(OR('Öğrenci Listesi'!B8="",AJ7=""),"",IF(AJ7="Çok İyi",CHOOSE(RANDBETWEEN(1,5),4,4,4,4,3),IF(AJ7="İyi",CHOOSE(RANDBETWEEN(1,5),3,3,3,4,2),IF(AJ7="Yeterli",CHOOSE(RANDBETWEEN(1,5),2,2,2,3,1),IF(AJ7="Geliştirilmeli",CHOOSE(RANDBETWEEN(1,5),1,1,1,1,2),""))))) | U7: =IF(OR('Öğrenci Listesi'!B8="",AJ7=""),"",IF(AJ7="Çok İyi",CHOOSE(RANDBETWEEN(1,5),4,4,4,4,3),IF(AJ7="İyi",CHOOSE(RANDBETWEEN(1,5),3,3,3,4,2),IF(AJ7="Yeterli",CHOOSE(RANDBETWEEN(1,5),2,2,2,3,1),IF(AJ7="Geliştirilmeli",CHOOSE(RANDBETWEEN(1,5),1,1,1,1,2),""))))) | V7: =IF(OR('Öğrenci Listesi'!B8="",AJ7=""),"",IF(AJ7="Çok İyi",CHOOSE(RANDBETWEEN(1,5),4,4,4,4,3),IF(AJ7="İyi",CHOOSE(RANDBETWEEN(1,5),3,3,3,4,2),IF(AJ7="Yeterli",CHOOSE(RANDBETWEEN(1,5),2,2,2,3,1),IF(AJ7="Geliştirilmeli",CHOOSE(RANDBETWEEN(1,5),1,1,1,1,2),""))))) | W7: =IF(OR('Öğrenci Listesi'!B8="",AJ7=""),"",IF(AJ7="Çok İyi",CHOOSE(RANDBETWEEN(1,5),4,4,4,4,3),IF(AJ7="İyi",CHOOSE(RANDBETWEEN(1,5),3,3,3,4,2),IF(AJ7="Yeterli",CHOOSE(RANDBETWEEN(1,5),2,2,2,3,1),IF(AJ7="Geliştirilmeli",CHOOSE(RANDBETWEEN(1,5),1,1,1,1,2),""))))) | X7: =IF(OR('Öğrenci Listesi'!B8="",AJ7=""),"",IF(AJ7="Çok İyi",CHOOSE(RANDBETWEEN(1,5),4,4,4,4,3),IF(AJ7="İyi",CHOOSE(RANDBETWEEN(1,5),3,3,3,4,2),IF(AJ7="Yeterli",CHOOSE(RANDBETWEEN(1,5),2,2,2,3,1),IF(AJ7="Geliştirilmeli",CHOOSE(RANDBETWEEN(1,5),1,1,1,1,2),""))))) | Y7: =IF(OR('Öğrenci Listesi'!B8="",AJ7=""),"",IF(AJ7="Çok İyi",CHOOSE(RANDBETWEEN(1,5),4,4,4,4,3),IF(AJ7="İyi",CHOOSE(RANDBETWEEN(1,5),3,3,3,4,2),IF(AJ7="Yeterli",CHOOSE(RANDBETWEEN(1,5),2,2,2,3,1),IF(AJ7="Geliştirilmeli",CHOOSE(RANDBETWEEN(1,5),1,1,1,1,2),""))))) | Z7: =IF(OR('Öğrenci Listesi'!B8="",AJ7=""),"",IF(AJ7="Çok İyi",CHOOSE(RANDBETWEEN(1,5),4,4,4,4,3),IF(AJ7="İyi",CHOOSE(RANDBETWEEN(1,5),3,3,3,4,2),IF(AJ7="Yeterli",CHOOSE(RANDBETWEEN(1,5),2,2,2,3,1),IF(AJ7="Geliştirilmeli",CHOOSE(RANDBETWEEN(1,5),1,1,1,1,2),""))))) | AA7: =IF(OR('Öğrenci Listesi'!B8="",AJ7=""),"",IF(AJ7="Çok İyi",CHOOSE(RANDBETWEEN(1,5),4,4,4,4,3),IF(AJ7="İyi",CHOOSE(RANDBETWEEN(1,5),3,3,3,4,2),IF(AJ7="Yeterli",CHOOSE(RANDBETWEEN(1,5),2,2,2,3,1),IF(AJ7="Geliştirilmeli",CHOOSE(RANDBETWEEN(1,5),1,1,1,1,2),""))))) | AB7: =IF(OR('Öğrenci Listesi'!B8="",AJ7=""),"",IF(AJ7="Çok İyi",CHOOSE(RANDBETWEEN(1,5),4,4,4,4,3),IF(AJ7="İyi",CHOOSE(RANDBETWEEN(1,5),3,3,3,4,2),IF(AJ7="Yeterli",CHOOSE(RANDBETWEEN(1,5),2,2,2,3,1),IF(AJ7="Geliştirilmeli",CHOOSE(RANDBETWEEN(1,5),1,1,1,1,2),""))))) | AC7: =IF(OR('Öğrenci Listesi'!B8="",AJ7=""),"",IF(AJ7="Çok İyi",CHOOSE(RANDBETWEEN(1,5),4,4,4,4,3),IF(AJ7="İyi",CHOOSE(RANDBETWEEN(1,5),3,3,3,4,2),IF(AJ7="Yeterli",CHOOSE(RANDBETWEEN(1,5),2,2,2,3,1),IF(AJ7="Geliştirilmeli",CHOOSE(RANDBETWEEN(1,5),1,1,1,1,2),""))))) | AD7: =IF(OR('Öğrenci Listesi'!B8="",AJ7=""),"",IF(AJ7="Çok İyi",CHOOSE(RANDBETWEEN(1,5),4,4,4,4,3),IF(AJ7="İyi",CHOOSE(RANDBETWEEN(1,5),3,3,3,4,2),IF(AJ7="Yeterli",CHOOSE(RANDBETWEEN(1,5),2,2,2,3,1),IF(AJ7="Geliştirilmeli",CHOOSE(RANDBETWEEN(1,5),1,1,1,1,2),""))))) | AE7: =IF(OR('Öğrenci Listesi'!B8="",AJ7=""),"",IF(AJ7="Çok İyi",CHOOSE(RANDBETWEEN(1,5),4,4,4,4,3),IF(AJ7="İyi",CHOOSE(RANDBETWEEN(1,5),3,3,3,4,2),IF(AJ7="Yeterli",CHOOSE(RANDBETWEEN(1,5),2,2,2,3,1),IF(AJ7="Geliştirilmeli",CHOOSE(RANDBETWEEN(1,5),1,1,1,1,2),""))))) | AF7: =IF(OR('Öğrenci Listesi'!B8="",AJ7=""),"",IF(AJ7="Çok İyi",CHOOSE(RANDBETWEEN(1,5),4,4,4,4,3),IF(AJ7="İyi",CHOOSE(RANDBETWEEN(1,5),3,3,3,4,2),IF(AJ7="Yeterli",CHOOSE(RANDBETWEEN(1,5),2,2,2,3,1),IF(AJ7="Geliştirilmeli",CHOOSE(RANDBETWEEN(1,5),1,1,1,1,2),""))))) | AG7: =IF(OR('Öğrenci Listesi'!B8="",AJ7=""),"",IF(AJ7="Çok İyi",CHOOSE(RANDBETWEEN(1,5),4,4,4,4,3),IF(AJ7="İyi",CHOOSE(RANDBETWEEN(1,5),3,3,3,4,2),IF(AJ7="Yeterli",CHOOSE(RANDBETWEEN(1,5),2,2,2,3,1),IF(AJ7="Geliştirilmeli",CHOOSE(RANDBETWEEN(1,5),1,1,1,1,2),""))))) | AH7: =IF(OR('Öğrenci Listesi'!B8="",AJ7=""),"",IF(AJ7="Çok İyi",CHOOSE(RANDBETWEEN(1,5),4,4,4,4,3),IF(AJ7="İyi",CHOOSE(RANDBETWEEN(1,5),3,3,3,4,2),IF(AJ7="Yeterli",CHOOSE(RANDBETWEEN(1,5),2,2,2,3,1),IF(AJ7="Geliştirilmeli",CHOOSE(RANDBETWEEN(1,5),1,1,1,1,2),""))))) | AI7: =IF(OR('Öğrenci Listesi'!B8="",AJ7=""),"",ROUND(AVERAGE(C7:AH7),2)) | AJ7: =IFERROR(IF('Öğrenci Listesi'!G8="","",IF(UPPER(TRIM('Öğrenci Listesi'!G8))="ÇOK İYİ","Çok İyi",IF(UPPER(TRIM('Öğrenci Listesi'!G8))="İYİ","İyi",IF(UPPER(TRIM('Öğrenci Listesi'!G8))="YETERLİ","Yeterli",IF(UPPER(TRIM('Öğrenci Listesi'!G8))="GELİŞTİRİLMELİ","Geliştirilmeli",'Öğrenci Listesi'!G8))))),"")
A8: =IFERROR(IF('Öğrenci Listesi'!A9="","",'Öğrenci Listesi'!A9),"") | B8: =IFERROR(IF('Öğrenci Listesi'!B9="","",'Öğrenci Listesi'!B9),"") | C8: =IF(OR('Öğrenci Listesi'!B9="",AJ8=""),"",IF(AJ8="Çok İyi",CHOOSE(RANDBETWEEN(1,5),4,4,4,4,3),IF(AJ8="İyi",CHOOSE(RANDBETWEEN(1,5),3,3,3,4,2),IF(AJ8="Yeterli",CHOOSE(RANDBETWEEN(1,5),2,2,2,3,1),IF(AJ8="Geliştirilmeli",CHOOSE(RANDBETWEEN(1,5),1,1,1,1,2),""))))) | D8: =IF(OR('Öğrenci Listesi'!B9="",AJ8=""),"",IF(AJ8="Çok İyi",CHOOSE(RANDBETWEEN(1,5),4,4,4,4,3),IF(AJ8="İyi",CHOOSE(RANDBETWEEN(1,5),3,3,3,4,2),IF(AJ8="Yeterli",CHOOSE(RANDBETWEEN(1,5),2,2,2,3,1),IF(AJ8="Geliştirilmeli",CHOOSE(RANDBETWEEN(1,5),1,1,1,1,2),""))))) | E8: =IF(OR('Öğrenci Listesi'!B9="",AJ8=""),"",IF(AJ8="Çok İyi",CHOOSE(RANDBETWEEN(1,5),4,4,4,4,3),IF(AJ8="İyi",CHOOSE(RANDBETWEEN(1,5),3,3,3,4,2),IF(AJ8="Yeterli",CHOOSE(RANDBETWEEN(1,5),2,2,2,3,1),IF(AJ8="Geliştirilmeli",CHOOSE(RANDBETWEEN(1,5),1,1,1,1,2),""))))) | F8: =IF(OR('Öğrenci Listesi'!B9="",AJ8=""),"",IF(AJ8="Çok İyi",CHOOSE(RANDBETWEEN(1,5),4,4,4,4,3),IF(AJ8="İyi",CHOOSE(RANDBETWEEN(1,5),3,3,3,4,2),IF(AJ8="Yeterli",CHOOSE(RANDBETWEEN(1,5),2,2,2,3,1),IF(AJ8="Geliştirilmeli",CHOOSE(RANDBETWEEN(1,5),1,1,1,1,2),""))))) | G8: =IF(OR('Öğrenci Listesi'!B9="",AJ8=""),"",IF(AJ8="Çok İyi",CHOOSE(RANDBETWEEN(1,5),4,4,4,4,3),IF(AJ8="İyi",CHOOSE(RANDBETWEEN(1,5),3,3,3,4,2),IF(AJ8="Yeterli",CHOOSE(RANDBETWEEN(1,5),2,2,2,3,1),IF(AJ8="Geliştirilmeli",CHOOSE(RANDBETWEEN(1,5),1,1,1,1,2),""))))) | H8: =IF(OR('Öğrenci Listesi'!B9="",AJ8=""),"",IF(AJ8="Çok İyi",CHOOSE(RANDBETWEEN(1,5),4,4,4,4,3),IF(AJ8="İyi",CHOOSE(RANDBETWEEN(1,5),3,3,3,4,2),IF(AJ8="Yeterli",CHOOSE(RANDBETWEEN(1,5),2,2,2,3,1),IF(AJ8="Geliştirilmeli",CHOOSE(RANDBETWEEN(1,5),1,1,1,1,2),""))))) | I8: =IF(OR('Öğrenci Listesi'!B9="",AJ8=""),"",IF(AJ8="Çok İyi",CHOOSE(RANDBETWEEN(1,5),4,4,4,4,3),IF(AJ8="İyi",CHOOSE(RANDBETWEEN(1,5),3,3,3,4,2),IF(AJ8="Yeterli",CHOOSE(RANDBETWEEN(1,5),2,2,2,3,1),IF(AJ8="Geliştirilmeli",CHOOSE(RANDBETWEEN(1,5),1,1,1,1,2),""))))) | J8: =IF(OR('Öğrenci Listesi'!B9="",AJ8=""),"",IF(AJ8="Çok İyi",CHOOSE(RANDBETWEEN(1,5),4,4,4,4,3),IF(AJ8="İyi",CHOOSE(RANDBETWEEN(1,5),3,3,3,4,2),IF(AJ8="Yeterli",CHOOSE(RANDBETWEEN(1,5),2,2,2,3,1),IF(AJ8="Geliştirilmeli",CHOOSE(RANDBETWEEN(1,5),1,1,1,1,2),""))))) | K8: =IF(OR('Öğrenci Listesi'!B9="",AJ8=""),"",IF(AJ8="Çok İyi",CHOOSE(RANDBETWEEN(1,5),4,4,4,4,3),IF(AJ8="İyi",CHOOSE(RANDBETWEEN(1,5),3,3,3,4,2),IF(AJ8="Yeterli",CHOOSE(RANDBETWEEN(1,5),2,2,2,3,1),IF(AJ8="Geliştirilmeli",CHOOSE(RANDBETWEEN(1,5),1,1,1,1,2),""))))) | L8: =IF(OR('Öğrenci Listesi'!B9="",AJ8=""),"",IF(AJ8="Çok İyi",CHOOSE(RANDBETWEEN(1,5),4,4,4,4,3),IF(AJ8="İyi",CHOOSE(RANDBETWEEN(1,5),3,3,3,4,2),IF(AJ8="Yeterli",CHOOSE(RANDBETWEEN(1,5),2,2,2,3,1),IF(AJ8="Geliştirilmeli",CHOOSE(RANDBETWEEN(1,5),1,1,1,1,2),""))))) | M8: =IF(OR('Öğrenci Listesi'!B9="",AJ8=""),"",IF(AJ8="Çok İyi",CHOOSE(RANDBETWEEN(1,5),4,4,4,4,3),IF(AJ8="İyi",CHOOSE(RANDBETWEEN(1,5),3,3,3,4,2),IF(AJ8="Yeterli",CHOOSE(RANDBETWEEN(1,5),2,2,2,3,1),IF(AJ8="Geliştirilmeli",CHOOSE(RANDBETWEEN(1,5),1,1,1,1,2),""))))) | N8: =IF(OR('Öğrenci Listesi'!B9="",AJ8=""),"",IF(AJ8="Çok İyi",CHOOSE(RANDBETWEEN(1,5),4,4,4,4,3),IF(AJ8="İyi",CHOOSE(RANDBETWEEN(1,5),3,3,3,4,2),IF(AJ8="Yeterli",CHOOSE(RANDBETWEEN(1,5),2,2,2,3,1),IF(AJ8="Geliştirilmeli",CHOOSE(RANDBETWEEN(1,5),1,1,1,1,2),""))))) | O8: =IF(OR('Öğrenci Listesi'!B9="",AJ8=""),"",IF(AJ8="Çok İyi",CHOOSE(RANDBETWEEN(1,5),4,4,4,4,3),IF(AJ8="İyi",CHOOSE(RANDBETWEEN(1,5),3,3,3,4,2),IF(AJ8="Yeterli",CHOOSE(RANDBETWEEN(1,5),2,2,2,3,1),IF(AJ8="Geliştirilmeli",CHOOSE(RANDBETWEEN(1,5),1,1,1,1,2),""))))) | P8: =IF(OR('Öğrenci Listesi'!B9="",AJ8=""),"",IF(AJ8="Çok İyi",CHOOSE(RANDBETWEEN(1,5),4,4,4,4,3),IF(AJ8="İyi",CHOOSE(RANDBETWEEN(1,5),3,3,3,4,2),IF(AJ8="Yeterli",CHOOSE(RANDBETWEEN(1,5),2,2,2,3,1),IF(AJ8="Geliştirilmeli",CHOOSE(RANDBETWEEN(1,5),1,1,1,1,2),""))))) | Q8: =IF(OR('Öğrenci Listesi'!B9="",AJ8=""),"",IF(AJ8="Çok İyi",CHOOSE(RANDBETWEEN(1,5),4,4,4,4,3),IF(AJ8="İyi",CHOOSE(RANDBETWEEN(1,5),3,3,3,4,2),IF(AJ8="Yeterli",CHOOSE(RANDBETWEEN(1,5),2,2,2,3,1),IF(AJ8="Geliştirilmeli",CHOOSE(RANDBETWEEN(1,5),1,1,1,1,2),""))))) | R8: =IF(OR('Öğrenci Listesi'!B9="",AJ8=""),"",IF(AJ8="Çok İyi",CHOOSE(RANDBETWEEN(1,5),4,4,4,4,3),IF(AJ8="İyi",CHOOSE(RANDBETWEEN(1,5),3,3,3,4,2),IF(AJ8="Yeterli",CHOOSE(RANDBETWEEN(1,5),2,2,2,3,1),IF(AJ8="Geliştirilmeli",CHOOSE(RANDBETWEEN(1,5),1,1,1,1,2),""))))) | S8: =IF(OR('Öğrenci Listesi'!B9="",AJ8=""),"",IF(AJ8="Çok İyi",CHOOSE(RANDBETWEEN(1,5),4,4,4,4,3),IF(AJ8="İyi",CHOOSE(RANDBETWEEN(1,5),3,3,3,4,2),IF(AJ8="Yeterli",CHOOSE(RANDBETWEEN(1,5),2,2,2,3,1),IF(AJ8="Geliştirilmeli",CHOOSE(RANDBETWEEN(1,5),1,1,1,1,2),""))))) | T8: =IF(OR('Öğrenci Listesi'!B9="",AJ8=""),"",IF(AJ8="Çok İyi",CHOOSE(RANDBETWEEN(1,5),4,4,4,4,3),IF(AJ8="İyi",CHOOSE(RANDBETWEEN(1,5),3,3,3,4,2),IF(AJ8="Yeterli",CHOOSE(RANDBETWEEN(1,5),2,2,2,3,1),IF(AJ8="Geliştirilmeli",CHOOSE(RANDBETWEEN(1,5),1,1,1,1,2),""))))) | U8: =IF(OR('Öğrenci Listesi'!B9="",AJ8=""),"",IF(AJ8="Çok İyi",CHOOSE(RANDBETWEEN(1,5),4,4,4,4,3),IF(AJ8="İyi",CHOOSE(RANDBETWEEN(1,5),3,3,3,4,2),IF(AJ8="Yeterli",CHOOSE(RANDBETWEEN(1,5),2,2,2,3,1),IF(AJ8="Geliştirilmeli",CHOOSE(RANDBETWEEN(1,5),1,1,1,1,2),""))))) | V8: =IF(OR('Öğrenci Listesi'!B9="",AJ8=""),"",IF(AJ8="Çok İyi",CHOOSE(RANDBETWEEN(1,5),4,4,4,4,3),IF(AJ8="İyi",CHOOSE(RANDBETWEEN(1,5),3,3,3,4,2),IF(AJ8="Yeterli",CHOOSE(RANDBETWEEN(1,5),2,2,2,3,1),IF(AJ8="Geliştirilmeli",CHOOSE(RANDBETWEEN(1,5),1,1,1,1,2),""))))) | W8: =IF(OR('Öğrenci Listesi'!B9="",AJ8=""),"",IF(AJ8="Çok İyi",CHOOSE(RANDBETWEEN(1,5),4,4,4,4,3),IF(AJ8="İyi",CHOOSE(RANDBETWEEN(1,5),3,3,3,4,2),IF(AJ8="Yeterli",CHOOSE(RANDBETWEEN(1,5),2,2,2,3,1),IF(AJ8="Geliştirilmeli",CHOOSE(RANDBETWEEN(1,5),1,1,1,1,2),""))))) | X8: =IF(OR('Öğrenci Listesi'!B9="",AJ8=""),"",IF(AJ8="Çok İyi",CHOOSE(RANDBETWEEN(1,5),4,4,4,4,3),IF(AJ8="İyi",CHOOSE(RANDBETWEEN(1,5),3,3,3,4,2),IF(AJ8="Yeterli",CHOOSE(RANDBETWEEN(1,5),2,2,2,3,1),IF(AJ8="Geliştirilmeli",CHOOSE(RANDBETWEEN(1,5),1,1,1,1,2),""))))) | Y8: =IF(OR('Öğrenci Listesi'!B9="",AJ8=""),"",IF(AJ8="Çok İyi",CHOOSE(RANDBETWEEN(1,5),4,4,4,4,3),IF(AJ8="İyi",CHOOSE(RANDBETWEEN(1,5),3,3,3,4,2),IF(AJ8="Yeterli",CHOOSE(RANDBETWEEN(1,5),2,2,2,3,1),IF(AJ8="Geliştirilmeli",CHOOSE(RANDBETWEEN(1,5),1,1,1,1,2),""))))) | Z8: =IF(OR('Öğrenci Listesi'!B9="",AJ8=""),"",IF(AJ8="Çok İyi",CHOOSE(RANDBETWEEN(1,5),4,4,4,4,3),IF(AJ8="İyi",CHOOSE(RANDBETWEEN(1,5),3,3,3,4,2),IF(AJ8="Yeterli",CHOOSE(RANDBETWEEN(1,5),2,2,2,3,1),IF(AJ8="Geliştirilmeli",CHOOSE(RANDBETWEEN(1,5),1,1,1,1,2),""))))) | AA8: =IF(OR('Öğrenci Listesi'!B9="",AJ8=""),"",IF(AJ8="Çok İyi",CHOOSE(RANDBETWEEN(1,5),4,4,4,4,3),IF(AJ8="İyi",CHOOSE(RANDBETWEEN(1,5),3,3,3,4,2),IF(AJ8="Yeterli",CHOOSE(RANDBETWEEN(1,5),2,2,2,3,1),IF(AJ8="Geliştirilmeli",CHOOSE(RANDBETWEEN(1,5),1,1,1,1,2),""))))) | AB8: =IF(OR('Öğrenci Listesi'!B9="",AJ8=""),"",IF(AJ8="Çok İyi",CHOOSE(RANDBETWEEN(1,5),4,4,4,4,3),IF(AJ8="İyi",CHOOSE(RANDBETWEEN(1,5),3,3,3,4,2),IF(AJ8="Yeterli",CHOOSE(RANDBETWEEN(1,5),2,2,2,3,1),IF(AJ8="Geliştirilmeli",CHOOSE(RANDBETWEEN(1,5),1,1,1,1,2),""))))) | AC8: =IF(OR('Öğrenci Listesi'!B9="",AJ8=""),"",IF(AJ8="Çok İyi",CHOOSE(RANDBETWEEN(1,5),4,4,4,4,3),IF(AJ8="İyi",CHOOSE(RANDBETWEEN(1,5),3,3,3,4,2),IF(AJ8="Yeterli",CHOOSE(RANDBETWEEN(1,5),2,2,2,3,1),IF(AJ8="Geliştirilmeli",CHOOSE(RANDBETWEEN(1,5),1,1,1,1,2),""))))) | AD8: =IF(OR('Öğrenci Listesi'!B9="",AJ8=""),"",IF(AJ8="Çok İyi",CHOOSE(RANDBETWEEN(1,5),4,4,4,4,3),IF(AJ8="İyi",CHOOSE(RANDBETWEEN(1,5),3,3,3,4,2),IF(AJ8="Yeterli",CHOOSE(RANDBETWEEN(1,5),2,2,2,3,1),IF(AJ8="Geliştirilmeli",CHOOSE(RANDBETWEEN(1,5),1,1,1,1,2),""))))) | AE8: =IF(OR('Öğrenci Listesi'!B9="",AJ8=""),"",IF(AJ8="Çok İyi",CHOOSE(RANDBETWEEN(1,5),4,4,4,4,3),IF(AJ8="İyi",CHOOSE(RANDBETWEEN(1,5),3,3,3,4,2),IF(AJ8="Yeterli",CHOOSE(RANDBETWEEN(1,5),2,2,2,3,1),IF(AJ8="Geliştirilmeli",CHOOSE(RANDBETWEEN(1,5),1,1,1,1,2),""))))) | AF8: =IF(OR('Öğrenci Listesi'!B9="",AJ8=""),"",IF(AJ8="Çok İyi",CHOOSE(RANDBETWEEN(1,5),4,4,4,4,3),IF(AJ8="İyi",CHOOSE(RANDBETWEEN(1,5),3,3,3,4,2),IF(AJ8="Yeterli",CHOOSE(RANDBETWEEN(1,5),2,2,2,3,1),IF(AJ8="Geliştirilmeli",CHOOSE(RANDBETWEEN(1,5),1,1,1,1,2),""))))) | AG8: =IF(OR('Öğrenci Listesi'!B9="",AJ8=""),"",IF(AJ8="Çok İyi",CHOOSE(RANDBETWEEN(1,5),4,4,4,4,3),IF(AJ8="İyi",CHOOSE(RANDBETWEEN(1,5),3,3,3,4,2),IF(AJ8="Yeterli",CHOOSE(RANDBETWEEN(1,5),2,2,2,3,1),IF(AJ8="Geliştirilmeli",CHOOSE(RANDBETWEEN(1,5),1,1,1,1,2),""))))) | AH8: =IF(OR('Öğrenci Listesi'!B9="",AJ8=""),"",IF(AJ8="Çok İyi",CHOOSE(RANDBETWEEN(1,5),4,4,4,4,3),IF(AJ8="İyi",CHOOSE(RANDBETWEEN(1,5),3,3,3,4,2),IF(AJ8="Yeterli",CHOOSE(RANDBETWEEN(1,5),2,2,2,3,1),IF(AJ8="Geliştirilmeli",CHOOSE(RANDBETWEEN(1,5),1,1,1,1,2),""))))) | AI8: =IF(OR('Öğrenci Listesi'!B9="",AJ8=""),"",ROUND(AVERAGE(C8:AH8),2)) | AJ8: =IFERROR(IF('Öğrenci Listesi'!G9="","",IF(UPPER(TRIM('Öğrenci Listesi'!G9))="ÇOK İYİ","Çok İyi",IF(UPPER(TRIM('Öğrenci Listesi'!G9))="İYİ","İyi",IF(UPPER(TRIM('Öğrenci Listesi'!G9))="YETERLİ","Yeterli",IF(UPPER(TRIM('Öğrenci Listesi'!G9))="GELİŞTİRİLMELİ","Geliştirilmeli",'Öğrenci Listesi'!G9))))),"")
A9: =IFERROR(IF('Öğrenci Listesi'!A10="","",'Öğrenci Listesi'!A10),"") | B9: =IFERROR(IF('Öğrenci Listesi'!B10="","",'Öğrenci Listesi'!B10),"") | C9: =IF(OR('Öğrenci Listesi'!B10="",AJ9=""),"",IF(AJ9="Çok İyi",CHOOSE(RANDBETWEEN(1,5),4,4,4,4,3),IF(AJ9="İyi",CHOOSE(RANDBETWEEN(1,5),3,3,3,4,2),IF(AJ9="Yeterli",CHOOSE(RANDBETWEEN(1,5),2,2,2,3,1),IF(AJ9="Geliştirilmeli",CHOOSE(RANDBETWEEN(1,5),1,1,1,1,2),""))))) | D9: =IF(OR('Öğrenci Listesi'!B10="",AJ9=""),"",IF(AJ9="Çok İyi",CHOOSE(RANDBETWEEN(1,5),4,4,4,4,3),IF(AJ9="İyi",CHOOSE(RANDBETWEEN(1,5),3,3,3,4,2),IF(AJ9="Yeterli",CHOOSE(RANDBETWEEN(1,5),2,2,2,3,1),IF(AJ9="Geliştirilmeli",CHOOSE(RANDBETWEEN(1,5),1,1,1,1,2),""))))) | E9: =IF(OR('Öğrenci Listesi'!B10="",AJ9=""),"",IF(AJ9="Çok İyi",CHOOSE(RANDBETWEEN(1,5),4,4,4,4,3),IF(AJ9="İyi",CHOOSE(RANDBETWEEN(1,5),3,3,3,4,2),IF(AJ9="Yeterli",CHOOSE(RANDBETWEEN(1,5),2,2,2,3,1),IF(AJ9="Geliştirilmeli",CHOOSE(RANDBETWEEN(1,5),1,1,1,1,2),""))))) | F9: =IF(OR('Öğrenci Listesi'!B10="",AJ9=""),"",IF(AJ9="Çok İyi",CHOOSE(RANDBETWEEN(1,5),4,4,4,4,3),IF(AJ9="İyi",CHOOSE(RANDBETWEEN(1,5),3,3,3,4,2),IF(AJ9="Yeterli",CHOOSE(RANDBETWEEN(1,5),2,2,2,3,1),IF(AJ9="Geliştirilmeli",CHOOSE(RANDBETWEEN(1,5),1,1,1,1,2),""))))) | G9: =IF(OR('Öğrenci Listesi'!B10="",AJ9=""),"",IF(AJ9="Çok İyi",CHOOSE(RANDBETWEEN(1,5),4,4,4,4,3),IF(AJ9="İyi",CHOOSE(RANDBETWEEN(1,5),3,3,3,4,2),IF(AJ9="Yeterli",CHOOSE(RANDBETWEEN(1,5),2,2,2,3,1),IF(AJ9="Geliştirilmeli",CHOOSE(RANDBETWEEN(1,5),1,1,1,1,2),""))))) | H9: =IF(OR('Öğrenci Listesi'!B10="",AJ9=""),"",IF(AJ9="Çok İyi",CHOOSE(RANDBETWEEN(1,5),4,4,4,4,3),IF(AJ9="İyi",CHOOSE(RANDBETWEEN(1,5),3,3,3,4,2),IF(AJ9="Yeterli",CHOOSE(RANDBETWEEN(1,5),2,2,2,3,1),IF(AJ9="Geliştirilmeli",CHOOSE(RANDBETWEEN(1,5),1,1,1,1,2),""))))) | I9: =IF(OR('Öğrenci Listesi'!B10="",AJ9=""),"",IF(AJ9="Çok İyi",CHOOSE(RANDBETWEEN(1,5),4,4,4,4,3),IF(AJ9="İyi",CHOOSE(RANDBETWEEN(1,5),3,3,3,4,2),IF(AJ9="Yeterli",CHOOSE(RANDBETWEEN(1,5),2,2,2,3,1),IF(AJ9="Geliştirilmeli",CHOOSE(RANDBETWEEN(1,5),1,1,1,1,2),""))))) | J9: =IF(OR('Öğrenci Listesi'!B10="",AJ9=""),"",IF(AJ9="Çok İyi",CHOOSE(RANDBETWEEN(1,5),4,4,4,4,3),IF(AJ9="İyi",CHOOSE(RANDBETWEEN(1,5),3,3,3,4,2),IF(AJ9="Yeterli",CHOOSE(RANDBETWEEN(1,5),2,2,2,3,1),IF(AJ9="Geliştirilmeli",CHOOSE(RANDBETWEEN(1,5),1,1,1,1,2),""))))) | K9: =IF(OR('Öğrenci Listesi'!B10="",AJ9=""),"",IF(AJ9="Çok İyi",CHOOSE(RANDBETWEEN(1,5),4,4,4,4,3),IF(AJ9="İyi",CHOOSE(RANDBETWEEN(1,5),3,3,3,4,2),IF(AJ9="Yeterli",CHOOSE(RANDBETWEEN(1,5),2,2,2,3,1),IF(AJ9="Geliştirilmeli",CHOOSE(RANDBETWEEN(1,5),1,1,1,1,2),""))))) | L9: =IF(OR('Öğrenci Listesi'!B10="",AJ9=""),"",IF(AJ9="Çok İyi",CHOOSE(RANDBETWEEN(1,5),4,4,4,4,3),IF(AJ9="İyi",CHOOSE(RANDBETWEEN(1,5),3,3,3,4,2),IF(AJ9="Yeterli",CHOOSE(RANDBETWEEN(1,5),2,2,2,3,1),IF(AJ9="Geliştirilmeli",CHOOSE(RANDBETWEEN(1,5),1,1,1,1,2),""))))) | M9: =IF(OR('Öğrenci Listesi'!B10="",AJ9=""),"",IF(AJ9="Çok İyi",CHOOSE(RANDBETWEEN(1,5),4,4,4,4,3),IF(AJ9="İyi",CHOOSE(RANDBETWEEN(1,5),3,3,3,4,2),IF(AJ9="Yeterli",CHOOSE(RANDBETWEEN(1,5),2,2,2,3,1),IF(AJ9="Geliştirilmeli",CHOOSE(RANDBETWEEN(1,5),1,1,1,1,2),""))))) | N9: =IF(OR('Öğrenci Listesi'!B10="",AJ9=""),"",IF(AJ9="Çok İyi",CHOOSE(RANDBETWEEN(1,5),4,4,4,4,3),IF(AJ9="İyi",CHOOSE(RANDBETWEEN(1,5),3,3,3,4,2),IF(AJ9="Yeterli",CHOOSE(RANDBETWEEN(1,5),2,2,2,3,1),IF(AJ9="Geliştirilmeli",CHOOSE(RANDBETWEEN(1,5),1,1,1,1,2),""))))) | O9: =IF(OR('Öğrenci Listesi'!B10="",AJ9=""),"",IF(AJ9="Çok İyi",CHOOSE(RANDBETWEEN(1,5),4,4,4,4,3),IF(AJ9="İyi",CHOOSE(RANDBETWEEN(1,5),3,3,3,4,2),IF(AJ9="Yeterli",CHOOSE(RANDBETWEEN(1,5),2,2,2,3,1),IF(AJ9="Geliştirilmeli",CHOOSE(RANDBETWEEN(1,5),1,1,1,1,2),""))))) | P9: =IF(OR('Öğrenci Listesi'!B10="",AJ9=""),"",IF(AJ9="Çok İyi",CHOOSE(RANDBETWEEN(1,5),4,4,4,4,3),IF(AJ9="İyi",CHOOSE(RANDBETWEEN(1,5),3,3,3,4,2),IF(AJ9="Yeterli",CHOOSE(RANDBETWEEN(1,5),2,2,2,3,1),IF(AJ9="Geliştirilmeli",CHOOSE(RANDBETWEEN(1,5),1,1,1,1,2),""))))) | Q9: =IF(OR('Öğrenci Listesi'!B10="",AJ9=""),"",IF(AJ9="Çok İyi",CHOOSE(RANDBETWEEN(1,5),4,4,4,4,3),IF(AJ9="İyi",CHOOSE(RANDBETWEEN(1,5),3,3,3,4,2),IF(AJ9="Yeterli",CHOOSE(RANDBETWEEN(1,5),2,2,2,3,1),IF(AJ9="Geliştirilmeli",CHOOSE(RANDBETWEEN(1,5),1,1,1,1,2),""))))) | R9: =IF(OR('Öğrenci Listesi'!B10="",AJ9=""),"",IF(AJ9="Çok İyi",CHOOSE(RANDBETWEEN(1,5),4,4,4,4,3),IF(AJ9="İyi",CHOOSE(RANDBETWEEN(1,5),3,3,3,4,2),IF(AJ9="Yeterli",CHOOSE(RANDBETWEEN(1,5),2,2,2,3,1),IF(AJ9="Geliştirilmeli",CHOOSE(RANDBETWEEN(1,5),1,1,1,1,2),""))))) | S9: =IF(OR('Öğrenci Listesi'!B10="",AJ9=""),"",IF(AJ9="Çok İyi",CHOOSE(RANDBETWEEN(1,5),4,4,4,4,3),IF(AJ9="İyi",CHOOSE(RANDBETWEEN(1,5),3,3,3,4,2),IF(AJ9="Yeterli",CHOOSE(RANDBETWEEN(1,5),2,2,2,3,1),IF(AJ9="Geliştirilmeli",CHOOSE(RANDBETWEEN(1,5),1,1,1,1,2),""))))) | T9: =IF(OR('Öğrenci Listesi'!B10="",AJ9=""),"",IF(AJ9="Çok İyi",CHOOSE(RANDBETWEEN(1,5),4,4,4,4,3),IF(AJ9="İyi",CHOOSE(RANDBETWEEN(1,5),3,3,3,4,2),IF(AJ9="Yeterli",CHOOSE(RANDBETWEEN(1,5),2,2,2,3,1),IF(AJ9="Geliştirilmeli",CHOOSE(RANDBETWEEN(1,5),1,1,1,1,2),""))))) | U9: =IF(OR('Öğrenci Listesi'!B10="",AJ9=""),"",IF(AJ9="Çok İyi",CHOOSE(RANDBETWEEN(1,5),4,4,4,4,3),IF(AJ9="İyi",CHOOSE(RANDBETWEEN(1,5),3,3,3,4,2),IF(AJ9="Yeterli",CHOOSE(RANDBETWEEN(1,5),2,2,2,3,1),IF(AJ9="Geliştirilmeli",CHOOSE(RANDBETWEEN(1,5),1,1,1,1,2),""))))) | V9: =IF(OR('Öğrenci Listesi'!B10="",AJ9=""),"",IF(AJ9="Çok İyi",CHOOSE(RANDBETWEEN(1,5),4,4,4,4,3),IF(AJ9="İyi",CHOOSE(RANDBETWEEN(1,5),3,3,3,4,2),IF(AJ9="Yeterli",CHOOSE(RANDBETWEEN(1,5),2,2,2,3,1),IF(AJ9="Geliştirilmeli",CHOOSE(RANDBETWEEN(1,5),1,1,1,1,2),""))))) | W9: =IF(OR('Öğrenci Listesi'!B10="",AJ9=""),"",IF(AJ9="Çok İyi",CHOOSE(RANDBETWEEN(1,5),4,4,4,4,3),IF(AJ9="İyi",CHOOSE(RANDBETWEEN(1,5),3,3,3,4,2),IF(AJ9="Yeterli",CHOOSE(RANDBETWEEN(1,5),2,2,2,3,1),IF(AJ9="Geliştirilmeli",CHOOSE(RANDBETWEEN(1,5),1,1,1,1,2),""))))) | X9: =IF(OR('Öğrenci Listesi'!B10="",AJ9=""),"",IF(AJ9="Çok İyi",CHOOSE(RANDBETWEEN(1,5),4,4,4,4,3),IF(AJ9="İyi",CHOOSE(RANDBETWEEN(1,5),3,3,3,4,2),IF(AJ9="Yeterli",CHOOSE(RANDBETWEEN(1,5),2,2,2,3,1),IF(AJ9="Geliştirilmeli",CHOOSE(RANDBETWEEN(1,5),1,1,1,1,2),""))))) | Y9: =IF(OR('Öğrenci Listesi'!B10="",AJ9=""),"",IF(AJ9="Çok İyi",CHOOSE(RANDBETWEEN(1,5),4,4,4,4,3),IF(AJ9="İyi",CHOOSE(RANDBETWEEN(1,5),3,3,3,4,2),IF(AJ9="Yeterli",CHOOSE(RANDBETWEEN(1,5),2,2,2,3,1),IF(AJ9="Geliştirilmeli",CHOOSE(RANDBETWEEN(1,5),1,1,1,1,2),""))))) | Z9: =IF(OR('Öğrenci Listesi'!B10="",AJ9=""),"",IF(AJ9="Çok İyi",CHOOSE(RANDBETWEEN(1,5),4,4,4,4,3),IF(AJ9="İyi",CHOOSE(RANDBETWEEN(1,5),3,3,3,4,2),IF(AJ9="Yeterli",CHOOSE(RANDBETWEEN(1,5),2,2,2,3,1),IF(AJ9="Geliştirilmeli",CHOOSE(RANDBETWEEN(1,5),1,1,1,1,2),""))))) | AA9: =IF(OR('Öğrenci Listesi'!B10="",AJ9=""),"",IF(AJ9="Çok İyi",CHOOSE(RANDBETWEEN(1,5),4,4,4,4,3),IF(AJ9="İyi",CHOOSE(RANDBETWEEN(1,5),3,3,3,4,2),IF(AJ9="Yeterli",CHOOSE(RANDBETWEEN(1,5),2,2,2,3,1),IF(AJ9="Geliştirilmeli",CHOOSE(RANDBETWEEN(1,5),1,1,1,1,2),""))))) | AB9: =IF(OR('Öğrenci Listesi'!B10="",AJ9=""),"",IF(AJ9="Çok İyi",CHOOSE(RANDBETWEEN(1,5),4,4,4,4,3),IF(AJ9="İyi",CHOOSE(RANDBETWEEN(1,5),3,3,3,4,2),IF(AJ9="Yeterli",CHOOSE(RANDBETWEEN(1,5),2,2,2,3,1),IF(AJ9="Geliştirilmeli",CHOOSE(RANDBETWEEN(1,5),1,1,1,1,2),""))))) | AC9: =IF(OR('Öğrenci Listesi'!B10="",AJ9=""),"",IF(AJ9="Çok İyi",CHOOSE(RANDBETWEEN(1,5),4,4,4,4,3),IF(AJ9="İyi",CHOOSE(RANDBETWEEN(1,5),3,3,3,4,2),IF(AJ9="Yeterli",CHOOSE(RANDBETWEEN(1,5),2,2,2,3,1),IF(AJ9="Geliştirilmeli",CHOOSE(RANDBETWEEN(1,5),1,1,1,1,2),""))))) | AD9: =IF(OR('Öğrenci Listesi'!B10="",AJ9=""),"",IF(AJ9="Çok İyi",CHOOSE(RANDBETWEEN(1,5),4,4,4,4,3),IF(AJ9="İyi",CHOOSE(RANDBETWEEN(1,5),3,3,3,4,2),IF(AJ9="Yeterli",CHOOSE(RANDBETWEEN(1,5),2,2,2,3,1),IF(AJ9="Geliştirilmeli",CHOOSE(RANDBETWEEN(1,5),1,1,1,1,2),""))))) | AE9: =IF(OR('Öğrenci Listesi'!B10="",AJ9=""),"",IF(AJ9="Çok İyi",CHOOSE(RANDBETWEEN(1,5),4,4,4,4,3),IF(AJ9="İyi",CHOOSE(RANDBETWEEN(1,5),3,3,3,4,2),IF(AJ9="Yeterli",CHOOSE(RANDBETWEEN(1,5),2,2,2,3,1),IF(AJ9="Geliştirilmeli",CHOOSE(RANDBETWEEN(1,5),1,1,1,1,2),""))))) | AF9: =IF(OR('Öğrenci Listesi'!B10="",AJ9=""),"",IF(AJ9="Çok İyi",CHOOSE(RANDBETWEEN(1,5),4,4,4,4,3),IF(AJ9="İyi",CHOOSE(RANDBETWEEN(1,5),3,3,3,4,2),IF(AJ9="Yeterli",CHOOSE(RANDBETWEEN(1,5),2,2,2,3,1),IF(AJ9="Geliştirilmeli",CHOOSE(RANDBETWEEN(1,5),1,1,1,1,2),""))))) | AG9: =IF(OR('Öğrenci Listesi'!B10="",AJ9=""),"",IF(AJ9="Çok İyi",CHOOSE(RANDBETWEEN(1,5),4,4,4,4,3),IF(AJ9="İyi",CHOOSE(RANDBETWEEN(1,5),3,3,3,4,2),IF(AJ9="Yeterli",CHOOSE(RANDBETWEEN(1,5),2,2,2,3,1),IF(AJ9="Geliştirilmeli",CHOOSE(RANDBETWEEN(1,5),1,1,1,1,2),""))))) | AH9: =IF(OR('Öğrenci Listesi'!B10="",AJ9=""),"",IF(AJ9="Çok İyi",CHOOSE(RANDBETWEEN(1,5),4,4,4,4,3),IF(AJ9="İyi",CHOOSE(RANDBETWEEN(1,5),3,3,3,4,2),IF(AJ9="Yeterli",CHOOSE(RANDBETWEEN(1,5),2,2,2,3,1),IF(AJ9="Geliştirilmeli",CHOOSE(RANDBETWEEN(1,5),1,1,1,1,2),""))))) | AI9: =IF(OR('Öğrenci Listesi'!B10="",AJ9=""),"",ROUND(AVERAGE(C9:AH9),2)) | AJ9: =IFERROR(IF('Öğrenci Listesi'!G10="","",IF(UPPER(TRIM('Öğrenci Listesi'!G10))="ÇOK İYİ","Çok İyi",IF(UPPER(TRIM('Öğrenci Listesi'!G10))="İYİ","İyi",IF(UPPER(TRIM('Öğrenci Listesi'!G10))="YETERLİ","Yeterli",IF(UPPER(TRIM('Öğrenci Listesi'!G10))="GELİŞTİRİLMELİ","Geliştirilmeli",'Öğrenci Listesi'!G10))))),"")
A10: =IFERROR(IF('Öğrenci Listesi'!A11="","",'Öğrenci Listesi'!A11),"") | B10: =IFERROR(IF('Öğrenci Listesi'!B11="","",'Öğrenci Listesi'!B11),"") | C10: =IF(OR('Öğrenci Listesi'!B11="",AJ10=""),"",IF(AJ10="Çok İyi",CHOOSE(RANDBETWEEN(1,5),4,4,4,4,3),IF(AJ10="İyi",CHOOSE(RANDBETWEEN(1,5),3,3,3,4,2),IF(AJ10="Yeterli",CHOOSE(RANDBETWEEN(1,5),2,2,2,3,1),IF(AJ10="Geliştirilmeli",CHOOSE(RANDBETWEEN(1,5),1,1,1,1,2),""))))) | D10: =IF(OR('Öğrenci Listesi'!B11="",AJ10=""),"",IF(AJ10="Çok İyi",CHOOSE(RANDBETWEEN(1,5),4,4,4,4,3),IF(AJ10="İyi",CHOOSE(RANDBETWEEN(1,5),3,3,3,4,2),IF(AJ10="Yeterli",CHOOSE(RANDBETWEEN(1,5),2,2,2,3,1),IF(AJ10="Geliştirilmeli",CHOOSE(RANDBETWEEN(1,5),1,1,1,1,2),""))))) | E10: =IF(OR('Öğrenci Listesi'!B11="",AJ10=""),"",IF(AJ10="Çok İyi",CHOOSE(RANDBETWEEN(1,5),4,4,4,4,3),IF(AJ10="İyi",CHOOSE(RANDBETWEEN(1,5),3,3,3,4,2),IF(AJ10="Yeterli",CHOOSE(RANDBETWEEN(1,5),2,2,2,3,1),IF(AJ10="Geliştirilmeli",CHOOSE(RANDBETWEEN(1,5),1,1,1,1,2),""))))) | F10: =IF(OR('Öğrenci Listesi'!B11="",AJ10=""),"",IF(AJ10="Çok İyi",CHOOSE(RANDBETWEEN(1,5),4,4,4,4,3),IF(AJ10="İyi",CHOOSE(RANDBETWEEN(1,5),3,3,3,4,2),IF(AJ10="Yeterli",CHOOSE(RANDBETWEEN(1,5),2,2,2,3,1),IF(AJ10="Geliştirilmeli",CHOOSE(RANDBETWEEN(1,5),1,1,1,1,2),""))))) | G10: =IF(OR('Öğrenci Listesi'!B11="",AJ10=""),"",IF(AJ10="Çok İyi",CHOOSE(RANDBETWEEN(1,5),4,4,4,4,3),IF(AJ10="İyi",CHOOSE(RANDBETWEEN(1,5),3,3,3,4,2),IF(AJ10="Yeterli",CHOOSE(RANDBETWEEN(1,5),2,2,2,3,1),IF(AJ10="Geliştirilmeli",CHOOSE(RANDBETWEEN(1,5),1,1,1,1,2),""))))) | H10: =IF(OR('Öğrenci Listesi'!B11="",AJ10=""),"",IF(AJ10="Çok İyi",CHOOSE(RANDBETWEEN(1,5),4,4,4,4,3),IF(AJ10="İyi",CHOOSE(RANDBETWEEN(1,5),3,3,3,4,2),IF(AJ10="Yeterli",CHOOSE(RANDBETWEEN(1,5),2,2,2,3,1),IF(AJ10="Geliştirilmeli",CHOOSE(RANDBETWEEN(1,5),1,1,1,1,2),""))))) | I10: =IF(OR('Öğrenci Listesi'!B11="",AJ10=""),"",IF(AJ10="Çok İyi",CHOOSE(RANDBETWEEN(1,5),4,4,4,4,3),IF(AJ10="İyi",CHOOSE(RANDBETWEEN(1,5),3,3,3,4,2),IF(AJ10="Yeterli",CHOOSE(RANDBETWEEN(1,5),2,2,2,3,1),IF(AJ10="Geliştirilmeli",CHOOSE(RANDBETWEEN(1,5),1,1,1,1,2),""))))) | J10: =IF(OR('Öğrenci Listesi'!B11="",AJ10=""),"",IF(AJ10="Çok İyi",CHOOSE(RANDBETWEEN(1,5),4,4,4,4,3),IF(AJ10="İyi",CHOOSE(RANDBETWEEN(1,5),3,3,3,4,2),IF(AJ10="Yeterli",CHOOSE(RANDBETWEEN(1,5),2,2,2,3,1),IF(AJ10="Geliştirilmeli",CHOOSE(RANDBETWEEN(1,5),1,1,1,1,2),""))))) | K10: =IF(OR('Öğrenci Listesi'!B11="",AJ10=""),"",IF(AJ10="Çok İyi",CHOOSE(RANDBETWEEN(1,5),4,4,4,4,3),IF(AJ10="İyi",CHOOSE(RANDBETWEEN(1,5),3,3,3,4,2),IF(AJ10="Yeterli",CHOOSE(RANDBETWEEN(1,5),2,2,2,3,1),IF(AJ10="Geliştirilmeli",CHOOSE(RANDBETWEEN(1,5),1,1,1,1,2),""))))) | L10: =IF(OR('Öğrenci Listesi'!B11="",AJ10=""),"",IF(AJ10="Çok İyi",CHOOSE(RANDBETWEEN(1,5),4,4,4,4,3),IF(AJ10="İyi",CHOOSE(RANDBETWEEN(1,5),3,3,3,4,2),IF(AJ10="Yeterli",CHOOSE(RANDBETWEEN(1,5),2,2,2,3,1),IF(AJ10="Geliştirilmeli",CHOOSE(RANDBETWEEN(1,5),1,1,1,1,2),""))))) | M10: =IF(OR('Öğrenci Listesi'!B11="",AJ10=""),"",IF(AJ10="Çok İyi",CHOOSE(RANDBETWEEN(1,5),4,4,4,4,3),IF(AJ10="İyi",CHOOSE(RANDBETWEEN(1,5),3,3,3,4,2),IF(AJ10="Yeterli",CHOOSE(RANDBETWEEN(1,5),2,2,2,3,1),IF(AJ10="Geliştirilmeli",CHOOSE(RANDBETWEEN(1,5),1,1,1,1,2),""))))) | N10: =IF(OR('Öğrenci Listesi'!B11="",AJ10=""),"",IF(AJ10="Çok İyi",CHOOSE(RANDBETWEEN(1,5),4,4,4,4,3),IF(AJ10="İyi",CHOOSE(RANDBETWEEN(1,5),3,3,3,4,2),IF(AJ10="Yeterli",CHOOSE(RANDBETWEEN(1,5),2,2,2,3,1),IF(AJ10="Geliştirilmeli",CHOOSE(RANDBETWEEN(1,5),1,1,1,1,2),""))))) | O10: =IF(OR('Öğrenci Listesi'!B11="",AJ10=""),"",IF(AJ10="Çok İyi",CHOOSE(RANDBETWEEN(1,5),4,4,4,4,3),IF(AJ10="İyi",CHOOSE(RANDBETWEEN(1,5),3,3,3,4,2),IF(AJ10="Yeterli",CHOOSE(RANDBETWEEN(1,5),2,2,2,3,1),IF(AJ10="Geliştirilmeli",CHOOSE(RANDBETWEEN(1,5),1,1,1,1,2),""))))) | P10: =IF(OR('Öğrenci Listesi'!B11="",AJ10=""),"",IF(AJ10="Çok İyi",CHOOSE(RANDBETWEEN(1,5),4,4,4,4,3),IF(AJ10="İyi",CHOOSE(RANDBETWEEN(1,5),3,3,3,4,2),IF(AJ10="Yeterli",CHOOSE(RANDBETWEEN(1,5),2,2,2,3,1),IF(AJ10="Geliştirilmeli",CHOOSE(RANDBETWEEN(1,5),1,1,1,1,2),""))))) | Q10: =IF(OR('Öğrenci Listesi'!B11="",AJ10=""),"",IF(AJ10="Çok İyi",CHOOSE(RANDBETWEEN(1,5),4,4,4,4,3),IF(AJ10="İyi",CHOOSE(RANDBETWEEN(1,5),3,3,3,4,2),IF(AJ10="Yeterli",CHOOSE(RANDBETWEEN(1,5),2,2,2,3,1),IF(AJ10="Geliştirilmeli",CHOOSE(RANDBETWEEN(1,5),1,1,1,1,2),""))))) | R10: =IF(OR('Öğrenci Listesi'!B11="",AJ10=""),"",IF(AJ10="Çok İyi",CHOOSE(RANDBETWEEN(1,5),4,4,4,4,3),IF(AJ10="İyi",CHOOSE(RANDBETWEEN(1,5),3,3,3,4,2),IF(AJ10="Yeterli",CHOOSE(RANDBETWEEN(1,5),2,2,2,3,1),IF(AJ10="Geliştirilmeli",CHOOSE(RANDBETWEEN(1,5),1,1,1,1,2),""))))) | S10: =IF(OR('Öğrenci Listesi'!B11="",AJ10=""),"",IF(AJ10="Çok İyi",CHOOSE(RANDBETWEEN(1,5),4,4,4,4,3),IF(AJ10="İyi",CHOOSE(RANDBETWEEN(1,5),3,3,3,4,2),IF(AJ10="Yeterli",CHOOSE(RANDBETWEEN(1,5),2,2,2,3,1),IF(AJ10="Geliştirilmeli",CHOOSE(RANDBETWEEN(1,5),1,1,1,1,2),""))))) | T10: =IF(OR('Öğrenci Listesi'!B11="",AJ10=""),"",IF(AJ10="Çok İyi",CHOOSE(RANDBETWEEN(1,5),4,4,4,4,3),IF(AJ10="İyi",CHOOSE(RANDBETWEEN(1,5),3,3,3,4,2),IF(AJ10="Yeterli",CHOOSE(RANDBETWEEN(1,5),2,2,2,3,1),IF(AJ10="Geliştirilmeli",CHOOSE(RANDBETWEEN(1,5),1,1,1,1,2),""))))) | U10: =IF(OR('Öğrenci Listesi'!B11="",AJ10=""),"",IF(AJ10="Çok İyi",CHOOSE(RANDBETWEEN(1,5),4,4,4,4,3),IF(AJ10="İyi",CHOOSE(RANDBETWEEN(1,5),3,3,3,4,2),IF(AJ10="Yeterli",CHOOSE(RANDBETWEEN(1,5),2,2,2,3,1),IF(AJ10="Geliştirilmeli",CHOOSE(RANDBETWEEN(1,5),1,1,1,1,2),""))))) | V10: =IF(OR('Öğrenci Listesi'!B11="",AJ10=""),"",IF(AJ10="Çok İyi",CHOOSE(RANDBETWEEN(1,5),4,4,4,4,3),IF(AJ10="İyi",CHOOSE(RANDBETWEEN(1,5),3,3,3,4,2),IF(AJ10="Yeterli",CHOOSE(RANDBETWEEN(1,5),2,2,2,3,1),IF(AJ10="Geliştirilmeli",CHOOSE(RANDBETWEEN(1,5),1,1,1,1,2),""))))) | W10: =IF(OR('Öğrenci Listesi'!B11="",AJ10=""),"",IF(AJ10="Çok İyi",CHOOSE(RANDBETWEEN(1,5),4,4,4,4,3),IF(AJ10="İyi",CHOOSE(RANDBETWEEN(1,5),3,3,3,4,2),IF(AJ10="Yeterli",CHOOSE(RANDBETWEEN(1,5),2,2,2,3,1),IF(AJ10="Geliştirilmeli",CHOOSE(RANDBETWEEN(1,5),1,1,1,1,2),""))))) | X10: =IF(OR('Öğrenci Listesi'!B11="",AJ10=""),"",IF(AJ10="Çok İyi",CHOOSE(RANDBETWEEN(1,5),4,4,4,4,3),IF(AJ10="İyi",CHOOSE(RANDBETWEEN(1,5),3,3,3,4,2),IF(AJ10="Yeterli",CHOOSE(RANDBETWEEN(1,5),2,2,2,3,1),IF(AJ10="Geliştirilmeli",CHOOSE(RANDBETWEEN(1,5),1,1,1,1,2),""))))) | Y10: =IF(OR('Öğrenci Listesi'!B11="",AJ10=""),"",IF(AJ10="Çok İyi",CHOOSE(RANDBETWEEN(1,5),4,4,4,4,3),IF(AJ10="İyi",CHOOSE(RANDBETWEEN(1,5),3,3,3,4,2),IF(AJ10="Yeterli",CHOOSE(RANDBETWEEN(1,5),2,2,2,3,1),IF(AJ10="Geliştirilmeli",CHOOSE(RANDBETWEEN(1,5),1,1,1,1,2),""))))) | Z10: =IF(OR('Öğrenci Listesi'!B11="",AJ10=""),"",IF(AJ10="Çok İyi",CHOOSE(RANDBETWEEN(1,5),4,4,4,4,3),IF(AJ10="İyi",CHOOSE(RANDBETWEEN(1,5),3,3,3,4,2),IF(AJ10="Yeterli",CHOOSE(RANDBETWEEN(1,5),2,2,2,3,1),IF(AJ10="Geliştirilmeli",CHOOSE(RANDBETWEEN(1,5),1,1,1,1,2),""))))) | AA10: =IF(OR('Öğrenci Listesi'!B11="",AJ10=""),"",IF(AJ10="Çok İyi",CHOOSE(RANDBETWEEN(1,5),4,4,4,4,3),IF(AJ10="İyi",CHOOSE(RANDBETWEEN(1,5),3,3,3,4,2),IF(AJ10="Yeterli",CHOOSE(RANDBETWEEN(1,5),2,2,2,3,1),IF(AJ10="Geliştirilmeli",CHOOSE(RANDBETWEEN(1,5),1,1,1,1,2),""))))) | AB10: =IF(OR('Öğrenci Listesi'!B11="",AJ10=""),"",IF(AJ10="Çok İyi",CHOOSE(RANDBETWEEN(1,5),4,4,4,4,3),IF(AJ10="İyi",CHOOSE(RANDBETWEEN(1,5),3,3,3,4,2),IF(AJ10="Yeterli",CHOOSE(RANDBETWEEN(1,5),2,2,2,3,1),IF(AJ10="Geliştirilmeli",CHOOSE(RANDBETWEEN(1,5),1,1,1,1,2),""))))) | AC10: =IF(OR('Öğrenci Listesi'!B11="",AJ10=""),"",IF(AJ10="Çok İyi",CHOOSE(RANDBETWEEN(1,5),4,4,4,4,3),IF(AJ10="İyi",CHOOSE(RANDBETWEEN(1,5),3,3,3,4,2),IF(AJ10="Yeterli",CHOOSE(RANDBETWEEN(1,5),2,2,2,3,1),IF(AJ10="Geliştirilmeli",CHOOSE(RANDBETWEEN(1,5),1,1,1,1,2),""))))) | AD10: =IF(OR('Öğrenci Listesi'!B11="",AJ10=""),"",IF(AJ10="Çok İyi",CHOOSE(RANDBETWEEN(1,5),4,4,4,4,3),IF(AJ10="İyi",CHOOSE(RANDBETWEEN(1,5),3,3,3,4,2),IF(AJ10="Yeterli",CHOOSE(RANDBETWEEN(1,5),2,2,2,3,1),IF(AJ10="Geliştirilmeli",CHOOSE(RANDBETWEEN(1,5),1,1,1,1,2),""))))) | AE10: =IF(OR('Öğrenci Listesi'!B11="",AJ10=""),"",IF(AJ10="Çok İyi",CHOOSE(RANDBETWEEN(1,5),4,4,4,4,3),IF(AJ10="İyi",CHOOSE(RANDBETWEEN(1,5),3,3,3,4,2),IF(AJ10="Yeterli",CHOOSE(RANDBETWEEN(1,5),2,2,2,3,1),IF(AJ10="Geliştirilmeli",CHOOSE(RANDBETWEEN(1,5),1,1,1,1,2),""))))) | AF10: =IF(OR('Öğrenci Listesi'!B11="",AJ10=""),"",IF(AJ10="Çok İyi",CHOOSE(RANDBETWEEN(1,5),4,4,4,4,3),IF(AJ10="İyi",CHOOSE(RANDBETWEEN(1,5),3,3,3,4,2),IF(AJ10="Yeterli",CHOOSE(RANDBETWEEN(1,5),2,2,2,3,1),IF(AJ10="Geliştirilmeli",CHOOSE(RANDBETWEEN(1,5),1,1,1,1,2),""))))) | AG10: =IF(OR('Öğrenci Listesi'!B11="",AJ10=""),"",IF(AJ10="Çok İyi",CHOOSE(RANDBETWEEN(1,5),4,4,4,4,3),IF(AJ10="İyi",CHOOSE(RANDBETWEEN(1,5),3,3,3,4,2),IF(AJ10="Yeterli",CHOOSE(RANDBETWEEN(1,5),2,2,2,3,1),IF(AJ10="Geliştirilmeli",CHOOSE(RANDBETWEEN(1,5),1,1,1,1,2),""))))) | AH10: =IF(OR('Öğrenci Listesi'!B11="",AJ10=""),"",IF(AJ10="Çok İyi",CHOOSE(RANDBETWEEN(1,5),4,4,4,4,3),IF(AJ10="İyi",CHOOSE(RANDBETWEEN(1,5),3,3,3,4,2),IF(AJ10="Yeterli",CHOOSE(RANDBETWEEN(1,5),2,2,2,3,1),IF(AJ10="Geliştirilmeli",CHOOSE(RANDBETWEEN(1,5),1,1,1,1,2),""))))) | AI10: =IF(OR('Öğrenci Listesi'!B11="",AJ10=""),"",ROUND(AVERAGE(C10:AH10),2)) | AJ10: =IFERROR(IF('Öğrenci Listesi'!G11="","",IF(UPPER(TRIM('Öğrenci Listesi'!G11))="ÇOK İYİ","Çok İyi",IF(UPPER(TRIM('Öğrenci Listesi'!G11))="İYİ","İyi",IF(UPPER(TRIM('Öğrenci Listesi'!G11))="YETERLİ","Yeterli",IF(UPPER(TRIM('Öğrenci Listesi'!G11))="GELİŞTİRİLMELİ","Geliştirilmeli",'Öğrenci Listesi'!G11))))),"")
