Workbook

Sheet Bilgiler
A1: 📝 BİLGİLERİ DOLDURUNUZ
A2: Aşağıdaki bilgileri kendi okulunuza ve sınıfınıza göre doldurun. 'Ölçek' sayfasındaki başlıklar otomatik güncellenecek.
A4: Okul Adı
A5: Eğitim Öğretim Yılı
A6: Sınıf / Şube
A7: Dönem
A8: Ders | B8: İngilizce
A9: Sınıf Öğretmeni
A10: Okul Müdürü

Sheet Öğrenci Listesi
A1: 📋 SİSTEMDEN ÖĞRENCİ LİSTESİNİ BURAYA YAPIŞTIRIN
A2: Sistemde notları işaretledikten sonra tüm tabloyu kopyalayın (Ctrl+C), aşağıdaki sarı alana yapıştırın (Ctrl+V).
A3: ✓ Öğrenci adları, numaraları ve seviyeler 'Ölçek' sayfasına otomatik aktarılacak.
A5: NO | B5: ADI SOYADI | C5: Geliştirilmeli | D5: Yeterli | E5: İyi | F5: Çok İyi | G5: SONUÇ | H5: (yok sayılır)

Sheet Ölçek
A1: =Bilgiler!B4&" • "&Bilgiler!B5&" EĞİTİM ÖĞRETİM YILI"
A2: =Bilgiler!B6&" SINIFI "&Bilgiler!B7&" "&Bilgiler!B8&" DERSİ KAZANIM DEĞERLENDİRME ÖLÇEĞİ"
A4: NO | B4: ADI VE SOYADI | C4: Basit yönergeleri dinleyerek anlar ve uygular | D4: Dinlediği kısa diyaloglarda geçen bilgileri anlar | E4: Şarkı ve tekerlemeleri anlayarak tekrarlar | F4: Tanıdık konularda kısa konuşmaları anlar | G4: Kendini tanıtır ve temel kişisel bilgileri paylaşır | H4: Günlük hayatta sık kullanılan kalıp ifadeleri kullanır | I4: Nesneleri, renkleri ve sayıları İngilizce söyler | J4: Aile üyelerini ve meslekleri tanıtır | K4: Hayvanları tanımlayan basit cümleler kurar | L4: Tanıdık sözcükleri okur | M4: Kısa ve basit cümleleri okuyarak anlar | N4: Görsellerle desteklenmiş metinleri anlar | O4: Kısa okuma parçalarındaki bilgilere yanıt verir | P4: Tanıdık sözcükleri yazar | Q4: Kısa ve basit cümleleri kopyalar | R4: Eksik bırakılan kelimeleri tamamlar | S4: Tekil-çoğul yapılarını fark eder | T4: Temel soru yapılarını kullanır | U4: Renk, sayı ve nesne kelime dağarcığını kullanır | V4: Günlük hayat konularında kısa diyalog kurar | W4: ORTALAMA | X4: SEVİYE
A5: =IFERROR(IF('Öğrenci Listesi'!A6="","",'Öğrenci Listesi'!A6),"") | B5: =IFERROR(IF('Öğrenci Listesi'!B6="","",'Öğrenci Listesi'!B6),"") | C5: =IF(OR('Öğrenci Listesi'!B6="",X5=""),"",IF(X5="Çok İyi",CHOOSE(RANDBETWEEN(1,5),4,4,4,4,3),IF(X5="İyi",CHOOSE(RANDBETWEEN(1,5),3,3,3,4,2),IF(X5="Yeterli",CHOOSE(RANDBETWEEN(1,5),2,2,2,3,1),IF(X5="Geliştirilmeli",CHOOSE(RANDBETWEEN(1,5),1,1,1,1,2),""))))) | D5: =IF(OR('Öğrenci Listesi'!B6="",X5=""),"",IF(X5="Çok İyi",CHOOSE(RANDBETWEEN(1,5),4,4,4,4,3),IF(X5="İyi",CHOOSE(RANDBETWEEN(1,5),3,3,3,4,2),IF(X5="Yeterli",CHOOSE(RANDBETWEEN(1,5),2,2,2,3,1),IF(X5="Geliştirilmeli",CHOOSE(RANDBETWEEN(1,5),1,1,1,1,2),""))))) | E5: =IF(OR('Öğrenci Listesi'!B6="",X5=""),"",IF(X5="Çok İyi",CHOOSE(RANDBETWEEN(1,5),4,4,4,4,3),IF(X5="İyi",CHOOSE(RANDBETWEEN(1,5),3,3,3,4,2),IF(X5="Yeterli",CHOOSE(RANDBETWEEN(1,5),2,2,2,3,1),IF(X5="Geliştirilmeli",CHOOSE(RANDBETWEEN(1,5),1,1,1,1,2),""))))) | F5: =IF(OR('Öğrenci Listesi'!B6="",X5=""),"",IF(X5="Çok İyi",CHOOSE(RANDBETWEEN(1,5),4,4,4,4,3),IF(X5="İyi",CHOOSE(RANDBETWEEN(1,5),3,3,3,4,2),IF(X5="Yeterli",CHOOSE(RANDBETWEEN(1,5),2,2,2,3,1),IF(X5="Geliştirilmeli",CHOOSE(RANDBETWEEN(1,5),1,1,1,1,2),""))))) | G5: =IF(OR('Öğrenci Listesi'!B6="",X5=""),"",IF(X5="Çok İyi",CHOOSE(RANDBETWEEN(1,5),4,4,4,4,3),IF(X5="İyi",CHOOSE(RANDBETWEEN(1,5),3,3,3,4,2),IF(X5="Yeterli",CHOOSE(RANDBETWEEN(1,5),2,2,2,3,1),IF(X5="Geliştirilmeli",CHOOSE(RANDBETWEEN(1,5),1,1,1,1,2),""))))) | H5: =IF(OR('Öğrenci Listesi'!B6="",X5=""),"",IF(X5="Çok İyi",CHOOSE(RANDBETWEEN(1,5),4,4,4,4,3),IF(X5="İyi",CHOOSE(RANDBETWEEN(1,5),3,3,3,4,2),IF(X5="Yeterli",CHOOSE(RANDBETWEEN(1,5),2,2,2,3,1),IF(X5="Geliştirilmeli",CHOOSE(RANDBETWEEN(1,5),1,1,1,1,2),""))))) | I5: =IF(OR('Öğrenci Listesi'!B6="",X5=""),"",IF(X5="Çok İyi",CHOOSE(RANDBETWEEN(1,5),4,4,4,4,3),IF(X5="İyi",CHOOSE(RANDBETWEEN(1,5),3,3,3,4,2),IF(X5="Yeterli",CHOOSE(RANDBETWEEN(1,5),2,2,2,3,1),IF(X5="Geliştirilmeli",CHOOSE(RANDBETWEEN(1,5),1,1,1,1,2),""))))) | J5: =IF(OR('Öğrenci Listesi'!B6="",X5=""),"",IF(X5="Çok İyi",CHOOSE(RANDBETWEEN(1,5),4,4,4,4,3),IF(X5="İyi",CHOOSE(RANDBETWEEN(1,5),3,3,3,4,2),IF(X5="Yeterli",CHOOSE(RANDBETWEEN(1,5),2,2,2,3,1),IF(X5="Geliştirilmeli",CHOOSE(RANDBETWEEN(1,5),1,1,1,1,2),""))))) | K5: =IF(OR('Öğrenci Listesi'!B6="",X5=""),"",IF(X5="Çok İyi",CHOOSE(RANDBETWEEN(1,5),4,4,4,4,3),IF(X5="İyi",CHOOSE(RANDBETWEEN(1,5),3,3,3,4,2),IF(X5="Yeterli",CHOOSE(RANDBETWEEN(1,5),2,2,2,3,1),IF(X5="Geliştirilmeli",CHOOSE(RANDBETWEEN(1,5),1,1,1,1,2),""))))) | L5: =IF(OR('Öğrenci Listesi'!B6="",X5=""),"",IF(X5="Çok İyi",CHOOSE(RANDBETWEEN(1,5),4,4,4,4,3),IF(X5="İyi",CHOOSE(RANDBETWEEN(1,5),3,3,3,4,2),IF(X5="Yeterli",CHOOSE(RANDBETWEEN(1,5),2,2,2,3,1),IF(X5="Geliştirilmeli",CHOOSE(RANDBETWEEN(1,5),1,1,1,1,2),""))))) | M5: =IF(OR('Öğrenci Listesi'!B6="",X5=""),"",IF(X5="Çok İyi",CHOOSE(RANDBETWEEN(1,5),4,4,4,4,3),IF(X5="İyi",CHOOSE(RANDBETWEEN(1,5),3,3,3,4,2),IF(X5="Yeterli",CHOOSE(RANDBETWEEN(1,5),2,2,2,3,1),IF(X5="Geliştirilmeli",CHOOSE(RANDBETWEEN(1,5),1,1,1,1,2),""))))) | N5: =IF(OR('Öğrenci Listesi'!B6="",X5=""),"",IF(X5="Çok İyi",CHOOSE(RANDBETWEEN(1,5),4,4,4,4,3),IF(X5="İyi",CHOOSE(RANDBETWEEN(1,5),3,3,3,4,2),IF(X5="Yeterli",CHOOSE(RANDBETWEEN(1,5),2,2,2,3,1),IF(X5="Geliştirilmeli",CHOOSE(RANDBETWEEN(1,5),1,1,1,1,2),""))))) | O5: =IF(OR('Öğrenci Listesi'!B6="",X5=""),"",IF(X5="Çok İyi",CHOOSE(RANDBETWEEN(1,5),4,4,4,4,3),IF(X5="İyi",CHOOSE(RANDBETWEEN(1,5),3,3,3,4,2),IF(X5="Yeterli",CHOOSE(RANDBETWEEN(1,5),2,2,2,3,1),IF(X5="Geliştirilmeli",CHOOSE(RANDBETWEEN(1,5),1,1,1,1,2),""))))) | P5: =IF(OR('Öğrenci Listesi'!B6="",X5=""),"",IF(X5="Çok İyi",CHOOSE(RANDBETWEEN(1,5),4,4,4,4,3),IF(X5="İyi",CHOOSE(RANDBETWEEN(1,5),3,3,3,4,2),IF(X5="Yeterli",CHOOSE(RANDBETWEEN(1,5),2,2,2,3,1),IF(X5="Geliştirilmeli",CHOOSE(RANDBETWEEN(1,5),1,1,1,1,2),""))))) | Q5: =IF(OR('Öğrenci Listesi'!B6="",X5=""),"",IF(X5="Çok İyi",CHOOSE(RANDBETWEEN(1,5),4,4,4,4,3),IF(X5="İyi",CHOOSE(RANDBETWEEN(1,5),3,3,3,4,2),IF(X5="Yeterli",CHOOSE(RANDBETWEEN(1,5),2,2,2,3,1),IF(X5="Geliştirilmeli",CHOOSE(RANDBETWEEN(1,5),1,1,1,1,2),""))))) | R5: =IF(OR('Öğrenci Listesi'!B6="",X5=""),"",IF(X5="Çok İyi",CHOOSE(RANDBETWEEN(1,5),4,4,4,4,3),IF(X5="İyi",CHOOSE(RANDBETWEEN(1,5),3,3,3,4,2),IF(X5="Yeterli",CHOOSE(RANDBETWEEN(1,5),2,2,2,3,1),IF(X5="Geliştirilmeli",CHOOSE(RANDBETWEEN(1,5),1,1,1,1,2),""))))) | S5: =IF(OR('Öğrenci Listesi'!B6="",X5=""),"",IF(X5="Çok İyi",CHOOSE(RANDBETWEEN(1,5),4,4,4,4,3),IF(X5="İyi",CHOOSE(RANDBETWEEN(1,5),3,3,3,4,2),IF(X5="Yeterli",CHOOSE(RANDBETWEEN(1,5),2,2,2,3,1),IF(X5="Geliştirilmeli",CHOOSE(RANDBETWEEN(1,5),1,1,1,1,2),""))))) | T5: =IF(OR('Öğrenci Listesi'!B6="",X5=""),"",IF(X5="Çok İyi",CHOOSE(RANDBETWEEN(1,5),4,4,4,4,3),IF(X5="İyi",CHOOSE(RANDBETWEEN(1,5),3,3,3,4,2),IF(X5="Yeterli",CHOOSE(RANDBETWEEN(1,5),2,2,2,3,1),IF(X5="Geliştirilmeli",CHOOSE(RANDBETWEEN(1,5),1,1,1,1,2),""))))) | U5: =IF(OR('Öğrenci Listesi'!B6="",X5=""),"",IF(X5="Çok İyi",CHOOSE(RANDBETWEEN(1,5),4,4,4,4,3),IF(X5="İyi",CHOOSE(RANDBETWEEN(1,5),3,3,3,4,2),IF(X5="Yeterli",CHOOSE(RANDBETWEEN(1,5),2,2,2,3,1),IF(X5="Geliştirilmeli",CHOOSE(RANDBETWEEN(1,5),1,1,1,1,2),""))))) | V5: =IF(OR('Öğrenci Listesi'!B6="",X5=""),"",IF(X5="Çok İyi",CHOOSE(RANDBETWEEN(1,5),4,4,4,4,3),IF(X5="İyi",CHOOSE(RANDBETWEEN(1,5),3,3,3,4,2),IF(X5="Yeterli",CHOOSE(RANDBETWEEN(1,5),2,2,2,3,1),IF(X5="Geliştirilmeli",CHOOSE(RANDBETWEEN(1,5),1,1,1,1,2),""))))) | W5: =IF(OR('Öğrenci Listesi'!B6="",X5=""),"",ROUND(AVERAGE(C5:V5),2)) | X5: =IFERROR(IF('Öğrenci Listesi'!G6="","",IF(UPPER(TRIM('Öğrenci Listesi'!G6))="ÇOK İYİ","Çok İyi",IF(UPPER(TRIM('Öğrenci Listesi'!G6))="İYİ","İyi",IF(UPPER(TRIM('Öğrenci Listesi'!G6))="YETERLİ","Yeterli",IF(UPPER(TRIM('Öğrenci Listesi'!G6))="GELİŞTİRİLMELİ","Geliştirilmeli",'Öğrenci Listesi'!G6))))),"")
A6: =IFERROR(IF('Öğrenci Listesi'!A7="","",'Öğrenci Listesi'!A7),"") | B6: =IFERROR(IF('Öğrenci Listesi'!B7="","",'Öğrenci Listesi'!B7),"") | C6: =IF(OR('Öğrenci Listesi'!B7="",X6=""),"",IF(X6="Çok İyi",CHOOSE(RANDBETWEEN(1,5),4,4,4,4,3),IF(X6="İyi",CHOOSE(RANDBETWEEN(1,5),3,3,3,4,2),IF(X6="Yeterli",CHOOSE(RANDBETWEEN(1,5),2,2,2,3,1),IF(X6="Geliştirilmeli",CHOOSE(RANDBETWEEN(1,5),1,1,1,1,2),""))))) | D6: =IF(OR('Öğrenci Listesi'!B7="",X6=""),"",IF(X6="Çok İyi",CHOOSE(RANDBETWEEN(1,5),4,4,4,4,3),IF(X6="İyi",CHOOSE(RANDBETWEEN(1,5),3,3,3,4,2),IF(X6="Yeterli",CHOOSE(RANDBETWEEN(1,5),2,2,2,3,1),IF(X6="Geliştirilmeli",CHOOSE(RANDBETWEEN(1,5),1,1,1,1,2),""))))) | E6: =IF(OR('Öğrenci Listesi'!B7="",X6=""),"",IF(X6="Çok İyi",CHOOSE(RANDBETWEEN(1,5),4,4,4,4,3),IF(X6="İyi",CHOOSE(RANDBETWEEN(1,5),3,3,3,4,2),IF(X6="Yeterli",CHOOSE(RANDBETWEEN(1,5),2,2,2,3,1),IF(X6="Geliştirilmeli",CHOOSE(RANDBETWEEN(1,5),1,1,1,1,2),""))))) | F6: =IF(OR('Öğrenci Listesi'!B7="",X6=""),"",IF(X6="Çok İyi",CHOOSE(RANDBETWEEN(1,5),4,4,4,4,3),IF(X6="İyi",CHOOSE(RANDBETWEEN(1,5),3,3,3,4,2),IF(X6="Yeterli",CHOOSE(RANDBETWEEN(1,5),2,2,2,3,1),IF(X6="Geliştirilmeli",CHOOSE(RANDBETWEEN(1,5),1,1,1,1,2),""))))) | G6: =IF(OR('Öğrenci Listesi'!B7="",X6=""),"",IF(X6="Çok İyi",CHOOSE(RANDBETWEEN(1,5),4,4,4,4,3),IF(X6="İyi",CHOOSE(RANDBETWEEN(1,5),3,3,3,4,2),IF(X6="Yeterli",CHOOSE(RANDBETWEEN(1,5),2,2,2,3,1),IF(X6="Geliştirilmeli",CHOOSE(RANDBETWEEN(1,5),1,1,1,1,2),""))))) | H6: =IF(OR('Öğrenci Listesi'!B7="",X6=""),"",IF(X6="Çok İyi",CHOOSE(RANDBETWEEN(1,5),4,4,4,4,3),IF(X6="İyi",CHOOSE(RANDBETWEEN(1,5),3,3,3,4,2),IF(X6="Yeterli",CHOOSE(RANDBETWEEN(1,5),2,2,2,3,1),IF(X6="Geliştirilmeli",CHOOSE(RANDBETWEEN(1,5),1,1,1,1,2),""))))) | I6: =IF(OR('Öğrenci Listesi'!B7="",X6=""),"",IF(X6="Çok İyi",CHOOSE(RANDBETWEEN(1,5),4,4,4,4,3),IF(X6="İyi",CHOOSE(RANDBETWEEN(1,5),3,3,3,4,2),IF(X6="Yeterli",CHOOSE(RANDBETWEEN(1,5),2,2,2,3,1),IF(X6="Geliştirilmeli",CHOOSE(RANDBETWEEN(1,5),1,1,1,1,2),""))))) | J6: =IF(OR('Öğrenci Listesi'!B7="",X6=""),"",IF(X6="Çok İyi",CHOOSE(RANDBETWEEN(1,5),4,4,4,4,3),IF(X6="İyi",CHOOSE(RANDBETWEEN(1,5),3,3,3,4,2),IF(X6="Yeterli",CHOOSE(RANDBETWEEN(1,5),2,2,2,3,1),IF(X6="Geliştirilmeli",CHOOSE(RANDBETWEEN(1,5),1,1,1,1,2),""))))) | K6: =IF(OR('Öğrenci Listesi'!B7="",X6=""),"",IF(X6="Çok İyi",CHOOSE(RANDBETWEEN(1,5),4,4,4,4,3),IF(X6="İyi",CHOOSE(RANDBETWEEN(1,5),3,3,3,4,2),IF(X6="Yeterli",CHOOSE(RANDBETWEEN(1,5),2,2,2,3,1),IF(X6="Geliştirilmeli",CHOOSE(RANDBETWEEN(1,5),1,1,1,1,2),""))))) | L6: =IF(OR('Öğrenci Listesi'!B7="",X6=""),"",IF(X6="Çok İyi",CHOOSE(RANDBETWEEN(1,5),4,4,4,4,3),IF(X6="İyi",CHOOSE(RANDBETWEEN(1,5),3,3,3,4,2),IF(X6="Yeterli",CHOOSE(RANDBETWEEN(1,5),2,2,2,3,1),IF(X6="Geliştirilmeli",CHOOSE(RANDBETWEEN(1,5),1,1,1,1,2),""))))) | M6: =IF(OR('Öğrenci Listesi'!B7="",X6=""),"",IF(X6="Çok İyi",CHOOSE(RANDBETWEEN(1,5),4,4,4,4,3),IF(X6="İyi",CHOOSE(RANDBETWEEN(1,5),3,3,3,4,2),IF(X6="Yeterli",CHOOSE(RANDBETWEEN(1,5),2,2,2,3,1),IF(X6="Geliştirilmeli",CHOOSE(RANDBETWEEN(1,5),1,1,1,1,2),""))))) | N6: =IF(OR('Öğrenci Listesi'!B7="",X6=""),"",IF(X6="Çok İyi",CHOOSE(RANDBETWEEN(1,5),4,4,4,4,3),IF(X6="İyi",CHOOSE(RANDBETWEEN(1,5),3,3,3,4,2),IF(X6="Yeterli",CHOOSE(RANDBETWEEN(1,5),2,2,2,3,1),IF(X6="Geliştirilmeli",CHOOSE(RANDBETWEEN(1,5),1,1,1,1,2),""))))) | O6: =IF(OR('Öğrenci Listesi'!B7="",X6=""),"",IF(X6="Çok İyi",CHOOSE(RANDBETWEEN(1,5),4,4,4,4,3),IF(X6="İyi",CHOOSE(RANDBETWEEN(1,5),3,3,3,4,2),IF(X6="Yeterli",CHOOSE(RANDBETWEEN(1,5),2,2,2,3,1),IF(X6="Geliştirilmeli",CHOOSE(RANDBETWEEN(1,5),1,1,1,1,2),""))))) | P6: =IF(OR('Öğrenci Listesi'!B7="",X6=""),"",IF(X6="Çok İyi",CHOOSE(RANDBETWEEN(1,5),4,4,4,4,3),IF(X6="İyi",CHOOSE(RANDBETWEEN(1,5),3,3,3,4,2),IF(X6="Yeterli",CHOOSE(RANDBETWEEN(1,5),2,2,2,3,1),IF(X6="Geliştirilmeli",CHOOSE(RANDBETWEEN(1,5),1,1,1,1,2),""))))) | Q6: =IF(OR('Öğrenci Listesi'!B7="",X6=""),"",IF(X6="Çok İyi",CHOOSE(RANDBETWEEN(1,5),4,4,4,4,3),IF(X6="İyi",CHOOSE(RANDBETWEEN(1,5),3,3,3,4,2),IF(X6="Yeterli",CHOOSE(RANDBETWEEN(1,5),2,2,2,3,1),IF(X6="Geliştirilmeli",CHOOSE(RANDBETWEEN(1,5),1,1,1,1,2),""))))) | R6: =IF(OR('Öğrenci Listesi'!B7="",X6=""),"",IF(X6="Çok İyi",CHOOSE(RANDBETWEEN(1,5),4,4,4,4,3),IF(X6="İyi",CHOOSE(RANDBETWEEN(1,5),3,3,3,4,2),IF(X6="Yeterli",CHOOSE(RANDBETWEEN(1,5),2,2,2,3,1),IF(X6="Geliştirilmeli",CHOOSE(RANDBETWEEN(1,5),1,1,1,1,2),""))))) | S6: =IF(OR('Öğrenci Listesi'!B7="",X6=""),"",IF(X6="Çok İyi",CHOOSE(RANDBETWEEN(1,5),4,4,4,4,3),IF(X6="İyi",CHOOSE(RANDBETWEEN(1,5),3,3,3,4,2),IF(X6="Yeterli",CHOOSE(RANDBETWEEN(1,5),2,2,2,3,1),IF(X6="Geliştirilmeli",CHOOSE(RANDBETWEEN(1,5),1,1,1,1,2),""))))) | T6: =IF(OR('Öğrenci Listesi'!B7="",X6=""),"",IF(X6="Çok İyi",CHOOSE(RANDBETWEEN(1,5),4,4,4,4,3),IF(X6="İyi",CHOOSE(RANDBETWEEN(1,5),3,3,3,4,2),IF(X6="Yeterli",CHOOSE(RANDBETWEEN(1,5),2,2,2,3,1),IF(X6="Geliştirilmeli",CHOOSE(RANDBETWEEN(1,5),1,1,1,1,2),""))))) | U6: =IF(OR('Öğrenci Listesi'!B7="",X6=""),"",IF(X6="Çok İyi",CHOOSE(RANDBETWEEN(1,5),4,4,4,4,3),IF(X6="İyi",CHOOSE(RANDBETWEEN(1,5),3,3,3,4,2),IF(X6="Yeterli",CHOOSE(RANDBETWEEN(1,5),2,2,2,3,1),IF(X6="Geliştirilmeli",CHOOSE(RANDBETWEEN(1,5),1,1,1,1,2),""))))) | V6: =IF(OR('Öğrenci Listesi'!B7="",X6=""),"",IF(X6="Çok İyi",CHOOSE(RANDBETWEEN(1,5),4,4,4,4,3),IF(X6="İyi",CHOOSE(RANDBETWEEN(1,5),3,3,3,4,2),IF(X6="Yeterli",CHOOSE(RANDBETWEEN(1,5),2,2,2,3,1),IF(X6="Geliştirilmeli",CHOOSE(RANDBETWEEN(1,5),1,1,1,1,2),""))))) | W6: =IF(OR('Öğrenci Listesi'!B7="",X6=""),"",ROUND(AVERAGE(C6:V6),2)) | X6: =IFERROR(IF('Öğrenci Listesi'!G7="","",IF(UPPER(TRIM('Öğrenci Listesi'!G7))="ÇOK İYİ","Çok İyi",IF(UPPER(TRIM('Öğrenci Listesi'!G7))="İYİ","İyi",IF(UPPER(TRIM('Öğrenci Listesi'!G7))="YETERLİ","Yeterli",IF(UPPER(TRIM('Öğrenci Listesi'!G7))="GELİŞTİRİLMELİ","Geliştirilmeli",'Öğrenci Listesi'!G7))))),"")
A7: =IFERROR(IF('Öğrenci Listesi'!A8="","",'Öğrenci Listesi'!A8),"") | B7: =IFERROR(IF('Öğrenci Listesi'!B8="","",'Öğrenci Listesi'!B8),"") | C7: =IF(OR('Öğrenci Listesi'!B8="",X7=""),"",IF(X7="Çok İyi",CHOOSE(RANDBETWEEN(1,5),4,4,4,4,3),IF(X7="İyi",CHOOSE(RANDBETWEEN(1,5),3,3,3,4,2),IF(X7="Yeterli",CHOOSE(RANDBETWEEN(1,5),2,2,2,3,1),IF(X7="Geliştirilmeli",CHOOSE(RANDBETWEEN(1,5),1,1,1,1,2),""))))) | D7: =IF(OR('Öğrenci Listesi'!B8="",X7=""),"",IF(X7="Çok İyi",CHOOSE(RANDBETWEEN(1,5),4,4,4,4,3),IF(X7="İyi",CHOOSE(RANDBETWEEN(1,5),3,3,3,4,2),IF(X7="Yeterli",CHOOSE(RANDBETWEEN(1,5),2,2,2,3,1),IF(X7="Geliştirilmeli",CHOOSE(RANDBETWEEN(1,5),1,1,1,1,2),""))))) | E7: =IF(OR('Öğrenci Listesi'!B8="",X7=""),"",IF(X7="Çok İyi",CHOOSE(RANDBETWEEN(1,5),4,4,4,4,3),IF(X7="İyi",CHOOSE(RANDBETWEEN(1,5),3,3,3,4,2),IF(X7="Yeterli",CHOOSE(RANDBETWEEN(1,5),2,2,2,3,1),IF(X7="Geliştirilmeli",CHOOSE(RANDBETWEEN(1,5),1,1,1,1,2),""))))) | F7: =IF(OR('Öğrenci Listesi'!B8="",X7=""),"",IF(X7="Çok İyi",CHOOSE(RANDBETWEEN(1,5),4,4,4,4,3),IF(X7="İyi",CHOOSE(RANDBETWEEN(1,5),3,3,3,4,2),IF(X7="Yeterli",CHOOSE(RANDBETWEEN(1,5),2,2,2,3,1),IF(X7="Geliştirilmeli",CHOOSE(RANDBETWEEN(1,5),1,1,1,1,2),""))))) | G7: =IF(OR('Öğrenci Listesi'!B8="",X7=""),"",IF(X7="Çok İyi",CHOOSE(RANDBETWEEN(1,5),4,4,4,4,3),IF(X7="İyi",CHOOSE(RANDBETWEEN(1,5),3,3,3,4,2),IF(X7="Yeterli",CHOOSE(RANDBETWEEN(1,5),2,2,2,3,1),IF(X7="Geliştirilmeli",CHOOSE(RANDBETWEEN(1,5),1,1,1,1,2),""))))) | H7: =IF(OR('Öğrenci Listesi'!B8="",X7=""),"",IF(X7="Çok İyi",CHOOSE(RANDBETWEEN(1,5),4,4,4,4,3),IF(X7="İyi",CHOOSE(RANDBETWEEN(1,5),3,3,3,4,2),IF(X7="Yeterli",CHOOSE(RANDBETWEEN(1,5),2,2,2,3,1),IF(X7="Geliştirilmeli",CHOOSE(RANDBETWEEN(1,5),1,1,1,1,2),""))))) | I7: =IF(OR('Öğrenci Listesi'!B8="",X7=""),"",IF(X7="Çok İyi",CHOOSE(RANDBETWEEN(1,5),4,4,4,4,3),IF(X7="İyi",CHOOSE(RANDBETWEEN(1,5),3,3,3,4,2),IF(X7="Yeterli",CHOOSE(RANDBETWEEN(1,5),2,2,2,3,1),IF(X7="Geliştirilmeli",CHOOSE(RANDBETWEEN(1,5),1,1,1,1,2),""))))) | J7: =IF(OR('Öğrenci Listesi'!B8="",X7=""),"",IF(X7="Çok İyi",CHOOSE(RANDBETWEEN(1,5),4,4,4,4,3),IF(X7="İyi",CHOOSE(RANDBETWEEN(1,5),3,3,3,4,2),IF(X7="Yeterli",CHOOSE(RANDBETWEEN(1,5),2,2,2,3,1),IF(X7="Geliştirilmeli",CHOOSE(RANDBETWEEN(1,5),1,1,1,1,2),""))))) | K7: =IF(OR('Öğrenci Listesi'!B8="",X7=""),"",IF(X7="Çok İyi",CHOOSE(RANDBETWEEN(1,5),4,4,4,4,3),IF(X7="İyi",CHOOSE(RANDBETWEEN(1,5),3,3,3,4,2),IF(X7="Yeterli",CHOOSE(RANDBETWEEN(1,5),2,2,2,3,1),IF(X7="Geliştirilmeli",CHOOSE(RANDBETWEEN(1,5),1,1,1,1,2),""))))) | L7: =IF(OR('Öğrenci Listesi'!B8="",X7=""),"",IF(X7="Çok İyi",CHOOSE(RANDBETWEEN(1,5),4,4,4,4,3),IF(X7="İyi",CHOOSE(RANDBETWEEN(1,5),3,3,3,4,2),IF(X7="Yeterli",CHOOSE(RANDBETWEEN(1,5),2,2,2,3,1),IF(X7="Geliştirilmeli",CHOOSE(RANDBETWEEN(1,5),1,1,1,1,2),""))))) | M7: =IF(OR('Öğrenci Listesi'!B8="",X7=""),"",IF(X7="Çok İyi",CHOOSE(RANDBETWEEN(1,5),4,4,4,4,3),IF(X7="İyi",CHOOSE(RANDBETWEEN(1,5),3,3,3,4,2),IF(X7="Yeterli",CHOOSE(RANDBETWEEN(1,5),2,2,2,3,1),IF(X7="Geliştirilmeli",CHOOSE(RANDBETWEEN(1,5),1,1,1,1,2),""))))) | N7: =IF(OR('Öğrenci Listesi'!B8="",X7=""),"",IF(X7="Çok İyi",CHOOSE(RANDBETWEEN(1,5),4,4,4,4,3),IF(X7="İyi",CHOOSE(RANDBETWEEN(1,5),3,3,3,4,2),IF(X7="Yeterli",CHOOSE(RANDBETWEEN(1,5),2,2,2,3,1),IF(X7="Geliştirilmeli",CHOOSE(RANDBETWEEN(1,5),1,1,1,1,2),""))))) | O7: =IF(OR('Öğrenci Listesi'!B8="",X7=""),"",IF(X7="Çok İyi",CHOOSE(RANDBETWEEN(1,5),4,4,4,4,3),IF(X7="İyi",CHOOSE(RANDBETWEEN(1,5),3,3,3,4,2),IF(X7="Yeterli",CHOOSE(RANDBETWEEN(1,5),2,2,2,3,1),IF(X7="Geliştirilmeli",CHOOSE(RANDBETWEEN(1,5),1,1,1,1,2),""))))) | P7: =IF(OR('Öğrenci Listesi'!B8="",X7=""),"",IF(X7="Çok İyi",CHOOSE(RANDBETWEEN(1,5),4,4,4,4,3),IF(X7="İyi",CHOOSE(RANDBETWEEN(1,5),3,3,3,4,2),IF(X7="Yeterli",CHOOSE(RANDBETWEEN(1,5),2,2,2,3,1),IF(X7="Geliştirilmeli",CHOOSE(RANDBETWEEN(1,5),1,1,1,1,2),""))))) | Q7: =IF(OR('Öğrenci Listesi'!B8="",X7=""),"",IF(X7="Çok İyi",CHOOSE(RANDBETWEEN(1,5),4,4,4,4,3),IF(X7="İyi",CHOOSE(RANDBETWEEN(1,5),3,3,3,4,2),IF(X7="Yeterli",CHOOSE(RANDBETWEEN(1,5),2,2,2,3,1),IF(X7="Geliştirilmeli",CHOOSE(RANDBETWEEN(1,5),1,1,1,1,2),""))))) | R7: =IF(OR('Öğrenci Listesi'!B8="",X7=""),"",IF(X7="Çok İyi",CHOOSE(RANDBETWEEN(1,5),4,4,4,4,3),IF(X7="İyi",CHOOSE(RANDBETWEEN(1,5),3,3,3,4,2),IF(X7="Yeterli",CHOOSE(RANDBETWEEN(1,5),2,2,2,3,1),IF(X7="Geliştirilmeli",CHOOSE(RANDBETWEEN(1,5),1,1,1,1,2),""))))) | S7: =IF(OR('Öğrenci Listesi'!B8="",X7=""),"",IF(X7="Çok İyi",CHOOSE(RANDBETWEEN(1,5),4,4,4,4,3),IF(X7="İyi",CHOOSE(RANDBETWEEN(1,5),3,3,3,4,2),IF(X7="Yeterli",CHOOSE(RANDBETWEEN(1,5),2,2,2,3,1),IF(X7="Geliştirilmeli",CHOOSE(RANDBETWEEN(1,5),1,1,1,1,2),""))))) | T7: =IF(OR('Öğrenci Listesi'!B8="",X7=""),"",IF(X7="Çok İyi",CHOOSE(RANDBETWEEN(1,5),4,4,4,4,3),IF(X7="İyi",CHOOSE(RANDBETWEEN(1,5),3,3,3,4,2),IF(X7="Yeterli",CHOOSE(RANDBETWEEN(1,5),2,2,2,3,1),IF(X7="Geliştirilmeli",CHOOSE(RANDBETWEEN(1,5),1,1,1,1,2),""))))) | U7: =IF(OR('Öğrenci Listesi'!B8="",X7=""),"",IF(X7="Çok İyi",CHOOSE(RANDBETWEEN(1,5),4,4,4,4,3),IF(X7="İyi",CHOOSE(RANDBETWEEN(1,5),3,3,3,4,2),IF(X7="Yeterli",CHOOSE(RANDBETWEEN(1,5),2,2,2,3,1),IF(X7="Geliştirilmeli",CHOOSE(RANDBETWEEN(1,5),1,1,1,1,2),""))))) | V7: =IF(OR('Öğrenci Listesi'!B8="",X7=""),"",IF(X7="Çok İyi",CHOOSE(RANDBETWEEN(1,5),4,4,4,4,3),IF(X7="İyi",CHOOSE(RANDBETWEEN(1,5),3,3,3,4,2),IF(X7="Yeterli",CHOOSE(RANDBETWEEN(1,5),2,2,2,3,1),IF(X7="Geliştirilmeli",CHOOSE(RANDBETWEEN(1,5),1,1,1,1,2),""))))) | W7: =IF(OR('Öğrenci Listesi'!B8="",X7=""),"",ROUND(AVERAGE(C7:V7),2)) | X7: =IFERROR(IF('Öğrenci Listesi'!G8="","",IF(UPPER(TRIM('Öğrenci Listesi'!G8))="ÇOK İYİ","Çok İyi",IF(UPPER(TRIM('Öğrenci Listesi'!G8))="İYİ","İyi",IF(UPPER(TRIM('Öğrenci Listesi'!G8))="YETERLİ","Yeterli",IF(UPPER(TRIM('Öğrenci Listesi'!G8))="GELİŞTİRİLMELİ","Geliştirilmeli",'Öğrenci Listesi'!G8))))),"")
A8: =IFERROR(IF('Öğrenci Listesi'!A9="","",'Öğrenci Listesi'!A9),"") | B8: =IFERROR(IF('Öğrenci Listesi'!B9="","",'Öğrenci Listesi'!B9),"") | C8: =IF(OR('Öğrenci Listesi'!B9="",X8=""),"",IF(X8="Çok İyi",CHOOSE(RANDBETWEEN(1,5),4,4,4,4,3),IF(X8="İyi",CHOOSE(RANDBETWEEN(1,5),3,3,3,4,2),IF(X8="Yeterli",CHOOSE(RANDBETWEEN(1,5),2,2,2,3,1),IF(X8="Geliştirilmeli",CHOOSE(RANDBETWEEN(1,5),1,1,1,1,2),""))))) | D8: =IF(OR('Öğrenci Listesi'!B9="",X8=""),"",IF(X8="Çok İyi",CHOOSE(RANDBETWEEN(1,5),4,4,4,4,3),IF(X8="İyi",CHOOSE(RANDBETWEEN(1,5),3,3,3,4,2),IF(X8="Yeterli",CHOOSE(RANDBETWEEN(1,5),2,2,2,3,1),IF(X8="Geliştirilmeli",CHOOSE(RANDBETWEEN(1,5),1,1,1,1,2),""))))) | E8: =IF(OR('Öğrenci Listesi'!B9="",X8=""),"",IF(X8="Çok İyi",CHOOSE(RANDBETWEEN(1,5),4,4,4,4,3),IF(X8="İyi",CHOOSE(RANDBETWEEN(1,5),3,3,3,4,2),IF(X8="Yeterli",CHOOSE(RANDBETWEEN(1,5),2,2,2,3,1),IF(X8="Geliştirilmeli",CHOOSE(RANDBETWEEN(1,5),1,1,1,1,2),""))))) | F8: =IF(OR('Öğrenci Listesi'!B9="",X8=""),"",IF(X8="Çok İyi",CHOOSE(RANDBETWEEN(1,5),4,4,4,4,3),IF(X8="İyi",CHOOSE(RANDBETWEEN(1,5),3,3,3,4,2),IF(X8="Yeterli",CHOOSE(RANDBETWEEN(1,5),2,2,2,3,1),IF(X8="Geliştirilmeli",CHOOSE(RANDBETWEEN(1,5),1,1,1,1,2),""))))) | G8: =IF(OR('Öğrenci Listesi'!B9="",X8=""),"",IF(X8="Çok İyi",CHOOSE(RANDBETWEEN(1,5),4,4,4,4,3),IF(X8="İyi",CHOOSE(RANDBETWEEN(1,5),3,3,3,4,2),IF(X8="Yeterli",CHOOSE(RANDBETWEEN(1,5),2,2,2,3,1),IF(X8="Geliştirilmeli",CHOOSE(RANDBETWEEN(1,5),1,1,1,1,2),""))))) | H8: =IF(OR('Öğrenci Listesi'!B9="",X8=""),"",IF(X8="Çok İyi",CHOOSE(RANDBETWEEN(1,5),4,4,4,4,3),IF(X8="İyi",CHOOSE(RANDBETWEEN(1,5),3,3,3,4,2),IF(X8="Yeterli",CHOOSE(RANDBETWEEN(1,5),2,2,2,3,1),IF(X8="Geliştirilmeli",CHOOSE(RANDBETWEEN(1,5),1,1,1,1,2),""))))) | I8: =IF(OR('Öğrenci Listesi'!B9="",X8=""),"",IF(X8="Çok İyi",CHOOSE(RANDBETWEEN(1,5),4,4,4,4,3),IF(X8="İyi",CHOOSE(RANDBETWEEN(1,5),3,3,3,4,2),IF(X8="Yeterli",CHOOSE(RANDBETWEEN(1,5),2,2,2,3,1),IF(X8="Geliştirilmeli",CHOOSE(RANDBETWEEN(1,5),1,1,1,1,2),""))))) | J8: =IF(OR('Öğrenci Listesi'!B9="",X8=""),"",IF(X8="Çok İyi",CHOOSE(RANDBETWEEN(1,5),4,4,4,4,3),IF(X8="İyi",CHOOSE(RANDBETWEEN(1,5),3,3,3,4,2),IF(X8="Yeterli",CHOOSE(RANDBETWEEN(1,5),2,2,2,3,1),IF(X8="Geliştirilmeli",CHOOSE(RANDBETWEEN(1,5),1,1,1,1,2),""))))) | K8: =IF(OR('Öğrenci Listesi'!B9="",X8=""),"",IF(X8="Çok İyi",CHOOSE(RANDBETWEEN(1,5),4,4,4,4,3),IF(X8="İyi",CHOOSE(RANDBETWEEN(1,5),3,3,3,4,2),IF(X8="Yeterli",CHOOSE(RANDBETWEEN(1,5),2,2,2,3,1),IF(X8="Geliştirilmeli",CHOOSE(RANDBETWEEN(1,5),1,1,1,1,2),""))))) | L8: =IF(OR('Öğrenci Listesi'!B9="",X8=""),"",IF(X8="Çok İyi",CHOOSE(RANDBETWEEN(1,5),4,4,4,4,3),IF(X8="İyi",CHOOSE(RANDBETWEEN(1,5),3,3,3,4,2),IF(X8="Yeterli",CHOOSE(RANDBETWEEN(1,5),2,2,2,3,1),IF(X8="Geliştirilmeli",CHOOSE(RANDBETWEEN(1,5),1,1,1,1,2),""))))) | M8: =IF(OR('Öğrenci Listesi'!B9="",X8=""),"",IF(X8="Çok İyi",CHOOSE(RANDBETWEEN(1,5),4,4,4,4,3),IF(X8="İyi",CHOOSE(RANDBETWEEN(1,5),3,3,3,4,2),IF(X8="Yeterli",CHOOSE(RANDBETWEEN(1,5),2,2,2,3,1),IF(X8="Geliştirilmeli",CHOOSE(RANDBETWEEN(1,5),1,1,1,1,2),""))))) | N8: =IF(OR('Öğrenci Listesi'!B9="",X8=""),"",IF(X8="Çok İyi",CHOOSE(RANDBETWEEN(1,5),4,4,4,4,3),IF(X8="İyi",CHOOSE(RANDBETWEEN(1,5),3,3,3,4,2),IF(X8="Yeterli",CHOOSE(RANDBETWEEN(1,5),2,2,2,3,1),IF(X8="Geliştirilmeli",CHOOSE(RANDBETWEEN(1,5),1,1,1,1,2),""))))) | O8: =IF(OR('Öğrenci Listesi'!B9="",X8=""),"",IF(X8="Çok İyi",CHOOSE(RANDBETWEEN(1,5),4,4,4,4,3),IF(X8="İyi",CHOOSE(RANDBETWEEN(1,5),3,3,3,4,2),IF(X8="Yeterli",CHOOSE(RANDBETWEEN(1,5),2,2,2,3,1),IF(X8="Geliştirilmeli",CHOOSE(RANDBETWEEN(1,5),1,1,1,1,2),""))))) | P8: =IF(OR('Öğrenci Listesi'!B9="",X8=""),"",IF(X8="Çok İyi",CHOOSE(RANDBETWEEN(1,5),4,4,4,4,3),IF(X8="İyi",CHOOSE(RANDBETWEEN(1,5),3,3,3,4,2),IF(X8="Yeterli",CHOOSE(RANDBETWEEN(1,5),2,2,2,3,1),IF(X8="Geliştirilmeli",CHOOSE(RANDBETWEEN(1,5),1,1,1,1,2),""))))) | Q8: =IF(OR('Öğrenci Listesi'!B9="",X8=""),"",IF(X8="Çok İyi",CHOOSE(RANDBETWEEN(1,5),4,4,4,4,3),IF(X8="İyi",CHOOSE(RANDBETWEEN(1,5),3,3,3,4,2),IF(X8="Yeterli",CHOOSE(RANDBETWEEN(1,5),2,2,2,3,1),IF(X8="Geliştirilmeli",CHOOSE(RANDBETWEEN(1,5),1,1,1,1,2),""))))) | R8: =IF(OR('Öğrenci Listesi'!B9="",X8=""),"",IF(X8="Çok İyi",CHOOSE(RANDBETWEEN(1,5),4,4,4,4,3),IF(X8="İyi",CHOOSE(RANDBETWEEN(1,5),3,3,3,4,2),IF(X8="Yeterli",CHOOSE(RANDBETWEEN(1,5),2,2,2,3,1),IF(X8="Geliştirilmeli",CHOOSE(RANDBETWEEN(1,5),1,1,1,1,2),""))))) | S8: =IF(OR('Öğrenci Listesi'!B9="",X8=""),"",IF(X8="Çok İyi",CHOOSE(RANDBETWEEN(1,5),4,4,4,4,3),IF(X8="İyi",CHOOSE(RANDBETWEEN(1,5),3,3,3,4,2),IF(X8="Yeterli",CHOOSE(RANDBETWEEN(1,5),2,2,2,3,1),IF(X8="Geliştirilmeli",CHOOSE(RANDBETWEEN(1,5),1,1,1,1,2),""))))) | T8: =IF(OR('Öğrenci Listesi'!B9="",X8=""),"",IF(X8="Çok İyi",CHOOSE(RANDBETWEEN(1,5),4,4,4,4,3),IF(X8="İyi",CHOOSE(RANDBETWEEN(1,5),3,3,3,4,2),IF(X8="Yeterli",CHOOSE(RANDBETWEEN(1,5),2,2,2,3,1),IF(X8="Geliştirilmeli",CHOOSE(RANDBETWEEN(1,5),1,1,1,1,2),""))))) | U8: =IF(OR('Öğrenci Listesi'!B9="",X8=""),"",IF(X8="Çok İyi",CHOOSE(RANDBETWEEN(1,5),4,4,4,4,3),IF(X8="İyi",CHOOSE(RANDBETWEEN(1,5),3,3,3,4,2),IF(X8="Yeterli",CHOOSE(RANDBETWEEN(1,5),2,2,2,3,1),IF(X8="Geliştirilmeli",CHOOSE(RANDBETWEEN(1,5),1,1,1,1,2),""))))) | V8: =IF(OR('Öğrenci Listesi'!B9="",X8=""),"",IF(X8="Çok İyi",CHOOSE(RANDBETWEEN(1,5),4,4,4,4,3),IF(X8="İyi",CHOOSE(RANDBETWEEN(1,5),3,3,3,4,2),IF(X8="Yeterli",CHOOSE(RANDBETWEEN(1,5),2,2,2,3,1),IF(X8="Geliştirilmeli",CHOOSE(RANDBETWEEN(1,5),1,1,1,1,2),""))))) | W8: =IF(OR('Öğrenci Listesi'!B9="",X8=""),"",ROUND(AVERAGE(C8:V8),2)) | X8: =IFERROR(IF('Öğrenci Listesi'!G9="","",IF(UPPER(TRIM('Öğrenci Listesi'!G9))="ÇOK İYİ","Çok İyi",IF(UPPER(TRIM('Öğrenci Listesi'!G9))="İYİ","İyi",IF(UPPER(TRIM('Öğrenci Listesi'!G9))="YETERLİ","Yeterli",IF(UPPER(TRIM('Öğrenci Listesi'!G9))="GELİŞTİRİLMELİ","Geliştirilmeli",'Öğrenci Listesi'!G9))))),"")
A9: =IFERROR(IF('Öğrenci Listesi'!A10="","",'Öğrenci Listesi'!A10),"") | B9: =IFERROR(IF('Öğrenci Listesi'!B10="","",'Öğrenci Listesi'!B10),"") | C9: =IF(OR('Öğrenci Listesi'!B10="",X9=""),"",IF(X9="Çok İyi",CHOOSE(RANDBETWEEN(1,5),4,4,4,4,3),IF(X9="İyi",CHOOSE(RANDBETWEEN(1,5),3,3,3,4,2),IF(X9="Yeterli",CHOOSE(RANDBETWEEN(1,5),2,2,2,3,1),IF(X9="Geliştirilmeli",CHOOSE(RANDBETWEEN(1,5),1,1,1,1,2),""))))) | D9: =IF(OR('Öğrenci Listesi'!B10="",X9=""),"",IF(X9="Çok İyi",CHOOSE(RANDBETWEEN(1,5),4,4,4,4,3),IF(X9="İyi",CHOOSE(RANDBETWEEN(1,5),3,3,3,4,2),IF(X9="Yeterli",CHOOSE(RANDBETWEEN(1,5),2,2,2,3,1),IF(X9="Geliştirilmeli",CHOOSE(RANDBETWEEN(1,5),1,1,1,1,2),""))))) | E9: =IF(OR('Öğrenci Listesi'!B10="",X9=""),"",IF(X9="Çok İyi",CHOOSE(RANDBETWEEN(1,5),4,4,4,4,3),IF(X9="İyi",CHOOSE(RANDBETWEEN(1,5),3,3,3,4,2),IF(X9="Yeterli",CHOOSE(RANDBETWEEN(1,5),2,2,2,3,1),IF(X9="Geliştirilmeli",CHOOSE(RANDBETWEEN(1,5),1,1,1,1,2),""))))) | F9: =IF(OR('Öğrenci Listesi'!B10="",X9=""),"",IF(X9="Çok İyi",CHOOSE(RANDBETWEEN(1,5),4,4,4,4,3),IF(X9="İyi",CHOOSE(RANDBETWEEN(1,5),3,3,3,4,2),IF(X9="Yeterli",CHOOSE(RANDBETWEEN(1,5),2,2,2,3,1),IF(X9="Geliştirilmeli",CHOOSE(RANDBETWEEN(1,5),1,1,1,1,2),""))))) | G9: =IF(OR('Öğrenci Listesi'!B10="",X9=""),"",IF(X9="Çok İyi",CHOOSE(RANDBETWEEN(1,5),4,4,4,4,3),IF(X9="İyi",CHOOSE(RANDBETWEEN(1,5),3,3,3,4,2),IF(X9="Yeterli",CHOOSE(RANDBETWEEN(1,5),2,2,2,3,1),IF(X9="Geliştirilmeli",CHOOSE(RANDBETWEEN(1,5),1,1,1,1,2),""))))) | H9: =IF(OR('Öğrenci Listesi'!B10="",X9=""),"",IF(X9="Çok İyi",CHOOSE(RANDBETWEEN(1,5),4,4,4,4,3),IF(X9="İyi",CHOOSE(RANDBETWEEN(1,5),3,3,3,4,2),IF(X9="Yeterli",CHOOSE(RANDBETWEEN(1,5),2,2,2,3,1),IF(X9="Geliştirilmeli",CHOOSE(RANDBETWEEN(1,5),1,1,1,1,2),""))))) | I9: =IF(OR('Öğrenci Listesi'!B10="",X9=""),"",IF(X9="Çok İyi",CHOOSE(RANDBETWEEN(1,5),4,4,4,4,3),IF(X9="İyi",CHOOSE(RANDBETWEEN(1,5),3,3,3,4,2),IF(X9="Yeterli",CHOOSE(RANDBETWEEN(1,5),2,2,2,3,1),IF(X9="Geliştirilmeli",CHOOSE(RANDBETWEEN(1,5),1,1,1,1,2),""))))) | J9: =IF(OR('Öğrenci Listesi'!B10="",X9=""),"",IF(X9="Çok İyi",CHOOSE(RANDBETWEEN(1,5),4,4,4,4,3),IF(X9="İyi",CHOOSE(RANDBETWEEN(1,5),3,3,3,4,2),IF(X9="Yeterli",CHOOSE(RANDBETWEEN(1,5),2,2,2,3,1),IF(X9="Geliştirilmeli",CHOOSE(RANDBETWEEN(1,5),1,1,1,1,2),""))))) | K9: =IF(OR('Öğrenci Listesi'!B10="",X9=""),"",IF(X9="Çok İyi",CHOOSE(RANDBETWEEN(1,5),4,4,4,4,3),IF(X9="İyi",CHOOSE(RANDBETWEEN(1,5),3,3,3,4,2),IF(X9="Yeterli",CHOOSE(RANDBETWEEN(1,5),2,2,2,3,1),IF(X9="Geliştirilmeli",CHOOSE(RANDBETWEEN(1,5),1,1,1,1,2),""))))) | L9: =IF(OR('Öğrenci Listesi'!B10="",X9=""),"",IF(X9="Çok İyi",CHOOSE(RANDBETWEEN(1,5),4,4,4,4,3),IF(X9="İyi",CHOOSE(RANDBETWEEN(1,5),3,3,3,4,2),IF(X9="Yeterli",CHOOSE(RANDBETWEEN(1,5),2,2,2,3,1),IF(X9="Geliştirilmeli",CHOOSE(RANDBETWEEN(1,5),1,1,1,1,2),""))))) | M9: =IF(OR('Öğrenci Listesi'!B10="",X9=""),"",IF(X9="Çok İyi",CHOOSE(RANDBETWEEN(1,5),4,4,4,4,3),IF(X9="İyi",CHOOSE(RANDBETWEEN(1,5),3,3,3,4,2),IF(X9="Yeterli",CHOOSE(RANDBETWEEN(1,5),2,2,2,3,1),IF(X9="Geliştirilmeli",CHOOSE(RANDBETWEEN(1,5),1,1,1,1,2),""))))) | N9: =IF(OR('Öğrenci Listesi'!B10="",X9=""),"",IF(X9="Çok İyi",CHOOSE(RANDBETWEEN(1,5),4,4,4,4,3),IF(X9="İyi",CHOOSE(RANDBETWEEN(1,5),3,3,3,4,2),IF(X9="Yeterli",CHOOSE(RANDBETWEEN(1,5),2,2,2,3,1),IF(X9="Geliştirilmeli",CHOOSE(RANDBETWEEN(1,5),1,1,1,1,2),""))))) | O9: =IF(OR('Öğrenci Listesi'!B10="",X9=""),"",IF(X9="Çok İyi",CHOOSE(RANDBETWEEN(1,5),4,4,4,4,3),IF(X9="İyi",CHOOSE(RANDBETWEEN(1,5),3,3,3,4,2),IF(X9="Yeterli",CHOOSE(RANDBETWEEN(1,5),2,2,2,3,1),IF(X9="Geliştirilmeli",CHOOSE(RANDBETWEEN(1,5),1,1,1,1,2),""))))) | P9: =IF(OR('Öğrenci Listesi'!B10="",X9=""),"",IF(X9="Çok İyi",CHOOSE(RANDBETWEEN(1,5),4,4,4,4,3),IF(X9="İyi",CHOOSE(RANDBETWEEN(1,5),3,3,3,4,2),IF(X9="Yeterli",CHOOSE(RANDBETWEEN(1,5),2,2,2,3,1),IF(X9="Geliştirilmeli",CHOOSE(RANDBETWEEN(1,5),1,1,1,1,2),""))))) | Q9: =IF(OR('Öğrenci Listesi'!B10="",X9=""),"",IF(X9="Çok İyi",CHOOSE(RANDBETWEEN(1,5),4,4,4,4,3),IF(X9="İyi",CHOOSE(RANDBETWEEN(1,5),3,3,3,4,2),IF(X9="Yeterli",CHOOSE(RANDBETWEEN(1,5),2,2,2,3,1),IF(X9="Geliştirilmeli",CHOOSE(RANDBETWEEN(1,5),1,1,1,1,2),""))))) | R9: =IF(OR('Öğrenci Listesi'!B10="",X9=""),"",IF(X9="Çok İyi",CHOOSE(RANDBETWEEN(1,5),4,4,4,4,3),IF(X9="İyi",CHOOSE(RANDBETWEEN(1,5),3,3,3,4,2),IF(X9="Yeterli",CHOOSE(RANDBETWEEN(1,5),2,2,2,3,1),IF(X9="Geliştirilmeli",CHOOSE(RANDBETWEEN(1,5),1,1,1,1,2),""))))) | S9: =IF(OR('Öğrenci Listesi'!B10="",X9=""),"",IF(X9="Çok İyi",CHOOSE(RANDBETWEEN(1,5),4,4,4,4,3),IF(X9="İyi",CHOOSE(RANDBETWEEN(1,5),3,3,3,4,2),IF(X9="Yeterli",CHOOSE(RANDBETWEEN(1,5),2,2,2,3,1),IF(X9="Geliştirilmeli",CHOOSE(RANDBETWEEN(1,5),1,1,1,1,2),""))))) | T9: =IF(OR('Öğrenci Listesi'!B10="",X9=""),"",IF(X9="Çok İyi",CHOOSE(RANDBETWEEN(1,5),4,4,4,4,3),IF(X9="İyi",CHOOSE(RANDBETWEEN(1,5),3,3,3,4,2),IF(X9="Yeterli",CHOOSE(RANDBETWEEN(1,5),2,2,2,3,1),IF(X9="Geliştirilmeli",CHOOSE(RANDBETWEEN(1,5),1,1,1,1,2),""))))) | U9: =IF(OR('Öğrenci Listesi'!B10="",X9=""),"",IF(X9="Çok İyi",CHOOSE(RANDBETWEEN(1,5),4,4,4,4,3),IF(X9="İyi",CHOOSE(RANDBETWEEN(1,5),3,3,3,4,2),IF(X9="Yeterli",CHOOSE(RANDBETWEEN(1,5),2,2,2,3,1),IF(X9="Geliştirilmeli",CHOOSE(RANDBETWEEN(1,5),1,1,1,1,2),""))))) | V9: =IF(OR('Öğrenci Listesi'!B10="",X9=""),"",IF(X9="Çok İyi",CHOOSE(RANDBETWEEN(1,5),4,4,4,4,3),IF(X9="İyi",CHOOSE(RANDBETWEEN(1,5),3,3,3,4,2),IF(X9="Yeterli",CHOOSE(RANDBETWEEN(1,5),2,2,2,3,1),IF(X9="Geliştirilmeli",CHOOSE(RANDBETWEEN(1,5),1,1,1,1,2),""))))) | W9: =IF(OR('Öğrenci Listesi'!B10="",X9=""),"",ROUND(AVERAGE(C9:V9),2)) | X9: =IFERROR(IF('Öğrenci Listesi'!G10="","",IF(UPPER(TRIM('Öğrenci Listesi'!G10))="ÇOK İYİ","Çok İyi",IF(UPPER(TRIM('Öğrenci Listesi'!G10))="İYİ","İyi",IF(UPPER(TRIM('Öğrenci Listesi'!G10))="YETERLİ","Yeterli",IF(UPPER(TRIM('Öğrenci Listesi'!G10))="GELİŞTİRİLMELİ","Geliştirilmeli",'Öğrenci Listesi'!G10))))),"")
A10: =IFERROR(IF('Öğrenci Listesi'!A11="","",'Öğrenci Listesi'!A11),"") | B10: =IFERROR(IF('Öğrenci Listesi'!B11="","",'Öğrenci Listesi'!B11),"") | C10: =IF(OR('Öğrenci Listesi'!B11="",X10=""),"",IF(X10="Çok İyi",CHOOSE(RANDBETWEEN(1,5),4,4,4,4,3),IF(X10="İyi",CHOOSE(RANDBETWEEN(1,5),3,3,3,4,2),IF(X10="Yeterli",CHOOSE(RANDBETWEEN(1,5),2,2,2,3,1),IF(X10="Geliştirilmeli",CHOOSE(RANDBETWEEN(1,5),1,1,1,1,2),""))))) | D10: =IF(OR('Öğrenci Listesi'!B11="",X10=""),"",IF(X10="Çok İyi",CHOOSE(RANDBETWEEN(1,5),4,4,4,4,3),IF(X10="İyi",CHOOSE(RANDBETWEEN(1,5),3,3,3,4,2),IF(X10="Yeterli",CHOOSE(RANDBETWEEN(1,5),2,2,2,3,1),IF(X10="Geliştirilmeli",CHOOSE(RANDBETWEEN(1,5),1,1,1,1,2),""))))) | E10: =IF(OR('Öğrenci Listesi'!B11="",X10=""),"",IF(X10="Çok İyi",CHOOSE(RANDBETWEEN(1,5),4,4,4,4,3),IF(X10="İyi",CHOOSE(RANDBETWEEN(1,5),3,3,3,4,2),IF(X10="Yeterli",CHOOSE(RANDBETWEEN(1,5),2,2,2,3,1),IF(X10="Geliştirilmeli",CHOOSE(RANDBETWEEN(1,5),1,1,1,1,2),""))))) | F10: =IF(OR('Öğrenci Listesi'!B11="",X10=""),"",IF(X10="Çok İyi",CHOOSE(RANDBETWEEN(1,5),4,4,4,4,3),IF(X10="İyi",CHOOSE(RANDBETWEEN(1,5),3,3,3,4,2),IF(X10="Yeterli",CHOOSE(RANDBETWEEN(1,5),2,2,2,3,1),IF(X10="Geliştirilmeli",CHOOSE(RANDBETWEEN(1,5),1,1,1,1,2),""))))) | G10: =IF(OR('Öğrenci Listesi'!B11="",X10=""),"",IF(X10="Çok İyi",CHOOSE(RANDBETWEEN(1,5),4,4,4,4,3),IF(X10="İyi",CHOOSE(RANDBETWEEN(1,5),3,3,3,4,2),IF(X10="Yeterli",CHOOSE(RANDBETWEEN(1,5),2,2,2,3,1),IF(X10="Geliştirilmeli",CHOOSE(RANDBETWEEN(1,5),1,1,1,1,2),""))))) | H10: =IF(OR('Öğrenci Listesi'!B11="",X10=""),"",IF(X10="Çok İyi",CHOOSE(RANDBETWEEN(1,5),4,4,4,4,3),IF(X10="İyi",CHOOSE(RANDBETWEEN(1,5),3,3,3,4,2),IF(X10="Yeterli",CHOOSE(RANDBETWEEN(1,5),2,2,2,3,1),IF(X10="Geliştirilmeli",CHOOSE(RANDBETWEEN(1,5),1,1,1,1,2),""))))) | I10: =IF(OR('Öğrenci Listesi'!B11="",X10=""),"",IF(X10="Çok İyi",CHOOSE(RANDBETWEEN(1,5),4,4,4,4,3),IF(X10="İyi",CHOOSE(RANDBETWEEN(1,5),3,3,3,4,2),IF(X10="Yeterli",CHOOSE(RANDBETWEEN(1,5),2,2,2,3,1),IF(X10="Geliştirilmeli",CHOOSE(RANDBETWEEN(1,5),1,1,1,1,2),""))))) | J10: =IF(OR('Öğrenci Listesi'!B11="",X10=""),"",IF(X10="Çok İyi",CHOOSE(RANDBETWEEN(1,5),4,4,4,4,3),IF(X10="İyi",CHOOSE(RANDBETWEEN(1,5),3,3,3,4,2),IF(X10="Yeterli",CHOOSE(RANDBETWEEN(1,5),2,2,2,3,1),IF(X10="Geliştirilmeli",CHOOSE(RANDBETWEEN(1,5),1,1,1,1,2),""))))) | K10: =IF(OR('Öğrenci Listesi'!B11="",X10=""),"",IF(X10="Çok İyi",CHOOSE(RANDBETWEEN(1,5),4,4,4,4,3),IF(X10="İyi",CHOOSE(RANDBETWEEN(1,5),3,3,3,4,2),IF(X10="Yeterli",CHOOSE(RANDBETWEEN(1,5),2,2,2,3,1),IF(X10="Geliştirilmeli",CHOOSE(RANDBETWEEN(1,5),1,1,1,1,2),""))))) | L10: =IF(OR('Öğrenci Listesi'!B11="",X10=""),"",IF(X10="Çok İyi",CHOOSE(RANDBETWEEN(1,5),4,4,4,4,3),IF(X10="İyi",CHOOSE(RANDBETWEEN(1,5),3,3,3,4,2),IF(X10="Yeterli",CHOOSE(RANDBETWEEN(1,5),2,2,2,3,1),IF(X10="Geliştirilmeli",CHOOSE(RANDBETWEEN(1,5),1,1,1,1,2),""))))) | M10: =IF(OR('Öğrenci Listesi'!B11="",X10=""),"",IF(X10="Çok İyi",CHOOSE(RANDBETWEEN(1,5),4,4,4,4,3),IF(X10="İyi",CHOOSE(RANDBETWEEN(1,5),3,3,3,4,2),IF(X10="Yeterli",CHOOSE(RANDBETWEEN(1,5),2,2,2,3,1),IF(X10="Geliştirilmeli",CHOOSE(RANDBETWEEN(1,5),1,1,1,1,2),""))))) | N10: =IF(OR('Öğrenci Listesi'!B11="",X10=""),"",IF(X10="Çok İyi",CHOOSE(RANDBETWEEN(1,5),4,4,4,4,3),IF(X10="İyi",CHOOSE(RANDBETWEEN(1,5),3,3,3,4,2),IF(X10="Yeterli",CHOOSE(RANDBETWEEN(1,5),2,2,2,3,1),IF(X10="Geliştirilmeli",CHOOSE(RANDBETWEEN(1,5),1,1,1,1,2),""))))) | O10: =IF(OR('Öğrenci Listesi'!B11="",X10=""),"",IF(X10="Çok İyi",CHOOSE(RANDBETWEEN(1,5),4,4,4,4,3),IF(X10="İyi",CHOOSE(RANDBETWEEN(1,5),3,3,3,4,2),IF(X10="Yeterli",CHOOSE(RANDBETWEEN(1,5),2,2,2,3,1),IF(X10="Geliştirilmeli",CHOOSE(RANDBETWEEN(1,5),1,1,1,1,2),""))))) | P10: =IF(OR('Öğrenci Listesi'!B11="",X10=""),"",IF(X10="Çok İyi",CHOOSE(RANDBETWEEN(1,5),4,4,4,4,3),IF(X10="İyi",CHOOSE(RANDBETWEEN(1,5),3,3,3,4,2),IF(X10="Yeterli",CHOOSE(RANDBETWEEN(1,5),2,2,2,3,1),IF(X10="Geliştirilmeli",CHOOSE(RANDBETWEEN(1,5),1,1,1,1,2),""))))) | Q10: =IF(OR('Öğrenci Listesi'!B11="",X10=""),"",IF(X10="Çok İyi",CHOOSE(RANDBETWEEN(1,5),4,4,4,4,3),IF(X10="İyi",CHOOSE(RANDBETWEEN(1,5),3,3,3,4,2),IF(X10="Yeterli",CHOOSE(RANDBETWEEN(1,5),2,2,2,3,1),IF(X10="Geliştirilmeli",CHOOSE(RANDBETWEEN(1,5),1,1,1,1,2),""))))) | R10: =IF(OR('Öğrenci Listesi'!B11="",X10=""),"",IF(X10="Çok İyi",CHOOSE(RANDBETWEEN(1,5),4,4,4,4,3),IF(X10="İyi",CHOOSE(RANDBETWEEN(1,5),3,3,3,4,2),IF(X10="Yeterli",CHOOSE(RANDBETWEEN(1,5),2,2,2,3,1),IF(X10="Geliştirilmeli",CHOOSE(RANDBETWEEN(1,5),1,1,1,1,2),""))))) | S10: =IF(OR('Öğrenci Listesi'!B11="",X10=""),"",IF(X10="Çok İyi",CHOOSE(RANDBETWEEN(1,5),4,4,4,4,3),IF(X10="İyi",CHOOSE(RANDBETWEEN(1,5),3,3,3,4,2),IF(X10="Yeterli",CHOOSE(RANDBETWEEN(1,5),2,2,2,3,1),IF(X10="Geliştirilmeli",CHOOSE(RANDBETWEEN(1,5),1,1,1,1,2),""))))) | T10: =IF(OR('Öğrenci Listesi'!B11="",X10=""),"",IF(X10="Çok İyi",CHOOSE(RANDBETWEEN(1,5),4,4,4,4,3),IF(X10="İyi",CHOOSE(RANDBETWEEN(1,5),3,3,3,4,2),IF(X10="Yeterli",CHOOSE(RANDBETWEEN(1,5),2,2,2,3,1),IF(X10="Geliştirilmeli",CHOOSE(RANDBETWEEN(1,5),1,1,1,1,2),""))))) | U10: =IF(OR('Öğrenci Listesi'!B11="",X10=""),"",IF(X10="Çok İyi",CHOOSE(RANDBETWEEN(1,5),4,4,4,4,3),IF(X10="İyi",CHOOSE(RANDBETWEEN(1,5),3,3,3,4,2),IF(X10="Yeterli",CHOOSE(RANDBETWEEN(1,5),2,2,2,3,1),IF(X10="Geliştirilmeli",CHOOSE(RANDBETWEEN(1,5),1,1,1,1,2),""))))) | V10: =IF(OR('Öğrenci Listesi'!B11="",X10=""),"",IF(X10="Çok İyi",CHOOSE(RANDBETWEEN(1,5),4,4,4,4,3),IF(X10="İyi",CHOOSE(RANDBETWEEN(1,5),3,3,3,4,2),IF(X10="Yeterli",CHOOSE(RANDBETWEEN(1,5),2,2,2,3,1),IF(X10="Geliştirilmeli",CHOOSE(RANDBETWEEN(1,5),1,1,1,1,2),""))))) | W10: =IF(OR('Öğrenci Listesi'!B11="",X10=""),"",ROUND(AVERAGE(C10:V10),2)) | X10: =IFERROR(IF('Öğrenci Listesi'!G11="","",IF(UPPER(TRIM('Öğrenci Listesi'!G11))="ÇOK İYİ","Çok İyi",IF(UPPER(TRIM('Öğrenci Listesi'!G11))="İYİ","İyi",IF(UPPER(TRIM('Öğrenci Listesi'!G11))="YETERLİ","Yeterli",IF(UPPER(TRIM('Öğrenci Listesi'!G11))="GELİŞTİRİLMELİ","Geliştirilmeli",'Öğrenci Listesi'!G11))))),"")
A11: =IFERROR(IF('Öğrenci Listesi'!A12="","",'Öğrenci Listesi'!A12),"") | B11: =IFERROR(IF('Öğrenci Listesi'!B12="","",'Öğrenci Listesi'!B12),"") | C11: =IF(OR('Öğrenci Listesi'!B12="",X11=""),"",IF(X11="Çok İyi",CHOOSE(RANDBETWEEN(1,5),4,4,4,4,3),IF(X11="İyi",CHOOSE(RANDBETWEEN(1,5),3,3,3,4,2),IF(X11="Yeterli",CHOOSE(RANDBETWEEN(1,5),2,2,2,3,1),IF(X11="Geliştirilmeli",CHOOSE(RANDBETWEEN(1,5),1,1,1,1,2),""))))) | D11: =IF(OR('Öğrenci Listesi'!B12="",X11=""),"",IF(X11="Çok İyi",CHOOSE(RANDBETWEEN(1,5),4,4,4,4,3),IF(X11="İyi",CHOOSE(RANDBETWEEN(1,5),3,3,3,4,2),IF(X11="Yeterli",CHOOSE(RANDBETWEEN(1,5),2,2,2,3,1),IF(X11="Geliştirilmeli",CHOOSE(RANDBETWEEN(1,5),1,1,1,1,2),""))))) | E11: =IF(OR('Öğrenci Listesi'!B12="",X11=""),"",IF(X11="Çok İyi",CHOOSE(RANDBETWEEN(1,5),4,4,4,4,3),IF(X11="İyi",CHOOSE(RANDBETWEEN(1,5),3,3,3,4,2),IF(X11="Yeterli",CHOOSE(RANDBETWEEN(1,5),2,2,2,3,1),IF(X11="Geliştirilmeli",CHOOSE(RANDBETWEEN(1,5),1,1,1,1,2),""))))) | F11: =IF(OR('Öğrenci Listesi'!B12="",X11=""),"",IF(X11="Çok İyi",CHOOSE(RANDBETWEEN(1,5),4,4,4,4,3),IF(X11="İyi",CHOOSE(RANDBETWEEN(1,5),3,3,3,4,2),IF(X11="Yeterli",CHOOSE(RANDBETWEEN(1,5),2,2,2,3,1),IF(X11="Geliştirilmeli",CHOOSE(RANDBETWEEN(1,5),1,1,1,1,2),""))))) | G11: =IF(OR('Öğrenci Listesi'!B12="",X11=""),"",IF(X11="Çok İyi",CHOOSE(RANDBETWEEN(1,5),4,4,4,4,3),IF(X11="İyi",CHOOSE(RANDBETWEEN(1,5),3,3,3,4,2),IF(X11="Yeterli",CHOOSE(RANDBETWEEN(1,5),2,2,2,3,1),IF(X11="Geliştirilmeli",CHOOSE(RANDBETWEEN(1,5),1,1,1,1,2),""))))) | H11: =IF(OR('Öğrenci Listesi'!B12="",X11=""),"",IF(X11="Çok İyi",CHOOSE(RANDBETWEEN(1,5),4,4,4,4,3),IF(X11="İyi",CHOOSE(RANDBETWEEN(1,5),3,3,3,4,2),IF(X11="Yeterli",CHOOSE(RANDBETWEEN(1,5),2,2,2,3,1),IF(X11="Geliştirilmeli",CHOOSE(RANDBETWEEN(1,5),1,1,1,1,2),""))))) | I11: =IF(OR('Öğrenci Listesi'!B12="",X11=""),"",IF(X11="Çok İyi",CHOOSE(RANDBETWEEN(1,5),4,4,4,4,3),IF(X11="İyi",CHOOSE(RANDBETWEEN(1,5),3,3,3,4,2),IF(X11="Yeterli",CHOOSE(RANDBETWEEN(1,5),2,2,2,3,1),IF(X11="Geliştirilmeli",CHOOSE(RANDBETWEEN(1,5),1,1,1,1,2),""))))) | J11: =IF(OR('Öğrenci Listesi'!B12="",X11=""),"",IF(X11="Çok İyi",CHOOSE(RANDBETWEEN(1,5),4,4,4,4,3),IF(X11="İyi",CHOOSE(RANDBETWEEN(1,5),3,3,3,4,2),IF(X11="Yeterli",CHOOSE(RANDBETWEEN(1,5),2,2,2,3,1),IF(X11="Geliştirilmeli",CHOOSE(RANDBETWEEN(1,5),1,1,1,1,2),""))))) | K11: =IF(OR('Öğrenci Listesi'!B12="",X11=""),"",IF(X11="Çok İyi",CHOOSE(RANDBETWEEN(1,5),4,4,4,4,3),IF(X11="İyi",CHOOSE(RANDBETWEEN(1,5),3,3,3,4,2),IF(X11="Yeterli",CHOOSE(RANDBETWEEN(1,5),2,2,2,3,1),IF(X11="Geliştirilmeli",CHOOSE(RANDBETWEEN(1,5),1,1,1,1,2),""))))) | L11: =IF(OR('Öğrenci Listesi'!B12="",X11=""),"",IF(X11="Çok İyi",CHOOSE(RANDBETWEEN(1,5),4,4,4,4,3),IF(X11="İyi",CHOOSE(RANDBETWEEN(1,5),3,3,3,4,2),IF(X11="Yeterli",CHOOSE(RANDBETWEEN(1,5),2,2,2,3,1),IF(X11="Geliştirilmeli",CHOOSE(RANDBETWEEN(1,5),1,1,1,1,2),""))))) | M11: =IF(OR('Öğrenci Listesi'!B12="",X11=""),"",IF(X11="Çok İyi",CHOOSE(RANDBETWEEN(1,5),4,4,4,4,3),IF(X11="İyi",CHOOSE(RANDBETWEEN(1,5),3,3,3,4,2),IF(X11="Yeterli",CHOOSE(RANDBETWEEN(1,5),2,2,2,3,1),IF(X11="Geliştirilmeli",CHOOSE(RANDBETWEEN(1,5),1,1,1,1,2),""))))) | N11: =IF(OR('Öğrenci Listesi'!B12="",X11=""),"",IF(X11="Çok İyi",CHOOSE(RANDBETWEEN(1,5),4,4,4,4,3),IF(X11="İyi",CHOOSE(RANDBETWEEN(1,5),3,3,3,4,2),IF(X11="Yeterli",CHOOSE(RANDBETWEEN(1,5),2,2,2,3,1),IF(X11="Geliştirilmeli",CHOOSE(RANDBETWEEN(1,5),1,1,1,1,2),""))))) | O11: =IF(OR('Öğrenci Listesi'!B12="",X11=""),"",IF(X11="Çok İyi",CHOOSE(RANDBETWEEN(1,5),4,4,4,4,3),IF(X11="İyi",CHOOSE(RANDBETWEEN(1,5),3,3,3,4,2),IF(X11="Yeterli",CHOOSE(RANDBETWEEN(1,5),2,2,2,3,1),IF(X11="Geliştirilmeli",CHOOSE(RANDBETWEEN(1,5),1,1,1,1,2),""))))) | P11: =IF(OR('Öğrenci Listesi'!B12="",X11=""),"",IF(X11="Çok İyi",CHOOSE(RANDBETWEEN(1,5),4,4,4,4,3),IF(X11="İyi",CHOOSE(RANDBETWEEN(1,5),3,3,3,4,2),IF(X11="Yeterli",CHOOSE(RANDBETWEEN(1,5),2,2,2,3,1),IF(X11="Geliştirilmeli",CHOOSE(RANDBETWEEN(1,5),1,1,1,1,2),""))))) | Q11: =IF(OR('Öğrenci Listesi'!B12="",X11=""),"",IF(X11="Çok İyi",CHOOSE(RANDBETWEEN(1,5),4,4,4,4,3),IF(X11="İyi",CHOOSE(RANDBETWEEN(1,5),3,3,3,4,2),IF(X11="Yeterli",CHOOSE(RANDBETWEEN(1,5),2,2,2,3,1),IF(X11="Geliştirilmeli",CHOOSE(RANDBETWEEN(1,5),1,1,1,1,2),""))))) | R11: =IF(OR('Öğrenci Listesi'!B12="",X11=""),"",IF(X11="Çok İyi",CHOOSE(RANDBETWEEN(1,5),4,4,4,4,3),IF(X11="İyi",CHOOSE(RANDBETWEEN(1,5),3,3,3,4,2),IF(X11="Yeterli",CHOOSE(RANDBETWEEN(1,5),2,2,2,3,1),IF(X11="Geliştirilmeli",CHOOSE(RANDBETWEEN(1,5),1,1,1,1,2),""))))) | S11: =IF(OR('Öğrenci Listesi'!B12="",X11=""),"",IF(X11="Çok İyi",CHOOSE(RANDBETWEEN(1,5),4,4,4,4,3),IF(X11="İyi",CHOOSE(RANDBETWEEN(1,5),3,3,3,4,2),IF(X11="Yeterli",CHOOSE(RANDBETWEEN(1,5),2,2,2,3,1),IF(X11="Geliştirilmeli",CHOOSE(RANDBETWEEN(1,5),1,1,1,1,2),""))))) | T11: =IF(OR('Öğrenci Listesi'!B12="",X11=""),"",IF(X11="Çok İyi",CHOOSE(RANDBETWEEN(1,5),4,4,4,4,3),IF(X11="İyi",CHOOSE(RANDBETWEEN(1,5),3,3,3,4,2),IF(X11="Yeterli",CHOOSE(RANDBETWEEN(1,5),2,2,2,3,1),IF(X11="Geliştirilmeli",CHOOSE(RANDBETWEEN(1,5),1,1,1,1,2),""))))) | U11: =IF(OR('Öğrenci Listesi'!B12="",X11=""),"",IF(X11="Çok İyi",CHOOSE(RANDBETWEEN(1,5),4,4,4,4,3),IF(X11="İyi",CHOOSE(RANDBETWEEN(1,5),3,3,3,4,2),IF(X11="Yeterli",CHOOSE(RANDBETWEEN(1,5),2,2,2,3,1),IF(X11="Geliştirilmeli",CHOOSE(RANDBETWEEN(1,5),1,1,1,1,2),""))))) | V11: =IF(OR('Öğrenci Listesi'!B12="",X11=""),"",IF(X11="Çok İyi",CHOOSE(RANDBETWEEN(1,5),4,4,4,4,3),IF(X11="İyi",CHOOSE(RANDBETWEEN(1,5),3,3,3,4,2),IF(X11="Yeterli",CHOOSE(RANDBETWEEN(1,5),2,2,2,3,1),IF(X11="Geliştirilmeli",CHOOSE(RANDBETWEEN(1,5),1,1,1,1,2),""))))) | W11: =IF(OR('Öğrenci Listesi'!B12="",X11=""),"",ROUND(AVERAGE(C11:V11),2)) | X11: =IFERROR(IF('Öğrenci Listesi'!G12="","",IF(UPPER(TRIM('Öğrenci Listesi'!G12))="ÇOK İYİ","Çok İyi",IF(UPPER(TRIM('Öğrenci Listesi'!G12))="İYİ","İyi",IF(UPPER(TRIM('Öğrenci Listesi'!G12))="YETERLİ","Yeterli",IF(UPPER(TRIM('Öğrenci Listesi'!G12))="GELİŞTİRİLMELİ","Geliştirilmeli",'Öğrenci Listesi'!G12))))),"")
A12: =IFERROR(IF('Öğrenci Listesi'!A13="","",'Öğrenci Listesi'!A13),"") | B12: =IFERROR(IF('Öğrenci Listesi'!B13="","",'Öğrenci Listesi'!B13),"") | C12: =IF(OR('Öğrenci Listesi'!B13="",X12=""),"",IF(X12="Çok İyi",CHOOSE(RANDBETWEEN(1,5),4,4,4,4,3),IF(X12="İyi",CHOOSE(RANDBETWEEN(1,5),3,3,3,4,2),IF(X12="Yeterli",CHOOSE(RANDBETWEEN(1,5),2,2,2,3,1),IF(X12="Geliştirilmeli",CHOOSE(RANDBETWEEN(1,5),1,1,1,1,2),""))))) | D12: =IF(OR('Öğrenci Listesi'!B13="",X12=""),"",IF(X12="Çok İyi",CHOOSE(RANDBETWEEN(1,5),4,4,4,4,3),IF(X12="İyi",CHOOSE(RANDBETWEEN(1,5),3,3,3,4,2),IF(X12="Yeterli",CHOOSE(RANDBETWEEN(1,5),2,2,2,3,1),IF(X12="Geliştirilmeli",CHOOSE(RANDBETWEEN(1,5),1,1,1,1,2),""))))) | E12: =IF(OR('Öğrenci Listesi'!B13="",X12=""),"",IF(X12="Çok İyi",CHOOSE(RANDBETWEEN(1,5),4,4,4,4,3),IF(X12="İyi",CHOOSE(RANDBETWEEN(1,5),3,3,3,4,2),IF(X12="Yeterli",CHOOSE(RANDBETWEEN(1,5),2,2,2,3,1),IF(X12="Geliştirilmeli",CHOOSE(RANDBETWEEN(1,5),1,1,1,1,2),""))))) | F12: =IF(OR('Öğrenci Listesi'!B13="",X12=""),"",IF(X12="Çok İyi",CHOOSE(RANDBETWEEN(1,5),4,4,4,4,3),IF(X12="İyi",CHOOSE(RANDBETWEEN(1,5),3,3,3,4,2),IF(X12="Yeterli",CHOOSE(RANDBETWEEN(1,5),2,2,2,3,1),IF(X12="Geliştirilmeli",CHOOSE(RANDBETWEEN(1,5),1,1,1,1,2),""))))) | G12: =IF(OR('Öğrenci Listesi'!B13="",X12=""),"",IF(X12="Çok İyi",CHOOSE(RANDBETWEEN(1,5),4,4,4,4,3),IF(X12="İyi",CHOOSE(RANDBETWEEN(1,5),3,3,3,4,2),IF(X12="Yeterli",CHOOSE(RANDBETWEEN(1,5),2,2,2,3,1),IF(X12="Geliştirilmeli",CHOOSE(RANDBETWEEN(1,5),1,1,1,1,2),""))))) | H12: =IF(OR('Öğrenci Listesi'!B13="",X12=""),"",IF(X12="Çok İyi",CHOOSE(RANDBETWEEN(1,5),4,4,4,4,3),IF(X12="İyi",CHOOSE(RANDBETWEEN(1,5),3,3,3,4,2),IF(X12="Yeterli",CHOOSE(RANDBETWEEN(1,5),2,2,2,3,1),IF(X12="Geliştirilmeli",CHOOSE(RANDBETWEEN(1,5),1,1,1,1,2),""))))) | I12: =IF(OR('Öğrenci Listesi'!B13="",X12=""),"",IF(X12="Çok İyi",CHOOSE(RANDBETWEEN(1,5),4,4,4,4,3),IF(X12="İyi",CHOOSE(RANDBETWEEN(1,5),3,3,3,4,2),IF(X12="Yeterli",CHOOSE(RANDBETWEEN(1,5),2,2,2,3,1),IF(X12="Geliştirilmeli",CHOOSE(RANDBETWEEN(1,5),1,1,1,1,2),""))))) | J12: =IF(OR('Öğrenci Listesi'!B13="",X12=""),"",IF(X12="Çok İyi",CHOOSE(RANDBETWEEN(1,5),4,4,4,4,3),IF(X12="İyi",CHOOSE(RANDBETWEEN(1,5),3,3,3,4,2),IF(X12="Yeterli",CHOOSE(RANDBETWEEN(1,5),2,2,2,3,1),IF(X12="Geliştirilmeli",CHOOSE(RANDBETWEEN(1,5),1,1,1,1,2),""))))) | K12: =IF(OR('Öğrenci Listesi'!B13="",X12=""),"",IF(X12="Çok İyi",CHOOSE(RANDBETWEEN(1,5),4,4,4,4,3),IF(X12="İyi",CHOOSE(RANDBETWEEN(1,5),3,3,3,4,2),IF(X12="Yeterli",CHOOSE(RANDBETWEEN(1,5),2,2,2,3,1),IF(X12="Geliştirilmeli",CHOOSE(RANDBETWEEN(1,5),1,1,1,1,2),""))))) | L12: =IF(OR('Öğrenci Listesi'!B13="",X12=""),"",IF(X12="Çok İyi",CHOOSE(RANDBETWEEN(1,5),4,4,4,4,3),IF(X12="İyi",CHOOSE(RANDBETWEEN(1,5),3,3,3,4,2),IF(X12="Yeterli",CHOOSE(RANDBETWEEN(1,5),2,2,2,3,1),IF(X12="Geliştirilmeli",CHOOSE(RANDBETWEEN(1,5),1,1,1,1,2),""))))) | M12: =IF(OR('Öğrenci Listesi'!B13="",X12=""),"",IF(X12="Çok İyi",CHOOSE(RANDBETWEEN(1,5),4,4,4,4,3),IF(X12="İyi",CHOOSE(RANDBETWEEN(1,5),3,3,3,4,2),IF(X12="Yeterli",CHOOSE(RANDBETWEEN(1,5),2,2,2,3,1),IF(X12="Geliştirilmeli",CHOOSE(RANDBETWEEN(1,5),1,1,1,1,2),""))))) | N12: =IF(OR('Öğrenci Listesi'!B13="",X12=""),"",IF(X12="Çok İyi",CHOOSE(RANDBETWEEN(1,5),4,4,4,4,3),IF(X12="İyi",CHOOSE(RANDBETWEEN(1,5),3,3,3,4,2),IF(X12="Yeterli",CHOOSE(RANDBETWEEN(1,5),2,2,2,3,1),IF(X12="Geliştirilmeli",CHOOSE(RANDBETWEEN(1,5),1,1,1,1,2),""))))) | O12: =IF(OR('Öğrenci Listesi'!B13="",X12=""),"",IF(X12="Çok İyi",CHOOSE(RANDBETWEEN(1,5),4,4,4,4,3),IF(X12="İyi",CHOOSE(RANDBETWEEN(1,5),3,3,3,4,2),IF(X12="Yeterli",CHOOSE(RANDBETWEEN(1,5),2,2,2,3,1),IF(X12="Geliştirilmeli",CHOOSE(RANDBETWEEN(1,5),1,1,1,1,2),""))))) | P12: =IF(OR('Öğrenci Listesi'!B13="",X12=""),"",IF(X12="Çok İyi",CHOOSE(RANDBETWEEN(1,5),4,4,4,4,3),IF(X12="İyi",CHOOSE(RANDBETWEEN(1,5),3,3,3,4,2),IF(X12="Yeterli",CHOOSE(RANDBETWEEN(1,5),2,2,2,3,1),IF(X12="Geliştirilmeli",CHOOSE(RANDBETWEEN(1,5),1,1,1,1,2),""))))) | Q12: =IF(OR('Öğrenci Listesi'!B13="",X12=""),"",IF(X12="Çok İyi",CHOOSE(RANDBETWEEN(1,5),4,4,4,4,3),IF(X12="İyi",CHOOSE(RANDBETWEEN(1,5),3,3,3,4,2),IF(X12="Yeterli",CHOOSE(RANDBETWEEN(1,5),2,2,2,3,1),IF(X12="Geliştirilmeli",CHOOSE(RANDBETWEEN(1,5),1,1,1,1,2),""))))) | R12: =IF(OR('Öğrenci Listesi'!B13="",X12=""),"",IF(X12="Çok İyi",CHOOSE(RANDBETWEEN(1,5),4,4,4,4,3),IF(X12="İyi",CHOOSE(RANDBETWEEN(1,5),3,3,3,4,2),IF(X12="Yeterli",CHOOSE(RANDBETWEEN(1,5),2,2,2,3,1),IF(X12="Geliştirilmeli",CHOOSE(RANDBETWEEN(1,5),1,1,1,1,2),""))))) | S12: =IF(OR('Öğrenci Listesi'!B13="",X12=""),"",IF(X12="Çok İyi",CHOOSE(RANDBETWEEN(1,5),4,4,4,4,3),IF(X12="İyi",CHOOSE(RANDBETWEEN(1,5),3,3,3,4,2),IF(X12="Yeterli",CHOOSE(RANDBETWEEN(1,5),2,2,2,3,1),IF(X12="Geliştirilmeli",CHOOSE(RANDBETWEEN(1,5),1,1,1,1,2),""))))) | T12: =IF(OR('Öğrenci Listesi'!B13="",X12=""),"",IF(X12="Çok İyi",CHOOSE(RANDBETWEEN(1,5),4,4,4,4,3),IF(X12="İyi",CHOOSE(RANDBETWEEN(1,5),3,3,3,4,2),IF(X12="Yeterli",CHOOSE(RANDBETWEEN(1,5),2,2,2,3,1),IF(X12="Geliştirilmeli",CHOOSE(RANDBETWEEN(1,5),1,1,1,1,2),""))))) | U12: =IF(OR('Öğrenci Listesi'!B13="",X12=""),"",IF(X12="Çok İyi",CHOOSE(RANDBETWEEN(1,5),4,4,4,4,3),IF(X12="İyi",CHOOSE(RANDBETWEEN(1,5),3,3,3,4,2),IF(X12="Yeterli",CHOOSE(RANDBETWEEN(1,5),2,2,2,3,1),IF(X12="Geliştirilmeli",CHOOSE(RANDBETWEEN(1,5),1,1,1,1,2),""))))) | V12: =IF(OR('Öğrenci Listesi'!B13="",X12=""),"",IF(X12="Çok İyi",CHOOSE(RANDBETWEEN(1,5),4,4,4,4,3),IF(X12="İyi",CHOOSE(RANDBETWEEN(1,5),3,3,3,4,2),IF(X12="Yeterli",CHOOSE(RANDBETWEEN(1,5),2,2,2,3,1),IF(X12="Geliştirilmeli",CHOOSE(RANDBETWEEN(1,5),1,1,1,1,2),""))))) | W12: =IF(OR('Öğrenci Listesi'!B13="",X12=""),"",ROUND(AVERAGE(C12:V12),2)) | X12: =IFERROR(IF('Öğrenci Listesi'!G13="","",IF(UPPER(TRIM('Öğrenci Listesi'!G13))="ÇOK İYİ","Çok İyi",IF(UPPER(TRIM('Öğrenci Listesi'!G13))="İYİ","İyi",IF(UPPER(TRIM('Öğrenci Listesi'!G13))="YETERLİ","Yeterli",IF(UPPER(TRIM('Öğrenci Listesi'!G13))="GELİŞTİRİLMELİ","Geliştirilmeli",'Öğrenci Listesi'!G13))))),"")
A13: =IFERROR(IF('Öğrenci Listesi'!A14="","",'Öğrenci Listesi'!A14),"") | B13: =IFERROR(IF('Öğrenci Listesi'!B14="","",'Öğrenci Listesi'!B14),"") | C13: =IF(OR('Öğrenci Listesi'!B14="",X13=""),"",IF(X13="Çok İyi",CHOOSE(RANDBETWEEN(1,5),4,4,4,4,3),IF(X13="İyi",CHOOSE(RANDBETWEEN(1,5),3,3,3,4,2),IF(X13="Yeterli",CHOOSE(RANDBETWEEN(1,5),2,2,2,3,1),IF(X13="Geliştirilmeli",CHOOSE(RANDBETWEEN(1,5),1,1,1,1,2),""))))) | D13: =IF(OR('Öğrenci Listesi'!B14="",X13=""),"",IF(X13="Çok İyi",CHOOSE(RANDBETWEEN(1,5),4,4,4,4,3),IF(X13="İyi",CHOOSE(RANDBETWEEN(1,5),3,3,3,4,2),IF(X13="Yeterli",CHOOSE(RANDBETWEEN(1,5),2,2,2,3,1),IF(X13="Geliştirilmeli",CHOOSE(RANDBETWEEN(1,5),1,1,1,1,2),""))))) | E13: =IF(OR('Öğrenci Listesi'!B14="",X13=""),"",IF(X13="Çok İyi",CHOOSE(RANDBETWEEN(1,5),4,4,4,4,3),IF(X13="İyi",CHOOSE(RANDBETWEEN(1,5),3,3,3,4,2),IF(X13="Yeterli",CHOOSE(RANDBETWEEN(1,5),2,2,2,3,1),IF(X13="Geliştirilmeli",CHOOSE(RANDBETWEEN(1,5),1,1,1,1,2),""))))) | F13: =IF(OR('Öğrenci Listesi'!B14="",X13=""),"",IF(X13="Çok İyi",CHOOSE(RANDBETWEEN(1,5),4,4,4,4,3),IF(X13="İyi",CHOOSE(RANDBETWEEN(1,5),3,3,3,4,2),IF(X13="Yeterli",CHOOSE(RANDBETWEEN(1,5),2,2,2,3,1),IF(X13="Geliştirilmeli",CHOOSE(RANDBETWEEN(1,5),1,1,1,1,2),""))))) | G13: =IF(OR('Öğrenci Listesi'!B14="",X13=""),"",IF(X13="Çok İyi",CHOOSE(RANDBETWEEN(1,5),4,4,4,4,3),IF(X13="İyi",CHOOSE(RANDBETWEEN(1,5),3,3,3,4,2),IF(X13="Yeterli",CHOOSE(RANDBETWEEN(1,5),2,2,2,3,1),IF(X13="Geliştirilmeli",CHOOSE(RANDBETWEEN(1,5),1,1,1,1,2),""))))) | H13: =IF(OR('Öğrenci Listesi'!B14="",X13=""),"",IF(X13="Çok İyi",CHOOSE(RANDBETWEEN(1,5),4,4,4,4,3),IF(X13="İyi",CHOOSE(RANDBETWEEN(1,5),3,3,3,4,2),IF(X13="Yeterli",CHOOSE(RANDBETWEEN(1,5),2,2,2,3,1),IF(X13="Geliştirilmeli",CHOOSE(RANDBETWEEN(1,5),1,1,1,1,2),""))))) | I13: =IF(OR('Öğrenci Listesi'!B14="",X13=""),"",IF(X13="Çok İyi",CHOOSE(RANDBETWEEN(1,5),4,4,4,4,3),IF(X13="İyi",CHOOSE(RANDBETWEEN(1,5),3,3,3,4,2),IF(X13="Yeterli",CHOOSE(RANDBETWEEN(1,5),2,2,2,3,1),IF(X13="Geliştirilmeli",CHOOSE(RANDBETWEEN(1,5),1,1,1,1,2),""))))) | J13: =IF(OR('Öğrenci Listesi'!B14="",X13=""),"",IF(X13="Çok İyi",CHOOSE(RANDBETWEEN(1,5),4,4,4,4,3),IF(X13="İyi",CHOOSE(RANDBETWEEN(1,5),3,3,3,4,2),IF(X13="Yeterli",CHOOSE(RANDBETWEEN(1,5),2,2,2,3,1),IF(X13="Geliştirilmeli",CHOOSE(RANDBETWEEN(1,5),1,1,1,1,2),""))))) | K13: =IF(OR('Öğrenci Listesi'!B14="",X13=""),"",IF(X13="Çok İyi",CHOOSE(RANDBETWEEN(1,5),4,4,4,4,3),IF(X13="İyi",CHOOSE(RANDBETWEEN(1,5),3,3,3,4,2),IF(X13="Yeterli",CHOOSE(RANDBETWEEN(1,5),2,2,2,3,1),IF(X13="Geliştirilmeli",CHOOSE(RANDBETWEEN(1,5),1,1,1,1,2),""))))) | L13: =IF(OR('Öğrenci Listesi'!B14="",X13=""),"",IF(X13="Çok İyi",CHOOSE(RANDBETWEEN(1,5),4,4,4,4,3),IF(X13="İyi",CHOOSE(RANDBETWEEN(1,5),3,3,3,4,2),IF(X13="Yeterli",CHOOSE(RANDBETWEEN(1,5),2,2,2,3,1),IF(X13="Geliştirilmeli",CHOOSE(RANDBETWEEN(1,5),1,1,1,1,2),""))))) | M13: =IF(OR('Öğrenci Listesi'!B14="",X13=""),"",IF(X13="Çok İyi",CHOOSE(RANDBETWEEN(1,5),4,4,4,4,3),IF(X13="İyi",CHOOSE(RANDBETWEEN(1,5),3,3,3,4,2),IF(X13="Yeterli",CHOOSE(RANDBETWEEN(1,5),2,2,2,3,1),IF(X13="Geliştirilmeli",CHOOSE(RANDBETWEEN(1,5),1,1,1,1,2),""))))) | N13: =IF(OR('Öğrenci Listesi'!B14="",X13=""),"",IF(X13="Çok İyi",CHOOSE(RANDBETWEEN(1,5),4,4,4,4,3),IF(X13="İyi",CHOOSE(RANDBETWEEN(1,5),3,3,3,4,2),IF(X13="Yeterli",CHOOSE(RANDBETWEEN(1,5),2,2,2,3,1),IF(X13="Geliştirilmeli",CHOOSE(RANDBETWEEN(1,5),1,1,1,1,2),""))))) | O13: =IF(OR('Öğrenci Listesi'!B14="",X13=""),"",IF(X13="Çok İyi",CHOOSE(RANDBETWEEN(1,5),4,4,4,4,3),IF(X13="İyi",CHOOSE(RANDBETWEEN(1,5),3,3,3,4,2),IF(X13="Yeterli",CHOOSE(RANDBETWEEN(1,5),2,2,2,3,1),IF(X13="Geliştirilmeli",CHOOSE(RANDBETWEEN(1,5),1,1,1,1,2),""))))) | P13: =IF(OR('Öğrenci Listesi'!B14="",X13=""),"",IF(X13="Çok İyi",CHOOSE(RANDBETWEEN(1,5),4,4,4,4,3),IF(X13="İyi",CHOOSE(RANDBETWEEN(1,5),3,3,3,4,2),IF(X13="Yeterli",CHOOSE(RANDBETWEEN(1,5),2,2,2,3,1),IF(X13="Geliştirilmeli",CHOOSE(RANDBETWEEN(1,5),1,1,1,1,2),""))))) | Q13: =IF(OR('Öğrenci Listesi'!B14="",X13=""),"",IF(X13="Çok İyi",CHOOSE(RANDBETWEEN(1,5),4,4,4,4,3),IF(X13="İyi",CHOOSE(RANDBETWEEN(1,5),3,3,3,4,2),IF(X13="Yeterli",CHOOSE(RANDBETWEEN(1,5),2,2,2,3,1),IF(X13="Geliştirilmeli",CHOOSE(RANDBETWEEN(1,5),1,1,1,1,2),""))))) | R13: =IF(OR('Öğrenci Listesi'!B14="",X13=""),"",IF(X13="Çok İyi",CHOOSE(RANDBETWEEN(1,5),4,4,4,4,3),IF(X13="İyi",CHOOSE(RANDBETWEEN(1,5),3,3,3,4,2),IF(X13="Yeterli",CHOOSE(RANDBETWEEN(1,5),2,2,2,3,1),IF(X13="Geliştirilmeli",CHOOSE(RANDBETWEEN(1,5),1,1,1,1,2),""))))) | S13: =IF(OR('Öğrenci Listesi'!B14="",X13=""),"",IF(X13="Çok İyi",CHOOSE(RANDBETWEEN(1,5),4,4,4,4,3),IF(X13="İyi",CHOOSE(RANDBETWEEN(1,5),3,3,3,4,2),IF(X13="Yeterli",CHOOSE(RANDBETWEEN(1,5),2,2,2,3,1),IF(X13="Geliştirilmeli",CHOOSE(RANDBETWEEN(1,5),1,1,1,1,2),""))))) | T13: =IF(OR('Öğrenci Listesi'!B14="",X13=""),"",IF(X13="Çok İyi",CHOOSE(RANDBETWEEN(1,5),4,4,4,4,3),IF(X13="İyi",CHOOSE(RANDBETWEEN(1,5),3,3,3,4,2),IF(X13="Yeterli",CHOOSE(RANDBETWEEN(1,5),2,2,2,3,1),IF(X13="Geliştirilmeli",CHOOSE(RANDBETWEEN(1,5),1,1,1,1,2),""))))) | U13: =IF(OR('Öğrenci Listesi'!B14="",X13=""),"",IF(X13="Çok İyi",CHOOSE(RANDBETWEEN(1,5),4,4,4,4,3),IF(X13="İyi",CHOOSE(RANDBETWEEN(1,5),3,3,3,4,2),IF(X13="Yeterli",CHOOSE(RANDBETWEEN(1,5),2,2,2,3,1),IF(X13="Geliştirilmeli",CHOOSE(RANDBETWEEN(1,5),1,1,1,1,2),""))))) | V13: =IF(OR('Öğrenci Listesi'!B14="",X13=""),"",IF(X13="Çok İyi",CHOOSE(RANDBETWEEN(1,5),4,4,4,4,3),IF(X13="İyi",CHOOSE(RANDBETWEEN(1,5),3,3,3,4,2),IF(X13="Yeterli",CHOOSE(RANDBETWEEN(1,5),2,2,2,3,1),IF(X13="Geliştirilmeli",CHOOSE(RANDBETWEEN(1,5),1,1,1,1,2),""))))) | W13: =IF(OR('Öğrenci Listesi'!B14="",X13=""),"",ROUND(AVERAGE(C13:V13),2)) | X13: =IFERROR(IF('Öğrenci Listesi'!G14="","",IF(UPPER(TRIM('Öğrenci Listesi'!G14))="ÇOK İYİ","Çok İyi",IF(UPPER(TRIM('Öğrenci Listesi'!G14))="İYİ","İyi",IF(UPPER(TRIM('Öğrenci Listesi'!G14))="YETERLİ","Yeterli",IF(UPPER(TRIM('Öğrenci Listesi'!G14))="GELİŞTİRİLMELİ","Geliştirilmeli",'Öğrenci Listesi'!G14))))),"")
